File: CSVs/24-01-08_Tensile_paper-PDMS/Laser_Coated_1/asdf.txt
File Path: C:\Users\apk5101\Desktop\Sandra\Laser_Coated_1 01-8-24 11 12 58 AM\DAQ- Crosshead, … - (Timed).txt
Test: MTS EM Tension (Simplified) with Video Extensometer apk5101 25
Test Run: Laser_Coated_1
Date: 1/8/2024 10:45:34 AM


Crosshead 	Load 	Time 	Strain 1 	Video Time
mm	N	sec	mm/mm	sec
-0.00017867580481834	-1.90872156620026	0.112000003457069	-5.553549999604E-05	4.60860013961792
5.95586016061134E-05	-1.8674772977829	0.211999997496605	-6.52546987112146E-06	4.60860013961792
0.00053602741445502	-1.83433592319489	0.312000006437302	-4.48366990895011E-05	4.69990015029907
0.00148896504015283	-1.7167809009552	0.412000000476837	-4.51570995210204E-05	4.79990005493164
0.00232278534895158	-1.54266679286957	0.512000024318695	7.24120991435484E-06	4.90000009536743
0.00333528168994235	-1.38059461116791	0.611999988555908	4.0927501686383E-05	5.09989976882935
0.00434777803093311	-1.19101202487946	0.712000012397766	4.0927501686383E-05	5.09989976882935
0.00553895006305538	-0.920598983764648	0.811999976634979	1.78561003849609E-05	5.30000019073486
0.0066705633798847	-0.688143134117126	0.912000000476837	6.73647991789039E-06	5.30000019073486
0.00768305926612811	-0.501816213130951	1.01199996471405	7.20637981430627E-05	5.40180015563965
0.00851688037073473	-0.310108244419098	1.11199998855591	4.06813996960409E-05	5.49989986419678
0.00941025882639224	-0.162136167287827	1.21200001239777	7.58558016968891E-05	5.59989976882935
0.0101845207609585	-0.0590404644608498	1.31200003623962	0.000117582996608689	5.79979991912842
0.011197016647202	0.131047904491425	1.41199994087219	0.000117582996608689	5.79979991912842
0.0122690717034857	0.311863124370575	1.51199996471405	0.000191248996998183	5.89989995956421
0.0132220093291835	0.483714699745178	1.61199998855591	0.000187747005838901	5.99989986419678
0.0140558295242954	0.690345942974091	1.71200001239777	0.000156683003297076	6.09989976882935
0.014889650628902	0.834886014461517	1.81200003623962	0.000215299995034002	6.19990015029907
0.0157830290845595	1.00033617019653	1.91199994087219	0.000135259993840009	6.3011999130249
0.0165572910191258	1.1892716884613	2.01200008392334	0.000216072992770933	6.49989986419678
0.0173315529536922	1.28830790519714	2.11199998855591	0.000251227000262588	6.49989986419678
0.0181058148882585	1.40732276439667	2.21199989318848	0.000283319008303806	6.59989976882935
0.018999193343916	1.59566450119019	2.31200003623962	0.000345948006724939	6.7007999420166
0.0201308066607453	1.73568415641785	2.41199994087219	0.00031505900551565	6.79979991912842
0.0208455112442607	1.8864609003067	2.51200008392334	0.000333272007992491	6.99989986419678
0.0216793305298779	2.06048583984375	2.61199998855591	0.000333272007992491	6.99989986419678
0.0226322681555757	2.19888496398926	2.71199989318848	0.000341198989190161	7.19980001449585
0.0232874135690508	2.35774993896484	2.81200003623962	0.000370833004126325	7.19980001449585
0.0241212328546681	2.51041412353516	2.91199994087219	0.000381693011149764	7.29990005493164
0.0251337296504062	2.66299271583557	3.01200008392334	0.000390405999496579	7.39979982376099
0.0259079915849725	2.83168268203735	3.11199998855591	0.000437226990470663	7.5
0.0266226943494985	2.91490721702576	3.21199989318848	0.000418134004576132	7.69980001449585
0.027516072805156	3.0386061668396	3.31200003623962	0.000519824970979244	7.69980001449585
0.0282903347397223	3.21826076507568	3.41199994087219	0.000487339013488963	7.79979991912842
0.0293028315354604	3.38454437255859	3.51200008392334	0.000490773993078619	7.89979982376099
0.0301962099911179	3.55145525932312	3.61199998855591	0.000532299978658557	7.99980020523071
0.0310300310957246	3.76035809516907	3.71199989318848	0.000520889996550977	8.19979953765869
0.0318042912113015	3.87700748443604	3.81200003623962	0.000520889996550977	8.19979953765869
0.0326976733049378	4.03724527359009	3.91199994087219	0.000512772996444255	8.39980030059814
0.0333528150804341	4.17693138122559	4.01200008392334	0.00062535802135244	8.39980030059814
0.0341270788339898	4.24396419525146	4.11199998855591	0.000631029019132257	8.49969959259033
0.0349608999385964	4.39565420150757	4.21199989318848	0.000614641990978271	8.59980010986328
0.0357351600541733	4.53647327423096	4.31199979782104	0.000637745019048452	8.69989967346191
0.0366880994988605	4.67448234558105	4.41200017929077	0.000651990994811058	8.89980030059814
0.0375219169654883	4.86380004882813	4.51200008392334	0.000640133977867663	8.89980030059814
0.0384152990591247	5.04255247116089	4.61199998855591	0.000664443999994546	9.09980010986328
0.0391895591747016	5.15684080123901	4.71199989318848	0.000682177022099495	9.09980010986328
0.0400829376303591	5.32666110992432	4.81199979782104	0.000688004016410559	9.19989967346191
0.0407976403948851	5.43525362014771	4.91200017929077	0.000712072011083364	9.29979991912842
0.0415719041484408	5.5187029838562	5.01200008392334	0.000733368971850723	9.40079975128174
0.0422866069129668	5.65065765380859	5.11199998855591	0.000771138991694897	9.49979972839355
0.0431204280175734	5.76840019226074	5.21199989318848	0.000771954015363008	9.5999002456665
0.04395424912218	5.89797401428223	5.31199979782104	0.000789746001828462	9.70699977874756
0.0448476275778376	6.0947437286377	5.41200017929077	0.000780479982495308	9.79979991912842
0.0457410060334951	6.25524187088013	5.51200008392334	0.000754491018597037	9.89980030059814
0.0466343844891526	6.43088340759277	5.61199998855591	0.000830672972369939	10.0998001098633
0.0474682055937592	6.57803869247437	5.71199989318848	0.000830672972369939	10.0998001098633
0.0482424657093361	6.66866397857666	5.81199979782104	0.00083705602446571	10.1997995376587
0.0490762868139427	6.79524803161621	5.91200017929077	0.000893792021088302	10.3009996414185
0.0498505505674984	6.94703769683838	6.01200008392334	0.000907704001292586	10.3998003005981
0.0506843680341262	7.02805185317993	6.11199998855591	0.000947910011745989	10.4996995925903
0.051458631787682	7.17280101776123	6.21199989318848	0.000966057006735355	10.5998001098633
0.0523520102433395	7.36538314819336	6.31199979782104	0.000966798979789019	10.6997995376587
0.0533049496880267	7.52118015289307	6.41200017929077	0.000952519010752439	10.8179998397827
0.0543770038348157	7.72294569015503	6.51200008392334	0.000921171973459423	10.9997997283936
0.0550917065993417	7.85623073577881	6.61199998855591	0.000933644012548029	10.9997997283936
0.0558064093638677	7.94776296615601	6.71199989318848	0.000959439028520137	11.0996999740601
0.0566997878195252	8.10074234008789	6.81199979782104	0.00100767996627837	11.207799911499
0.0575931662751827	8.23502826690674	6.91200017929077	0.0010515300091356	11.2997999191284
0.0584269873797894	8.34738636016846	7.01200008392334	0.0010735800024122	11.4997997283936
0.0591416901443154	8.4647912979126	7.11199998855591	0.000800844980403781	11.4997997283936
0.0598563929088414	8.5915641784668	7.21199989318848	0.00108761002775282	11.5998001098633
0.0608093323535286	8.76413059234619	7.31199979782104	0.0010843500494957	11.6997995376587
0.0619409474893473	8.98209285736084	7.41200017929077	0.00108803005423397	11.808500289917
0.0627747649559751	9.10951614379883	7.51200008392334	0.00111769000068307	11.9998998641968
0.0636085824226029	9.24722194671631	7.61199998855591	0.00111769000068307	11.9998998641968
0.0643828461761586	9.36797904968262	7.71199989318848	0.00114287005271763	12.1997995376587
0.0652166709187441	9.47320652008057	7.81199979782104	0.000998310977593064	12.1997995376587
0.0659909273963422	9.57305431365967	7.91200017929077	0.00104410003405064	12.2997999191284
0.0668247521389276	9.71549606323242	8.01200008392334	0.00105752004310489	12.3998003005981
0.0675394549034536	9.82325077056885	8.11200046539307	0.00105478998739272	12.5087003707886
0.0681350429658778	9.9243860244751	8.21199989318848	0.00126966997049749	12.5996999740601
0.0690284214215353	10.0989933013916	8.3120002746582	0.00125810003373772	12.6998996734619
0.0699813535902649	10.2608394622803	8.41199970245361	0.00126199994701892	12.8997001647949
0.0709938540239818	10.4365177154541	8.51200008392334	0.00127919996157289	12.8997001647949
0.0717681177775376	10.5236663818359	8.61200046539307	0.00128341000527143	12.9997997283936
0.0725423742551357	10.6596822738647	8.71199989318848	0.00116772996261716	13.1997003555298
0.0734357527107932	10.7748050689697	8.8120002746582	0.00116772996261716	13.1997003555298
0.0741504554753192	10.8801355361938	8.91199970245361	0.00121184997260571	13.3997001647949
0.0749842802179046	10.9754114151001	9.01200008392334	0.00121499004308134	13.3997001647949
0.0757585439714603	11.1111688613892	9.11200046539307	0.00121628004126251	13.4997997283936
0.0766519224271178	11.2952108383179	9.21199989318848	0.00152875005733222	13.5996999740601
0.0774857398937456	11.436728477478	9.3120002746582	0.00142601004336029	13.6997003555298
0.0784982330515049	11.5952577590942	9.41199970245361	0.0014077799860388	13.7997999191284
0.0795107334852219	11.7590789794922	9.51200008392334	0.00144629005808383	13.9062995910645
0.0802254362497479	11.866307258606	9.61200046539307	0.00129973003640771	14.1073999404907
0.0809997000033036	11.9443874359131	9.71199989318848	0.0013520399807021	14.1073999404907
0.0817144027678296	12.0388145446777	9.8120002746582	0.00137210998218507	14.1997003555298
0.0824886592454277	12.1596431732178	9.91199970245361	0.00136930996086448	14.3015003204346
0.0832033620099537	12.2689781188965	10.0120000839233	0.00137092999648303	14.3997001647949
0.0840371867525391	12.3900842666626	10.1120004653931	0.00136918004136533	14.5996999740601
0.0850496799102984	12.5703277587891	10.2119998931885	0.00158021994866431	14.5996999740601
0.0858835046528839	12.7100114822388	10.3120002746582	0.00158449995797127	14.6997995376587
0.0867768831085414	12.8183832168579	10.4119997024536	0.00142095994669944	14.7996997833252
0.0875511468620971	12.9139642715454	10.5120000839233	0.00145115004852414	14.8997001647949
0.0883254033396952	12.9977283477783	10.6120004653931	0.00148065004032105	15.0996999740601
0.0892187817953527	13.1092319488525	10.7119998931885	0.00148065004032105	15.0996999740601
0.0900526065379381	13.2288875579834	10.8120002746582	0.00150608003605157	15.2996997833252
0.0907673093024641	13.3213443756104	10.9119997024536	0.00151984998956323	15.2996997833252
0.0917798024602234	13.4934301376343	11.0120000839233	0.00152513000648469	15.4071998596191
0.0924945052247494	13.6072463989258	11.1120004653931	0.00154674996156245	15.4996995925903
0.0931496542762034	13.7036609649658	11.2119998931885	0.00154503004159778	15.608699798584
0.0943408231250942	13.8746118545532	11.3120002746582	0.00155817996710539	15.799599647522
0.0949959721765481	13.951563835144	11.4119997024536	0.00159144005738199	15.799599647522
0.0959489043452777	14.0689134597778	11.5120000839233	0.00163231999613345	15.9996995925903
0.0968422828009352	14.1909866333008	11.6120004653931	0.00165413995273411	15.9996995925903
0.0976761075435206	14.2937650680542	11.7119998931885	0.00166483002249151	16.0997009277344
0.0984503640211187	14.4070062637329	11.8120002746582	0.00166048994287848	16.2024993896484
0.0992246277746744	14.5137825012207	11.9119997024536	0.00168975000269711	16.3076992034912
0.0999988915282302	14.6419448852539	12.0120000839233	0.00170890998560935	16.3997001647949
0.100832708994858	14.7468690872192	12.1120004653931	0.00169444002676755	16.4997005462646
0.101726087450515	14.8617000579834	12.2119998931885	0.00171600002795458	16.6081008911133
0.102679026895203	14.963568687439	12.3120002746582	0.00173904001712799	16.6996994018555
0.10363196633989	15.087836265564	12.4119997024536	0.00177463004365563	16.7996997833252
0.104406230093446	15.1438770294189	12.5120000839233	0.00180468999315053	16.9997005462646
0.105240047560073	15.2541027069092	12.6120004653931	0.00183530000504106	16.9997005462646
0.106073865026701	15.3540868759155	12.7119998931885	0.00184476003050804	17.1996994018555
0.106669453089125	15.4307680130005	12.8120002746582	0.00186276994645596	17.1996994018555
0.107443716842681	15.5277547836304	12.9119997024536	0.00183964997995645	17.2996997833252
0.108217980596237	15.6389770507813	13.0120000839233	0.0018457300029695	17.3997001647949
0.109111359051894	15.76185131073	13.1120004653931	0.00186118995770812	17.4997005462646
0.110123852209654	15.8736486434937	13.2119998931885	0.00188412005081773	17.5995998382568
0.111136352643371	16.0142288208008	13.3120002746582	0.00190032995305955	17.6996002197266
0.111791494418867	16.0617408752441	13.4119997024536	0.00192645995412022	17.7996997833252
0.112982663267758	16.2165641784668	13.5120000839233	0.00204891990870237	17.8997001647949
0.11345913662808	16.2584991455078	13.6120004653931	0.00198029004968703	17.9995994567871
0.113876041723415	16.3042221069336	13.7119998931885	0.00199624011293054	18.0995998382568
0.114828981168102	16.4505615234375	13.8120002746582	0.00202147010713816	18.1996002197266
0.115841481601819	16.6089153289795	13.9119997024536	0.00203231000341475	18.2996997833252
0.116615738079417	16.7087287902832	14.0120000839233	0.00205309991724789	18.3997001647949
0.117390001832973	16.7834281921387	14.1120004653931	0.00207116990350187	18.4995994567871
0.11834294127766	16.8864612579346	14.2119998931885	0.00213287002407014	18.5995998382568
0.119295880722348	16.9891586303711	14.3120002746582	0.00214843009598553	18.6996002197266
0.120070137199946	17.0639495849609	14.4119997024536	0.00216405000537634	18.7996006011963
0.120903961942531	17.1801338195801	14.5120000839233	0.0021798200905323	18.8995990753174
0.121797340398189	17.2870960235596	14.6120004653931	0.00217048008926213	19.0995006561279
0.122571596875787	17.4016094207764	14.7119998931885	0.00219296989962459	19.0995006561279
0.123464982607402	17.5153789520264	14.8120002746582	0.00218611001037061	19.1996002197266
0.124239246360958	17.6278820037842	14.9119997024536	0.00219246000051498	19.2996006011963
0.125132617540658	17.7057113647461	15.0120000839233	0.00221673003397882	19.3995990753174
0.126026003272273	17.7438144683838	15.1120004653931	0.00226193992421031	19.4995994567871
0.126859813462943	17.7272968292236	15.2119998931885	0.00227284990251064	19.5995998382568
0.127872321172617	17.6883811950684	15.3120002746582	0.00228577991947532	19.7996006011963
0.128884814330377	17.6889095306396	15.4119997024536	0.00230660010129213	19.7996006011963
0.129539956105873	17.663064956665	15.5120000839233	0.00233027990907431	19.8995990753174
0.130195097881369	17.5987854003906	15.6120004653931	0.00233895005658269	20.0995998382568
0.131088483612984	17.5338191986084	15.7119998931885	0.00233895005658269	20.0995998382568
0.13186274736654	17.4536533355713	15.8120002746582	0.00239065010100603	20.2996006011963
0.13275611854624	17.3527317047119	15.9119997024536	0.00239136000163853	20.2996006011963
0.133530382299796	17.0891933441162	16.011999130249	0.00242790998890996	20.3997993469238
0.134483314468525	16.6690158843994	16.1119995117188	0.00245623989030719	20.4995994567871
0.135317139211111	15.9734134674072	16.2119998931885	0.00247704004868865	20.5995998382568
0.136150963953696	15.3966617584229	16.3120002746582	0.00251496001146734	20.7994995117188
0.136984788696282	15.1349611282349	16.4120006561279	0.00253126001916826	20.7994995117188
0.137759037897922	14.9706478118896	16.511999130249	0.00254326988942921	20.9995002746582
0.138533301651478	14.7446966171265	16.6119995117188	0.00256583001464605	20.9995002746582
0.139307565405034	14.1452331542969	16.7119998931885	0.00259287003427744	21.0995998382568
0.140081829158589	13.2788095474243	16.8120002746582	0.00268842000514269	21.199499130249
0.140975214890204	12.4414730072021	16.9120006561279	0.00275682006031275	21.3083992004395
0.141868586069904	10.9616775512695	17.011999130249	0.00289243995212018	21.3994998931885
0.14270241081249	9.46432781219482	17.1119995117188	0.0030113800894469	21.5144004821777
0.143536235555075	8.46798038482666	17.2119998931885	0.00335699995048344	21.699499130249
0.144429606734775	7.68337154388428	17.3120002746582	0.00382070010527968	21.699499130249
0.14526343147736	7.27223587036133	17.4120006561279	0.00397490989416838	21.7996006011963
0.145978134241886	6.90794277191162	17.511999130249	0.00421212008222938	21.8994998931885
0.146752397995442	6.25397348403931	17.6119995117188	0.00444532977417111	22.0004005432129
0.147586208186112	5.60994482040405	17.7119998931885	0.00480647990480065	22.1996002197266
0.148420032928698	4.91191911697388	17.8120002746582	0.0050542401149869	22.1996002197266
0.149134735693224	4.14948320388794	17.9120006561279	0.00530544016510248	22.2994995117188
0.149908999446779	3.82499432563782	18.011999130249	0.00526158977299929	22.3994998931885
0.150683263200335	3.61813473701477	18.1119995117188	0.00546535989269614	22.4995002746582
0.151576634380035	3.41915202140808	18.2119998931885	0.0055770599283278	22.5995006561279
0.152648688526824	3.2571268081665	18.3120002746582	0.00589367980137467	22.699499130249
0.15342295228038	3.00542068481445	18.4120006561279	0.00600126991048455	22.8995990753174
0.154197216033936	2.71995878219604	18.511999130249	0.00610426021739841	22.8995990753174
0.155090601765551	2.48839497566223	18.6119995117188	0.00625703996047378	22.9995002746582
0.155805304530077	2.30009126663208	18.7119998931885	0.00643419986590743	23.0995006561279
0.156520007294603	2.12225008010864	18.8120002746582	0.00664696982130408	23.1996002197266
0.157413378474303	1.98555970191956	18.9120006561279	0.00681074010208249	23.2994995117188
0.158068520249799	1.75664484500885	19.011999130249	0.00691741984337568	23.4006004333496
0.158128081238829	1.75926637649536	19.0139999389648	0.00691741984337568	23.4006004333496