File: CSVs/24-01-08_Tensile_paper-PDMS/Laser_Uncoated_3/asdf.txt
File Path: C:\Users\apk5101\Desktop\Sandra\Laser_Uncoated_3 01-8-24 11 12 58 AM\DAQ- Crosshead, … - (Timed).txt
Test: MTS EM Tension (Simplified) with Video Extensometer apk5101 25
Test Run: Laser_Uncoated_3
Date: 1/8/2024 10:42:28 AM


Crosshead 	Load 	Time 	Strain 1 	Video Time
mm	N	sec	mm/mm	sec
-0.000297793008030567	-0.0652844831347466	0.112000003457069	1.58750008267816E-05	5.59989976882935
0	-0.0725491791963577	0.211999997496605	1.58750008267816E-05	5.71339988708496
0.000476468812848907	0.00544917536899447	0.312000006437302	4.42220007244032E-05	5.79990005493164
0.00125073063372838	0.178067952394485	0.412000000476837	4.91011996928137E-05	5.89989995956421
0.00214410965782008	0.302794903516769	0.512000024318695	8.5647996456828E-05	5.99980020523071
0.0032757229746494	0.490452378988266	0.611999988555908	8.08753975434229E-05	6.09989976882935
0.00416910188505426	0.653174102306366	0.712000012397766	8.08753975434229E-05	6.19990015029907
0.00553895006305538	0.884159445762634	0.811999976634979	9.91980996332131E-05	6.29990005493164
0.00661100466459175	1.04796612262726	0.912000000476837	9.91980996332131E-05	6.42729997634888
0.00762350100558251	1.24647057056427	1.01199996471405	0.000141866999911144	6.49989986419678
0.00851688037073473	1.43657028675079	1.11199998855591	0.000160818002768792	6.59980010986328
0.00941025882639224	1.61815857887268	1.21200001239777	0.000116925002657808	6.69990015029907
0.0103036381915445	1.79279983043671	1.31200003623962	0.000172082000062801	6.79979991912842
0.011197016647202	1.95961141586304	1.41199994087219	0.000229954996029846	6.89989995956421
0.0122095134429401	2.13408255577087	1.51199996471405	0.00019421600154601	6.99980020523071
0.0131624510686379	2.30767750740051	1.61199998855591	0.000284790992736816	7.09989976882935
0.0141153886943357	2.43795251846313	1.71200001239777	0.000267090013949201	7.19999980926514
0.0149492088894476	2.56154441833496	1.81200003623962	0.000228498000069521	7.29990005493164
0.0157830290845595	2.69972681999207	1.91199994087219	0.000228498000069521	7.39979982376099
0.0165572910191258	2.85090112686157	2.01200008392334	0.000256616011029109	7.49980020523071
0.0173315529536922	2.99327111244202	2.11199998855591	0.000174489003256895	7.59980010986328
0.0181058148882585	3.15634155273438	2.21199989318848	0.000225180003326386	7.69990015029907
0.0191778690350475	3.3494508266449	2.31200003623962	0.000179266993654892	7.79990005493164
0.0201308066607453	3.53801155090332	2.41199994087219	0.000292585988063365	7.89979982376099
0.0207263929041801	3.62607073783875	2.51200008392334	0.000339074991643429	7.99980020523071
0.0218580062210094	3.78394412994385	2.61199998855591	0.000693194975610822	8.09980010986328
0.0226322681555757	3.90419983863831	2.71199989318848	0.000390945991966873	8.19979953765869
0.0231087378779193	3.96654844284058	2.81200003623962	0.000427071994636208	8.29979991912842
0.0241807920247084	4.14079570770264	2.91199994087219	0.000452078005764633	8.39980030059814
0.0251932888204465	4.33688640594482	3.01200008392334	0.000424208992626518	8.50339984893799
0.0258484324149322	4.47065496444702	3.11199998855591	0.000424208992626518	8.59980010986328
0.0266822535195388	4.63687896728516	3.21199989318848	0.000715103989932686	8.69989967346191
0.027516072805156	4.77384996414185	3.31200003623962	0.000241501998971216	8.79979991912842
0.0282903347397223	4.8970890045166	3.41199994087219	0.0004298810090404	8.89980030059814
0.0293028315354604	5.03953075408936	3.51200008392334	0.000424005993409082	8.99979972839355
0.0301962099911179	5.1688814163208	3.61199998855591	0.000923299987334758	9.09980010986328
0.0309704737446737	5.30580282211304	3.71199989318848	0.000402450008550659	9.19979953765869
0.0318638522003312	5.44769430160522	3.81200003623962	0.000402450008550659	9.29979991912842
0.0326381123159081	5.60426235198975	3.91199994087219	0.000508334022015333	9.39980030059814
0.0334123760694638	5.76786231994629	4.01200008392334	0.000806470983661711	9.49979972839355
0.0341270788339898	5.88320112228394	4.11199998855591	0.000510967976879328	9.59980010986328
0.0349608999385964	6.02848529815674	4.21199989318848	0.000539784028660506	9.69979953765869
0.0357351600541733	6.17176342010498	4.31199979782104	0.000528701988514513	9.79979991912842
0.0366285385098308	6.29790639877319	4.41200017929077	0.000552824989426881	9.89980030059814
0.037581477954518	6.4345383644104	4.51200008392334	0.000558545987587422	9.99979972839355
0.038355738070095	6.53093671798706	4.61199998855591	0.00052638998022303	10.0998001098633
0.0393086775147822	6.69741153717041	4.71199989318848	0.000581799016799778	10.1997995376587
0.0400829376303591	6.83038282394409	4.81199979782104	0.000623365980572999	10.2997999191284
0.0408572013839148	6.98774909973145	4.91200017929077	0.000661607016809285	10.3997001647949
0.0415719041484408	7.10566186904907	5.01200008392334	0.000649479974526912	10.4996995925903
0.0422270495619159	7.23138093948364	5.11199998855591	0.000646655971650034	10.5996999740601
0.0431204280175734	7.35895729064941	5.21199989318848	0.000655971991363913	10.6997995376587
0.04395424912218	7.49618339538574	5.31199979782104	0.000696262985002249	10.8009996414185
0.0448476275778376	7.61609649658203	5.41200017929077	0.000670322973746806	10.8997001647949
0.045800563384546	7.73806858062744	5.51200008392334	0.000673744012601674	10.9996995925903
0.0466343844891526	7.86913776397705	5.61199998855591	0.000713612011168152	11.0996999740601
0.0475277629448101	8.00160312652588	5.71199989318848	0.000713612011168152	11.1997003555298
0.0482424657093361	8.15498638153076	5.81199979782104	0.000747992016840726	11.2997999191284
0.0490762868139427	8.31400012969971	5.91200017929077	0.000751184998080134	11.3997001647949
0.0499101079185493	8.44519138336182	6.01200008392334	0.000736783025786281	11.4996995925903
0.0506843680341262	8.57147312164307	6.11199998855591	0.000815093982964754	11.5996999740601
0.051458631787682	8.66779041290283	6.21199989318848	0.000880985986441374	11.6997995376587
0.0523520102433395	8.79698371887207	6.31199979782104	0.000895594013854861	11.7996997833252
0.0533049496880267	8.93940448760986	6.41200017929077	0.000924509018659592	11.8997001647949
0.0543770038348157	9.10029125213623	6.51200008392334	0.00089904002379626	11.9996995925903
0.0550917065993417	9.22597503662109	6.61199998855591	0.000885055982507765	12.0996999740601
0.0559255277039483	9.35991954803467	6.71199989318848	0.00090256001567468	12.1997003555298
0.0566997878195252	9.49362945556641	6.81199979782104	0.000888706999830902	12.2996997833252
0.0575336089241318	9.64453220367432	6.91200017929077	0.000858299026731402	12.3997001647949
0.0583078690397087	9.77232360839844	7.01200008392334	0.00092595600290224	12.4996995925903
0.0591416901443154	9.87524223327637	7.11199998855591	0.000943252991419286	12.5996999740601
0.0598563929088414	9.9760160446167	7.21199989318848	0.000908308022189885	12.6997003555298
0.0608688897045795	10.1177206039429	7.31199979782104	0.000971051980741322	12.8104000091553
0.0618813865003176	10.2638654708862	7.41200017929077	0.000934923009481281	12.8997001647949
0.0627747649559751	10.415319442749	7.51200008392334	0.000995213980786502	12.9996995925903
0.0636681434116326	10.5486793518066	7.61199998855591	0.000993244000710547	13.0996999740601
0.0644424071651883	10.6764812469482	7.71199989318848	0.00095637101912871	13.1997003555298
0.0652762246318161	10.8272352218628	7.81199979782104	0.000998731004074216	13.2996997833252
0.0659909273963422	10.9347877502441	7.91200017929077	0.00105884997174144	13.3998003005981
0.0667651911498979	11.0539541244507	8.01200008392334	0.00106327002868056	13.5151996612549
0.0674798939144239	11.1331777572632	8.11200046539307	0.00113135005813092	13.6281003952026
0.0681350429658778	11.2030467987061	8.21199989318848	0.00114827998913825	13.7151002883911
0.0690284214215353	11.3045501708984	8.3120002746582	0.00113200000487268	13.7996997833252
0.0700409145792946	11.4826822280884	8.41199970245361	0.00113144004717469	13.8996000289917
0.0709938540239818	11.6372022628784	8.51200008392334	0.0011445899726823	13.9996995925903
0.0717085567885078	11.76735496521	8.61200046539307	0.00113023002631962	14.0996999740601
0.0725423742551357	11.8966178894043	8.71199989318848	0.00121619005221874	14.1997003555298
0.0734953136998229	12.0571308135986	8.8120002746582	0.00145880004856735	14.2996997833252
0.0740909017622471	12.1199588775635	8.91199970245361	0.00154195004142821	14.3998003005981
0.0749247192288749	12.2226934432983	9.01200008392334	0.00150332995690405	14.5037002563477
0.0757585439714603	12.3288908004761	9.11200046539307	0.00148950994480401	14.5996999740601
0.0766519224271178	12.4490976333618	9.21199989318848	0.00162305997218937	14.6997995376587
0.0774261789047159	12.5495309829712	9.3120002746582	0.00127225997857749	14.7996997833252
0.0783791183494031	12.7050313949585	9.41199970245361	0.00132396002300084	14.9059000015259
0.0794511724961922	12.8928985595703	9.51200008392334	0.00156052003148943	14.9996995925903
0.0802849972387776	13.0120153427124	9.61200046539307	0.00163970002904534	15.1034002304077
0.0809401390142739	13.1001310348511	9.71199989318848	0.00165463995654136	15.1997003555298
0.0817144027678296	13.2069730758667	9.8120002746582	0.0016242100391537	15.3001003265381
0.0824886592454277	13.2898969650269	9.91199970245361	0.00161183997988701	15.3998003005981
0.0832033620099537	13.3729591369629	10.0120000839233	0.00162885000463575	15.4996004104614
0.0840967477415688	13.4826498031616	10.1120004653931	0.00158835004549474	15.5996999740601
0.0849901261972263	13.6007261276245	10.2119998931885	0.00158835004549474	15.7073001861572
0.0858835046528839	13.7487268447876	10.3120002746582	0.00166454003192484	15.7996997833252
0.0867768831085414	13.8654985427856	10.4119997024536	0.0016804599436	15.8996000289917
0.0875511468620971	14.0003929138184	10.5120000839233	0.00173885002732277	15.9996995925903
0.0883254033396952	14.1234245300293	10.6120004653931	0.0017222500173375	16.0997009277344
0.0892187817953527	14.2392206192017	10.7119998931885	0.00167359004262835	16.1996002197266
0.0900526065379381	14.337363243103	10.8120002746582	0.00174434005748481	16.2996997833252
0.0907673093024641	14.394645690918	10.9119997024536	0.00172467995434999	16.4120998382568
0.0918393634492531	14.5419616699219	11.0120000839233	0.00176460004877299	16.5041999816895
0.0923753905226476	14.6038408279419	11.1120004653931	0.0018162700580433	16.5995998382568
0.0932092079892755	14.6882963180542	11.2119998931885	0.00182674999814481	16.6996994018555
0.0942812621360645	14.8976545333862	11.3120002746582	0.00188574998173863	16.7996997833252
0.0948768501984887	14.9766216278076	11.4119997024536	0.00189792003948241	16.8995990753174
0.0960084653343074	15.1512460708618	11.5120000839233	0.00190252996981144	16.9997005462646
0.0969018437899649	15.2903699874878	11.6120004653931	0.00153957994189113	17.0995998382568
0.0976761075435206	15.371376991272	11.7119998931885	0.00153807003516704	17.1996994018555
0.0985099250101484	15.4555578231812	11.8120002746582	0.00154345005284995	17.2996997833252
0.0992841887637042	15.5362300872803	11.9119997024536	0.00195118994452059	17.3997001647949
0.0999988915282302	15.6080017089844	12.0120000839233	0.0019492000574246	17.4997005462646
0.100832708994858	15.7083177566528	12.1120004653931	0.00193749996833503	17.5997009277344
0.101785648439545	15.8619327545166	12.2119998931885	0.00194619002286345	17.6996002197266
0.102738587884232	16.0112342834473	12.3120002746582	0.00198135990649462	17.7996006011963
0.10363196633989	16.135232925415	12.4119997024536	0.00170644000172615	17.8997001647949
0.104406230093446	16.2343654632568	12.5120000839233	0.001622169977054	17.9995994567871
0.105299608549103	16.3484859466553	12.6120004653931	0.00173687003552914	18.0995998382568
0.106014311313629	16.4044704437256	12.7119998931885	0.00186852994374931	18.1996994018555
0.106669453089125	16.4567546844482	12.8120002746582	0.00173951999749988	18.2996006011963
0.107443716842681	16.5298309326172	12.9119997024536	0.00170817994512618	18.3995990753174
0.108217980596237	16.6229286193848	13.0120000839233	0.002411870053038	18.4995994567871
0.109111359051894	16.7510318756104	13.1120004653931	0.00227767997421324	18.5995998382568
0.110242966911756	16.9099864959717	13.2119998931885	0.0017533500213176	18.6996002197266
0.111076791654341	17.0402908325195	13.3120002746582	0.00176242005545646	18.7996006011963
0.111731933429837	17.1265830993652	13.4119997024536	0.00177239999175072	18.8995990753174
0.112923109554686	17.2771224975586	13.5120000839233	0.00183027004823089	18.9995994567871
0.11339957563905	17.3094787597656	13.6120004653931	0.00185412005521357	19.0998001098633
0.113935602712445	17.3230171203613	13.7119998931885	0.00182398001197726	19.1996002197266
0.114888542157132	17.4416027069092	13.8120002746582	0.00181923003401607	19.2996997833252
0.11578192061279	17.5848598480225	13.9119997024536	0.00184147001709789	19.3995990753174
0.116615738079417	17.6679534912109	14.0120000839233	0.00185511994641274	19.4997005462646
0.117449562822003	17.7917957305908	14.1120004653931	0.00187982001807541	19.5995998382568
0.118283380288631	17.9125957489014	14.2119998931885	0.00193256000056863	19.6996002197266
0.119236319733318	18.0444793701172	14.3120002746582	0.00188561994582415	19.7996006011963
0.120189259178005	18.1748905181885	14.4119997024536	0.00190147000830621	19.8995990753174
0.120903961942531	18.2578639984131	14.5120000839233	0.00197317008860409	19.9995994567871
0.121678218420129	18.323558807373	14.6120004653931	0.00201149005442858	20.0995998382568
0.122631157864816	18.4136371612549	14.7119998931885	0.00201275991275907	20.1996002197266
0.123464982607402	18.5111103057861	14.8120002746582	0.00196724990382791	20.2996997833252
0.124239246360958	18.6087894439697	14.9119997024536	0.00200094003230333	20.3995990753174
0.125073056551628	18.7242679595947	15.0120000839233	0.00200495007447898	20.4995002746582
0.126085564261302	18.8745632171631	15.1120004653931	0.00206279009580612	20.5995006561279
0.126919374451973	18.9893093109131	15.2119998931885	0.00203660991974175	20.699499130249
0.127812760183588	19.1007957458496	15.3120002746582	0.00239847996272147	20.7996006011963
0.128765692352317	19.2090892791748	15.4119997024536	0.0024747799616307	20.8995990753174
0.129480395116843	19.2658958435059	15.5120000839233	0.00249609001912177	20.9995994567871
0.130314219859429	19.3461399078369	15.6120004653931	0.00208392995409667	21.0995998382568
0.131028922623955	19.4020004272461	15.7119998931885	0.00203832006081939	21.1996002197266
0.13192230835557	19.5169525146484	15.8120002746582	0.00210598995909095	21.2996006011963
0.13269655755721	19.6213684082031	15.9119997024536	0.00210461998358369	21.3994998931885
0.133530382299796	19.7252559661865	16.011999130249	0.00221044989302754	21.4995994567871
0.134423768031411	19.8585109710693	16.1119995117188	0.00239405990578234	21.5995006561279
0.13537670020014	19.9733467102051	16.2119998931885	0.00237950007431209	21.6996002197266
0.136270085931756	20.068452835083	16.3120002746582	0.00246700993739069	21.7994995117188
0.136984788696282	20.1385345458984	16.4120006561279	0.00246700993739069	21.8997993469238
0.137759037897922	20.1911563873291	16.511999130249	0.0025044500362128	21.9995994567871
0.138592862640508	20.2987022399902	16.6119995117188	0.00257721007801592	22.0995998382568
0.139307565405034	20.3604145050049	16.7119998931885	0.00259596994146705	22.199499130249
0.140081829158589	20.4485740661621	16.8120002746582	0.00259932992048562	22.2994995117188
0.140915653901175	20.565616607666	16.9120006561279	0.00259147002361715	22.3995990753174
0.141809025080875	20.6921253204346	17.011999130249	0.00258015003055334	22.4995994567871
0.14264284982346	20.8136081695557	17.1119995117188	0.00258015003055334	22.5995998382568
0.143536235555075	20.9014739990234	17.2119998931885	0.00258933007717133	22.6996002197266
0.144429606734775	20.9834423065186	17.3120002746582	0.00258034002035856	22.7994995117188
0.14526343147736	21.0618171691895	17.4120006561279	0.00262234010733664	22.8997993469238
0.145918573252857	21.1121940612793	17.511999130249	0.00266728992573917	22.9995994567871
0.146752397995442	21.2006912231445	17.6119995117188	0.00266728992573917	23.0995006561279
0.147586208186112	21.3023738861084	17.7119998931885	0.00266911997459829	23.1996002197266
0.148360471939668	21.4112186431885	17.8120002746582	0.00266911997459829	23.2994995117188
0.149194296682253	21.5336666107178	17.9120006561279	0.00271214009262621	23.3995990753174
0.149908999446779	21.5735530853271	18.011999130249	0.00271156989037991	23.4995002746582
0.150623702211305	21.6488800048828	18.1119995117188	0.00242853001691401	23.5995006561279
0.151695756358095	21.7635250091553	18.2119998931885	0.0024293300230056	23.699499130249
0.152648688526824	21.8731212615967	18.3120002746582	0.00279738008975983	23.7994995117188
0.15342295228038	21.9308376312256	18.4120006561279	0.00272178999148309	23.8994998931885
0.154197216033936	21.9978580474854	18.511999130249	0.00284016993828118	23.9995002746582
0.155031040776521	22.1068096160889	18.6119995117188	0.00277272006496787	24.0995006561279
0.155805304530077	22.2067031860352	18.7119998931885	0.00281025003641844	24.199499130249
0.156579568283632	22.2984409332275	18.8120002746582	0.00249063991941512	24.2994995117188
0.157353817485273	22.3935947418213	18.9120006561279	0.00255073001608253	24.3994998931885
0.158068520249799	22.4656829833984	19.011999130249	0.00261764996685088	24.4995002746582
0.158902344992384	22.5543479919434	19.1119995117188	0.00259388005360961	24.5993995666504
0.15973616973497	22.6262073516846	19.2119998931885	0.00262005999684334	24.699499130249
0.160748662892729	22.7438831329346	19.3120002746582	0.00258018006570637	24.7994995117188
0.161642048624344	22.8327770233154	19.4120006561279	0.00265143997967243	24.8994998931885
0.16235675138887	22.8987789154053	19.511999130249	0.00266728992573917	24.9995002746582
0.16319056157954	22.9911842346191	19.6119995117188	0.00263418001122773	25.0998001098633
0.163905264344066	23.0768203735352	19.7119998931885	0.0026942000258714	25.199499130249
0.164739089086652	23.1970462799072	19.8120002746582	0.00267930002883077	25.2994995117188
0.165632474818267	23.2949333190918	19.9120006561279	0.00269591994583607	25.3994998931885
0.166525845997967	23.3919887542725	20.011999130249	0.00273752002976835	25.5004005432129
0.167300109751523	23.4534454345703	20.1119995117188	0.00272170989774168	25.5995006561279
0.168074373505078	23.5165996551514	20.2119998931885	0.00272170989774168	25.699499130249
0.169146427651867	23.6355819702148	20.3120002746582	0.0028033300768584	25.7996006011963
0.169980252394453	23.7234992980957	20.4120006561279	0.00278211990371346	25.8994998931885
0.170873623574153	23.8438205718994	20.511999130249	0.00281304004602134	25.9995002746582
0.171588326338679	23.9244823455811	20.6119995117188	0.00280708004720509	26.1004009246826
0.172422151081264	24.0248203277588	20.7119998931885	0.00279882992617786	26.1993999481201
0.173375083249994	24.1340770721436	20.8120002746582	0.00306342006660998	26.2994995117188
0.174268468981609	24.2206420898438	20.9120006561279	0.00310584995895624	26.3994998931885
0.175280962139368	24.3282051086426	21.011999130249	0.00312809995375574	26.4995002746582
0.176174347870983	24.3944854736328	21.1119995117188	0.00324017996899784	26.5995006561279
0.177127280039713	24.5211696624756	21.2119998931885	0.00326865003444254	26.6993999481201
0.177961104782298	24.5948162078857	21.3120002746582	0.00292716990225017	26.7994995117188
0.178735368535854	24.676944732666	21.4120006561279	0.00295800995081663	26.8994998931885
0.17945007130038	24.7661666870117	21.511999130249	0.00319240009412169	26.9993991851807
0.18028388149105	24.8722400665283	21.6119995117188	0.00320923002436757	27.0993995666504
0.181177267222665	24.9924755096436	21.7119998931885	0.00320612988434732	27.1993999481201
0.181951530976221	25.0375919342041	21.8120002746582	0.00321857002563775	27.2994003295898
0.182547111762688	25.0813636779785	21.9120006561279	0.0032296699937433	27.3994007110596
0.183738287887536	25.2088069915771	22.011999130249	0.00321348989382386	27.4993991851807
0.184452990652062	25.2600135803223	22.1119995117188	0.00331663992255926	27.5993995666504
0.185108132427558	25.3146877288818	22.2119998931885	0.0033049900084734	27.6993999481201
0.186061064596288	25.4320201873779	22.3120002746582	0.00330825010314584	27.7994995117188
0.186954450327903	25.555025100708	22.4120006561279	0.00335109001025558	27.8994007110596
0.187609592103399	25.6044025421143	22.511999130249	0.00341450003907084	27.9993991851807
0.188383855856955	25.6920375823975	22.6119995117188	0.00334107992239296	28.0993995666504
0.189158119610511	25.7833423614502	22.7119998931885	0.00344652007333934	28.1993999481201
0.19011105177924	25.8702430725098	22.8120002746582	0.00344929005950689	28.2994995117188
0.190885315532796	25.9029655456543	22.9120006561279	0.00341052003204823	28.3994007110596
0.191778701264411	25.9872303009033	23.011999130249	0.00346197001636028	28.4993991851807
0.192612511455081	26.0720901489258	23.1119995117188	0.00341025996021926	28.5993995666504
0.193505897186697	26.171365737915	23.2119998931885	0.00342230009846389	28.6993999481201
0.194339721929282	26.281702041626	23.3120002746582	0.00342230009846389	28.7994995117188
0.195173532119952	26.3865394592285	23.4120006561279	0.00347608001902699	28.899299621582
0.195828673895448	26.4467086791992	23.511999130249	0.00347608001902699	28.9995002746582
0.196662498638034	26.5394992828369	23.6119995117188	0.00356193003244698	29.0995006561279
0.197555884369649	26.5996799468994	23.7119998931885	0.00357597996480763	29.1993999481201
0.198211026145145	26.6242179870605	23.8120002746582	0.00363111007027328	29.2994003295898
0.199104397324845	26.7230377197266	23.9120006561279	0.00361392996273935	29.3994007110596
0.199938222067431	26.7917633056641	24.011999130249	0.00365812005475163	29.4993991851807
0.201188959181309	26.9620780944824	24.1119995117188	0.00368408998474479	29.5993995666504
0.201724978978746	26.9962596893311	24.2119998931885	0.00371316005475819	29.6993007659912
0.202558803721331	27.0956497192383	24.3120002746582	0.00377759011462331	29.7994003295898
0.203452174901031	27.2129573822021	24.4120006561279	0.00378194008953869	29.8994007110596
0.203869087272324	27.2366771697998	24.511999130249	0.00379069009795785	29.9993991851807
0.204643351025879	27.2951793670654	24.6119995117188	0.00381821999326348	30.0993995666504
0.205715405172668	27.4092044830322	24.7119998931885	0.00371637009084225	30.1993999481201
0.206608790904284	27.4738140106201	24.8120002746582	0.0037233498878777	30.2992992401123
0.207442601094954	27.5462055206299	24.9120006561279	0.00377636007033288	30.3994007110596
0.208395547815599	27.6424884796143	25.011999130249	0.00377273000776768	30.4997005462646
0.209288918995298	27.7415008544922	25.1119995117188	0.00379178998991847	30.5993995666504
0.210182304726914	27.8574333190918	25.2119998931885	0.00380088994279504	30.6993999481201
0.210956568480469	27.9456634521484	25.3120002746582	0.00378853990696371	30.7994003295898
0.211730832234025	28.0143661499023	25.4120006561279	0.00385509990155697	30.8994007110596
0.212505081435665	28.0816402435303	25.511999130249	0.00388575997203588	30.9993991851807
0.213279345189221	28.132942199707	25.6119995117188	0.00387945002876222	31.0993003845215
0.214172730920836	28.2076110839844	25.7119998931885	0.00386099005118012	31.1993007659912
0.215006555663422	28.2710742950439	25.8120002746582	0.00396801019087434	31.2992992401123
0.215959487832151	28.3615493774414	25.9120006561279	0.00399558991193771	31.399299621582
0.216912420000881	28.4856452941895	26.011999130249	0.0039913197979331	31.4993000030518
0.217805805732496	28.6012725830078	26.1119995117188	0.00399461993947625	31.5993003845215
0.218639630475082	28.6886692047119	26.2119998931885	0.00404602009803057	31.6993999481201
0.219413879676722	28.7790813446045	26.3120002746582	0.00429486017674208	31.7994003295898
0.220188143430278	28.8354549407959	26.4120006561279	0.00399008998647332	31.899299621582
0.220962407183833	28.8888053894043	26.511999130249	0.0039979200810194	31.9993000030518
0.221736670937389	28.9320983886719	26.6119995117188	0.00402707979083061	32.0993003845215
0.222689603106119	29.0171604156494	26.7119998931885	0.00432628998532891	32.1994018554688
0.223463866859674	29.0742835998535	26.8120002746582	0.00440433016046882	32.2993011474609
0.22435725259129	29.1887950897217	26.9120006561279	0.00408820016309619	32.399299621582
0.225191077333875	29.2978744506836	27.011999130249	0.0043538399040699	32.4992980957031
0.226024887524545	29.3855609893799	27.1119995117188	0.00448670983314514	32.5993003845215
0.22691827325616	29.4807300567627	27.2119998931885	0.00409833993762732	32.6992988586426
0.227692537009716	29.5559253692627	27.3120002746582	0.00406539021059871	32.7994003295898
0.228466786211357	29.6254024505615	27.4120006561279	0.004115030169487	32.899299621582
0.229181503527798	29.6468868255615	27.511999130249	0.00404735002666712	32.9994010925293
0.230015313718468	29.7055816650391	27.6119995117188	0.00411069020628929	33.0993003845215
0.230908699450083	29.7814254760742	27.7119998931885	0.00401732977479696	33.1992988586426
0.231742509640753	29.882963180542	27.8120002746582	0.00416037021204829	33.2993011474609
0.232576334383339	29.9633979797363	27.9120006561279	0.00418666005134583	33.399299621582
0.233410159125924	30.0613536834717	28.011999130249	0.00420165993273258	33.4992980957031
0.234303530305624	30.1541156768799	28.1119995117188	0.00424228981137276	33.5993003845215
0.235137355048209	30.2547016143799	28.2119998931885	0.00425750017166138	33.6992988586426
0.235911618801765	30.3094081878662	28.3120002746582	0.00425750017166138	33.7993011474609
0.236626321566291	30.3444728851318	28.4120006561279	0.00428271014243364	33.899299621582
0.237460146308877	30.4018077850342	28.511999130249	0.00430744979530573	33.9992980957031
0.238413078477606	30.4768028259277	28.6119995117188	0.0043992199935019	34.0993003845215
0.239306464209221	30.5701313018799	28.7119998931885	0.0042985500767827	34.1992988586426
0.240080713410862	30.6487503051758	28.8120002746582	0.00432942993938923	34.2993011474609
0.240974099142477	30.7358703613281	28.9120006561279	0.00434317998588085	34.3992004394531
0.241927031311207	30.8723564147949	29.011999130249	0.004364849999547	34.4992980957031
0.242760856053792	30.9587421417236	29.1119995117188	0.00436781020835042	34.5993003845215
0.243535119807348	31.0130710601807	29.2119998931885	0.00428720004856586	34.6992988586426
0.244309369008988	31.0636501312256	29.3120002746582	0.00439888006076217	34.7993011474609
0.245143193751574	31.1037731170654	29.4120006561279	0.00416516000404954	34.899299621582
0.246036594035104	31.1971492767334	29.511999130249	0.00449405005201697	34.9992980957031
0.246810843236744	31.2551136016846	29.6119995117188	0.00443102978169918	35.0993003845215
0.247585092438385	31.342679977417	29.7119998931885	0.00447857985273004	35.1992988586426
0.248359370743856	31.4329013824463	29.8120002746582	0.00450281007215381	35.2993011474609
0.249014497967437	31.4868450164795	29.9120006561279	0.00447526015341282	35.399299621582
0.249967444688082	31.5886478424072	30.011999130249	0.0043876301497221	35.4991989135742
0.250979937845841	31.6886348724365	30.1119995117188	0.00440779002383351	35.5993003845215
0.251873309025541	31.7651958465576	30.2119998931885	0.00450253998860717	35.6992988586426
0.252528465352952	31.806921005249	30.3120002746582	0.00447604013606906	35.7993011474609
0.253362290095538	31.8544120788574	30.4120006561279	0.00447979010641575	35.899299621582
0.254076992860064	31.8988990783691	30.511999130249	0.00475346017628908	35.9991989135742
0.254910817602649	31.971887588501	30.6119995117188	0.00459741009399295	36.0993003845215
0.255863764323294	32.0846252441406	30.7119998931885	0.00460581015795469	36.1992988586426
0.256876257481053	32.2070007324219	30.8120002746582	0.0045341202057898	36.2993011474609
0.257769628660753	32.3193244934082	30.9120006561279	0.00459088012576103	36.399299621582
0.258484331425279	32.368278503418	31.011999130249	0.00458442000672221	36.4991989135742
0.259318156167865	32.4324226379395	31.1119995117188	0.00466246996074915	36.5993003845215
0.260211527347565	32.4912796020508	31.2119998931885	0.00469203991815448	36.6991996765137
0.261104898527265	32.5605735778809	31.3120002746582	0.00472034979611635	36.7991981506348
0.261879176832736	32.6015281677246	31.4120006561279	0.00470880977809429	36.899299621582
0.262534304056317	32.6514282226563	31.511999130249	0.00467181019484997	36.9991989135742
0.263368128798902	32.7195701599121	31.6119995117188	0.00469502992928028	37.0992012023926
0.264261499978602	32.8392868041992	31.7119998931885	0.0047022202052176	37.1991996765137
0.265154900262132	32.9468612670898	31.8120002746582	0.00473228003829718	37.2991981506348
0.265988725004718	33.0276908874512	31.9120006561279	0.00476338993757963	37.3992004394531
0.266882096184418	33.0904998779297	32.0120010375977	0.00476077990606427	37.4991989135742
0.267656345386058	33.1555480957031	32.1119995117188	0.00475131021812558	37.5992012023926
0.26831150171347	33.1600608825684	32.2120018005371	0.00482869008556008	37.6991996765137
0.26920487289317	33.2278747558594	32.3120002746582	0.00477290991693735	37.7990989685059
0.26997915119864	33.2883033752441	32.4119987487793	0.00479417992755771	37.8992004394531
0.270634278422222	33.3595008850098	32.5120010375977	0.00479436991736293	37.9991989135742
0.271468103164807	33.4486885070801	32.6119995117188	0.00485114986076951	38.0992012023926
0.272480596322566	33.5815162658691	32.7120018005371	0.00486643984913826	38.1991996765137
0.273016630671918	33.6073532104492	32.8120002746582	0.00485522020608187	38.2991981506348
0.274326914222911	33.7471961975098	32.9119987487793	0.0048772799782455	38.3992004394531
0.274922495009378	33.7754898071289	33.0120010375977	0.00490813003852963	38.4991989135742
0.27545852935873	33.7828330993652	33.1119995117188	0.00486097997054458	38.5992012023926
0.276411476079375	33.8462104797363	33.2120018005371	0.00539229996502399	38.6991996765137
0.277483515674248	33.9701499938965	33.3120002746582	0.0049906000494957	38.7991981506348
0.278257793979719	34.0365905761719	33.4119987487793	0.00519206002354622	38.8992004394531
0.2789129212033	34.0892601013184	33.5120010375977	0.00529860984534025	38.9991989135742
0.27992541436106	34.1991195678711	33.6119995117188	0.00494549982249737	39.0992012023926
0.28081881464459	34.2926063537598	33.7120018005371	0.00505498005077243	39.1991996765137
0.281652610283345	34.3583984375	33.8120002746582	0.00511188013479114	39.2991981506348
0.28260555700399	34.4415397644043	33.9119987487793	0.00503815012052655	39.399299621582
0.28349892818369	34.4982872009277	34.0120010375977	0.00502073997631669	39.4991989135742
0.284332752926275	34.5726013183594	34.1119995117188	0.00505786016583443	39.5992012023926
0.285107031231746	34.6292610168457	34.2120018005371	0.00546786980703473	39.6991996765137
0.285821733996272	34.664234161377	34.3120002746582	0.00544642983004451	39.7991981506348
0.286536436760798	34.7423133850098	34.4119987487793	0.00549860997125506	39.8992004394531
0.287370261503384	34.8309364318848	34.5120010375977	0.00511422008275986	39.9990997314453
0.288263632683083	34.9389114379883	34.6119995117188	0.00517361983656883	40.0992012023926
0.289037881884724	34.9837341308594	34.7120018005371	0.00512226019054651	40.1991996765137
0.290050375042483	35.0797920227051	34.8120002746582	0.00514886016026139	40.2991981506348
0.291122443741187	35.1690940856934	34.9119987487793	0.00520337978377938	40.3992004394531
0.292015814920887	35.2331047058105	35.0120010375977	0.00517253996804357	40.4990997314453
0.292611395707354	35.2660179138184	35.1119995117188	0.00518308999016881	40.5990982055664
0.293504795990884	35.3413352966309	35.2120018005371	0.005622330121696	40.6991996765137
0.29421949875541	35.4034957885742	35.3120002746582	0.00560249015688896	40.7991981506348
0.294815079541877	35.4488372802734	35.4119987487793	0.0052976799197495	40.8991012573242
0.295529782306403	35.5042037963867	35.5120010375977	0.00525046978145838	40.9991989135742
0.296840065857396	35.666202545166	35.6119995117188	0.00529746990650892	41.0990982055664
0.297852559015155	35.753002166748	35.7120018005371	0.00536310020834208	41.1991004943848
0.298745930194855	35.8239402770996	35.8120002746582	0.00536180986091495	41.2990989685059
0.299460632959381	35.8457527160645	35.9119987487793	0.00537433987483382	41.3992004394531
0.300294457701966	35.9149208068848	36.0120010375977	0.00539408996701241	41.4990997314453
0.301068736007437	35.9730033874512	36.1119995117188	0.00541095994412899	41.5990982055664
0.301902560750023	36.0354614257813	36.2120018005371	0.00544494995847344	41.6991996765137
0.302676809951663	36.1234664916992	36.3120002746582	0.00547552015632391	41.7990989685059
0.303451059153304	36.1825828552246	36.4119987487793	0.00548327015712857	41.8991012573242
0.304284883895889	36.2549934387207	36.5120010375977	0.00550206005573273	41.9990997314453
0.305297377053648	36.3407669067383	36.6119995117188	0.00552960997447371	42.0990982055664
0.306071655359119	36.3944244384766	36.7120018005371	0.00553291011601686	42.1991004943848
0.307024602079764	36.459587097168	36.8120002746582	0.00556345982477069	42.2991981506348
0.307917973259464	36.5194358825684	36.9119987487793	0.00556008983403444	42.3991012573242
0.308692222461104	36.5833625793457	37.0120010375977	0.00558583019301295	42.4990997314453
0.309347378788516	36.6403884887695	37.1119995117188	0.00559413013979793	42.5993995666504
0.310121627990156	36.7007141113281	37.2120018005371	0.00559775019064546	42.6991004943848
0.310836330754682	36.7627983093262	37.3120002746582	0.00566814001649618	42.7990989685059
0.311729731038213	36.8405494689941	37.4119987487793	0.00565729010850191	42.899299621582
0.312563526676968	36.910472869873	37.5120010375977	0.00564834009855986	42.9990997314453
0.313397351419553	36.9689254760742	37.6119995117188	0.00599124981090426	43.0990982055664
0.314171629725024	37.006534576416	37.7120018005371	0.00599006004631519	43.1991004943848
0.31500545446761	37.0635948181152	37.8120002746582	0.0057227797806263	43.2990989685059
0.315958372084424	37.1504554748535	37.9119987487793	0.00575225008651614	43.3991012573242
0.316732650389895	37.228328704834	38.0120010375977	0.00576055003330112	43.4990997314453
0.317506899591535	37.2890510559082	38.1119995117188	0.00579030998051167	43.5990982055664
0.318281177897006	37.357536315918	38.2120018005371	0.00572510017082095	43.6990013122559
0.319174549076706	37.4517707824707	38.3120002746582	0.00607908982783556	43.7990989685059
0.320008373819292	37.5257186889648	38.4119987487793	0.00611172011122108	43.898998260498
0.320842169458047	37.5697021484375	38.5120010375977	0.00609188014641404	43.9991989135742
0.321735569741577	37.6253318786621	38.6119995117188	0.00611427007243037	44.0998992919922
0.322807609336451	37.7161521911621	38.7120018005371	0.00614451989531517	44.1991004943848
0.323641434079036	37.7883911132813	38.8120002746582	0.00626605981960893	44.2991981506348
0.324296590406448	37.8269271850586	38.9119987487793	0.00616864021867514	44.3991012573242
0.325070839608088	37.8868637084961	39.0120010375977	0.00613177986815572	44.4990005493164
0.325964210787788	37.9774398803711	39.1119995117188	0.00615894980728626	44.5990982055664
0.326678913552314	38.0181694030762	39.2120018005371	0.00620944984257221	44.6991004943848
0.32739361631684	38.0636444091797	39.3120002746582	0.00618257001042366	44.7990989685059
0.32828701660037	38.1183471679688	39.4119987487793	0.00625198986381292	44.8991012573242
0.329359056195244	38.2113723754883	39.5120010375977	0.00619428977370262	44.9990997314453
0.33019288093783	38.2699012756348	39.6119995117188	0.00621148012578487	45.0990982055664
0.330848037265241	38.2977142333984	39.7120018005371	0.00629153987392783	45.1991004943848
0.331622286466882	38.3538436889648	39.8120002746582	0.0063051600009203	45.2990989685059
0.332575233187526	38.4581260681152	39.9119987487793	0.00633028987795115	45.398998260498
0.333349482389167	38.5370140075684	40.0120010375977	0.00639578979462385	45.4990005493164
0.334183307131752	38.6011543273926	40.1119995117188	0.00641835015267134	45.5989990234375
0.334957585437223	38.6766586303711	40.2120018005371	0.00636890018358827	45.6991996765137
0.335791381075978	38.7317047119141	40.3120002746582	0.00642888015136123	45.7990989685059
0.336625205818564	38.7674560546875	40.4119987487793	0.00641233986243606	45.8992004394531
0.337518606102094	38.824764251709	40.5120010375977	0.00645921006798744	45.9990005493164
0.338352401740849	38.884147644043	40.6119995117188	0.00649764016270638	46.0989990234375
0.339305348461494	38.9547004699707	40.7120018005371	0.00651125004515052	46.1990013122559
0.340139173204079	39.0353851318359	40.8120002746582	0.0064908298663795	46.2991981506348
0.34079430042766	39.0850448608398	40.9119987487793	0.00656524021178484	46.4001007080078
0.341747247148305	39.1856384277344	41.0120010375977	0.00655861990526319	46.4990997314453
0.342640618328005	39.2718391418457	41.1119995117188	0.00622178986668587	46.5989990234375
0.343355321092531	39.3078269958496	41.2120018005371	0.00625063013285398	46.6990013122559
0.344070023857057	39.3288497924805	41.3120002746582	0.00629071006551385	46.7990989685059
0.345022970577702	39.3924560546875	41.4119987487793	0.00629521999508142	46.898998260498
0.345856795320287	39.445011138916	41.5120010375977	0.00658778008073568	46.9990005493164
0.346809742040932	39.5152587890625	41.6119995117188	0.00659292982891202	47.0999984741211
0.347643566783518	39.5861778259277	41.7120018005371	0.00664761988446116	47.1992988586426
0.348417815985158	39.6459846496582	41.8120002746582	0.00674280012026429	47.2990989685059
0.349311187164858	39.7164154052734	41.9119987487793	0.0063683302141726	47.398998260498
0.350025889929384	39.7748908996582	42.0120010375977	0.00639022001996636	47.4990005493164
0.350800168234855	39.8275375366211	42.1119995117188	0.00639022001996636	47.5989990234375
0.351574417436495	39.8585510253906	42.2120018005371	0.00645550014451146	47.6990013122559
0.352408242179081	39.9025573730469	42.3120002746582	0.00645917980000377	47.798999786377
0.353182491380721	39.951358795166	42.4119987487793	0.00648928992450237	47.8997993469238
0.354016316123307	40.0012321472168	42.5120010375977	0.00648193014785647	47.9990005493164
0.355028809281066	40.130500793457	42.6119995117188	0.00649046013131738	48.0989990234375
0.355981756001711	40.2167015075684	42.7120018005371	0.00653976015746593	48.1990013122559
0.356875127181411	40.3064346313477	42.8120002746582	0.0065251998603344	48.298999786377
0.357530283508822	40.3476715087891	42.9119987487793	0.00683925021439791	48.398998260498
0.358244986273348	40.3728485107422	43.0120010375977	0.00684170005843043	48.4990005493164
0.359019235474989	40.4130783081055	43.1119995117188	0.00687196990475059	48.5989990234375
0.359912635758519	40.4782409667969	43.2120018005371	0.00685029989108443	48.6990013122559
0.360746460501105	40.5308074951172	43.3120002746582	0.00687544979155064	48.798999786377
0.361699378117919	40.5985527038574	43.4119987487793	0.00689418008551002	48.898998260498
0.362711871275678	40.7047157287598	43.5120010375977	0.00691113015636802	48.9990005493164
0.363545696018264	40.7738037109375	43.6119995117188	0.00689256982877851	49.0989990234375
0.364617764716968	40.8938941955566	43.7120018005371	0.00694683007895947	49.1990013122559
0.365272891940549	40.9227027893066	43.8120002746582	0.00695142010226846	49.298999786377
0.365630257874727	40.9148979187012	43.9119987487793	0.00701809022575617	49.398998260498
0.366464082617313	40.9561386108398	44.0120010375977	0.00700026983395219	49.4990005493164
0.367536122212186	41.029369354248	44.1119995117188	0.00695350999012589	49.5989990234375
0.368489068932831	41.1000175476074	44.2120018005371	0.00700201978906989	49.6991004943848
0.369382440112531	41.1610641479492	44.3120002746582	0.00707513000816107	49.798900604248
0.370216264855117	41.2240219116211	44.4119987487793	0.00711969006806612	49.8997001647949
0.371228758012876	41.308910369873	44.5120010375977	0.00712851015850902	49.9990005493164
0.372122129192576	41.422248840332	44.6119995117188	0.00712297996506095	50.0988998413086
0.372896407498047	41.4534606933594	44.7120018005371	0.00711061013862491	50.1990013122559
0.373730232240632	41.5323677062988	44.8120002746582	0.00710452999919653	50.298999786377
0.374444935005158	41.5536613464355	44.9119987487793	0.00713871978223324	50.398998260498
0.375159637769684	41.5841827392578	45.0120010375977	0.00713959988206625	50.4990005493164
0.375933886971325	41.6035041809082	45.1119995117188	0.00715096015483141	50.5989990234375
0.376827258151025	41.6672210693359	45.2120018005371	0.00715096015483141	50.6990013122559
0.377720658434555	41.7431564331055	45.3120002746582	0.00718799978494644	50.798900604248
0.37855445407331	41.8143615722656	45.4119987487793	0.00724211009219289	50.898998260498
0.379388278815895	41.8989791870117	45.5120010375977	0.00730268005281687	50.9989013671875
0.380102981580421	41.9451332092285	45.6119995117188	0.00724181020632386	51.0989990234375
0.381055928301066	42.0230979919434	45.7120018005371	0.00721014011651278	51.1990013122559
0.381949299480766	42.0962524414063	45.8120002746582	0.00724836019799113	51.298900604248
0.382723577786237	42.1206359863281	45.9119987487793	0.00728006986901164	51.3988990783691
0.383497826987877	42.1567535400391	46.0120010375977	0.00726963020861149	51.4989013671875
0.384152983315289	42.168571472168	46.1119995117188	0.00726875010877848	51.5996017456055
0.385105900932103	42.2481346130371	46.2120018005371	0.00730624981224537	51.6988983154297
0.385820603696629	42.2965240478516	46.3120002746582	0.00733917020261288	51.798900604248
0.386475760024041	42.3139953613281	46.4119987487793	0.00734465010464191	51.8988990783691
0.387666921596974	42.4709777832031	46.5120010375977	0.00736752012744546	51.9989013671875
0.388619868317619	42.5604209899902	46.6119995117188	0.00742478016763926	52.0992012023926
0.389453693060204	42.5903358459473	46.7120018005371	0.00742047978565097	52.1988983154297
0.390227942261845	42.6162605285645	46.8120002746582	0.00738262990489602	52.298900604248
0.391002220567316	42.632007598877	46.9119987487793	0.00736341020092368	52.3988990783691
0.391776469768956	42.6692123413086	47.0120010375977	0.00739740021526814	52.4990005493164
0.392491172533482	42.7052803039551	47.1119995117188	0.00743190990760922	52.5988998413086
0.393265450838953	42.7501907348633	47.2120018005371	0.00746800005435944	52.6988983154297
0.394099275581539	42.8145408630371	47.3120002746582	0.00745713012292981	52.798900604248
0.394992646761239	42.897102355957	47.4119987487793	0.00745696993544698	52.8987998962402
0.395886017940938	42.9824981689453	47.5120010375977	0.00748977018520236	52.9989013671875
0.396719842683524	43.0285491943359	47.6119995117188	0.00751233985647559	53.0989990234375
0.39743454544805	43.0624694824219	47.7120018005371	0.00759280007332563	53.1988983154297
0.398268370190635	43.0800285339355	47.8120002746582	0.00759280007332563	53.2999992370605
0.399102194933221	43.1338005065918	47.9119987487793	0.00762788997963071	53.3988990783691
0.399816897697747	43.169605255127	48.0120010375977	0.00760805979371071	53.4989013671875
0.400591146899387	43.2135047912598	48.1119995117188	0.00774354999884963	53.5994987487793
0.401424971641973	43.2962951660156	48.2120018005371	0.00748259015381336	53.6990013122559
0.402377918362617	43.3931312561035	48.3120002746582	0.00748259015381336	53.798900604248
0.403271289542317	43.4747467041016	48.4119987487793	0.00766019010916352	53.8987998962402
0.404343329137191	43.5557594299316	48.5120010375977	0.00768512021750212	53.9995994567871
0.405117607442662	43.6049041748047	48.6119995117188	0.00772137008607388	54.0988998413086
0.405951432185248	43.6247215270996	48.7120018005371	0.00776572991162539	54.1988983154297
0.406725681386888	43.6536331176758	48.8120002746582	0.00773828011006117	54.2988014221191
0.407559506129473	43.689022064209	48.9119987487793	0.00773255992680788	54.3988990783691
0.408452877309173	43.7685508728027	49.0120010375977	0.0077561498619616	54.4987983703613
0.409167580073699	43.7977561950684	49.1119995117188	0.0077894302085042	54.5988006591797
0.41006098035723	43.8893623352051	49.2120018005371	0.00782126002013683	54.6987991333008
0.410894775995985	43.9609146118164	49.3120002746582	0.0076463301666081	54.7988014221191
0.41184772271663	44.0170364379883	49.4119987487793	0.0080154100432992	54.8987998962402
0.412741093896329	44.1082038879395	49.5120010375977	0.00785601045936346	54.9989013671875
0.413574918638915	44.107063293457	49.6119995117188	0.0078284302726388	55.0988006591797
0.4144087433815	44.1374282836914	49.7120018005371	0.0078284302726388	55.1988983154297
0.415183021686971	44.1526031494141	49.8120002746582	0.00781102990731597	55.298900604248
0.416135939303786	44.2251739501953	49.9119987487793	0.00728107010945678	55.3987998962402
0.416791095631197	44.2619400024414	50.0120010375977	0.00784390978515148	55.4995994567871
0.417386676417664	44.2876472473145	50.1119995117188	0.00790589023381472	55.5988006591797
0.418458716012537	44.4000854492188	50.2120018005371	0.00790526997298002	55.6988983154297
0.419530784711242	44.5014801025391	50.3120002746582	0.00794440042227507	55.7988014221191
0.420424155890942	44.5350608825684	50.4119987487793	0.00794440042227507	55.8992004394531
0.421079312218353	44.5536956787109	50.5120010375977	0.00800784025341272	55.9987983703613
0.421615346567705	44.514347076416	50.6119995117188	0.00798978004604578	56.1002998352051
0.422508717747405	44.5604400634766	50.7120018005371	0.00804901029914618	56.1987991333008
0.42346166446805	44.6540985107422	50.8120002746582	0.00800270959734917	56.298900604248
0.424116791691631	44.6680946350098	50.9119987487793	0.00800270959734917	56.3988990783691
0.424950616434216	44.7168655395508	51.0120010375977	0.00801210012286901	56.4987983703613
0.425784441176802	44.777645111084	51.1119995117188	0.00805392954498529	56.5988998413086
0.426677812356502	44.8442687988281	51.2120018005371	0.00821410957723856	56.6987991333008
0.427511637099087	44.9183235168457	51.3120002746582	0.00816124957054853	56.7988014221191
0.428345461841673	44.9326553344727	51.4119987487793	0.00824231002479792	56.8987998962402
0.429357954999432	44.9936065673828	51.5120010375977	0.00829960033297539	56.9987983703613
0.429953535785899	45.0043411254883	51.6119995117188	0.00839523039758205	57.0988006591797
0.430668238550425	45.0077056884766	51.7120018005371	0.00839915964752436	57.1987991333008
0.43150206329301	45.0359840393066	51.8120002746582	0.00834434013813734	57.298900604248
0.43239543447271	45.1030158996582	51.9119987487793	0.00832504034042358	57.3987998962402
0.433169712778181	45.1414566040039	52.0120010375977	0.00821715034544468	57.4987983703613
0.434003537520766	45.1863098144531	52.1119995117188	0.00821715034544468	57.5988998413086
0.434896908700466	45.2303047180176	52.2120018005371	0.00827713962644339	57.6987991333008
0.435849855421111	45.2849617004395	52.3120002746582	0.00827713962644339	57.7988014221191
0.436743226600811	45.3210372924805	52.4119987487793	0.00828323978930712	57.8987007141113
0.437696144217625	45.3402137756348	52.5120010375977	0.00828387960791588	57.9990005493164
0.438589544501156	45.3338966369629	52.6119995117188	0.00824507046490908	58.0997009277344
0.439244671724737	45.2876243591309	52.7120018005371	0.00828281976282597	58.1988983154297
0.439959374489263	45.2584114074707	52.8120002746582	0.00825641956180334	58.2988014221191
0.440674077253789	44.9417839050293	52.9119987487793	0.00828391034156084	58.3987998962402
0.440852774772793	-33.852653503418	52.9389991760254	0.00828391034156084	58.3987998962402