File: CSVs/24-01-08_Tensile_paper-PDMS/Oven_Coated_2/asdf.txt
File Path: C:\Users\apk5101\Desktop\Sandra\Oven_Coated_2 01-8-24 11 12 58 AM\DAQ- Crosshead, … - (Timed).txt
Test: MTS EM Tension (Simplified) with Video Extensometer apk5101 25
Test Run: Oven_Coated_2
Date: 1/8/2024 11:06:16 AM


Crosshead 	Load 	Time 	Strain 1 	Video Time
mm	N	sec	mm/mm	sec
-0.000119117203212227	-0.0800774842500687	0.112000003457069	1.86571996891871E-05	4.19990015029907
0.000476468812848907	-0.102282479405403	0.312000006437302	-1.01508003353956E-05	4.39989995956421
0.00238234406424453	0.242977529764175	0.512000024318695	1.0620399734762E-05	4.60129976272583
0.00446689500677167	0.666002690792084	0.712000012397766	3.709700104082E-05	4.79990005493164
0.0064918876887532	1.09624350070953	0.912000000476837	6.50338988634758E-05	5.09989976882935
0.00857643863128033	1.5218722820282	1.11199998855591	0.000102220001281239	5.19990015029907
0.0103036381915445	1.77897822856903	1.31200003623962	0.000187715006177314	5.39989995956421
0.0121499542728998	2.10939335823059	1.51199996471405	0.000192371997400187	5.59989976882935
0.0140558295242954	2.52285623550415	1.71200001239777	0.000210174999665469	5.79990005493164
0.0157830290845595	2.90085887908936	1.91199994087219	0.00024809199385345	5.99989986419678
0.0174506694747834	3.15704798698425	2.11199998855591	0.000278452993370593	6.19990015029907
0.0189396359928651	3.41427326202393	2.31200003623962	0.000313842989271507	6.39989995956421
0.0208455112442607	3.75655007362366	2.51200008392334	0.00031796601251699	6.59980010986328
0.022691827325616	4.15070533752441	2.71199989318848	0.000329406990204006	6.79990005493164
0.0241807920247084	4.42814350128174	2.91199994087219	0.000382992002414539	6.99989986419678
0.0256101975537604	4.63276290893555	3.11199998855591	0.000457446003565565	7.19990015029907
0.0274565154541051	4.95569324493408	3.31200003623962	0.000403018988436088	7.39989995956421
0.0292432723654201	5.29653692245483	3.51200008392334	0.00049087597290054	7.59980010986328
0.0310300310957246	5.66438055038452	3.71199989318848	0.000496272987220436	7.79990005493164
0.0326381123159081	5.94540596008301	3.91199994087219	0.000502886017784476	7.99980020523071
0.0341866361850407	6.1689248085022	4.11199998855591	0.000570563017390668	8.19979953765869
0.0358542783942539	6.49116039276123	4.31199979782104	0.000583996006753296	8.39990043640137
0.0374623596144374	6.82563257217407	4.51200008392334	0.000673824979458004	8.5999002456665
0.0392491165257525	7.15488243103027	4.71199989318848	0.000690152985043824	8.89980030059814
0.0408572013839148	7.4113621711731	4.91200017929077	0.000729443971067667	8.99979972839355
0.0424057252530474	7.63287401199341	5.11199998855591	0.000786011980380863	9.19979953765869
0.04395424912218	7.91168880462646	5.31199979782104	0.000785593001637608	9.39980030059814
0.0457410060334951	8.26596260070801	5.51200008392334	0.000773389008827507	9.60000038146973
0.0475277629448101	8.56193828582764	5.71199989318848	0.000863167981151491	9.79979991912842
0.0491358441649936	8.79267120361328	5.91200017929077	0.000906327972188592	9.99979972839355
0.0507439290231559	9.04885673522949	6.11199998855591	0.000917149009183049	10.1997995376587
0.0524711285834201	9.38496494293213	6.31199979782104	0.000860226980876178	10.3998003005981
0.0540792098036036	9.6998815536499	6.51200008392334	0.000854207028169185	10.5996999740601
0.0559255277039483	10.0081663131714	6.71199989318848	0.000938680022954941	10.7997999191284
0.0574740515730809	10.2096548080444	6.91200017929077	0.00103450997266918	10.9997997283936
0.0591416901443154	10.5047092437744	7.11199998855591	0.00106549996417016	11.1997995376587
0.0609284470556304	10.8252458572388	7.31199979782104	0.00109014997724444	11.3998003005981
0.0625365282758139	11.1151075363159	7.51200008392334	0.00109058001544327	11.5998001098633
0.0643232924630865	11.3755674362183	7.71199989318848	0.00107647001277655	11.7999000549316
0.0659313736832701	11.6121501922607	7.91200017929077	0.00112436001654714	11.9996995925903
0.0675990086165257	11.8952980041504	8.11200046539307	0.00115052994806319	12.1997003555298
0.0691475361236371	12.1879014968872	8.3120002746582	0.00117440999019891	12.3997001647949
0.0708151783328503	12.4531879425049	8.51200008392334	0.00134217995218933	12.5996999740601
0.0725423742551357	12.6938152313232	8.71199989318848	0.00135152996517718	12.7996997833252
0.0740909017622471	12.914644241333	8.91199970245361	0.00137970002833754	12.9997997283936
0.0758776586735621	13.2549896240234	9.11200046539307	0.00128603004850447	13.1997995376587
0.0776644155848771	13.5563449859619	9.3120002746582	0.00132176000624895	13.3997001647949
0.0793320577940904	13.805775642395	9.51200008392334	0.00149388995487243	13.5996999740601
0.0809997000033036	14.0316534042358	9.71199989318848	0.0013645599829033	13.7997999191284
0.0826077812234871	14.2959327697754	9.91199970245361	0.00139276997651905	13.9996995925903
0.0841563014546409	14.5512323379517	10.1120004653931	0.00145575997885317	14.1997003555298
0.0857643826748244	14.7923545837402	10.3120002746582	0.00145835999865085	14.3997001647949
0.0876107005751692	15.0507488250732	10.5120000839233	0.00148401001933962	14.5996999740601
0.0892783427843824	15.2805995941162	10.7119998931885	0.00153587001841515	14.7996997833252
0.0907673093024641	15.5080547332764	10.9119997024536	0.00163623003754765	14.9998998641968
0.0923753905226476	15.7802476882935	11.1120004653931	0.00166989001445472	15.299599647522
0.0942217084229924	16.0665817260742	11.3120002746582	0.00172523001674563	15.3997001647949
0.0960680263233371	16.311107635498	11.5120000839233	0.00174743996467441	15.5996999740601
0.0974378708633594	16.5106658935547	11.7119998931885	0.00178666005376726	15.7996997833252
0.0991650740616024	16.8056640625	11.9119997024536	0.0018224100349471	15.9996995925903
0.100832708994858	17.0600109100342	12.1120004653931	0.00182801997289062	16.1996002197266
0.102619465906173	17.2825622558594	12.3120002746582	0.00186580000445247	16.3997001647949
0.104406230093446	17.5106582641602	12.5120000839233	0.00191939005162567	16.5995998382568
0.105954750324599	17.7656421661377	12.7119998931885	0.00192702002823353	16.7996006011963
0.107562831544783	18.0083332061768	12.9119997024536	0.00194521003868431	16.9995994567871
0.109111359051894	18.2243061065674	13.1120004653931	0.00195629009976983	17.1996002197266
0.110779001261108	18.4094715118408	13.3120002746582	0.00199139001779258	17.3995990753174
0.112744433863554	18.7102165222168	13.5120000839233	0.00202841009013355	17.5995998382568
0.114352515083738	18.9541149139404	13.7119998931885	0.00206410000100732	17.7996006011963
0.115543683932628	19.1295547485352	13.9119997024536	0.00218575005419552	17.9995994567871
0.117509116535075	19.3857021331787	14.1120004653931	0.0021343301050365	18.1996002197266
0.11935543443542	19.6446800231934	14.3120002746582	0.00215173000469804	18.3995990753174
0.120903961942531	19.8610858917236	14.5120000839233	0.00218524993397295	18.5995998382568
0.122631157864816	20.1355648040771	14.7119998931885	0.0021656199824065	18.7996006011963
0.124060563393869	20.3506183624268	14.9119997024536	0.00228746002539992	18.9995002746582
0.126026003272273	20.5912113189697	15.1120004653931	0.00233125989325345	19.199499130249
0.127693638205528	20.7873458862305	15.3120002746582	0.00232819002121687	19.3995990753174
0.129539956105873	21.090295791626	15.5120000839233	0.00235659000463784	19.5995998382568
0.131088483612984	21.3198413848877	15.7119998931885	0.00242404011078179	19.7994995117188
0.13275611854624	21.5226097106934	15.9119997024536	0.00249995989724994	19.9995994567871
0.134423768031411	21.7085285186768	16.1119995117188	0.00246837991289794	20.2996006011963
0.136091402964666	21.9205646514893	16.3120002746582	0.00250564003363252	20.3994998931885
0.137759037897922	22.2038593292236	16.511999130249	0.00252299988642335	20.5995006561279
0.139307565405034	22.4229393005371	16.7119998931885	0.00256066001020372	20.7996006011963
0.140915653901175	22.5919990539551	16.9120006561279	0.00259639997966588	20.9995002746582
0.14270241081249	22.8078384399414	17.1119995117188	0.00264857010915875	21.199499130249
0.144429606734775	23.0506076812744	17.3120002746582	0.00271607004106045	21.3995990753174
0.146037695230916	23.3055095672607	17.511999130249	0.00270924996584654	21.5995006561279
0.147526661748998	23.4877529144287	17.7119998931885	0.00269486010074615	21.7994995117188
0.149134735693224	23.6329784393311	17.9120006561279	0.00272727990522981	21.9995002746582
0.150802370626479	23.8370227813721	18.1119995117188	0.00285195000469685	22.199499130249
0.15247002011165	24.1018218994141	18.3120002746582	0.00286400993354619	22.3994998931885
0.154256777022965	24.357759475708	18.511999130249	0.0029409599956125	22.5995006561279
0.155686182552017	24.483512878418	18.7119998931885	0.00293284002691507	22.7994995117188
0.157294271048158	24.6489315032959	18.9120006561279	0.00299246003851295	22.9995002746582
0.159021466970444	24.8993549346924	19.1119995117188	0.00298525998368859	23.199499130249
0.160510433488525	25.1048965454102	19.3120002746582	0.00303083006292582	23.3997001647949
0.16229719039984	25.3387928009033	19.511999130249	0.00303546991199255	23.5995006561279
0.163964825333096	25.5166969299316	19.7119998931885	0.00311101996339858	23.7994995117188
0.165513352840208	25.6743316650391	19.9120006561279	0.00317114009521902	23.9995002746582
0.167300109751523	25.9490737915039	20.1119995117188	0.00330608990043402	24.1993999481201
0.169146427651867	26.2087783813477	20.3120002746582	0.00324956001713872	24.3994998931885
0.170814062585123	26.4026508331299	20.511999130249	0.00322825997136533	24.5993995666504
0.172541273059323	26.5789241790771	20.7119998931885	0.00329367001540959	24.7994995117188
0.174268468981609	26.7718276977539	20.9120006561279	0.00332901999354362	24.9995002746582
0.176114786881953	27.0693588256836	21.1119995117188	0.00339464005082846	25.199499130249
0.177961104782298	27.3248062133789	21.3120002746582	0.00340595003217459	25.3994998931885
0.179509617737494	27.4734649658203	21.511999130249	0.00341834989376366	25.5993995666504
0.181058145244606	27.6268863677979	21.7119998931885	0.00341333006508648	25.7994995117188
0.182844902155921	27.8899364471436	21.9120006561279	0.0035054599866271	25.9995002746582
0.184452990652062	28.1115875244141	22.1119995117188	0.00357391010038555	26.199499130249
0.186120625585318	28.3047389984131	22.3120002746582	0.00354459998197854	26.3994998931885
0.18749047012534	28.3744201660156	22.511999130249	0.00359458010643721	26.6016998291016
0.189277227036655	28.5979137420654	22.7119998931885	0.00354697997681797	26.7994003295898
0.190825754543766	28.7927131652832	22.9120006561279	0.00359895010478795	27.0006008148193
0.192612511455081	29.0464897155762	23.1119995117188	0.00360697996802628	27.1993999481201
0.194339721929282	29.2322540283203	23.3120002746582	0.00368119007907808	27.3994007110596
0.195947795873508	29.3715496063232	23.511999130249	0.00376202003099024	27.5993995666504
0.197496323380619	29.5501823425293	23.7119998931885	0.00369945005513728	27.7994003295898
0.199163958313875	29.7898044586182	23.9120006561279	0.00376928993500769	27.9993991851807
0.200831607799046	29.9665126800537	24.1119995117188	0.00372755993157625	28.1993999481201
0.20267792569939	30.1659641265869	24.3120002746582	0.00385868991725147	28.3994007110596
0.204047770239413	30.2791328430176	24.511999130249	0.00388901005499065	28.5993995666504
0.205596297746524	30.4589405059814	24.7119998931885	0.00395285012200475	28.7994003295898
0.20732349366881	30.669942855835	24.9120006561279	0.00393927982077003	28.9993991851807
0.209288918995298	30.8793277740479	25.1119995117188	0.00404983013868332	29.1993999481201
0.21089700749144	31.0078029632568	25.3120002746582	0.00398829020559788	29.3994007110596
0.212505081435665	31.1664028167725	25.511999130249	0.00402591982856393	29.5993995666504
0.214172730920836	31.3784866333008	25.7119998931885	0.00408681016415358	29.7994003295898
0.215899926843122	31.6099262237549	25.9120006561279	0.00408717012032866	29.9993991851807
0.217686683754437	31.7742042541504	26.1119995117188	0.0041270898655057	30.199499130249
0.219473440665752	31.9436511993408	26.3120002746582	0.00422724010422826	30.3994007110596
0.220962407183833	32.1006393432617	26.511999130249	0.00425586989149451	30.5993003845215
0.222630056669004	32.3174591064453	26.7119998931885	0.00432142987847328	30.7992992401123
0.224476360017434	32.5269012451172	26.9120006561279	0.00432152021676302	30.9993000030518
0.226144009502605	32.6694259643555	27.1119995117188	0.00429897010326385	31.1993007659912
0.227573415031657	32.8208847045898	27.3120002746582	0.00436190003529191	31.4001007080078
0.229300610953942	33.0259742736816	27.511999130249	0.00434079999104142	31.5993003845215
0.230849138461053	33.1981315612793	27.7119998931885	0.00434155995026231	31.7992992401123
0.232635895372368	33.3878402709961	27.9120006561279	0.00434256019070745	31.9993000030518
0.234303530305624	33.5130271911621	28.1119995117188	0.00442468002438545	32.1992988586426
0.235911618801765	33.6908416748047	28.3120002746582	0.0045596300624311	32.399299621582
0.237579253735021	33.8947906494141	28.511999130249	0.00455480022355914	32.5993003845215
0.239127781242132	34.0499076843262	28.7119998931885	0.00461419997736812	32.7993011474609
0.241152782109566	34.2489356994629	28.9120006561279	0.00462340982630849	32.9992980957031
0.242641734075733	34.3580932617188	29.1119995117188	0.00465749995782971	33.1992988586426
0.244368944549933	34.548168182373	29.3120002746582	0.0046695601195097	33.399299621582
0.245917472057045	34.7475166320801	29.511999130249	0.00472356006503105	33.5992012023926
0.24764466797933	34.9074287414551	29.7119998931885	0.00472813984379172	33.7991981506348
0.249371863901615	35.0279808044434	29.9120006561279	0.00477101979777217	34.0992012023926
0.250860815867782	35.1600799560547	30.1119995117188	0.0047792699187994	34.1991996765137
0.252468918915838	35.3731994628906	30.3120002746582	0.00486906012520194	34.3992004394531
0.254076992860064	35.5301094055176	30.511999130249	0.00485763000324368	34.5992012023926
0.255804188782349	35.6688461303711	30.7119998931885	0.00494940998032689	34.7991981506348
0.257769628660753	35.8791885375977	30.9120006561279	0.00492394994944334	34.9992980957031
0.259437278145924	36.0537223815918	31.1119995117188	0.00499917007982731	35.1991996765137
0.260985776549205	36.2344093322754	31.3120002746582	0.00496307015419006	35.399299621582
0.262534304056317	36.3769607543945	31.511999130249	0.00498556019738317	35.5992012023926
0.264321075519547	36.520393371582	31.7119998931885	0.00505778007209301	35.7991981506348
0.266048271441832	36.6835403442383	31.9120006561279	0.00511098001152277	35.9991989135742
0.267596798948944	36.8416786193848	32.1119995117188	0.00518702995032072	36.1991996765137
0.269145326456055	37.0285110473633	32.3120002746582	0.00527804996818304	36.3992004394531
0.270574731985107	37.1287422180176	32.5120010375977	0.00525966007262468	36.5992012023926
0.272361474344507	37.2635116577148	32.7120018005371	0.005239840131253	36.7991981506348
0.274267367785797	37.4712409973145	32.9119987487793	0.00536605017259717	36.9991989135742
0.275934988167137	37.6289367675781	33.1119995117188	0.00536374980583787	37.1991996765137
0.277066603302956	37.6986083984375	33.3120002746582	0.00543534988537431	37.3992004394531
0.278853374766186	37.8286628723145	33.5120010375977	0.00544044002890587	37.5992012023926
0.280759239103645	38.016918182373	33.7120018005371	0.0055123302154243	37.7991981506348
0.28260555700399	38.2187614440918	33.9119987487793	0.00554190017282963	37.9991989135742
0.284273206489161	38.3782730102539	34.1119995117188	0.00554422987625003	38.1991996765137
0.285821733996272	38.5031204223633	34.3120002746582	0.00543999020010233	38.3992004394531
0.287429807940498	38.6308403015137	34.5120010375977	0.00548163009807467	38.5992012023926
0.289216579403728	38.79443359375	34.7120018005371	0.00562477018684149	38.7991981506348
0.290765077807009	38.971061706543	34.9119987487793	0.00567359989508986	38.9990997314453
0.292790093226358	39.2071914672852	35.1119995117188	0.0056768199428916	39.1991996765137
0.294457713607699	39.3381652832031	35.3120002746582	0.00578647013753653	39.3992004394531
0.295827572699636	39.3844909667969	35.5120010375977	0.00576166994869709	39.5990982055664
0.297376100206748	39.5440711975098	35.7120018005371	0.00581857981160283	39.7991981506348
0.299639330478385	39.850658416748	35.9119987487793	0.0058941300958395	39.9991989135742
0.301187857985497	39.9591293334961	36.1119995117188	0.00588670000433922	40.1991004943848
0.302617263514549	40.0104026794434	36.3120002746582	0.0059180399402976	40.3991012573242
0.304344459436834	40.136905670166	36.5120010375977	0.00597342988476157	40.5990982055664
0.306071655359119	40.3178939819336	36.7120018005371	0.00595685001462698	40.7991981506348
0.30773930484429	40.488826751709	36.9119987487793	0.00600655982270837	40.9990997314453
0.30940692522563	40.5999794006348	37.1119995117188	0.0060691898688674	41.1991004943848
0.310776784317568	40.6391220092773	37.3120002746582	0.00612733000889421	41.3992004394531
0.312563526676968	40.8129539489746	37.5120010375977	0.00615049991756678	41.5990982055664
0.314231176162139	40.9941482543945	37.7120018005371	0.00620529986917973	41.7990989685059
0.316017947625369	41.1707000732422	37.9119987487793	0.0062163001857698	41.9990997314453
0.317506899591535	41.2375526428223	38.1119995117188	0.00628254003822803	42.1991004943848
0.319174549076706	41.3595390319824	38.3120002746582	0.00629176013171673	42.3991012573242
0.320842169458047	41.539665222168	38.5120010375977	0.00635041017085314	42.5990982055664
0.322807609336451	41.7791061401367	38.7120018005371	0.00635117013007402	42.7990989685059
0.324415712384507	41.9066963195801	38.9119987487793	0.00645630992949009	42.9991989135742
0.325964210787788	42.0079612731934	39.1119995117188	0.00646881014108658	43.1991004943848
0.327572313835844	42.1411018371582	39.3120002746582	0.00647285999730229	43.3992004394531
0.329120841342956	42.299243927002	39.5120010375977	0.00651295017451048	43.5989990234375
0.331026705680415	42.5212898254395	39.7120018005371	0.00654722983017564	43.798999786377
0.332515657646582	42.6334648132324	39.9119987487793	0.00660564005374908	43.9990997314453
0.334123760694638	42.744514465332	40.1119995117188	0.00661514000967145	44.1990013122559
0.335731834638864	42.9044494628906	40.3120002746582	0.00673389993607998	44.398998260498
0.33733990858309	43.074878692627	40.5120010375977	0.00673918006941676	44.5990982055664
0.339364894898608	43.296070098877	40.7120018005371	0.00679490016773343	44.7990989685059
0.34091342240572	43.4071769714355	40.9119987487793	0.00684235990047455	44.9990997314453
0.342342827934772	43.4794044494629	41.1119995117188	0.00687661021947861	45.1990013122559
0.344129599398002	43.6864624023438	41.3120002746582	0.00692802015691996	45.3992004394531
0.345856795320287	43.8640327453613	41.5120010375977	0.00695761991664767	45.5989990234375
0.347643566783518	44.0218391418457	41.7120018005371	0.00697098998352885	45.798999786377
0.349311187164858	44.1164436340332	41.9119987487793	0.00705259991809726	45.9990005493164
0.350800168234855	44.2246856689453	42.1119995117188	0.00707176001742482	46.1990013122559
0.352348695741966	44.3911170959473	42.3120002746582	0.00706483982503414	46.3995018005371
0.354075891664252	44.5666580200195	42.5120010375977	0.00712407985702157	46.5989990234375
0.355862634023651	44.7039909362793	42.7120018005371	0.0071519399061799	46.798999786377
0.357530283508822	44.8098487854004	42.9119987487793	0.00714587001129985	46.9990997314453
0.359197932993993	44.9678268432617	43.1119995117188	0.00719255022704601	47.1990013122559
0.360806006938219	45.1568222045898	43.3120002746582	0.00722861010581255	47.398998260498
0.362533202860504	45.2922058105469	43.5120010375977	0.00725007988512516	47.5989990234375
0.364439067197964	45.4425849914551	43.7120018005371	0.00726506020873785	47.798999786377
0.366106716683134	45.5820236206055	43.9119987487793	0.00727599021047354	47.9989013671875
0.367297878256068	45.6546249389648	44.1119995117188	0.00741421990096569	48.1988983154297
0.369263318134472	45.8882713317871	44.3120002746582	0.00730108981952071	48.398998260498
0.371109636034817	46.0353012084961	44.5120010375977	0.00740642985329032	48.5989990234375
0.372955953935161	46.1530075073242	44.7120018005371	0.00747674982994795	48.798900604248
0.374325813027099	46.2395324707031	44.9119987487793	0.00748444022610784	48.9990005493164
0.376053008949384	46.4367866516113	45.1119995117188	0.00751218013465405	49.1988983154297
0.377601536456496	46.5582618713379	45.3120002746582	0.00750654004514217	49.3988990783691
0.379388278815895	46.6780662536621	45.5120010375977	0.00760701019316912	49.5989990234375
0.381115474738181	46.8025665283203	45.7120018005371	0.00754775013774633	49.798900604248
0.382604455808178	46.9083099365234	45.9119987487793	0.00761740002781153	49.9990005493164
0.384212529752403	47.0766487121582	46.1119995117188	0.00764488987624645	50.1988983154297
0.385820603696629	47.1922378540039	46.3120002746582	0.00770242977887392	50.3988990783691
0.387666921596974	47.3261032104492	46.5120010375977	0.00773173989728093	50.5988998413086
0.38927502464503	47.4127540588379	46.7120018005371	0.0077647902071476	50.798900604248
0.391002220567316	47.5869636535645	46.9119987487793	0.00784493982791901	50.9989013671875
0.392550748074427	47.7021713256836	47.1119995117188	0.0078929103910923	51.1988983154297
0.394218368455768	47.7993316650391	47.3120002746582	0.00786389969289303	51.3988990783691
0.395886017940938	47.8945808410645	47.5120010375977	0.00795069988816977	51.5988998413086
0.397494091885164	48.0610771179199	47.7120018005371	0.0080012995749712	51.798900604248
0.399102194933221	48.1834411621094	47.9119987487793	0.00798978004604578	51.9989013671875
0.400710268877447	48.3203125	48.1119995117188	0.00801260024309158	52.1988983154297
0.402377918362617	48.3880500793457	48.3120002746582	0.00809974037110806	52.3987998962402
0.404164660722017	48.5488739013672	48.5120010375977	0.00810020975768566	52.5988006591797
0.406130100600421	48.7604179382324	48.7120018005371	0.00804227031767368	52.7988014221191
0.407559506129473	48.8567199707031	48.9119987487793	0.00813964009284973	52.9987983703613
0.409167580073699	48.9583435058594	49.1119995117188	0.00827927980571985	53.1987991333008
0.410894775995985	49.0709571838379	49.3120002746582	0.00835544988512993	53.3987998962402
0.412741093896329	49.2308921813965	49.5120010375977	0.00842151045799255	53.5988998413086
0.414349196944386	49.3973693847656	49.7120018005371	0.008433329872787	53.798900604248
0.416076392866671	49.5292739868164	49.9119987487793	0.00849112030118704	53.9987983703613
0.417684466810897	49.5968589782715	50.1119995117188	0.00851671025156975	54.1988983154297
0.419352116296068	49.7154884338379	50.3120002746582	0.00850080978125334	54.3988990783691
0.421198434196413	49.8915367126465	50.5120010375977	0.0085503701120615	54.5988006591797
0.422925630118698	50.0741157531738	50.7120018005371	0.00855206046253443	54.7988014221191
0.424057245254517	50.0763854980469	50.9119987487793	0.00860843993723392	54.9989013671875
0.425843987613916	50.1761474609375	51.1119995117188	0.00866486039012671	55.1987991333008
0.427571183536202	50.3007926940918	51.3120002746582	0.00870629958808422	55.4048004150391
0.429298408562317	50.5057029724121	51.5120010375977	0.00871909037232399	55.5988006591797
0.431025604484603	50.6277275085449	51.7120018005371	0.00880117993801832	55.7988014221191
0.432335888035595	50.6407165527344	51.9119987487793	0.0088153900578618	55.9987983703613
0.433943961979821	50.7253608703613	52.1119995117188	0.00887448992580175	56.1987991333008
0.435849855421111	50.9025268554688	52.3120002746582	0.00894120987504721	56.3987998962402
0.437577051343396	51.0746650695801	52.5120010375977	0.00892193987965584	56.5988006591797
0.439244671724737	51.1957702636719	52.7120018005371	0.00897321011871099	56.7988014221191
0.440793199231848	51.2607383728027	52.9119987487793	0.00897432956844568	56.9987983703613
0.442401302279904	51.3403282165527	53.1119995117188	0.00904379040002823	57.1988983154297
0.444247591076419	51.5075874328613	53.3120002746582	0.00910327024757862	57.3987998962402
0.445974816102535	51.6789970397949	53.5120010375977	0.00910887029021978	57.5988006591797
0.44770201202482	51.7907066345215	53.7120018005371	0.00916026998311281	57.7988014221191
0.449190963990986	51.8155136108398	53.9119987487793	0.00918454024940729	57.9986991882324
0.450739491498098	51.9281730651855	54.1119995117188	0.00920902006328106	58.1987991333008
0.452704931376502	52.1195449829102	54.3120002746582	0.00924867019057274	58.3987998962402
0.454432127298787	52.2608489990234	54.5120010375977	0.00935177970677614	58.5988006591797
0.455980654805899	52.3262214660645	54.7120018005371	0.00936257001012564	58.7988014221191
0.457886519143358	52.4479598999023	54.9119987487793	0.00937887001782656	58.9986991882324
0.458660797448829	52.4015121459961	55.1119995117188	0.00943197961896658	59.1986999511719
0.461043120594695	52.6744804382324	55.3120002746582	0.00948632974177599	59.3987007141113
0.462710770079866	52.7713012695313	55.5120010375977	0.00951317977160215	59.5987014770508
0.464318844024092	52.8433074951172	55.7120018005371	0.00954425986856222	59.798698425293
0.465867371531203	52.9169960021973	55.9119987487793	0.00965857971459627	59.9986991882324
0.467475445475429	53.0605621337891	56.1119995117188	0.00971718970686197	60.1986999511719
0.469381338916719	53.1953659057617	56.3120002746582	0.00957296043634415	60.3987007141113
0.470989412860945	53.2715873718262	56.5120010375977	0.0097472695633769	60.5987014770508
0.472537940368056	53.3260231018066	56.7120018005371	0.00986586976796389	60.798698425293
0.474324711831287	53.4517860412598	56.9119987487793	0.00989028997719288	60.9986991882324
0.475754117360339	53.5459976196289	57.1119995117188	0.00993380974978209	61.1986999511719
0.477362191304564	53.6306381225586	57.3120002746582	0.00995177030563354	61.3987998962402
0.479148933663964	53.7300720214844	57.5120010375977	0.0100063001736999	61.5985984802246
0.480935705127195	53.8156051635742	57.7120018005371	0.0100363995879889	61.798698425293
0.482484232634306	53.9072608947754	57.9119987487793	0.0100437998771667	61.9986991882324
0.484330550534651	54.0531578063965	58.1119995117188	0.0100964996963739	62.198600769043
0.485879078041762	54.1206970214844	58.3120002746582	0.0101762004196644	62.3987007141113
0.487725395942107	54.2010116577148	58.5120010375977	0.0102557996287942	62.5987014770508
0.489154772367328	54.2390670776367	58.7120018005371	0.0102642998099327	62.7985992431641
0.490822421852499	54.342830657959	58.9119987487793	0.0103070996701717	62.9986991882324
0.492549617774785	54.4038734436035	59.1119995117188	0.0103379003703594	63.1986999511719
0.493919476866722	-29.9755363464355	59.2560005187988	0.0104572996497154	63.3986015319824