File: CSVs/24-01-08_Tensile_paper-PDMS/Laser_Coated_3/asdf.txt
File Path: C:\Users\apk5101\Desktop\Sandra\Laser_Coated_3 01-8-24 11 12 58 AM\DAQ- Crosshead, … - (Timed).txt
Test: MTS EM Tension (Simplified) with Video Extensometer apk5101 25
Test Run: Laser_Coated_3
Date: 1/8/2024 10:50:01 AM


Crosshead 	Load 	Time 	Strain 1 	Video Time
mm	N	sec	mm/mm	sec
0.000238234406424453	-0.0743433386087418	0.114000000059605	9.77905983745586E-06	4.49490022659302
0.000893379024091701	-0.0161191057413816	0.314000010490417	-4.64061995444354E-05	4.69500017166138
0.00238234406424453	0.180742844939232	0.513999998569489	-4.02426994696725E-05	4.89489984512329
0.00434777803093311	0.422079592943192	0.71399998664856	2.30540008487878E-05	5.0952000617981
0.00661100466459175	0.775962889194489	0.913999974727631	9.72820998867974E-05	5.31470012664795
0.00839776294014882	1.13799023628235	1.1139999628067	0.000106977997347713	5.49499988555908
0.0101845207609585	1.4852420091629	1.31400001049042	0.000137705996166915	5.6956000328064
0.0122095134429401	1.79804563522339	1.51400005817413	-0.00156473997049034	5.89489984512329
0.0139962712637498	2.06480383872986	1.71399998664856	0.00167567003518343	5.99860000610352
0.0157830290845595	2.37179684638977	1.91400003433228	-0.000273154000751674	6.29979991912842
0.0173911121237325	2.68064498901367	2.11400008201599	0.000163235003128648	6.49499988555908
0.0189396359928651	2.98779058456421	2.31399989128113	0.000207307995879091	6.69869995117188
0.0209050685953116	3.29490494728088	2.51399993896484	0.000592559983488172	6.89489984512329
0.0226322681555757	3.55105328559875	2.71399998664856	0.000775589025579393	7.09490013122559
0.0240616755036172	3.8058009147644	2.91400003433228	0.00214810995385051	7.29489994049072
0.0259079915849725	4.16520595550537	3.11400008201599	-0.000821436988189816	7.49490022659302
0.0274565154541051	4.43440341949463	3.31399989128113	0.00064863997977227	7.69509983062744
0.0293028315354604	4.72376585006714	3.51399993896484	0.000681768986396492	7.89860010147095
0.0310300310957246	4.99851036071777	3.71399998664856	0.000379856996005401	8.09619998931885
0.0326976733049378	5.34094381332397	3.91400003433228	0.000715940026566386	8.29489994049072
0.0341270788339898	5.63348388671875	4.11399984359741	0.00086915900465101	8.49489974975586
0.0357947174052242	5.90319967269897	4.31400012969971	0.000930121983401477	8.69480037689209
0.037581477954518	6.18058204650879	4.51399993896484	0.00103161996230483	8.89680004119873
0.0391895591747016	6.45006990432739	4.71400022506714	0.00100002996623516	9.09510040283203
0.0408572013839148	6.79062175750732	4.91400003433228	0.00104171002749354	9.30729961395264
0.0423461642640177	7.07003879547119	5.11399984359741	0.00118089001625776	9.49499988555908
0.0440733638242818	7.32203102111816	5.31400012969971	0.00127369002439082	9.69499969482422
0.0457410060334951	7.56873989105225	5.51399993896484	0.00139534997288138	9.79650020599365
0.0474682055937592	7.89702320098877	5.71400022506714	0.00140370998997241	10.0949001312256
0.0490762868139427	8.23067283630371	5.91400003433228	0.00144321995321661	10.2948999404907
0.0506843680341262	8.4830904006958	6.11399984359741	0.0012049600481987	10.4948997497559
0.0524115675943904	8.76389598846436	6.31400012969971	0.00114645005669445	10.694899559021
0.0543770038348157	9.09044361114502	6.51399993896484	0.00147873000241816	10.8949003219604
0.0558064093638677	9.385329246521	6.71400022506714	0.00136490003205836	11.0949001312256
0.0575931662751827	9.73025989532471	6.91400003433228	0.00122059998102486	11.2948999404907
0.0591416901443154	9.97006034851074	7.11399984359741	0.00132190005388111	11.5016002655029
0.0608093323535286	10.2406797409058	7.31400012969971	0.00139657000545412	11.7054996490479
0.0627747649559751	10.6096248626709	7.51399993896484	0.00145044003147632	11.9097003936768
0.0643828461761586	10.9254331588745	7.71400022506714	0.00191503996029496	12.0949001312256
0.0660504883853719	11.210693359375	7.91400003433228	0.00194927002303302	12.3073997497559
0.0675394549034536	11.4471492767334	8.11400032043457	0.00135626003611833	12.4948997497559
0.0690879751346074	11.6801300048828	8.31400012969971	0.00158234999980778	12.694899559021
0.0709938540239818	12.052734375	8.51399993896484	0.00215242989361286	12.9079999923706
0.0726019352441654	12.3761682510376	8.71399974822998	0.00191496999468654	13.0946998596191
0.0742100164643489	12.6368837356567	8.91399955749512	0.00185563997365534	13.2947998046875
0.0757585439714603	12.8589372634888	9.11400032043457	0.00193420995492488	13.4947996139526
0.0775453008827753	13.1915674209595	9.31400012969971	0.00203226995654404	13.6948003768921
0.0795107334852219	13.5897769927979	9.51399993896484	0.00193835003301501	13.894700050354
0.0809997000033036	13.8462333679199	9.71399974822998	0.00179465999826789	14.0952997207642
0.0825482202344574	14.0592269897461	9.91399955749512	0.00177315005566925	14.2947998046875
0.0840371867525391	14.2949237823486	10.1140003204346	0.00216148002073169	14.4951000213623
0.0859430583659559	14.6447334289551	10.3140001296997	0.0021764300763607	14.6948003768921
0.0875511468620971	14.9495658874512	10.5139999389648	0.00229266006499529	14.8948001861572
0.0892187817953527	15.2344646453857	10.71399974823	0.00217227009125054	15.0946998596191
0.0907077483134344	15.4628734588623	10.9139995574951	0.00207690009847283	15.2946996688843
0.0926136272028089	15.7830371856689	11.1140003204346	0.00231178989633918	15.4947996139526
0.0942812621360645	16.0958271026611	11.3140001296997	0.00225579994730651	15.6974000930786
0.0959489043452777	16.3981266021729	11.5139999389648	0.00218526995740831	15.894700050354
0.0976761075435206	16.6669330596924	11.71399974823	0.00219962000846863	16.1112003326416
0.0992246277746744	16.9133262634277	11.9139995574951	0.00236428994685411	16.2947998046875
0.100832708994858	17.2244682312012	12.1140003204346	0.00246457988396287	16.494800567627
0.102738587884232	17.5648365020752	12.3140001296997	0.00241239997558296	16.6947002410889
0.104406230093446	17.8555927276611	12.5139999389648	0.00225717993453145	16.8964996337891
0.106073865026701	18.0825939178467	12.71399974823	0.00224496005102992	17.0946998596191
0.107443716842681	18.2883930206299	12.9139995574951	0.00238556996919215	17.2952995300293
0.109051798062865	18.5937767028809	13.1140003204346	0.00230421009473503	17.4946994781494
0.111136352643371	18.9752616882324	13.3140001296997	0.00229254993610084	17.6947002410889
0.112982663267758	19.2778339385986	13.5139999389648	0.00236503989435732	17.8948001861572
0.113935602712445	19.3839149475098	13.71399974823	0.00241309008561075	18.0958003997803
0.115841481601819	19.7164516448975	13.9139995574951	0.00244192988611758	18.2947006225586
0.117390001832973	20.0326900482178	14.1140003204346	0.00240994989871979	18.494800567627
0.119236319733318	20.3638725280762	14.3140001296997	0.00278464006260037	18.6947994232178
0.120963515655603	20.6111660003662	14.5139999389648	0.00285039003938437	18.8950996398926
0.122571596875787	20.83473777771	14.71399974823	0.0029341799672693	19.0949001312256
0.124239246360958	21.1531066894531	14.9139995574951	0.00298870005644858	19.2963008880615
0.125966442283243	21.5010185241699	15.1140003204346	0.00301424995996058	19.4946002960205
0.127931882161647	21.8199329376221	15.3140001296997	0.00276776007376611	19.6947994232178
0.129480395116843	22.0239868164063	15.5139999389648	0.00402228021994233	19.8966999053955
0.131088483612984	22.2817497253418	15.71399974823	0.00120195001363754	20.0946998596191
0.13275611854624	22.6001815795898	15.9139995574951	0.00128974998369813	20.2947998046875
0.134483314468525	22.8916416168213	16.1140003204346	0.00276123988442123	20.4946994781494
0.136150963953696	23.1659030914307	16.3139991760254	0.00280661997385323	20.6945991516113
0.137818598886952	23.3831005096436	16.5139999389648	0.00284678000025451	20.8948001861572
0.139367126394063	23.6562519073486	16.7140007019043	0.00286337989382446	21.0946006774902
0.140975214890204	23.9584655761719	16.9139995574951	0.003087850054726	21.2947006225586
0.14264284982346	24.2435874938965	17.1140003204346	0.00301600992679596	21.4946002960205
0.144429606734775	24.4904117584229	17.3139991760254	0.00288199004717171	21.6945991516113
0.146037695230916	24.719518661499	17.5139999389648	0.00277810008265078	21.8946990966797
0.147586208186112	25.0072956085205	17.7140007019043	0.00182910996954888	22.0946006774902
0.149075174704194	25.290620803833	17.9139995574951	0.00463367998600006	22.2952003479004
0.150683263200335	25.5351963043213	18.1140003204346	0.00168155005667359	22.4951992034912
0.15258914208971	25.7860851287842	18.3139991760254	0.00169959000777453	22.6945991516113
0.154197216033936	26.0376510620117	18.5139999389648	0.00479047000408173	22.8945999145508
0.155805304530077	26.3181419372559	18.7140007019043	0.00209909002296627	23.0958995819092
0.157472939463332	26.6124877929688	18.9139995574951	0.00169941002968699	23.2945003509521
0.158902344992384	26.8019351959229	19.1140003204346	0.00181211996823549	23.4974002838135
0.160689101903699	27.0530700683594	19.3139991760254	0.00181912002153695	23.6944999694824
0.162416297825985	27.3625888824463	19.5139999389648	0.00187514000572264	23.8948001861572
0.163964825333096	27.6507186889648	19.7140007019043	0.00189514004159719	24.0944995880127
0.165572913829237	27.8854923248291	19.9139995574951	0.00288348994217813	24.2952995300293
0.167419231729582	28.1455135345459	20.1140003204346	0.00353002990595996	24.4946002960205
0.169086866662838	28.3877029418945	20.3139991760254	0.00365854008123279	24.6947002410889
0.170873623574153	28.7227973937988	20.5139999389648	0.00369815994054079	24.8945007324219
0.172422151081264	28.9894142150879	20.7140007019043	0.00342605006881058	25.0949993133545
0.174328029970638	29.2626705169678	20.9139995574951	0.00340392999351025	25.2945995330811
0.176174347870983	29.5128040313721	21.1140003204346	0.00357690989039838	25.4946002960205
0.177961104782298	29.8176155090332	21.3139991760254	0.0034945800434798	25.6944999694824
0.179509617737494	30.0858669281006	21.5139999389648	0.00377952004782856	25.8946990966797
0.181177267222665	30.3611469268799	21.7140007019043	0.003460279898718	26.0946006774902
0.182666233740747	30.5505294799805	21.9139995574951	0.00359704997390509	26.2952995300293
0.184512551641092	30.8376693725586	22.1140003204346	0.0037040701135993	26.4974002838135
0.185941957170144	31.0780143737793	22.3139991760254	0.00380240008234978	26.6956005096436
0.187728714081459	31.3650321960449	22.5139999389648	0.00352978007867932	26.8957996368408
0.189277227036655	31.5889587402344	22.7140007019043	0.00347920996136963	27.0949993133545
0.190825754543766	31.7867031097412	22.9139995574951	0.00348312989808619	27.2945003509521
0.192672072444111	32.0707206726074	23.1140003204346	0.00349946995265782	27.4957008361816
0.194339721929282	32.3656578063965	23.3139991760254	0.00552192982286215	27.6944999694824
0.195828673895448	32.6021766662598	23.5139999389648	0.00244397995993495	27.8945007324219
0.197555884369649	32.8191947937012	23.7140007019043	0.00541078019887209	28.0949993133545
0.199104397324845	33.0180015563965	23.9139995574951	0.00551183987408876	28.2945995330811
0.201188959181309	33.3898963928223	24.1140003204346	0.00546558992937207	28.4946002960205
0.202618364710361	33.6316146850586	24.3139991760254	0.00544050009921193	28.5946006774902
0.203988209250383	33.833740234375	24.5139999389648	0.00547203002497554	28.8964996337891
0.205655844183639	34.0212135314941	24.7140007019043	0.00332381995394826	29.0944995880127
0.207502162083983	34.3107147216797	24.9139995574951	0.00252691004425287	29.2961006164551
0.209288918995298	34.6225547790527	25.1140003204346	0.00265151006169617	29.4944000244141
0.210956568480469	34.8822822570801	25.3139991760254	0.00264439010061324	29.6945991516113
0.212505081435665	35.0872764587402	25.5139999389648	0.00389934005215764	29.8945999145508
0.214172730920836	35.2824859619141	25.7140007019043	0.0043562101200223	30.0944995880127
0.215959487832151	35.5675621032715	25.9139995574951	0.00383139005862176	30.2945003509521
0.217805805732496	35.8726844787598	26.1140003204346	0.00435202987864614	30.494499206543
0.219354333239608	36.1072463989258	26.3139991760254	0.00400651013478637	30.6944007873535
0.221021968172863	36.3003959655762	26.5139999389648	0.00412470009177923	30.8945999145508
0.222630056669004	36.5148124694824	26.7140007019043	0.00427045999094844	31.0946006774902
0.224416813580319	36.8254470825195	26.9139995574951	0.00427302997559309	31.2945995330811
0.226084448513575	37.1118316650391	27.1140003204346	0.00422972999513149	31.4944000244141
0.227692537009716	37.3221702575684	27.3139991760254	0.00424350006505847	31.6944999694824
0.229241049964912	37.4894218444824	27.5139999389648	0.00420662015676498	31.8945007324219
0.230908699450083	37.7405815124512	27.7140007019043	0.0043010301887989	32.0945014953613
0.232635895372368	38.0268630981445	27.9139995574951	0.00417328998446465	32.2944984436035
0.234303530305624	38.2747459411621	28.1140003204346	0.00418605003505945	32.494499206543
0.235971179790795	38.4816741943359	28.3139991760254	0.00425386009737849	32.6944999694824
0.237460146308877	38.655158996582	28.5139999389648	0.00425712019205093	32.894401550293
0.239366010646336	38.9424171447754	28.7140007019043	0.00430577015504241	33.0945014953613
0.240914538153447	39.189640045166	28.9139995574951	0.00430712988600135	33.2944984436035
0.242760856053792	39.4671592712402	29.1140003204346	0.00443333992734551	33.4944000244141
0.244368944549933	39.6366310119629	29.3139991760254	0.00454164016991854	33.6944999694824
0.246036594035104	39.8632164001465	29.5139999389648	0.00456932978704572	33.8942985534668
0.247585092438385	40.1095161437988	29.7140007019043	0.00456866016611457	34.094799041748
0.249252741923556	40.3873481750488	29.9139995574951	0.00458115013316274	34.2943992614746
0.250979937845841	40.5994186401367	30.1140003204346	0.00501004979014397	34.4943008422852
0.252468918915838	40.7540588378906	30.3139991760254	0.00454922998324037	34.6943016052246
0.254076992860064	40.9927444458008	30.5139999389648	0.0047070998698473	34.894401550293
0.255923310760409	41.3023643493652	30.7140007019043	0.00473697017878294	35.0971984863281
0.257769628660753	41.5533485412598	30.9139995574951	0.00494528980925679	35.2943992614746
0.259377702604979	41.7369422912598	31.1140003204346	0.00494431983679533	35.4944000244141
0.261104898527265	41.942138671875	31.3139991760254	0.00463744020089507	35.6953010559082
0.262593879597262	42.1650085449219	31.5139999389648	0.00448566023260355	35.894401550293
0.264321075519547	42.4419479370117	31.7140007019043	0.00451370980590582	36.0943984985352
0.266048271441832	42.6637306213379	31.9139995574951	0.00496107013896108	36.2943992614746
0.267656345386058	42.8350028991699	32.1139984130859	0.00478244991973042	36.4958000183105
0.269145326456055	43.0107498168945	32.3139991760254	0.00440210988745093	36.6944007873535
0.270574731985107	43.233211517334	32.5139999389648	0.00456072017550468	36.8942985534668
0.272599718300626	43.5630912780762	32.7140007019043	0.00476081995293498	37.0946006774902
0.274267367785797	43.7327995300293	32.9140014648438	0.00483189010992646	37.2943992614746
0.275518075795844	43.8426208496094	33.1139984130859	0.00482460996136069	37.4944000244141
0.277304847259074	44.1035346984863	33.3139991760254	0.00484575983136892	37.69580078125
0.27903204318136	44.3804244995117	33.5139999389648	0.00483151990920305	37.8942985534668
0.28081881464459	44.6142997741699	33.7140007019043	0.00492516998201609	38.0942993164063
0.28260555700399	44.7972602844238	33.9140014648438	0.00501717021688819	38.2943000793457
0.284332752926275	45.0134315490723	34.1139984130859	0.00507298996672034	38.4944000244141
0.285881280433387	45.2491645812988	34.3139991760254	0.00511363986879587	38.6944007873535
0.287310685962439	45.4629173278809	34.5139999389648	0.00510630011558533	38.8942985534668
0.289097457425669	45.6904716491699	34.7140007019043	0.00522190006449819	39.0950012207031
0.291062897304073	45.9148483276367	34.9140014648438	0.00533126993104815	39.2952003479004
0.292790093226358	46.1292953491211	35.1139984130859	0.00533417006954551	39.4944000244141
0.294100376777351	46.3391227722168	35.3139991760254	0.00531403999775648	39.6946983337402
0.295648904284462	46.5423202514648	35.5139999389648	0.00511620007455349	39.8942985534668
0.297852559015155	46.7872276306152	35.7140007019043	0.00560691999271512	40.0950012207031
0.299520208500326	46.968994140625	35.9140014648438	0.00581694999709725	40.2942008972168
0.301068736007437	47.1971969604492	36.1139984130859	0.00555258011445403	40.494499206543
0.302736356388777	47.4319343566895	36.3139991760254	0.00525414990261197	40.6941986083984
0.304344459436834	47.5985260009766	36.5139999389648	0.00501277996227145	40.8941993713379
0.306131201796234	47.7975006103516	36.7140007019043	0.0051469998434186	41.0960998535156
0.307798851281404	47.9870719909668	36.9140014648438	0.00780841009691358	41.2958984375
0.30940692522563	48.2248954772949	37.1139984130859	0.00602617999538779	41.4942016601563
0.310836330754682	48.419189453125	37.3139991760254	0.00563406012952328	41.6941986083984
0.312623102217913	48.6327247619629	37.5139999389648	0.00553203979507089	41.894100189209
0.314290751703084	48.7775382995605	37.7140007019043	0.00546800019219518	42.095100402832
0.315898825647309	48.9972152709961	37.9140014648438	0.00578424008563161	42.2951011657715
0.31756644602865	49.2360763549805	38.1139984130859	0.00567580992355943	42.4942016601563
0.319174549076706	49.4506797790527	38.3139991760254	0.00562252989038825	42.6941986083984
0.320901744998991	49.6185531616211	38.5139999389648	0.00570916011929512	42.894100189209
0.322748062899336	49.8395080566406	38.7140007019043	0.00576322991400957	43.0942001342773
0.324356136843562	50.0647010803223	38.9140014648438	0.0057263202033937	43.298698425293
0.325964210787788	50.2831382751465	39.1139984130859	0.00578317977488041	43.4954986572266
0.327512738294899	50.4091339111328	39.3139991760254	0.00593265984207392	43.6941986083984
0.32929950975813	50.5945587158203	39.5139999389648	0.00591437006369233	43.8942985534668
0.330848037265241	50.8081817626953	39.7140007019043	0.00596466008573771	44.0942993164063
0.332575233187526	51.057201385498	39.9140014648438	0.00597637984901667	44.2942008972168
0.334242882672697	51.2574615478516	40.1139984130859	0.00602997001260519	44.4940986633301
0.335672288201749	51.371467590332	40.3139991760254	0.00651053991168737	44.6940994262695
0.337459030561149	51.5640106201172	40.5139999389648	0.00626350985839963	44.8942985534668
0.339424470439553	51.8572807312012	40.7140007019043	0.00625558011233807	45.0942001342773
0.340734753990546	52.0148811340332	40.9140014648438	0.00599296996369958	45.2942008972168
0.342640618328005	52.2453422546387	41.1139984130859	0.00644569005817175	45.4942016601563
0.344129599398002	52.3344841003418	41.3139991760254	0.00581497978419065	45.6941986083984
0.345916341757402	52.5534515380859	41.5139999389648	0.00651685986667871	45.8941993713379
0.347703113220632	52.8052368164063	41.7140007019043	0.00644750008359551	46.0942001342773
0.349311187164858	52.9761962890625	41.9140014648438	0.00593204982578754	46.1941986083984
0.35074059269391	53.1039199829102	42.1139984130859	0.00608365004882216	46.4939994812012
0.352467788616195	53.2673683166504	42.3139991760254	0.00608982983976603	46.6941986083984
0.354075891664252	53.4768524169922	42.5139999389648	0.00644445000216365	46.8941993713379
0.355922209564596	53.7541732788086	42.7140007019043	0.00635026022791862	47.0942001342773
0.357589829945937	53.9237213134766	42.9140014648438	0.00623894995078444	47.2941017150879
0.359019235474989	54.020580291748	43.1139984130859	0.00621192017570138	47.3941993713379
0.360746460501105	54.2230834960938	43.3139991760254	0.00657455017790198	47.6941986083984
0.362771446816623	54.498119354248	43.5139999389648	0.00644583022221923	47.894100189209
0.364617764716968	54.7696762084961	43.7140007019043	0.0063159498386085	48.0942001342773
0.365749379852787	54.8262519836426	43.9140014648438	0.00634557008743286	48.2942008972168
0.367536122212186	54.9958992004395	44.1139984130859	0.00647288979962468	48.4940986633301
0.369263318134472	55.178638458252	44.3139991760254	0.00654197996482253	48.6940002441406
0.37140742642805	55.5011024475098	44.5139999389648	0.00649981992319226	48.8953018188477
0.372836831957102	55.6621894836426	44.7140007019043	0.00658485991880298	49.0940017700195
0.374504481442273	55.792064666748	44.9140014648438	0.00666269985958934	49.2983016967773
0.375993433408439	55.8964195251465	45.1139984130859	0.00673558004200459	49.4940986633301
0.377720658434555	56.1410980224609	45.3139991760254	0.00678593013435602	49.6940994262695
0.379388278815895	56.3541717529297	45.5139999389648	0.00675363978371024	49.894100189209
0.380936806323007	56.5137023925781	45.7140007019043	0.00691627012565732	49.9959983825684
0.382723577786237	56.6806640625	45.9140014648438	0.00777558982372284	50.2939987182617
0.384152983315289	56.7990684509277	46.1139984130859	0.00704760011285543	50.4956016540527
0.385880179237574	57.0190658569336	46.3139991760254	0.00703806988894939	50.6940994262695
0.387666921596974	57.2358589172363	46.5139999389648	0.00674019986763597	50.894100189209
0.389513239497319	57.4277648925781	46.7140007019043	0.00696907006204128	51.0938987731934
0.390942645026371	57.5166816711426	46.9140014648438	0.00689586019143462	51.2939987182617
0.392491172533482	57.6627769470215	47.1139984130859	0.00733174988999963	51.4940986633301
0.394099275581539	57.8697929382324	47.3139991760254	0.00688453018665314	51.6940002441406
0.395945593481883	58.0882835388184	47.5139999389648	0.00655301008373499	51.8939018249512
0.39743454544805	58.1859397888184	47.7140007019043	0.00687106978148222	52.094898223877
0.399102194933221	58.3308792114258	47.9140014648438	0.00756218982860446	52.2939987182617
0.400650722440332	58.4969062805176	48.1139984130859	0.0069797202013433	52.4939002990723
0.402258796384558	58.7084808349609	48.3139991760254	0.0070766001008451	52.6940002441406
0.404283782700077	58.9540481567383	48.5139999389648	0.00706548010930419	52.8940010070801
0.405891856644303	59.0559844970703	48.7140007019043	0.00711680017411709	53.0938987731934
0.407559506129473	59.2208518981934	48.9140014648438	0.00715071987360716	53.2939987182617
0.409227155614644	59.4278526306152	49.1139984130859	0.0071943299844861	53.4939994812012
0.410894775995985	59.6261596679688	49.3139991760254	0.00725068990141153	53.6939010620117
0.412800669437274	59.8362045288086	49.5139999389648	0.00731938006356359	53.8939018249512
0.4144087433815	59.9302368164063	49.7140007019043	0.00737952999770641	54.0940017700195
0.416076392866671	60.091983795166	49.9140014648438	0.00738287018612027	54.2938995361328
0.417624920373783	60.2973022460938	50.1139984130859	0.00741410022601485	54.4939002990723
0.419471238274127	60.5133476257324	50.3139991760254	0.00750826019793749	54.6944999694824
0.421198434196413	60.6482276916504	50.5139999389648	0.00763172982260585	54.894401550293
0.42256826418452	60.7208976745605	50.7140007019043	0.00763174006715417	55.0940017700195
0.42423591366969	60.9171295166016	50.9140014648438	0.00759594980627298	55.2939987182617
0.425784441176802	61.1030616760254	51.1139984130859	0.00763690983876586	55.4938011169434
0.427571183536202	61.269962310791	51.3139991760254	0.00745641021057963	55.6939010620117
0.429298408562317	61.4018096923828	51.5139999389648	0.00774696003645658	55.8939018249512
0.43072781409137	61.5239448547363	51.7140007019043	0.0078467195853591	56.0940017700195
0.432335888035595	61.6809997558594	51.9140014648438	0.00931038986891508	56.2939987182617
0.434122630394995	61.88134765625	52.1139984130859	0.00630922988057137	56.4939994812012
0.435849855421111	62.0148048400879	52.3139991760254	0.00671968003734946	56.6939010620117
0.437815266195685	62.189208984375	52.5139999389648	0.00636831996962428	56.8940010070801
0.439185125287622	62.3062973022461	52.7140007019043	0.00760000012814999	57.0940017700195
0.440674077253789	62.4736633300781	52.9140014648438	0.00759712979197502	57.2939987182617
0.442520395154133	62.6427192687988	53.1139984130859	0.00777016999199986	57.4939002990723
0.444366713054478	62.2952613830566	53.3139991760254	0.00781605020165443	57.6939010620117
0.446153484517708	62.4000778198242	53.5139999389648	0.00794047955423594	57.8958015441895
0.447523314505816	62.5567092895508	53.7140007019043	0.00812031980603933	58.0938987731934
0.449190963990986	62.7633819580078	53.9140014648438	0.00795844011008739	58.2939987182617
0.450858613476157	62.8870964050293	54.1139984130859	0.00797876995056868	58.4954986572266
0.452645355835557	63.0709037780762	54.3139991760254	0.00804971996694803	58.6939010620117
0.454372580861673	63.265869140625	54.5139999389648	0.00802299007773399	58.893798828125
0.456278445199132	63.505500793457	54.7140007019043	0.00797125045210123	59.0950012207031
0.457052694400772	63.4895935058594	54.9140014648438	0.00809090957045555	59.2953987121582
0.45931592467241	63.7176055908203	55.1139984130859	0.00818912032991648	59.4950981140137
0.46110269613564	63.8677291870117	55.3139991760254	0.00823836028575897	59.6939010620117
0.462651223642752	64.0470886230469	55.5139999389648	0.00826654024422169	59.8939018249512
0.464199722046033	64.2190704345703	55.7140007019043	0.00828344002366066	60.0937995910645
0.465867371531203	64.353515625	55.9140014648438	0.00837630033493042	60.2938003540039
0.467654142994434	64.5060272216797	56.1139984130859	0.0084824301302433	60.4938011169434
0.469321763375774	64.6683349609375	56.3139991760254	0.00849501043558121	60.6938018798828
0.470989412860945	64.8680572509766	56.5139999389648	0.00850030966103077	60.8939018249512
0.472776184324175	65.0453262329102	56.7140007019043	0.00860419031232595	61.0938987731934
0.474205589853227	65.1210327148438	56.9140014648438	0.00901663955301046	61.2938995361328
0.475754117360339	65.2194595336914	57.1139984130859	0.00877248030155897	61.4936981201172
0.477540859719738	65.4250183105469	57.3139991760254	0.00876365043222904	61.6986999511719
0.479208509204909	65.6005706787109	57.5139999389648	0.00847467035055161	61.8939018249512
0.480697461171076	65.7121353149414	57.7140007019043	0.0083355400711298	62.094898223877
0.48254377907142	65.8391342163086	57.9140014648438	0.00823917984962463	62.2938003540039
0.484211428556591	65.9697494506836	58.1139984130859	0.00908484030514956	62.4939002990723
0.485998170915991	66.189826965332	58.3139991760254	0.00830685999244452	62.6938018798828
0.487606273964047	66.3419952392578	58.5139999389648	0.00897250976413488	62.893798828125
0.489273923449218	66.4742202758789	58.7140007019043	0.00883437972515821	63.0937995910645
0.490881968289614	66.5522003173828	58.9140014648438	0.00839531980454922	63.2938003540039
0.492728315293789	66.7498931884766	59.1139984130859	0.00860762968659401	63.4936981201172
0.49427681369707	66.9050750732422	59.3139991760254	0.00898166000843048	63.6939010620117
0.496004009619355	67.0573806762695	59.5139999389648	0.00897474959492683	63.8936004638672
0.497612112667412	67.144401550293	59.7140007019043	0.00897836033254862	64.0938034057617
0.499398855026811	67.2859420776367	59.9140014648438	0.00900586042553186	64.293701171875
0.501304748468101	67.5183563232422	60.1139984130859	0.00898457039147615	64.4936981201172
0.503091490827501	67.6970748901367	60.3139991760254	0.00902136974036694	64.6949005126953
0.504699593875557	67.7935333251953	60.5139999389648	0.00916428025811911	64.8958969116211
0.506069452967495	67.8334732055664	60.7140007019043	0.00930048990994692	65.0936965942383
0.50767749780789	67.9735946655273	60.9140014648438	0.00929473992437124	65.2944030761719
0.509345147293061	68.1218032836914	61.1139984130859	0.00928428955376148	65.4936981201172
0.511012796778232	68.2958908081055	61.3139991760254	0.00937435962259769	65.6937026977539
0.512442202307284	68.3444137573242	61.5139999389648	0.00984388962388039	65.8936996459961
0.51393115427345	68.4049301147461	61.7140007019043	0.00964313000440598	66.0936965942383
0.515598803758621	68.548469543457	61.9140014648438	0.0096144201233983	66.293701171875
0.517445150762796	68.7811737060547	62.1139984130859	0.00941605027765036	66.4949035644531
0.519350985996425	68.9519119262695	62.3139991760254	0.00966633018106222	66.693603515625
0.520720845088363	68.9747467041016	62.5139999389648	0.00949420966207981	66.893798828125
0.522150250617415	69.0460357666016	62.7140007019043	0.00941095035523176	67.0936965942383
0.524175236932933	69.2809753417969	62.9140014648438	0.00971841998398304	67.2936019897461
0.526021583937109	69.4408493041992	63.1139984130859	0.00958881992846727	67.4935989379883
0.527629628777504	69.5525207519531	63.3139991760254	0.00958546996116638	67.6937026977539
0.52923773182556	69.6325988769531	63.5139999389648	0.00990580022335052	67.8947982788086
0.530726683791727	69.6986618041992	63.7140007019043	0.00972072966396809	68.0935974121094
0.532513426151127	69.9021682739258	63.9140014648438	0.00978169031441212	68.293701171875
0.534359773155302	70.0746536254883	64.1139984130859	0.00979204010218382	68.4936981201172
0.536027422640473	70.1570587158203	64.3140029907227	0.00986041035503149	68.693603515625
0.537635467480868	70.2529678344727	64.5139999389648	0.00993612036108971	68.8936996459961
0.539243570528924	70.3803253173828	64.713996887207	0.00996263045817614	69.0935974121094
0.541030312888324	70.5631942749023	64.9140014648438	0.00998857989907265	69.2936019897461
0.542697962373495	70.6816253662109	65.1139984130859	0.00854394026100636	69.4951019287109
0.544484704732895	70.7957077026367	65.3140029907227	0.00820272974669933	69.6949996948242
0.545854563824832	70.8543243408203	65.5139999389648	0.00988565012812614	69.8936004638672
0.547522213310003	71.032829284668	65.713996887207	0.0100146997720003	70.0936965942383
0.549487653188407	71.2032623291016	65.9140014648438	0.00968866981565952	70.2936019897461
0.551274395547807	71.3017578125	66.1139984130859	0.00997245032340288	70.4936981201172
0.552882498595864	71.3923110961914	66.3140029907227	0.00976044032722712	70.6957015991211
0.554252357687801	71.4686584472656	66.5139999389648	0.00987367983907461	70.8936004638672
0.555920007172972	71.638427734375	66.713996887207	0.00976848974823952	71.0935974121094
0.557468505576253	71.7322845458984	66.9140014648438	0.00977370981127024	71.2935028076172
0.559136155061424	71.8188705444336	67.1139984130859	0.00980888027697802	71.4957962036133
0.560863350983709	71.9118957519531	67.3140029907227	0.00984254013746977	71.693603515625
0.562173663638532	72.0163269042969	67.5139999389648	0.00989133957773447	71.8936004638672
0.564079498872161	72.2008285522461	67.713996887207	0.00992979016155005	72.0934982299805
0.565747148357332	72.2898025512695	67.9140014648438	0.0100675001740456	72.2936019897461
0.567355251405388	72.3504180908203	68.1139984130859	0.0101284002885222	72.4951019287109
0.569082447327673	72.4984436035156	68.3140029907227	0.0101126004010439	72.6934967041016
0.570928736124188	72.683464050293	68.5139999389648	0.0101990001276135	72.8935012817383
0.572239048779011	72.7152633666992	68.713996887207	0.00993505027145147	73.0934982299805
0.5741449422203	72.8480987548828	68.9140014648438	0.0105347996577621	73.2936019897461
0.575872138142586	72.9584808349609	69.1139984130859	0.0125989997759461	73.4935989379883
0.577539729420096	73.0769271850586	69.3140029907227	0.0111961998045444	73.693603515625
0.579028739593923	73.1895370483398	69.5139999389648	0.0103214997798204	73.8936004638672
0.580875028390437	73.3344268798828	69.713996887207	0.0102981999516487	74.0935974121094
0.582780921831727	73.4590530395508	69.9140014648438	0.0105093000456691	74.2934036254883
0.584567664191127	73.5877838134766	70.1139984130859	0.00990481022745371	74.4934997558594
0.586235313676298	73.6868667602539	70.3140029907227	0.0104476995766163	74.6933975219727
0.587843416724354	73.8154907226563	70.5139999389648	0.0102623999118805	74.8936004638672
0.589630159083754	73.8971405029297	70.713996887207	0.0103377997875214	75.0934982299805
0.591357355006039	73.9660949707031	70.9140014648438	0.0103380000218749	75.2936019897461
0.592965458054096	74.0581588745117	71.1139984130859	0.0103294001892209	75.4934005737305
0.594513956457376	74.1740798950195	71.3140029907227	0.0102340998128057	75.6933975219727
0.595943361986428	74.2034759521484	71.5139999389648	0.0104019995778799	75.8935012817383
0.597551465034485	74.2557525634766	71.713996887207	0.0105219995602965	76.0934982299805
0.599219056311995	74.3597717285156	71.9140014648438	0.0106378998607397	76.2935028076172
0.60106540331617	74.5176849365234	72.1139984130859	0.0105942999944091	76.4934005737305
0.602613901719451	74.5902481079102	72.3140029907227	0.0106472000479698	76.6933975219727
0.603924214374274	74.5798950195313	72.5139999389648	0.0108171999454498	76.8939971923828
0.605770503170788	74.643684387207	72.713996887207	0.0108502004295588	77.0933990478516
0.607616850174963	74.7225494384766	72.9140014648438	0.0108657004311681	77.2935028076172
0.609403592534363	74.849479675293	73.1139984130859	0.0112097999081016	77.4934997558594
0.61101169558242	74.9176254272461	73.3140029907227	0.0105668995529413	77.6934967041016
0.612381554674357	74.7981033325195	73.5139999389648	0.0108728995546699	77.893798828125
0.614525633864105	74.671745300293	73.713996887207	0.0105243995785713	78.0941009521484
0.61625282978639	74.3099594116211	73.9140014648438	0.010482800193131	78.2935028076172
0.617860932834446	73.6196899414063	74.1139984130859	0.0102907996624708	78.4934997558594
0.619528582319617	72.1581954956055	74.3140029907227	0.0103689003735781	78.6934967041016
0.620302802417427	-13.3974714279175	74.4300003051758	0.0102385003119707	78.7932968139648