File: CSVs/24-01-08_Tensile_paper-PDMS/na_Uncoated_3/asdf.txt
File Path: C:\Users\apk5101\Desktop\Sandra\Uncoated_3 01-8-24 11 12 58 AM\DAQ- Crosshead, … - (Timed).txt
Test: MTS EM Tension (Simplified) with Video Extensometer apk5101 25
Test Run: Uncoated_3
Date: 1/8/2024 10:22:26 AM


Crosshead 	Load 	Time 	Strain 1 	Video Time
mm	N	sec	mm/mm	sec
0.000416910211242794	7.90925788879395	0.112000003457069	-1.53037999552907E-05	5.69990015029907
0.00136984783694061	7.88971662521362	0.312000006437302	3.10532996081747E-05	5.89989995956421
0.00232278534895158	8.01015949249268	0.512000024318695	-9.41168036661111E-06	6.09989976882935
0.00428821931564016	8.36959934234619	0.712000012397766	-7.66166976973182E-06	6.29990005493164
0.00637277025816729	8.72211647033691	0.912000000476837	0.000103122001746669	6.59989976882935
0.00833820377010852	9.03248500823975	1.11199998855591	0.000107177998870611	6.79979991912842
0.0101249625004129	9.34843158721924	1.31200003623962	0.000127423001686111	6.89979982376099
0.0118521611511824	9.68631076812744	1.51199996471405	0.000175528999534436	7.09980010986328
0.0138175955726183	10.0897970199585	1.71200001239777	0.000197611007024534	7.29979991912842
0.015604353393428	10.3832063674927	1.91199994087219	0.000230557998293079	7.49980020523071
0.0173315529536922	10.6416053771973	2.11199998855591	0.000252219993853942	7.69990015029907
0.0189396359928651	10.9353466033936	2.31200003623962	0.000287670991383493	7.99980020523071
0.0207859520742204	11.2781295776367	2.51200008392334	0.000295195990474895	8.09980010986328
0.0221558002522215	11.5222635269165	2.71199989318848	0.000362763996236026	8.29990005493164
0.0242403511947487	11.867392539978	2.91199994087219	0.000374333001673222	8.49979972839355
0.0258484324149322	12.1300859451294	3.11199998855591	0.000406211009249091	8.69979953765869
0.0273969562840648	12.397834777832	3.31200003623962	0.000454483000794426	8.89980030059814
0.0292432723654201	12.7481708526611	3.51200008392334	0.00043600398930721	9.19979953765869
0.0308513554045931	13.0167722702026	3.71199989318848	0.000557064020540565	9.29979991912842
0.0325189976138063	13.273889541626	3.91199994087219	0.000562580011319369	9.49979972839355
0.0340675214829389	13.5307760238647	4.11199998855591	0.000578213017433882	9.69979953765869
0.0357351600541733	13.8330488204956	4.31199979782104	0.000614647986367345	9.89980030059814
0.0373432412743568	14.1364164352417	4.51200008392334	0.000672247027978301	10.1997995376587
0.0391895591747016	14.4035110473633	4.71199989318848	0.000672889000270516	10.3998003005981
0.0407380830438342	14.6336765289307	4.91200017929077	0.000707836996298283	10.4997997283936
0.0422270495619159	14.9036426544189	5.11199998855591	0.000723216973710805	10.6997995376587
0.0438946881331503	15.2034301757813	5.31199979782104	0.000765560020226985	10.8998003005981
0.0455623303423636	15.4968662261963	5.51200008392334	0.000780133996158838	11.0996999740601
0.0474086446047295	15.7589750289917	5.71199989318848	0.00117003999184817	11.2996997833252
0.0490167294628918	16.0094833374023	5.91200017929077	0.000863822991959751	11.5996999740601
0.0506843680341262	16.3099212646484	6.11199998855591	0.000876646023243666	11.6997995376587
0.0524115675943904	16.617790222168	6.31199979782104	0.000885848014149815	11.8997001647949
0.0539005341124721	16.8409614562988	6.51200008392334	0.000948033994063735	12.0996999740601
0.0559850850549992	17.1794395446777	6.71199989318848	0.00100464001297951	12.2997999191284
0.0575336089241318	17.4282646179199	6.91200017929077	0.000954693998210132	12.4996995925903
0.0590225718042348	17.6977348327637	7.11199998855591	0.00062182400142774	12.7996997833252
0.0608093323535286	18.0090751647949	7.31199979782104	0.00102984998375177	12.9996995925903
0.0625960892648436	18.2742137908936	7.51200008392334	0.00109395000617951	13.0996999740601
0.0643828461761586	18.5531005859375	7.71199989318848	0.00113532994873822	13.2996997833252
0.0659909273963422	18.843225479126	7.91200017929077	0.0011628499487415	13.4996995925903
0.0670034278300591	19.015115737915	8.11200046539307	0.00130580994300544	13.6997003555298
0.0691475361236371	19.3548717498779	8.3120002746582	0.0011929499451071	13.9996995925903
0.0706960563547909	19.5683650970459	8.51200008392334	0.00124732998665422	14.1996002197266
0.0724828205420636	19.8647270202637	8.71199989318848	0.00122705998364836	14.2996997833252
0.0740909017622471	20.1582412719727	8.91199970245361	0.00130351004190743	14.4996995925903
0.0756394219934009	20.4174137115479	9.11200046539307	0.0013182699913159	14.6997003555298
0.0773666251916438	20.6660175323486	9.3120002746582	0.001393310027197	14.8996000289917
0.0792129358160309	20.9470996856689	9.51200008392334	0.00138916005380452	15.0995998382568
0.0808210243121721	21.221700668335	9.71199989318848	0.0014466600259766	15.3996000289917
0.0824886592454277	21.5004444122314	9.91199970245361	0.00143278995528817	15.4996004104614
0.0840371867525391	21.7488460540771	10.1120004653931	0.00146149995271116	15.6996002197266
0.0857048289617524	21.9598007202148	10.3120002746582	0.00154420000035316	15.8996000289917
0.0874915858730674	22.2327728271484	10.5120000839233	0.00153198000043631	16.0995998382568
0.0892783427843824	22.5465965270996	10.7119998931885	0.00157164002303034	16.2996997833252
0.0907673093024641	22.8023433685303	10.9119997024536	0.00162872998043895	16.5995998382568
0.0924349515116774	23.0438861846924	11.1120004653931	0.00164768996182829	16.6996002197266
0.0939239107538015	23.2501182556152	11.3120002746582	0.00163227994926274	16.8995990753174
0.0960084653343074	23.6071128845215	11.5120000839233	0.0016942200018093	17.0995998382568
0.0977356612565927	23.92112159729	11.7119998931885	0.00174958002753556	17.3474998474121
0.0991650740616024	24.1341190338135	11.9119997024536	0.00175327004399151	17.4995994567871
0.100892269983888	24.3691596984863	12.1120004653931	0.00178589997813106	17.7996006011963
0.102679026895203	24.6122951507568	12.3120002746582	0.0017965700244531	17.9995994567871
0.104287108115386	24.8852844238281	12.5120000839233	0.00185096997302026	18.0995998382568
0.105954750324599	25.1748714447021	12.7119998931885	0.0018595700385049	18.2996006011963
0.107443716842681	25.3760509490967	12.9119997024536	0.00189104001037776	18.4995994567871
0.109409149445128	25.6571464538574	13.1120004653931	0.0019085300154984	18.6996002197266
0.110779001261108	25.8346824645996	13.3120002746582	0.00192963995505124	18.9995994567871
0.112387082481291	26.1090507507324	13.5120000839233	0.0019686899613589	19.1996002197266
0.114233393105678	26.408821105957	13.7119998931885	0.00197167997248471	19.2996006011963
0.11572235962376	26.5946826934814	13.9119997024536	0.00204782001674175	19.4995002746582
0.117330440843944	26.8017864227295	14.1120004653931	0.00206653005443513	19.6996002197266
0.119176758744288	27.1282939910889	14.3120002746582	0.00206295005045831	19.8995990753174
0.120963515655603	27.4449329376221	14.5120000839233	0.00211041001603007	20.0997009277344
0.122631157864816	27.6815547943115	14.7119998931885	0.00213769008405507	20.2994995117188
0.124120124382898	27.8704586029053	14.9119997024536	0.00213903002440929	20.5995006561279
0.126145110698417	28.1740474700928	15.1120004653931	0.00214012991636992	20.699499130249
0.127753199194558	28.4181594848633	15.3120002746582	0.00220065005123615	20.8994998931885
0.129599517094903	28.7383079528809	15.5120000839233	0.00221567996777594	21.0995998382568
0.131088483612984	28.9499683380127	15.7119998931885	0.00226149009540677	21.2994995117188
0.132577450131066	29.1122093200684	15.9119997024536	0.0022577301133424	21.4995994567871
0.134423768031411	29.3767528533936	16.1119995117188	0.00228929007425904	21.7994995117188
0.136091402964666	29.6639060974121	16.3120002746582	0.0023212400265038	21.8995990753174
0.137878159875982	29.9331741333008	16.511999130249	0.00234223995357752	22.0995006561279
0.139367126394063	30.1343002319336	16.7119998931885	0.002390620065853	22.2994995117188
0.140856092912145	30.3318881988525	16.9120006561279	0.00247400999069214	22.4995002746582
0.14258328883443	30.6046180725098	17.1119995117188	0.0024963200557977	22.7994995117188
0.144250938319601	30.8710899353027	17.3120002746582	0.00249942997470498	22.9995002746582
0.145978134241886	31.0949440002441	17.511999130249	0.00251920009031892	23.0995006561279
0.147586208186112	31.3135795593262	17.7119998931885	0.00257282005622983	23.2994995117188
0.14883694529999	31.459077835083	17.9120006561279	0.00220185006037354	23.4995002746582
0.150861931615509	31.8119144439697	18.1119995117188	0.00266846991144121	23.699499130249
0.15258914208971	32.0563049316406	18.3120002746582	0.00262154010124505	23.9995002746582
0.154256777022965	32.268440246582	18.511999130249	0.00267874007113278	24.199499130249
0.155864865519106	32.4549827575684	18.7119998931885	0.00270362989977002	24.2994995117188
0.157115588081069	32.6075706481934	18.9120006561279	0.00276041007600725	24.4993991851807
0.158961905981414	32.9265594482422	19.1119995117188	0.00262021995149553	24.6993999481201
0.160808223881759	33.2290229797363	19.3120002746582	0.00277714990079403	24.8994007110596
0.16235675138887	33.3743171691895	19.511999130249	0.00282873003743589	25.0993995666504
0.163905264344066	33.578052520752	19.7119998931885	0.0028498200699687	25.2994003295898
0.165572913829237	33.8440361022949	19.9120006561279	0.00249385996721685	25.5995006561279
0.167180987773463	34.0857887268066	20.1119995117188	0.00286229001358151	25.699499130249
0.169146427651867	34.3511734008789	20.3120002746582	0.00293649989180267	25.8994007110596
0.170575833180919	34.5133399963379	20.511999130249	0.00296782003715634	26.0995006561279
0.172362590092234	34.769702911377	20.7119998931885	0.00299196993000805	26.2994995117188
0.174208907992579	35.0537796020508	20.9120006561279	0.00300595001317561	26.4995002746582
0.175936103914864	35.2988586425781	21.1119995117188	0.00303507992066443	26.7994995117188
0.177782421815209	35.5270385742188	21.3120002746582	0.0030743801034987	26.8994007110596
0.179509617737494	35.7353363037109	21.511999130249	0.0031190300360322	27.0993995666504
0.180939023266546	35.9519424438477	21.7119998931885	0.00311093009077013	27.2994003295898
0.182725794729777	36.22314453125	21.9120006561279	0.00316063989885151	27.4993991851807
0.18397651729174	36.370735168457	22.1119995117188	0.00320668006315827	27.7994003295898
0.186120625585318	36.6453704833984	22.3120002746582	0.00324308010749519	27.9993991851807
0.187609592103399	36.8325576782227	22.511999130249	0.00329352007247508	28.1993999481201
0.189098558621481	37.0652313232422	22.7119998931885	0.0032746100332588	28.2994003295898
0.190766193554737	37.2886276245117	22.9120006561279	0.00329990009777248	28.4993991851807
0.192552950466052	37.4913215637207	23.1119995117188	0.00336649990640581	28.6993999481201
0.194161038962193	37.6814308166504	23.3120002746582	0.00337237003259361	28.8994007110596
0.195947795873508	37.9324264526367	23.511999130249	0.0034043500199914	29.1993007659912
0.1972580794245	38.1088523864746	23.7119998931885	0.00346577004529536	29.3994007110596
0.199283080291934	38.3897247314453	23.9120006561279	0.00349267991259694	29.4993000030518
0.200831607799046	38.5717926025391	24.1119995117188	0.00353060988709331	29.6993999481201
0.202499242732301	38.7949714660645	24.3120002746582	0.00353053002618253	29.8994007110596
0.203928648261353	38.9702262878418	24.511999130249	0.00356532004661858	30.0993995666504
0.205715405172668	39.2445793151855	24.7119998931885	0.0035882000811398	30.2992992401123
0.207383054657839	39.4398651123047	24.9120006561279	0.00360946008004248	30.5993995666504
0.209288918995298	39.6502075195313	25.1119995117188	0.00362920993939042	30.6993999481201
0.21089700749144	39.8579597473145	25.3120002746582	0.00369108002632856	30.8994007110596
0.212445534998551	40.0866050720215	25.511999130249	0.00370160001330078	31.0993995666504
0.214113169931807	40.3119964599609	25.7119998931885	0.00371025991626084	31.2992992401123
0.215899926843122	40.504077911377	25.9120006561279	0.0035392299760133	31.4993000030518
0.217686683754437	40.7113380432129	26.1119995117188	0.00354907009750605	31.7992992401123
0.219354333239608	40.9311485290527	26.3120002746582	0.00377517007291317	31.8994007110596
0.220962407183833	41.1525077819824	26.511999130249	0.00384160992689431	32.0993003845215
0.222570495679975	41.3616523742676	26.7119998931885	0.00364901009015739	32.2993011474609
0.22429769160226	41.5474548339844	26.9120006561279	0.00368262990377843	32.4992980957031
0.226084448513575	41.7695007324219	27.1119995117188	0.00369644002057612	32.6992988586426
0.227632976020686	41.9673957824707	27.3120002746582	0.00373862008564174	32.9992980957031
0.229181503527798	42.2094192504883	27.511999130249	0.0037833999376744	33.1992988586426
0.230670455493964	42.3510475158691	27.7119998931885	0.00380827998742461	33.2993011474609
0.232457212405279	42.5373191833496	27.9120006561279	0.00379779003560543	33.4992980957031
0.234303530305624	42.7916870117188	28.1119995117188	0.00383757008239627	33.6992988586426
0.235792496823706	42.9797019958496	28.3120002746582	0.00387410004623234	33.899299621582
0.237460146308877	43.197925567627	28.511999130249	0.00389711000025272	34.0993003845215
0.239068220253102	43.3605499267578	28.7119998931885	0.00396709004417062	34.399299621582
0.240914538153447	43.5573577880859	28.9120006561279	0.00396784022450447	34.5004997253418
0.242701295064762	43.8124694824219	29.1119995117188	0.00392015976831317	34.6992988586426
0.244368944549933	44.0476264953613	29.3120002746582	0.00407148990780115	34.899299621582
0.245798350078985	44.1996841430664	29.511999130249	0.00408424017950892	35.0993995666504
0.247346877586097	44.3566932678223	29.7119998931885	0.00409821001812816	35.2991981506348
0.248954951530322	44.5447044372559	29.9120006561279	0.00415003020316362	35.5992012023926
0.250979937845841	44.8280830383301	30.1119995117188	0.00418045977130532	35.6992988586426
0.252409343374893	45.0105133056641	30.3120002746582	0.00422972021624446	35.8992004394531
0.254017446422949	45.1645278930664	30.511999130249	0.00424626003950834	36.0996017456055
0.255863764323294	45.3509864807129	30.7119998931885	0.00428292015567422	36.2993011474609
0.25747183826752	45.554630279541	30.9120006561279	0.00429882016032934	36.4991989135742
0.259437278145924	45.847110748291	31.1119995117188	0.00432618986815214	36.7991981506348
0.260985776549205	46.0266647338867	31.3120002746582	0.00434598000720143	36.9991989135742
0.262534304056317	46.1500816345215	31.511999130249	0.00437826989218593	37.0992012023926
0.264321075519547	46.3285903930664	31.7119998931885	0.00439540017396212	37.2991981506348
0.265869603026658	46.5332336425781	31.9120006561279	0.00443226005882025	37.4990997314453
0.267537223407999	46.7672271728516	32.1119995117188	0.00445418991148472	37.6991996765137
0.269026204477996	46.9071464538574	32.3120002746582	0.00450373999774456	37.8992004394531
0.27087252237834	47.0851783752441	32.5120010375977	0.00452195992693305	38.1991996765137
0.272182805929333	47.2130279541016	32.7120018005371	0.00454428000375628	38.2991981506348
0.273850455414504	47.4282341003418	32.9119987487793	0.00458720978349447	38.4991989135742
0.275696773314849	47.694652557373	33.1119995117188	0.00458998000249267	38.6991996765137
0.277364393696189	47.8419151306152	33.3120002746582	0.0046251998282969	38.8992004394531
0.2789129212033	47.9665031433105	33.5120010375977	0.00465084007009864	39.0992012023926
0.280640117125586	48.1757583618164	33.7120018005371	0.00468087010085583	39.3992004394531
0.28260555700399	48.4742660522461	33.9119987487793	0.00470189983025193	39.4991989135742
0.284154084511101	48.6015090942383	34.1119995117188	0.00477065984159708	39.6991996765137
0.285643036477268	48.7370414733887	34.3120002746582	0.00479748006910086	39.8991012573242
0.287370261503384	48.9265785217285	34.5120010375977	0.0048525701276958	40.0992012023926
0.289097457425669	49.1619033813477	34.7120018005371	0.00482576014474034	40.2991981506348
0.291003321763128	49.4198722839355	34.9119987487793	0.00487826019525528	40.5990982055664
0.292670971248299	49.5709266662598	35.1119995117188	0.00496501987800002	40.6991996765137
0.293802586384118	49.6300239562988	35.3120002746582	0.00500563019886613	40.8991012573242
0.295887119136751	49.8827514648438	35.5120010375977	0.00499609019607306	41.0989990234375
0.297614315059036	50.1147689819336	35.7120018005371	0.00505483988672495	41.2990989685059
0.299460632959381	50.3482818603516	35.9119987487793	0.0050480798818171	41.4990997314453
0.301068736007437	50.4809150695801	36.1119995117188	0.0051652598194778	41.7990989685059
0.302617263514549	50.5964317321777	36.3120002746582	0.00501463003456593	41.9990997314453
0.304284883895889	50.8085594177246	36.5120010375977	0.00517441006377339	42.0990982055664
0.306131201796234	51.0256423950195	36.7120018005371	0.00516676995903254	42.2991981506348
0.307917973259464	51.2151260375977	36.9119987487793	0.00508499005809426	42.4990997314453
0.309347378788516	51.3196220397949	37.1119995117188	0.00525311985984445	42.6991004943848
0.310895906295627	51.4919052124023	37.3120002746582	0.00531867984682322	42.8991012573242
0.312503980239853	51.6965751647949	37.5120010375977	0.00530077982693911	43.1991004943848
0.314171629725024	51.8573608398438	37.7120018005371	0.0053005600348115	43.2991981506348
0.315898825647309	52.0387992858887	37.9119987487793	0.00536799989640713	43.4990997314453
0.317506899591535	52.1785163879395	38.1119995117188	0.00540013983845711	43.6991004943848
0.318995880661532	52.3444900512695	38.3120002746582	0.00541826989501715	43.8991012573242
0.320842169458047	52.5729522705078	38.5120010375977	0.00533019006252289	44.0990982055664
0.322509818943217	52.7652053833008	38.7120018005371	0.00547994999215007	44.3991012573242
0.324415712384507	52.9421997070313	38.9119987487793	0.00551655981689692	44.4990997314453
0.325785542372614	53.0291938781738	39.1119995117188	0.00554599007591605	44.6991004943848
0.327691435813904	53.2912139892578	39.3120002746582	0.00560106011107564	44.898998260498
0.32918038778007	53.4552764892578	39.5120010375977	0.00563134020194411	45.0990982055664
0.330550246872008	53.537166595459	39.7120018005371	0.00564990984275937	45.298999786377
0.332575233187526	53.7466812133789	39.9119987487793	0.00567294005304575	45.5989990234375
0.334004638716578	53.8925437927246	40.1119995117188	0.00570042990148067	45.6990013122559
0.335731834638864	54.1159820556641	40.3120002746582	0.00574606982991099	45.898998260498
0.337518606102094	54.3224487304688	40.5120010375977	0.0057727200910449	46.0989990234375
0.339067104505375	54.4268493652344	40.7120018005371	0.00581115018576384	46.298999786377
0.341032544383779	54.6312713623047	40.9119987487793	0.00586888985708356	46.4990005493164
0.342521525453776	54.8085021972656	41.1119995117188	0.00580283999443054	46.798999786377
0.344129599398002	54.987361907959	41.3120002746582	0.00584613997489214	46.898998260498
0.345916341757402	55.1561584472656	41.5120010375977	0.00584064004942775	47.0989990234375
0.347524444805458	55.264518737793	41.7120018005371	0.0059598102234304	47.298999786377
0.349132518749684	55.4113616943359	41.9119987487793	0.00601133005693555	47.4990005493164
0.35074059269391	55.6079025268555	42.1119995117188	0.00603401008993387	47.7044982910156
0.352289120201021	55.7557640075684	42.3120002746582	0.00606339983642101	47.9990005493164
0.354016316123307	55.9034538269043	42.5120010375977	0.00616557989269495	48.1990013122559
0.355803087586537	56.0713920593262	42.7120018005371	0.00627199001610279	48.298900604248
0.357411161530763	56.242431640625	42.9119987487793	0.00602281978353858	48.4990005493164
0.359138357453048	56.4587936401367	43.1119995117188	0.00615245010703802	48.6988983154297
0.360865553375334	56.6178817749023	43.3120002746582	0.00629052985459566	48.8988990783691
0.362414080882445	56.7423515319824	43.5120010375977	0.00623671011999249	49.1988983154297
0.364200852345675	56.9247550964355	43.7120018005371	0.0064605800434947	49.398998260498
0.365868472727016	57.1090469360352	43.9119987487793	0.00623562000691891	49.4989013671875
0.367655244190246	57.3162536621094	44.1119995117188	0.00644436990842223	49.6988983154297
0.369025103282183	57.3864555358887	44.3120002746582	0.00635766005143523	49.9081993103027
0.370930967619643	57.5693092346191	44.5120010375977	0.00637461012229323	50.0988998413086
0.372955953935161	57.7799644470215	44.7120018005371	0.00639830017462373	50.398998260498
0.374444935005158	57.9382286071777	44.9119987487793	0.00667583011090755	50.5988998413086
0.37587434053421	58.0714988708496	45.1119995117188	0.00645710993558168	50.6990013122559
0.377601536456496	58.2306823730469	45.3120002746582	0.00648901984095573	50.8988990783691
0.379209610400721	58.3310356140137	45.5120010375977	0.00650581996887922	51.0988998413086
0.38123459671624	58.5932998657227	45.7120018005371	0.00656339013949037	51.298900604248
0.382664002245292	58.727352142334	45.9119987487793	0.00660477997735143	51.5988998413086
0.384093407774344	58.8367156982422	46.1119995117188	0.0066072097979486	51.798900604248
0.3857015108224	58.93603515625	46.3120002746582	0.00666408985853195	51.8988990783691
0.387726497137919	59.159049987793	46.5120010375977	0.00666526984423399	52.0988998413086
0.38939414662309	59.3600273132324	46.7120018005371	0.00670268014073372	52.298900604248
0.390942645026371	59.4780464172363	46.9119987487793	0.00673899007961154	52.4989013671875
0.392431626096368	59.5801239013672	47.1119995117188	0.00674486998468637	52.6988983154297
0.394158822018653	59.6988639831543	47.3120002746582	0.00679745990782976	52.9987983703613
0.395886017940938	59.8799934387207	47.5120010375977	0.00681862980127335	53.0988006591797
0.397374999010935	60.0413246154785	47.7120018005371	0.00686004990711808	53.2988014221191
0.399042619392276	60.1985244750977	47.9119987487793	0.00685621006414294	53.4987983703613
0.400531600462273	60.289379119873	48.1119995117188	0.00700066983699799	53.6988983154297
0.402258796384558	60.4253807067871	48.3120002746582	0.00699931988492608	53.9987983703613
0.404164660722017	60.6748809814453	48.5120010375977	0.00704333977773786	54.1987991333008
0.405951432185248	60.8710823059082	48.7120018005371	0.00705920998007059	54.2988014221191
0.407499959692359	60.976634979248	48.9119987487793	0.0070848697796464	54.4987983703613
0.409108033636585	61.0750770568848	49.1119995117188	0.00712411012500525	54.6987991333008
0.41083522955887	61.2417869567871	49.3120002746582	0.00707207014784217	54.8987998962402
0.412741093896329	61.4749870300293	49.5120010375977	0.0071782898157835	55.0988006591797
0.4144087433815	61.6316070556641	49.7120018005371	0.00718499021604657	55.3987998962402
0.415957270888612	61.7300148010254	49.9119987487793	0.0072550899349153	55.4987983703613
0.417624920373783	61.8405952453613	50.1119995117188	0.00729979015886784	55.6987991333008
0.419471238274127	62.0747261047363	50.3120002746582	0.00726688001304865	55.8987998962402
0.420900643803179	62.1892013549805	50.5120010375977	0.00736923003569245	56.0988006591797
0.422687386162579	62.357536315918	50.7120018005371	0.00740652019158006	56.2988014221191
0.424176367232576	62.4285888671875	50.9119987487793	0.0073948698118329	56.4987983703613
0.425724865635857	62.5630264282227	51.1119995117188	0.00745978020131588	56.6987991333008
0.427452090661973	62.7572021484375	51.3120002746582	0.00748550985008478	56.8987998962402
0.429060164606199	62.9133911132813	51.5120010375977	0.00753688020631671	57.0988006591797
0.43072781409137	63.0289993286133	51.7120018005371	0.00756506016477942	57.2988014221191
0.432455010013655	63.1525421142578	51.9119987487793	0.00755904987454414	57.4987983703613
0.433884415542707	63.2516746520996	52.1119995117188	0.00760714011266828	57.6987991333008
0.435730733443052	63.4574279785156	52.3120002746582	0.00761778000742197	57.9986991882324
0.437577051343396	63.6459999084473	52.5120010375977	0.00765941990539432	58.0988006591797
0.439185125287622	63.7231025695801	52.7120018005371	0.00768753979355097	58.2988014221191
0.440793199231848	63.8537368774414	52.9119987487793	0.00772893009707332	58.4986991882324
0.442401302279904	64.0208129882813	53.1119995117188	0.00778240989893675	58.6987991333008
0.444188044639304	64.2073669433594	53.3120002746582	0.00777686992660165	58.8987998962402
0.445855694124475	64.3133773803711	53.5120010375977	0.00787406042218208	59.1986999511719
0.447523314505816	64.4375076293945	53.7120018005371	0.00792113970965147	59.2988014221191
0.449190963990986	64.5834426879883	53.9119987487793	0.00793651025742292	59.4987983703613
0.450679945060983	64.7175140380859	54.1119995117188	0.00792387966066599	59.6986999511719
0.452764477813616	64.9687652587891	54.3120002746582	0.00800679996609688	59.8987007141113
0.454491673735902	65.060791015625	54.5120010375977	0.00802676007151604	60.0992012023926
0.455325498478487	65.023078918457	54.7120018005371	0.00805861968547106	60.3987998962402
0.45752918231301	65.2950820922852	54.9119987487793	0.00809807982295752	60.4986991882324
0.45919680269435	65.4445114135742	55.1119995117188	0.008143600076437	60.6986999511719
0.461043120594695	65.5974578857422	55.3120002746582	0.00816501956433058	60.8987007141113
0.462591648101807	65.6739959716797	55.5120010375977	0.00818045996129513	61.0987014770508
0.464199722046033	65.7957534790039	55.7120018005371	0.00821327045559883	61.298698425293
0.46568870311603	65.9378662109375	55.9119987487793	0.00825926009565592	61.5987014770508
0.4673563526012	66.0831527709961	56.1119995117188	0.00827255006879568	61.6986999511719
0.4691430949606	66.2229156494141	56.3120002746582	0.00833136029541492	61.8987007141113
0.471108534839004	66.3811111450195	56.5120010375977	0.00835087988525629	62.0985984802246
0.472418818389997	66.4473342895508	56.7120018005371	0.00839428044855595	62.298698425293
0.474086467875168	66.632942199707	56.9119987487793	0.00843106955289841	62.5987014770508
0.475575419841334	66.7480773925781	57.1119995117188	0.00843997020274401	62.7985992431641
0.477540859719738	66.8921813964844	57.3120002746582	0.00846019014716148	62.9986000061035
0.479208509204909	67.0101089477539	57.5120010375977	0.00850722007453442	63.0987014770508
0.480757036712021	67.1274108886719	57.7120018005371	0.00853667035698891	63.298698425293
0.482365110656247	67.2877197265625	57.9119987487793	0.00854902993887663	63.4986991882324
0.484092306578532	67.4030609130859	58.1119995117188	0.00860801991075277	63.698600769043
0.485938624478877	67.54638671875	58.3120002746582	0.00865214038640261	63.9986000061035
0.487606273964047	67.6673202514648	58.5120010375977	0.00867622997611761	64.198600769043
0.489214377012104	67.8334579467773	58.7120018005371	0.00867077987641096	64.2985992431641
0.49070332897827	67.9408340454102	58.9119987487793	0.00873686000704765	64.4985961914063
0.492549617774785	68.0932846069336	59.1119995117188	0.00876562017947435	64.698600769043
0.49439596477896	68.2001800537109	59.3120002746582	0.00882771983742714	64.8985977172852
0.495825370308012	68.3324508666992	59.5120010375977	0.00885563995689154	65.198600769043
0.497612112667412	68.5089721679688	59.7120018005371	0.00886058993637562	65.3985977172852
0.499339308589697	68.6524658203125	59.9119987487793	0.00893853046000004	65.4987030029297
0.501185655593872	68.7693252563477	60.1119995117188	0.00888225995004177	65.698600769043
0.503031944390386	68.9140930175781	60.3120002746582	0.0087942099198699	65.8985977172852
0.504640047438443	69.1118698120117	60.5120010375977	0.00902528036385775	66.0986022949219
0.506128999404609	69.2167510986328	60.7120018005371	0.00909033045172691	66.2985992431641
0.507558404933661	69.2608184814453	60.9119987487793	0.00890845991671085	66.5986022949219
0.509345147293061	69.3697738647461	61.1119995117188	0.00890475977212191	66.6985015869141
0.510834099259228	69.4751815795898	61.3120002746582	0.00894923973828554	66.8984985351563
0.512442202307284	69.6454162597656	61.5120010375977	0.00898914039134979	67.0986022949219
0.51393115427345	69.7377319335938	61.7120018005371	0.00900017004460096	67.2985000610352
0.515598803758621	69.8246612548828	61.9119987487793	0.00903313979506493	67.4984970092773
0.517385546118021	69.9662551879883	62.1119995117188	0.00907703954726458	67.7985000610352
0.519112742040306	70.1098098754883	62.3120002746582	0.00911534018814564	67.9985961914063
0.520482601132244	70.2068939208984	62.5120010375977	0.00915201008319855	68.0986022949219
0.522388494573534	70.3740463256836	62.7120018005371	0.00918226037174463	68.2985000610352
0.523758353665471	70.4021682739258	62.9119987487793	0.0092044398188591	68.4985961914063
0.525842886418104	70.5906448364258	63.1119995117188	0.00922778993844986	68.6985015869141
0.527570082340389	70.7599029541016	63.3120002746582	0.00931423995643854	68.9984970092773
0.529118638951331	70.8966217041016	63.5120010375977	0.00928966980427504	69.1985015869141
0.530667137354612	70.963737487793	63.7120018005371	0.00932930037379265	69.2985992431641
0.532394333276898	71.0673370361328	63.9119987487793	0.00933586992323399	69.4984970092773
0.534359773155302	71.2721557617188	64.1119995117188	0.00939357001334429	69.6985015869141
0.536027422640473	71.4351501464844	64.3119964599609	0.00943148043006659	69.8983993530273
0.537456828169525	71.5001678466797	64.5120010375977	0.00943615008145571	70.1985015869141
0.53918402409181	71.6101226806641	64.7119979858398	0.00943307019770145	70.3984985351563
0.540911220014095	71.7164154052734	64.9120025634766	0.00948925968259573	70.4984970092773
0.542876659892499	71.9270401000977	65.1119995117188	0.00952471978962421	70.6985015869141
0.544186914339662	71.9977645874023	65.3119964599609	0.00952737033367157	70.8983993530273
0.545914110261947	72.1254730224609	65.5120010375977	0.00959318969398737	71.0983963012695
0.547403120435774	72.1410980224609	65.7119979858398	0.0096144201233983	71.3983993530273
0.549368560314178	72.3421249389648	65.9120025634766	0.00964737962931395	71.5983963012695
0.551214849110693	72.5154724121094	66.1119995117188	0.00967450998723507	71.6985015869141
0.552703801076859	72.622932434082	66.3119964599609	0.00973275024443865	71.8983993530273
0.554252357687801	72.6953582763672	66.5120010375977	0.0098163103684783	72.0983963012695
0.555741309653968	72.7461242675781	66.7119979858398	0.00982484966516495	72.2984008789063
0.557349412702024	72.8832092285156	66.9120025634766	0.00977980997413397	72.4983978271484
0.559076608624309	73.0550003051758	67.1119995117188	0.00981761980801821	72.7985000610352
0.560565560590476	73.1252746582031	67.3119964599609	0.00988669041544199	72.8984985351563
0.56241184938699	73.2243118286133	67.5120010375977	0.00989983975887299	73.098503112793
0.563841254916042	73.2821578979492	67.7119979858398	0.00996773038059473	73.2984008789063
0.565449357964098	73.4321670532227	67.9120025634766	0.0100157000124454	73.4983978271484
0.567414797842503	73.6357498168945	68.1119995117188	0.0100431004539132	73.7984008789063
0.569141993764788	73.7162628173828	68.3119964599609	0.0100809996947646	73.9991989135742
0.570630945730954	73.7578506469727	68.5120010375977	0.0100982999429107	74.0983963012695
0.57235814165324	73.902214050293	68.7119979858398	0.0101421000435948	74.2985000610352
0.574204488657415	74.0919036865234	68.9120025634766	0.0101736001670361	74.4983978271484
0.575752987060696	74.1951141357422	69.1119995117188	0.0102016003802419	74.6984024047852
0.577361090108752	74.26025390625	69.3119964599609	0.0103230001404881	74.9983978271484
0.579028739593923	74.3596420288086	69.5120010375977	0.0103197004646063	75.1984024047852
0.580815481953323	74.522102355957	69.7119979858398	0.0103307003155351	75.2983016967773
0.582780921831727	74.7209930419922	69.9120025634766	0.0103615000844002	75.4983978271484
0.584448571316898	74.8229598999023	70.1119995117188	0.0103511996567249	75.6983032226563
0.586175767239183	74.8971176147461	70.3119964599609	0.0104157999157906	75.8983001708984
0.587843416724354	75.019905090332	70.5120010375977	0.0104593997821212	76.1983032226563
0.589511008001864	75.1716384887695	70.7119979858398	0.0104652000591159	76.3983001708984
0.591357355006039	75.3180541992188	70.9120025634766	0.0105218999087811	76.4983978271484
0.592965458054096	75.3773956298828	71.1119995117188	0.01053879968822	76.6983032226563
0.594394863583148	75.4248733520508	71.3119964599609	0.0106351003050804	76.8983001708984
0.595943361986428	75.5280151367188	71.5120010375977	0.0105744004249573	77.0982971191406
0.597432313952595	75.661262512207	71.7119979858398	0.0107683995738626	77.3983001708984
0.599219056311995	75.7785034179688	71.9120025634766	0.0107142999768257	77.5982971191406
0.600946310441941	75.8606109619141	72.1119995117188	0.0107035003602505	77.7042999267578
0.602197018451989	75.8815841674805	72.3119964599609	0.0107880998402834	77.8983001708984
0.604102911893278	76.0862121582031	72.5120010375977	0.0107605000957847	78.0982971191406
0.605710956733674	76.2001953125	72.7119979858398	0.0107985995709896	78.2983016967773
0.607557303737849	76.3195266723633	72.9120025634766	0.0108711002394557	78.4982986450195
0.609344046097249	76.421028137207	73.1119995117188	0.0109163001179695	78.6983032226563
0.610535207670182	76.4599685668945	73.3119964599609	0.0109312003478408	78.9982986450195
0.612441101111472	76.6372833251953	73.5120010375977	0.0109615996479988	79.0982971191406
0.614168297033757	76.7597122192383	73.7119979858398	0.0110368002206087	79.2983016967773
0.61625282978639	76.9095458984375	73.9120025634766	0.011085799895227	79.4982986450195
0.617741781752557	76.964225769043	74.1119995117188	0.0111033003777266	79.6981964111328
0.619171187281609	77.0614700317383	74.3119964599609	0.0111234001815319	79.9982986450195
0.620898441411555	77.206787109375	74.5120010375977	0.0111899003386497	80.1981964111328
0.622566032689065	77.3020858764648	74.7119979858398	0.0111975995823741	80.2982025146484
0.624233682174236	77.3761138916016	74.9120025634766	0.0112357996404171	80.4981994628906
0.625841785222292	77.4628448486328	75.1119995117188	0.0112851997837424	80.6984024047852
0.627271190751344	77.5612106323242	75.3119964599609	0.011306400410831	80.8982009887695
0.628938840236515	77.6858367919922	75.5120010375977	0.0113445995375514	81.0981979370117
0.630606489721686	77.7369232177734	75.7119979858398	0.0113594997674227	81.2982025146484
0.632512324955314	77.8778686523438	75.9120025634766	0.0113746002316475	81.5982971191406
0.6342395208776	77.9951629638672	76.1119995117188	0.011430200189352	81.6981964111328
0.635728531051427	78.1062393188477	76.3119964599609	0.0114430002868176	81.8982009887695
0.637157936580479	78.1396026611328	76.5120010375977	0.011515099555254	82.0981979370117
0.639182922895998	78.2629089355469	76.7119979858398	0.0115341003984213	82.2982025146484
0.640671874862164	78.3466796875	76.9120025634766	0.0115814004093409	82.4981994628906
0.64239907078445	78.5017929077148	77.1119995117188	0.0116154998540878	82.7983016967773
0.643768929876387	78.5670776367188	77.3119964599609	0.0116432001814246	82.8982009887695
0.645555672235787	78.6787796020508	77.5120010375977	0.0116624003276229	83.0981979370117
0.647461565677077	78.7867050170898	77.7119979858398	0.0117079000920057	83.2982025146484
0.649307854473591	78.9468994140625	77.9120025634766	0.0117108002305031	83.4981994628906
0.650737260002643	79.0244903564453	78.1119995117188	0.0118020996451378	83.7982025146484
0.652464455924928	79.1722259521484	78.3119964599609	0.0118011999875307	83.9981994628906
0.654132105410099	79.2250671386719	78.5120010375977	0.0118551999330521	84.0981979370117
0.656037998851389	79.3402633666992	78.7119979858398	0.0118856001645327	84.2982025146484
0.65770564833656	79.4582290649414	78.9120025634766	0.011935000307858	84.4981994628906
0.65937329782173	79.6052398681641	79.1119995117188	0.0120040997862816	84.6981964111328
0.660921796225011	79.6466522216797	79.3119964599609	0.012041199952364	84.8981018066406
0.662708538584411	79.7631530761719	79.5120010375977	0.0120481001213193	85.1981964111328
0.664435734506696	79.8821487426758	79.7119979858398	0.0120722996070981	85.3982009887695
0.666162930428982	80.0287017822266	79.9120025634766	0.0121363997459412	85.4981994628906
0.667711487039924	80.0886154174805	80.1119995117188	0.0121590998023748	85.6980972290039
0.66920043900609	80.1491241455078	80.3119964599609	0.0121764997020364	85.8981018066406
0.670927634928375	80.2287750244141	80.5120010375977	0.0122050000354648	86.0980987548828
0.672714377287775	80.3513793945313	80.7119979858398	0.0122718000784516	86.3981018066406
0.674441573210061	80.5018005371094	80.9120025634766	0.0123161002993584	86.5980987548828
0.675870978739113	80.5337219238281	81.1119995117188	0.0123142004013062	86.6980972290039
0.677479081787169	80.5794143676758	81.3119964599609	0.0123261995613575	86.8981018066406
0.679206277709454	80.6885757446289	81.5120010375977	0.0124060995876789	87.0980987548828
0.681112171150744	80.86767578125	81.7119979858398	0.0124292997643352	87.2981033325195
0.682779820635915	80.9617080688477	81.9120025634766	0.0124773997813463	87.4983978271484
0.684268772602081	80.998046875	82.1119995117188	0.0124974995851517	87.7982025146484
0.685876875650138	81.0513153076172	82.3119964599609	0.0124971996992826	87.8981018066406
0.687484920490533	81.1388854980469	82.5120010375977	0.0125556997954845	88.0980987548828
0.689271662849933	81.2955017089844	82.7119979858398	0.0125799002125859	88.2981033325195
0.690998916979879	81.4010848999023	82.9120025634766	0.0125960996374488	88.4981002807617
0.692368717864156	81.4030838012695	83.1119995117188	0.0126815000548959	88.697998046875
0.693857728037983	81.4224395751953	83.3119964599609	0.0126628000289202	88.9980010986328
0.695704016834497	81.6031188964844	83.5120010375977	0.0126628996804357	89.0980987548828
0.697490759193897	81.7347717285156	83.7119979858398	0.0127053000032902	89.2981033325195
0.699158408679068	81.8041763305664	83.9120025634766	0.0125658996403217	89.5011978149414
0.70058781420812	81.8018188476563	84.1119995117188	0.0125649003311992	89.697998046875
0.702195917256176	81.8961791992188	84.3119964599609	0.0125890001654625	89.9980010986328
0.704220903571695	82.0891342163086	84.5120010375977	0.0126157999038696	90.197998046875
0.705888553056866	82.1462936401367	84.7119979858398	0.0126818995922804	90.3980026245117
0.707556202542037	82.2094039916992	84.9120025634766	0.0126606002449989	90.4980010986328
0.709164247382432	82.2605667114258	85.1119995117188	0.0127127999439836	90.697998046875
0.710712803993374	82.3493881225586	85.3119964599609	0.0127774002030492	90.8980026245117
0.712678243871778	82.5327529907227	85.5120010375977	0.0127809001132846	91.0979995727539
0.714405439794064	82.6200714111328	85.7119979858398	0.0129199000075459	91.2979965209961
0.716013484634459	82.6371994018555	85.9120025634766	0.0129324998706579	91.5979995727539
0.717621587682515	82.695915222168	86.1119995117188	0.0129110999405384	91.697998046875
0.719170086085796	82.7310104370117	86.3119964599609	0.0129450000822544	91.8980026245117
0.720778189133853	82.7908782958984	86.5120010375977	0.0130062000826001	92.0979995727539
0.722684082575142	82.7881393432617	86.7119979858398	0.0130187002941966	92.2979965209961
0.724232580978423	82.6431884765625	86.9120025634766	0.0130679002031684	92.4980010986328
0.725542893633246	81.6301345825195	87.1119995117188	0.013089899905026	92.7978973388672
0.726436264812946	-3.08060765266418	87.1940002441406	0.0131058003753424	92.7978973388672