File: CSVs/24-01-08_Tensile_paper-PDMS/Laser_Uncoated_2/asdf.txt
File Path: C:\Users\apk5101\Desktop\Sandra\Laser_Uncoated_2 01-8-24 11 12 58 AM\DAQ- Crosshead, … - (Timed).txt
Test: MTS EM Tension (Simplified) with Video Extensometer apk5101 25
Test Run: Laser_Uncoated_2
Date: 1/8/2024 10:33:15 AM


Crosshead 	Load 	Time 	Strain 1 	Video Time
mm	N	sec	mm/mm	sec
0	-0.0599854588508606	0.112999998033047	-6.87486999595421E-06	5.19990015029907
0.000893379024091701	0.0330808833241463	0.412999987602234	0.000170942003023811	5.49989986419678
0.00440733629147871	0.236728921532631	0.712999999523163	1.66175996128004E-05	5.8112998008728
0.00762350100558251	0.41941249370575	1.01300001144409	7.96024978626519E-05	6.19990015029907
0.0103631964520901	0.657767176628113	1.31299996376038	0.000159215996973217	6.39989995956421
0.013043333638052	0.856512188911438	1.61300003528595	0.000210245998459868	6.69990015029907
0.0159021456056507	0.965773820877075	1.91299998760223	0.000277957995422184	6.99989986419678
0.0182249314093497	1.16858220100403	2.21300005912781	0.000309752009343356	7.39989995956421
0.0207263929041801	1.35761773586273	2.51300001144409	0.000389711000025272	7.59989976882935
0.0232874135690508	1.44129598140717	2.81299996376038	0.000463080010376871	7.89989995956421
0.0259079915849725	1.64751160144806	3.11299991607666	0.000480890012113377	8.29990005493164
0.0284094530798029	1.82920372486115	3.41300010681152	0.000537559972144663	8.50860023498535
0.0309704737446737	1.95276594161987	3.71300005912781	0.000559060019440949	8.79990005493164
0.0334123760694638	2.13949632644653	4.01300001144409	0.000646476983092725	9.09980010986328
0.0357351600541733	2.31598734855652	4.31300020217896	0.000695179973263294	9.49979972839355
0.038355738070095	2.42699027061462	4.61299991607666	0.000750982027966529	9.69979953765869
0.0407976403948851	2.5792670249939	4.91300010681152	0.000817705993540585	9.99979972839355
0.0431204280175734	2.75795984268188	5.21299982070923	0.000819288019556552	10.2999000549316
0.0457410060334951	2.87119483947754	5.51300001144409	0.000903188018128276	10.6997995376587
0.0483020266983658	3.03515601158142	5.81300020217896	0.000919618993066251	10.8998003005981
0.0507439290231559	3.21761417388916	6.11299991607666	0.00101838994305581	11.1997995376587
0.0533049496880267	3.31601548194885	6.41300010681152	0.00106942001730204	11.4997997283936
0.0561042033950798	3.46021842956543	6.71299982070923	0.00110559002496302	11.8998003005981
0.0583078690397087	3.66275596618652	7.01300001144409	0.00115290004760027	12.0998001098633
0.0609284470556304	3.76603293418884	7.31300020217896	0.00108446995727718	12.3998003005981
0.0636681434116326	3.91491866111755	7.61299991607666	0.00124720996245742	12.6997995376587
0.0659909273963422	4.09416580200195	7.91300010681152	0.001316920039244	13.0998001098633
0.0681350429658778	4.17535448074341	8.21300029754639	0.00138339004479349	13.2997999191284
0.0708747320459224	4.31020545959473	8.51299953460693	0.00144794001244009	13.5998001098633
0.0733166380086914	4.51132249832153	8.8129997253418	0.00152785005047917	13.8998003005981
0.0758776586735621	4.61185550689697	9.11299991607666	0.00156333995983005	14.2996997833252
0.0783791183494031	4.71005296707153	9.41300010681152	0.00168266997206956	14.4996995925903
0.0809401390142739	4.89811706542969	9.71300029754639	0.00163507997058332	14.7997999191284
0.0832629229989834	4.98717451095581	10.0129995346069	0.00172274000942707	15.1997003555298
0.0857643826748244	5.0895414352417	10.3129997253418	0.00179104995913804	15.3997001647949
0.0884445253177546	5.26273155212402	10.6129999160767	0.00183875998482108	15.6997003555298
0.0910055387066677	5.37407970428467	10.9130001068115	0.0018709700088948	15.9996004104614
0.0934474446694367	5.44274759292603	11.2130002975464	0.00190537003800273	16.3997001647949
0.0960680263233371	5.63068866729736	11.5129995346069	0.00196326989680529	16.6996002197266
0.0985099250101484	5.73431396484375	11.8129997253418	0.00206581992097199	16.9004001617432
0.100951830972917	5.81428289413452	12.1129999160767	0.00210457993671298	17.1996994018555
0.10357240535086	5.97294759750366	12.4130001068115	0.00217375997453928	17.5995998382568
0.105954750324599	6.07440614700317	12.7130002975464	0.00223092990927398	17.7996997833252
0.108217980596237	6.12472152709961	13.0129995346069	0.0023434900213033	18.0995998382568
0.110957676952239	6.29500961303711	13.3129997253418	0.00231900997459888	18.3995990753174
0.113101785245817	6.40749835968018	13.6129999160767	0.00236709997989237	18.7996006011963
0.115841481601819	6.45767545700073	13.9130001068115	0.00245667994022369	19.0009002685547
0.118283380288631	6.59677791595459	14.2130002975464	0.00249184994027019	19.3092994689941
0.120963515655603	6.74691104888916	14.5129995346069	0.00258674006909132	19.5995998382568
0.123405421618372	6.79002094268799	14.8129997253418	0.00262953992933035	19.9995002746582
0.125966442283243	6.95117235183716	15.1129999160767	0.00271069002337754	20.1996002197266
0.128706131363288	7.06919860839844	15.4130001068115	0.00274892989546061	20.4995994567871
0.131148044602014	7.13219547271729	15.7130002975464	0.00278145004995167	20.8995990753174
0.133411260321736	7.2419810295105	16.0130004882813	0.00296376994810998	21.199499130249
0.136270085931756	7.39453983306885	16.3129997253418	0.00299827009439468	21.3995990753174
0.138592862640508	7.40486431121826	16.613000869751	0.00306456000544131	21.699499130249
0.140975214890204	7.54849767684937	16.9130001068115	0.00309255998581648	22.0995006561279
0.14359578199219	7.69270753860474	17.2129993438721	0.00322871003299952	22.3997001647949
0.145918573252857	7.71363830566406	17.5130004882813	0.00320317992009223	22.5995006561279
0.148420032928698	7.82370710372925	17.8129997253418	0.00324983010068536	22.8994998931885
0.150861931615509	7.96902084350586	18.113000869751	0.00333644007332623	23.2994995117188
0.15342295228038	8.02391624450684	18.4130001068115	0.00337803992442787	23.5995998382568
0.155805304530077	8.09175109863281	18.7129993438721	0.00342075992375612	23.7994995117188
0.158008973812684	8.21383094787598	19.0130004882813	0.00351045001298189	24.0995006561279
0.160808223881759	8.28023433685303	19.3129997253418	0.00349311996251345	24.4995002746582
0.16319056157954	8.36387062072754	19.613000869751	0.00359128997661173	24.699499130249
0.165632474818267	8.52538299560547	19.9130001068115	0.00362157006748021	24.9995002746582
0.168253041920252	8.58041763305664	20.2129993438721	0.00365915009751916	25.2994995117188
0.170814062585123	8.63523864746094	20.5130004882813	0.0037703700363636	25.699499130249
0.173315522260964	8.78721237182617	20.8129997253418	0.00384403998032212	25.8995990753174
0.176174347870983	8.86169242858887	21.113000869751	0.00388506008312106	26.199499130249
0.178735368535854	8.93705368041992	21.4130001068115	0.00397355016320944	26.4993991851807
0.181117706233636	9.05590343475342	21.7129993438721	0.00404958985745907	26.8994007110596
0.183559604920447	9.13771915435791	22.0130004882813	0.00404735002666712	27.0993995666504
0.186180186574347	9.19738388061523	22.3129997253418	0.00409842003136873	27.3994007110596
0.188502977835014	9.31767272949219	22.613000869751	0.00416412018239498	27.6993999481201
0.190825754543766	9.37440490722656	22.9130001068115	0.00427905982360244	28.0993995666504
0.193446336197667	9.4304256439209	23.2129993438721	0.00434338999912143	28.2994003295898
0.195828673895448	9.5630931854248	23.5130004882813	0.00434103002771735	28.5993995666504
0.198211026145145	9.61399555206299	23.8129997253418	0.00440871994942427	28.9993991851807
0.20095071522519	9.69107913970947	24.113000869751	0.00447404989972711	29.3026008605957
0.203273506485857	9.8068962097168	24.4130001068115	0.00453562987968326	29.4993991851807
0.205715405172668	9.86760330200195	24.7129993438721	0.00457978993654251	29.7994003295898
0.208395547815599	9.93742752075195	25.0130004882813	0.00468971021473408	30.1993999481201
0.210956568480469	10.0431833267212	25.3129997253418	0.00471219979226589	30.4993991851807
0.213338906178251	10.1282997131348	25.613000869751	0.00478198006749153	30.6993999481201
0.215899926843122	10.1668891906738	25.9130001068115	0.00482837995514274	30.9993000030518
0.218639630475082	10.3043193817139	26.2129993438721	0.00490276981145144	31.399299621582
0.220962407183833	10.3525705337524	26.5130004882813	0.00497741019353271	31.5993995666504
0.223463866859674	10.4059934616089	26.8129997253418	0.00503847980871797	31.899299621582
0.226084448513575	10.5433025360107	27.113000869751	0.00509259989485145	32.1992988586426
0.228407239774242	10.6174182891846	27.4130001068115	0.00514798983931541	32.5993003845215
0.230908699450083	10.624701499939	27.7129993438721	0.00521173980087042	32.8003005981445
0.233469720114954	10.7445077896118	28.0130004882813	0.00530991004779935	33.0993995666504
0.235852057812735	10.839243888855	28.3129997253418	0.00535338977351785	33.399299621582
0.238413078477606	10.8695039749146	28.613000869751	0.00542395981028676	33.7993011474609
0.240974099142477	10.9680814743042	28.9130001068115	0.00547396996989846	33.9992980957031
0.243594680796377	11.0825815200806	29.2129993438721	0.00552655011415482	34.2991981506348
0.245917472057045	11.0844602584839	29.5130004882813	0.00555867003276944	34.6991996765137
0.248240248765796	11.162239074707	29.8129997253418	0.00561892986297607	34.9992980957031
0.250979937845841	11.3008890151978	30.113000869751	0.00567616010084748	35.1991996765137
0.253362290095538	11.3085851669312	30.4130001068115	0.00580069981515408	35.502498626709
0.255863764323294	11.39919090271	30.7129993438721	0.005846600048244	35.8992004394531
0.258484331425279	11.5194053649902	31.0130004882813	0.00593368010595441	36.1991996765137
0.26104535209015	11.5179643630981	31.3129997253418	0.00602716999128461	36.3992004394531
0.263487250776961	11.6123046875	31.613000869751	0.00607000011950731	36.6991996765137
0.265988725004718	11.7229824066162	31.9130001068115	0.00614714017137885	37.0992012023926
0.268371048150584	11.7279739379883	32.2130012512207	0.00615660985931754	37.3992004394531
0.270753400400281	11.7968006134033	32.5130004882813	0.0061983298510313	37.5993003845215
0.273135752649978	11.9241962432861	32.8129997253418	0.0062559898942709	37.8992004394531
0.275637197773904	11.9296436309814	33.1129989624023	0.00635153008624911	38.2991981506348
0.27813867200166	11.9917936325073	33.4129981994629	0.00637210998684168	38.4991989135742
0.280699692666531	12.1166038513184	33.7130012512207	0.00645790016278625	38.7991981506348
0.28349892818369	12.1677112579346	34.0130004882813	0.00651742005720735	39.0992012023926
0.285821733996272	12.175799369812	34.3129997253418	0.00661503989249468	39.4991989135742
0.288144510705024	12.3049831390381	34.6129989624023	0.00663908990100026	39.6991004943848
0.291181990178302	12.3903951644897	34.9129981994629	0.00663687009364367	39.9991989135742
0.293385674012825	12.3940124511719	35.2130012512207	0.00680528022348881	40.3991012573242
0.295887119136751	12.513373374939	35.5130004882813	0.00682093994691968	40.6991004943848
0.298626837320626	12.5731182098389	35.8129997253418	0.00690431986004114	40.8991012573242
0.301187857985497	12.6204147338867	36.1129989624023	0.00689925020560622	41.1991004943848
0.303391512716189	12.7074041366577	36.4129981994629	0.00706036994233727	41.5990982055664
0.306131201796234	12.7497053146362	36.7130012512207	0.00708608981221914	41.8991012573242
0.30863267602399	12.7915077209473	37.0130004882813	0.00714747980237007	42.0990982055664
0.310895906295627	12.8744974136353	37.3129997253418	0.00720890006050467	42.3991012573242
0.313456926960498	12.9400682449341	37.6129989624023	0.00724887987598777	42.7990989685059
0.315839250106364	12.9396467208862	37.9129981994629	0.00732344994321465	42.9990997314453
0.318340724334121	13.0742864608765	38.2130012512207	0.00736287981271744	43.3042984008789
0.320901744998991	13.12486743927	38.5130004882813	0.00747899990528822	43.5990982055664
0.323462765663862	13.1400918960571	38.8129997253418	0.00754444999620318	43.9990997314453
0.325964210787788	13.2476196289063	39.1129989624023	0.00759446015581489	44.2990989685059
0.32840613857843	13.3106575012207	39.4129981994629	0.00768710998818278	44.4990997314453
0.330788461724296	13.3271322250366	39.7130012512207	0.00777263008058071	44.798999786377
0.333409057930112	13.4303760528564	40.0130004882813	0.00778905022889376	45.1991004943848
0.335791381075978	13.4814767837524	40.3129997253418	0.00779087003320456	45.398998260498
0.338411977281794	13.4946317672729	40.6129989624023	0.00790087040513754	45.6990013122559
0.340853875968605	13.584454536438	40.9129981994629	0.00800998974591494	45.9990997314453
0.343355321092531	13.6786880493164	41.2130012512207	0.00806981045752764	46.398998260498
0.345797248883173	13.6692962646484	41.5130004882813	0.00809216033667326	46.5989990234375
0.348477362422273	13.775785446167	41.8129997253418	0.00821571983397007	46.898998260498
0.350919290212914	13.8190107345581	42.1129989624023	0.00826102960854769	47.1990013122559
0.353122944943607	13.8395385742188	42.4129981994629	0.00833528023213148	47.4989013671875
0.355862634023651	13.9280977249146	42.7130012512207	0.00840300042182207	47.8003005981445
0.358364108251408	14.0015087127686	43.0130004882813	0.00843473989516497	48.0989990234375
0.36068688496016	13.9974718093872	43.3129997253418	0.00852753967046738	48.4990005493164
0.363486149581149	14.0975961685181	43.6129989624023	0.008606250397861	48.7999000549316
0.365987594705075	14.1871223449707	43.9129981994629	0.00855159014463425	48.9990005493164
0.368310400517657	14.1722011566162	44.2130012512207	0.00874845962971449	49.298900604248
0.371228758012876	14.2665777206421	44.5130004882813	0.00881372019648552	49.6988983154297
0.373789778677747	14.3527269363403	44.8129997253418	0.00890582986176014	49.9989013671875
0.375993433408439	14.3378753662109	45.1129989624023	0.00892569031566381	50.1988983154297
0.37855445407331	14.4094877243042	45.4129981994629	0.00899340026080608	50.4989013671875
0.381294172257185	14.5319919586182	45.7130012512207	0.00906207971274853	50.8988990783691
0.383378705009818	14.5056304931641	46.0130004882813	0.00910721998661757	51.1988983154297
0.385641935281456	14.5316944122314	46.3129997253418	0.00915616005659103	51.3988990783691
0.388679443858564	14.6834363937378	46.6129989624023	0.00927705969661474	51.6988983154297
0.391002220567316	14.6712741851807	46.9129981994629	0.00930713023990393	52.0988998413086
0.393265450838953	14.6867780685425	47.2130012512207	0.00935100018978119	52.298900604248
0.395826471503824	14.7915182113647	47.5130004882813	0.0094112204387784	52.5988998413086
0.398387492168695	14.7996597290039	47.8129997253418	0.00947083998471498	52.8988990783691
0.400650722440332	14.8253936767578	48.1129989624023	0.00957094039767981	53.2988014221191
0.403271289542317	14.937575340271	48.4129981994629	0.00962250027805567	53.4987983703613
0.405951432185248	14.9906444549561	48.7130012512207	0.00968636013567448	53.7988014221191
0.408333755331114	14.9855470657349	49.0130004882813	0.00972186028957367	54.0988998413086
0.41095435153693	15.1078596115112	49.3129997253418	0.0098141198977828	54.4987983703613
0.41363449417986	15.151008605957	49.6129989624023	0.00991297978907824	54.6987991333008
0.416076392866671	15.1340045928955	49.9129981994629	0.00993079971522093	54.9989013671875
0.418518291553482	15.2474498748779	50.2130012512207	0.0100260004401207	55.3987998962402
0.421019736677408	15.2929048538208	50.5130004882813	0.010114099830389	55.7018013000488
0.42346166446805	15.2903966903687	50.8129997253418	0.0102001000195742	55.9082984924316
0.425784441176802	15.3748617172241	51.1129989624023	0.0102308997884393	56.1988983154297
0.428583705797791	15.4286193847656	51.4129981994629	0.010321700014174	56.5988006591797
0.43072781409137	15.4241600036621	51.7130012512207	0.0103756003081799	56.8987998962402
0.433229259215295	15.5060043334961	52.0130004882813	0.0105915004387498	57.0988006591797
0.435849855421111	15.5686187744141	52.3129997253418	0.010504400357604	57.3987998962402
0.438410876085982	15.5462312698364	52.6129989624023	0.0105723002925515	57.7988014221191
0.440912321209908	15.6576204299927	52.9129981994629	0.0106686996296048	57.9986991882324
0.443235097918659	15.6805686950684	53.2130012512207	0.0107055995613337	58.298698425293
0.446034362539649	15.7198886871338	53.5130004882813	0.0107731996104121	58.6110000610352
0.448416714789346	15.7824220657349	53.8129997253418	0.0108252000063658	58.9986991882324
0.450858613476157	15.8645896911621	54.1129989624023	0.0109021002426744	59.1987991333008
0.453479180578142	15.8681192398071	54.4129981994629	0.0109817003831267	59.4986991882324
0.45574241084978	15.9032707214355	54.7130012512207	0.01105170045048	59.7993011474609
0.45842255349271	15.9948387145996	55.0130004882813	0.0111103001981974	60.1986999511719
0.4612218181137	15.9993476867676	55.3129997253418	0.0111942999064922	60.3987998962402
0.463544594822451	16.0437545776367	55.6129989624023	0.0112522998824716	60.6986999511719
0.46568870311603	16.1129493713379	55.9129981994629	0.0113303000107408	60.9986991882324
0.468547514174134	16.1318302154541	56.2130012512207	0.0113960998132825	61.3987007141113
0.470870290882885	16.1679058074951	56.5130004882813	0.0114422999322414	61.5987014770508
0.473312189569697	16.2563095092773	56.8129997253418	0.0115197002887726	61.8987007141113
0.475694541819394	16.2472267150879	57.1129989624023	0.0116055002436042	62.1986999511719
0.478434230899438	16.3090972900391	57.4129981994629	0.0116601996123791	62.5992012023926
0.480757036712021	16.3910903930664	57.7130012512207	0.0117199001833797	62.7988014221191
0.483258481835946	16.3835296630859	58.0130004882813	0.0117921000346541	63.0987014770508
0.485998170915991	16.4309139251709	58.3129997253418	0.0118554001674056	63.3986015319824
0.488440098706633	16.5197734832764	58.6129989624023	0.0119257997721434	63.798698425293
0.490822421852499	16.5058174133301	58.9129981994629	0.0120687000453472	63.9986991882324
0.493562140036374	16.5661602020264	59.2130012512207	0.0120545001700521	64.2985992431641
0.496004009619355	16.6475353240967	59.5130004882813	0.0120860002934933	64.5987014770508
0.498445937409997	16.6455326080322	59.8129997253418	0.0121881002560258	64.9985961914063
0.501304748468101	16.7018775939941	60.1129989624023	0.0122654996812344	65.1987991333008
0.503865769132972	16.7872676849365	60.4129981994629	0.0123450001701713	65.4985961914063
0.506188545841724	16.7751216888428	60.7130012512207	0.0123985996469855	65.8988037109375
0.508511322550476	16.7889347076416	61.0130004882813	0.0124372001737356	66.0986022949219
0.511072343215346	16.8886260986328	61.3129997253418	0.0125278001651168	66.3985977172852
0.513335573486984	16.9001903533936	61.6129989624023	0.0125631997361779	66.698600769043
0.515658350195736	16.8793525695801	61.9129981994629	0.0126483999192715	67.0986022949219
0.518398068379611	17.0097522735596	62.2130012512207	0.0127429002895951	67.3984985351563
0.520661298651248	17.0040988922119	62.5130004882813	0.0127948997542262	67.598503112793
0.523281865753233	17.0194110870361	62.8129997253418	0.0128410998731852	67.8986968994141
0.525961979292333	17.1362743377686	63.1129989624023	0.0129193998873234	68.2988967895508
0.528463453520089	17.1597690582275	63.4129981994629	0.0129910996183753	68.598503112793
0.530667137354612	17.12965965271	63.7130012512207	0.0130289997905493	68.7985992431641
0.533347250893712	17.2484397888184	64.0130004882813	0.0131265996024013	69.098503112793
0.536086969077587	17.3026447296143	64.3130035400391	0.0132414000108838	69.502799987793
0.538409745786339	17.2690544128418	64.6129989624023	0.013272600248456	69.6985015869141
0.54097076645121	17.3604736328125	64.9130020141602	0.0133351003751159	69.9983978271484
0.543948728591204	17.4335994720459	65.2129974365234	0.0134207000955939	70.2991027832031
0.546033261343837	17.3969917297363	65.5130004882813	0.01349369995296	70.6984024047852
0.548415584489703	17.4659385681152	65.8130035400391	0.0135423000901937	70.8984985351563
0.551274395547807	17.5313606262207	66.1129989624023	0.0136198000982404	71.1985015869141
0.553537625819445	17.508129119873	66.4130020141602	0.0136556997895241	71.4983978271484
0.555860402528197	17.558521270752	66.7129974365234	0.0137555003166199	71.8983993530273
0.558242783881724	17.6271877288818	67.0130004882813	0.0138734998181462	72.0983963012695
0.56062510702759	17.5999279022217	67.3130035400391	0.0138710997998714	72.3983993530273
0.563186127692461	17.6581993103027	67.6129989624023	0.0140672996640205	72.7984008789063
0.565628055483103	17.7340412139893	67.9130020141602	0.0139753995463252	72.9984970092773
0.568427261896431	17.6993846893311	68.2129974365234	0.0140763996168971	73.2984008789063
0.570750096812844	17.7790260314941	68.5130004882813	0.0141415996477008	73.5983963012695
0.573370663914829	17.8420448303223	68.8130035400391	0.0141842002049088	73.9983978271484
0.575872138142586	17.8287334442139	69.1129989624023	0.0142005998641253	74.2984008789063
0.578135368414223	17.8398056030273	69.4130020141602	0.0143497996032238	74.4983978271484
0.580934574827552	17.9497375488281	69.7129974365234	0.0144534995779395	74.8004989624023
0.583733839448541	17.9642524719238	70.0130004882813	0.0145284999161959	75.1984024047852
0.586294860113412	17.9995861053467	70.3130035400391	0.0145904999226332	75.4982986450195
0.588736787904054	18.0841121673584	70.6129989624023	0.0146882999688387	75.6984024047852
0.591357355006039	18.0912780761719	70.9130020141602	0.0147428996860981	75.9983978271484
0.59379922458902	18.0975036621094	71.2129974365234	0.0147970002144575	76.3991012573242
0.595943361986428	18.1538066864014	71.5130004882813	0.014831000007689	76.6983032226563
0.59838528977707	18.1365413665771	71.8130035400391	0.0149133000522852	76.8983001708984
0.601124949753284	18.1778736114502	72.1129989624023	0.0150103000923991	77.1985015869141
0.603149936068803	18.2395896911621	72.4130020141602	0.0150670995935798	77.4983978271484
0.605770503170788	18.2534236907959	72.7129974365234	0.015175599604845	77.7984008789063
0.608569767791778	18.2828330993652	73.0130004882813	0.0152289001271129	78.0982971191406
0.610832998063415	18.3760509490967	73.3130035400391	0.0152438003569841	78.4084014892578
0.613513169810176	18.3664054870605	73.6129989624023	0.0153325004503131	78.7984008789063
0.616133736912161	18.3914127349854	73.9130020141602	0.0154261002317071	78.9982986450195
0.618635211139917	18.4757633209229	74.2129974365234	0.0154819004237652	79.2983016967773
0.620898441411555	18.4875640869141	74.5130004882813	0.0155608998611569	79.5983963012695
0.62351900851354	18.5006427764893	74.8130035400391	0.0156642999500036	79.9982986450195
0.625841785222292	18.5554790496826	75.1129989624023	0.0156532991677523	80.1983032226563
0.628105015493929	18.5717086791992	75.4130020141602	0.0157594997435808	80.4981994628906
0.630725582595915	18.5777702331543	75.7129974365234	0.0158204007893801	80.8983001708984
0.6333461496979	18.6620025634766	76.0130004882813	0.0159085001796484	81.1981964111328
0.635668926406652	18.6713104248047	76.3130035400391	0.0159517005085945	81.3982009887695
0.637932156678289	18.6275615692139	76.6129989624023	0.0160108990967274	81.6981964111328
0.640850572381169	18.7603359222412	76.9130020141602	0.0160662997514009	82.0982971191406
0.643232895527035	18.7822151184082	77.2129974365234	0.0161466002464294	82.3982009887695
0.645615218672901	18.7462940216064	77.5130004882813	0.0162099990993738	82.5981979370117
0.648474029731005	18.8652305603027	77.8130035400391	0.0163158997893333	82.8982009887695
0.650915957521647	18.895486831665	78.1129989624023	0.0163965001702309	83.2982025146484
0.653417431749403	18.8954734802246	78.4130020141602	0.0164355002343655	83.4981994628906
0.655978452414274	18.9737281799316	78.7129974365234	0.016542699187994	83.7982025146484
0.658539473079145	19.0351867675781	79.0130004882813	0.016559200361371	84.0981979370117
0.660981342662126	18.9887523651123	79.3130035400391	0.0166309997439384	84.4981002807617
0.663542363326997	19.0706672668457	79.6129989624023	0.0167309995740652	84.6981964111328
0.666162930428982	19.117618560791	79.9130020141602	0.0167957004159689	84.9981994628906
0.668545311782509	19.0898609161377	80.2129974365234	0.0168903991580009	85.2981033325195
0.671046786010265	19.1608638763428	80.5130004882813	0.0169501006603241	85.6981964111328
0.673667353112251	19.2170944213867	80.8130035400391	0.0170112997293472	85.8982009887695
0.676109222695231	19.1979789733887	81.1129989624023	0.0170719008892775	86.1980972290039
0.678312906529754	19.2443332672119	81.4130020141602	0.0171284005045891	86.4981002807617
0.681171717587858	19.3395195007324	81.7129974365234	0.0172096006572247	86.7982025146484
0.6836136453785	19.278377532959	82.0130004882813	0.0173000991344452	87.1108016967773
0.685817271005362	19.3097743988037	82.3130035400391	0.0174071006476879	87.3981018066406
0.688437896315008	19.4092712402344	82.6129989624023	0.017451599240303	87.7981033325195
0.690998916979879	19.391902923584	82.9130020141602	0.0175020005553961	87.9981002807617
0.693142996169627	19.3998584747314	83.2129974365234	0.0175835993140936	88.2981033325195
0.695823109708726	19.4829368591309	83.5130004882813	0.0176618006080389	88.5980987548828
0.698443735018373	19.4892139434814	83.8130035400391	0.0177711006253958	88.9981002807617
0.700766511727124	19.484375	84.1129989624023	0.0177941992878914	89.1980972290039
0.703208381310105	19.5584888458252	84.4130020141602	0.0178366992622614	89.4981994628906
0.705888553056866	19.5793399810791	84.7129974365234	0.0180383995175362	89.7981033325195
0.708449573721737	19.593505859375	85.0130004882813	0.0179610997438431	90.1980972290039
0.710772350430489	19.6594753265381	85.3130035400391	0.0180210005491972	90.3980026245117
0.713690707925707	19.6875553131104	85.6129989624023	0.0181521996855736	90.697998046875
0.716132635716349	19.6906318664551	85.9130020141602	0.0181767996400595	90.9981002807617
0.718455412425101	19.7636470794678	86.2129974365234	0.0182620994746685	91.3981018066406
0.721016433089972	19.769437789917	86.5130004882813	0.0183591991662979	91.6016006469727
0.723517907317728	19.7690410614014	86.8130035400391	0.0184205006808043	91.8981018066406
0.725900230463594	19.8411312103271	87.1129989624023	0.018469400703907	92.1980972290039
0.728223007172346	19.8457260131836	87.4130020141602	0.0185566991567612	92.5979995727539
0.730903178919107	19.8742065429688	87.7129974365234	0.0185940992087126	92.8980026245117
0.733345048502088	19.9419384002686	88.0130004882813	0.0187030006200075	93.0980987548828
0.735786976292729	19.9489612579346	88.3130035400391	0.0187643002718687	93.3980026245117
0.7383479969576	19.9484691619873	88.6129989624023	0.0188504997640848	93.7979965209961
0.740730320103467	20.0176162719727	88.9130020141602	0.0189158003777266	93.9980010986328
0.743291340768337	20.0451240539551	89.2129974365234	0.018817100673914	94.2979965209961
0.745971454307437	20.0481548309326	89.5130004882813	0.0189957991242409	94.5979995727539
0.748234684579074	20.1035919189453	89.8130035400391	0.0191353000700474	94.9979019165039
0.750974402762949	20.1765537261963	90.1129989624023	0.0191840995103121	95.197998046875
0.753475876990706	20.1363830566406	90.4130020141602	0.0192530006170273	95.5025024414063
0.756036897655576	20.238977432251	90.7129974365234	0.0192754007875919	95.8980026245117
0.758478767238557	20.2551708221436	91.0130004882813	0.0194106996059418	96.1978988647461
0.761099334340543	20.2488250732422	91.3130035400391	0.0194640997797251	96.3979034423828
0.763600808568299	20.3357353210449	91.6129989624023	0.019539799541235	96.6978988647461
0.765983189921826	20.350923538208	91.9130020141602	0.0196157991886139	97.0982971191406
0.768365513067693	20.3127326965332	92.2129974365234	0.0196978002786636	97.2978973388672
0.771045626606792	20.4002494812012	92.5130004882813	0.0197240002453327	97.5978012084961
0.773368461523205	20.4338626861572	92.8130035400391	0.0197841990739107	97.8979034423828
0.775750784669071	20.4030170440674	93.1129989624023	0.0197991002351046	98.2978973388672
0.778430898208171	20.4727306365967	93.4130020141602	0.0199331007897854	98.597900390625
0.781051465310156	20.5433616638184	93.7129974365234	0.0200079008936882	98.7978973388672
0.783374300226569	20.5076847076416	94.0130004882813	0.0200635008513927	99.0978012084961
0.786173506639898	20.5775260925293	94.3130035400391	0.020108699798584	99.497802734375
0.788674980867654	20.6293468475342	94.6129989624023	0.0203131008893251	99.6977996826172
0.791057362221181	20.5811176300049	94.9130020141602	0.0203090999275446	99.997802734375
0.793439685367048	20.621919631958	95.2129974365234	0.0203597992658615	100.297798156738
0.796179403550923	20.704927444458	95.5130004882813	0.0204406008124352	100.697799682617
0.798383029177785	20.6564407348633	95.8130035400391	0.0205205995589495	100.897903442383
0.800824956968427	20.6828079223633	96.1129989624023	0.0205616001039743	101.197799682617
0.803385977633297	20.7813453674316	96.4130020141602	0.0206052009016275	101.597801208496
0.805768300779164	20.743501663208	96.7129974365234	0.0207024998962879	101.897796630859
0.80826977500692	20.7668228149414	97.0130004882813	0.0207445994019508	102.097702026367
0.811009493190795	20.862756729126	97.3130035400391	0.0208374001085758	102.397796630859
0.813451362773776	20.8366718292236	97.6129989624023	0.0209286008030176	102.697700500488
0.815893290564418	20.8502578735352	97.9130020141602	0.0209961999207735	103.097702026367
0.818394764792174	20.9163055419922	98.2129974365234	0.0210337992757559	103.299598693848
0.82077708793804	20.9039649963379	98.5130004882813	0.0211321990936995	103.597801208496
0.823278562165797	20.9316749572754	98.8130035400391	0.0211689993739128	103.89769744873
0.825839582830667	20.9987373352051	99.1129989624023	0.0212645009160042	104.297698974609
0.828400603495538	20.9965362548828	99.4130020141602	0.02134820073843	104.497703552246
0.830961624160409	21.0046195983887	99.7129974365234	0.0214540008455515	104.799896240234
0.83340349374339	21.0872383117676	100.013000488281	0.0214606001973152	105.197799682617
0.835964514408261	21.0875701904297	100.313003540039	0.0215574000030756	105.497703552246
0.838227744679898	21.0579319000244	100.612998962402	0.0216180998831987	105.697700500488
0.840848311781883	21.1688766479492	100.91300201416	0.021696899086237	105.997802734375
0.843290239572525	21.1570148468018	101.212997436523	0.0217503998428583	106.39769744873
0.84591080667451	21.170841217041	101.513000488281	0.0218391995877028	106.697700500488
0.848352734465152	21.2220516204834	101.813003540039	0.0219158008694649	106.89769744873
0.851151940878481	21.2790584564209	102.112998962402	0.022019000723958	107.197601318359
0.853593868669122	21.2386207580566	102.41300201416	0.0221887994557619	107.597702026367
0.856095342896879	21.3320026397705	102.712997436523	0.0223283991217613	107.897598266602
0.858715909998864	21.3695087432861	103.013000488281	0.0222392007708549	108.097702026367
0.86121738422662	21.3112773895264	103.313003540039	0.02225730009377	108.397598266602
0.863421009853482	21.3999614715576	103.612998962402	0.0224367994815111	108.79759979248
0.86580339120701	21.3888034820557	103.91300201416	0.0223827995359898	108.997596740723
0.86824526078999	21.3695907592773	104.212997436523	0.0224849004298449	109.29759979248
0.87027030531317	21.4050140380859	104.513000488281	0.02252840064466	109.697601318359
0.87295041885227	21.4574737548828	104.813003540039	0.0226166006177664	109.997596740723
0.875690137036145	21.4456481933594	105.112998962402	0.0226984992623329	110.197601318359
0.878429797012359	21.5174198150635	105.41300201416	0.0227713994681835	110.497703552246
0.881229061633348	21.5846920013428	105.712997436523	0.0228316001594067	110.897598266602
0.88367098942399	21.5661792755127	106.013000488281	0.0229212008416653	111.197601318359
0.886232010088861	21.6251945495605	106.313003540039	0.0230007003992796	111.397499084473
0.888673879671842	21.6590366363525	106.612998962402	0.0230631995946169	111.697601318359
0.891294446773827	21.6698055267334	106.91300201416	0.0231304001063108	112.097602844238
0.893617223482579	21.6902084350586	107.212997436523	0.0231852997094393	112.397598266602
0.895820907317102	21.7258205413818	107.513000488281	0.0231685005128384	112.597602844238
0.898381927981973	21.7012577056885	107.813003540039	0.0233545005321503	112.897598266602
0.900942948646843	21.7383613586426	108.112998962402	0.0233932007104158	113.297500610352
0.903325330000371	21.7978744506836	108.41300201416	0.0235443003475666	113.597503662109
0.90600544353947	21.7868480682373	108.712997436523	0.0235479008406401	113.79759979248
0.908506917767227	21.8127746582031	109.013000488281	0.0237150993198156	114.097602844238
0.910948787350208	21.8802814483643	109.313003540039	0.0236986000090837	114.497596740723
0.913331168703735	21.8483333587646	109.612998962402	0.0237702000886202	114.797500610352
0.91583258472383	21.878755569458	109.91300201416	0.023853300139308	114.997497558594
0.918393605388701	21.9480304718018	110.212997436523	0.023938100785017	115.297500610352
0.920716440305114	21.9200801849365	110.513000488281	0.0239403005689383	115.69750213623
0.923277460969985	21.9242191314697	110.813003540039	0.0240502003580332	115.897499084473
0.926136272028089	22.0139694213867	111.112998962402	0.0241372007876635	116.197402954102
0.928280351217836	21.9994812011719	111.41300201416	0.0241701994091272	116.597503662109
0.931079615838826	22.0339374542236	111.712997436523	0.0242554005235434	116.897598266602
0.933640636503696	22.1066017150879	112.013000488281	0.0243188999593258	117.097396850586
0.935844320338219	22.0724182128906	112.313003540039	0.0244568008929491	117.397399902344
0.9382861899212	22.0812168121338	112.612998962402	0.0244826003909111	117.799797058105
0.940847210586071	22.1622695922852	112.91300201416	0.0245469994843006	118.097396850586
0.943289138376713	22.146125793457	113.212997436523	0.0245638992637396	118.309700012207
0.945850159041584	22.1485691070557	113.513000488281	0.0246556997299194	118.597396850586
0.948351575061679	22.2344627380371	113.813003540039	0.0246923007071018	118.997398376465
0.950972200371325	22.2634124755859	114.112998962402	0.0248505994677544	119.19750213623
0.953294977080077	22.2031059265137	114.41300201416	0.0248550996184349	119.497497558594
0.955855997744948	22.2991714477539	114.712997436523	0.024906300008297	119.797401428223
0.958476564846933	22.3359317779541	115.013000488281	0.0250652991235256	120.19750213623
0.960799341555685	22.3010787963867	115.313003540039	0.0250752996653318	120.497299194336
0.96353905973956	22.371114730835	115.612998962402	0.0251723006367683	120.697303771973
0.966100080404431	22.4160823822021	115.91300201416	0.0252432990819216	120.997299194336
0.968422857113183	22.3715744018555	116.212997436523	0.0253289993852377	121.397399902344
0.971222121734172	22.4704093933105	116.513000488281	0.025407699868083	121.697402954102
0.973604444880038	22.4883613586426	116.813003540039	0.0254813004285097	121.897300720215
0.976344163063914	22.4702854156494	117.112998962402	0.0255215000361204	122.197402954102
0.97860733512789	22.5209903717041	117.41300201416	0.0255893003195524	122.597297668457
0.981049262918532	22.5841789245605	117.712997436523	0.0256472006440163	122.797302246094
0.983431586064398	22.5235042572021	118.013000488281	0.0257294997572899	123.097396850586
0.98587351385504	22.6046142578125	118.313003540039	0.0258034002035856	123.397300720215
0.988077139481902	22.6136493682861	118.612998962402	0.0258932001888752	123.797302246094
0.990757369436324	22.5859851837158	118.91300201416	0.0259202998131514	123.997299194336
0.993199180811644	22.6368255615234	119.212997436523	0.0259757004678249	124.297302246094
0.995581620372832	22.6787281036377	119.513000488281	0.0260602999478579	124.597198486328
0.998440431430936	22.6744976043701	119.813003540039	0.0263362992554903	124.997200012207
1.00070366170257	22.6938934326172	120.112998962402	0.026239300146699	125.197303771973
1.00326468236744	22.7782688140869	120.41300201416	0.0263158995658159	125.497299194336
1.00594479590654	22.7464962005615	120.712997436523	0.0263356994837523	125.797203063965
1.00844621192664	22.7843036651611	121.013000488281	0.0264455992728472	126.197303771973
1.01082853507251	22.8479652404785	121.313003540039	0.0264995992183685	126.397300720215
1.01338955573738	22.8205299377441	121.612998962402	0.0265998002141714	126.697303771973
1.01624836679548	22.8535804748535	121.91300201416	0.0266283992677927	127.097198486328
1.01833301596344	22.890438079834	122.212997436523	0.026724100112915	127.397201538086
1.02083443198353	22.8677215576172	122.513000488281	0.0267983004450798	127.597198486328
1.02351454552263	22.9067115783691	122.813003540039	0.0268578995019197	127.897201538086
1.02595647331327	22.9651260375977	123.112998962402	0.0269533004611731	128.29719543457
1.02839840110391	22.94655418396	123.41300201416	0.0269866995513439	128.597305297852
1.03101890999824	22.9762153625488	123.712997436523	0.0270451009273529	128.79719543457
1.03357993066311	23.039234161377	124.013000488281	0.0271511003375053	129.097305297852
1.03590276557952	23.0159111022949	124.313003540039	0.0271384008228779	129.497192382813
1.0386424837634	23.0190200805664	124.612998962402	0.0273380000144243	129.797103881836
1.04102480690926	23.0780506134033	124.91300201416	0.0273672994226217	129.997192382813
1.04316894430667	23.0765724182129	125.212997436523	0.0274413991719484	130.297302246094
1.04572996497154	23.0642890930176	125.513000488281	0.0275001991540194	130.69709777832
1.04835047386587	23.1369400024414	125.813003540039	0.0275021996349096	130.897094726563
1.05055421590805	23.1271648406982	126.112998962402	0.0276737995445728	131.197204589844
1.0532938176766	23.1318016052246	126.41300201416	0.027734600007534	131.497100830078
1.05573574546725	23.2062339782715	126.712997436523	0.0277920998632908	131.897094726563
1.05847546365112	23.2222003936768	127.013000488281	0.0278537999838591	132.097106933594
1.06115557719022	23.2117519378662	127.313003540039	0.0279322993010283	132.397201538086
1.06353790033609	23.2731838226318	127.612998962402	0.0280255991965532	132.797103881836
1.06597982812673	23.2959518432617	127.91300201416	0.0279859993606806	133.097106933594
1.06836215127259	23.263277053833	128.212997436523	0.0281524006277323	133.297103881836
1.07116147410125	23.3531913757324	128.513000488281	0.0282061994075775	133.597106933594
1.07360328547657	23.3681354522705	128.813003540039	0.0283084008842707	133.997100830078
1.07610481791198	23.3210563659668	129.113006591797	0.0283439997583628	134.299301147461
1.07866583857685	23.4068088531494	129.412994384766	0.0283959992229939	134.497100830078
1.08116725459695	23.4272537231445	129.712997436523	0.028532300144434	134.79719543457
1.08343048486859	23.3804893493652	130.013000488281	0.0286053996533155	135.19709777832
1.08587241265923	23.4539432525635	130.313003540039	0.028651399537921	135.497100830078
1.08825473580509	23.464864730835	130.613006591797	0.0287043992429972	135.697204589844
1.09033926855773	23.4090137481689	130.912994384766	0.0288228001445532	135.997100830078
1.09313859138638	23.4882984161377	131.212997436523	0.0288705006241798	136.397094726563
1.09581870492548	23.5552501678467	131.513000488281	0.0289264004677534	136.59700012207
1.09826063271612	23.5188999176025	131.813003540039	0.0289465002715588	136.897003173828
1.10064295586199	23.5472221374512	132.113006591797	0.0290472991764545	137.197006225586
1.10344216227531	23.6298408508301	132.412994384766	0.0290124993771315	137.59700012207
1.10600318294019	23.5959587097168	132.712997436523	0.0292016007006168	137.799697875977
1.10826641321182	23.6296443939209	133.013000488281	0.0292850993573666	138.09700012207
1.11064873635769	23.6537799835205	133.313003540039	0.0293442998081446	138.397201538086
1.11362675670534	23.6746597290039	133.613006591797	0.0294508002698421	138.796997070313
1.11594947520643	23.685230255127	133.912994384766	0.0294949002563953	138.997100830078
1.11845100764185	23.7613506317139	134.212997436523	0.0295561999082565	139.297103881836
1.12113112118095	23.7458381652832	134.513000488281	0.0296339001506567	139.69709777832
1.12363253720105	23.7647018432617	134.813003540039	0.0297014005482197	139.908294677734
1.12595537211746	23.815113067627	135.113006591797	0.0297864992171526	140.197006225586
1.12869509030133	23.7936630249023	135.412994384766	0.0299005005508661	140.496994018555
1.13095832057297	23.8099040985107	135.712997436523	0.0299529004842043	140.896896362305
1.13328103907406	23.8638877868652	136.013000488281	0.0299846008419991	141.197006225586
1.13602075725794	23.8738231658936	136.313003540039	0.0300546996295452	141.396896362305
1.13846268504858	23.8762512207031	136.613006591797	0.030103599652648	141.69709777832
1.14084500819445	23.9298439025879	136.912994384766	0.0301661007106304	142.096893310547
1.14346563350409	23.9289703369141	137.212997436523	0.0302801001816988	142.296905517578
1.14584795664996	23.924633026123	137.513000488281	0.0302949994802475	142.596893310547
1.14846846554428	23.9973640441895	137.813003540039	0.0303589999675751	142.896896362305
1.15108909085393	23.9861869812012	138.113006591797	0.0304279997944832	143.296905517578
1.15359050687402	23.9785079956055	138.412994384766	0.0305228997021914	143.496795654297
1.15585373714566	24.0587348937988	138.712997436523	0.0306094996631145	143.796997070313
1.15847436245531	24.0403823852539	139.013000488281	0.0306682996451855	144.096801757813
1.16127356886864	24.0563812255859	139.313003540039	0.0307535994797945	144.49690246582
1.16347731091082	24.1124744415283	139.613006591797	0.030833899974823	144.696792602539
1.16591912228614	24.1080474853516	139.912994384766	0.0309136994183064	144.996795654297
1.16848014295101	24.0821533203125	140.212997436523	0.0309603996574879	145.396896362305
1.17116037290543	24.1592578887939	140.513000488281	0.0310328006744385	145.696792602539
1.17330439388752	24.1735649108887	140.813003540039	0.0311214998364449	145.897094726563
1.17586541455239	24.1487350463867	141.113006591797	0.031182799488306	146.196899414063
1.17842643521726	24.2231674194336	141.412994384766	0.0312425997108221	146.596801757813
1.1806896654889	24.22607421875	141.712997436523	0.0312976986169815	146.89680480957
1.18331029079854	24.2001476287842	142.013000488281	0.0313607007265091	147.108001708984
1.18599040433764	24.2763175964355	142.313003540039	0.031436700373888	147.39680480957
1.18825363460928	24.2958908081055	142.613006591797	0.0315001010894775	147.796798706055
1.1907551670447	24.264820098877	142.912994384766	0.0315935984253883	148.096801757813
1.19355437345803	24.3339462280273	143.212997436523	0.0316480994224548	148.296798706055
1.19581760372967	24.358003616333	143.513000488281	0.0317049995064735	148.596801757813
1.19819992687553	24.3007392883301	143.813003540039	0.0317853987216949	148.996704101563
1.20064185466617	24.3633575439453	144.113006591797	0.0318602994084358	149.196899414063
1.20356015395373	24.4317226409912	144.412994384766	0.0320441983640194	149.496795654297
1.20594259351492	24.3637809753418	144.712997436523	0.0319994017481804	149.89680480957
1.20856310240924	24.4352149963379	145.013000488281	0.0320675000548363	150.196701049805
1.21118372771889	24.4977931976318	145.313003540039	0.0321603007614613	150.396697998047
1.21356605086476	24.4580116271973	145.613006591797	0.032250601798296	150.696792602539
1.21606746688485	24.4692802429199	145.912994384766	0.0323053002357483	151.096694946289
1.21874769683927	24.5405368804932	146.212997436523	0.03238819912076	151.396697998047
1.22083222959191	24.4967994689941	146.513000488281	0.0324485003948212	151.596694946289
1.22321455273777	24.5248718261719	146.813003540039	0.0325164012610912	151.896697998047
1.22565648052841	24.5710830688477	147.113006591797	0.0325610004365444	152.298400878906
1.22809840831906	24.5351219177246	147.412994384766	0.032633900642395	152.596694946289
1.23048073146492	24.549280166626	147.712997436523	0.0327221006155014	152.79670715332
1.23298214748502	24.6071395874023	148.013000488281	0.0327817015349865	153.096694946289
1.2359005631879	24.6204738616943	148.313003540039	0.032838799059391	153.496795654297
1.23840197920799	24.6293029785156	148.613006591797	0.0329091995954514	153.79670715332
1.24090339522809	24.682788848877	148.912994384766	0.0329876989126205	153.996704101563
1.24370271805674	24.6861591339111	149.212997436523	0.0330461002886295	154.29670715332
1.2457276461646	24.65944480896	149.513000488281	0.0331231988966465	154.696701049805
1.24846736434847	24.7603397369385	149.813003540039	0.0332100987434387	154.89680480957
1.25114747788757	24.7428226470947	150.113006591797	0.0333537012338638	155.196792602539
1.25347031280398	24.7213668823242	150.412994384766	0.0333518981933594	155.496704101563
1.25615042634308	24.8299999237061	150.712997436523	0.0334126986563206	155.896697998047
1.25877105165273	24.8167247772217	151.013000488281	0.0337658002972603	156.096694946289
1.2611533747986	24.7911758422852	151.313003540039	0.0335922986268997	156.396697998047
1.26341660507023	24.8328819274902	151.613006591797	0.0336539000272751	156.79670715332
1.26603723037988	24.83766746521	151.912994384766	0.0339688993990421	157.096603393555
1.26871734391898	24.8134918212891	152.212997436523	0.0339334011077881	157.296600341797
1.27109966706485	24.8617382049561	152.513000488281	0.0339128002524376	157.596603393555
1.27342250198126	24.8693370819092	152.813003540039	0.0338919013738632	157.996597290039
1.27598352264613	24.8398818969727	153.113006591797	0.0339772999286652	158.29670715332
1.278365845792	24.8749237060547	153.412994384766	0.0341725014150143	158.496597290039
1.28086726181209	24.8849411010742	153.712997436523	0.0340971015393734	158.79670715332
1.28354737535119	24.8646183013916	154.013000488281	0.0341712012887001	159.196594238281
1.28581060562283	24.903600692749	154.313003540039	0.0341757982969284	159.496597290039
1.28831213805825	24.9373035430908	154.613006591797	0.0342119000852108	159.696701049805
1.29075394943357	24.8924312591553	154.912994384766	0.0343388989567757	159.996597290039
1.29325548186898	24.9307594299316	155.212997436523	0.0343952998518944	160.396697998047
1.29575689788908	24.9480743408203	155.513000488281	0.0344388000667095	160.596694946289
1.29831791855395	24.9256725311279	155.813003540039	0.0345393009483814	160.896697998047
1.30105763673782	24.9974193572998	156.113006591797	0.0346263013780117	161.196594238281
1.30343995988369	25.0138893127441	156.412994384766	0.03471440076828	161.596603393555
1.30588188767433	24.9548645019531	156.712997436523	0.0348177999258041	161.796600341797
1.30856200121343	25.0077533721924	157.013000488281	0.0348711982369423	162.096603393555
1.31088483612984	24.9913482666016	157.313003540039	0.0348845012485981	162.396697998047
1.31332676392049	24.9332637786865	157.613006591797	0.0349190011620522	162.796600341797
1.31600687745959	24.9575824737549	157.912994384766	0.034987099468708	162.996597290039
1.31844880525023	24.9775047302246	158.212997436523	0.0350124016404152	163.296600341797
1.32083112839609	24.8902645111084	158.513000488281	0.0350995995104313	163.696594238281
1.32351124193519	24.902416229248	158.813003540039	0.0352123007178307	163.996505737305
1.32625096011907	24.9184284210205	159.113006591797	0.0352774001657963	164.196502685547
1.32839498110116	24.7611999511719	159.412994384766	0.0352621003985405	164.496398925781
1.33107521105558	24.7055282592773	159.712997436523	0.0352877005934715	164.896606445313
1.3335170224309	24.511926651001	160.013000488281	0.0353653989732265	165.196502685547
1.33512518368661	-10.1133518218994	160.218002319336	0.035376500338316	165.396499633789