File: CSVs/24-01-08_Tensile_paper-PDMS/Oven_Coated_3/asdf.txt
File Path: C:\Users\apk5101\Desktop\Sandra\Oven_Coated_3 01-8-24 11 12 58 AM\DAQ- Crosshead, … - (Timed).txt
Test: MTS EM Tension (Simplified) with Video Extensometer apk5101 25
Test Run: Oven_Coated_3
Date: 1/8/2024 11:08:55 AM


Crosshead 	Load 	Time 	Strain 1 	Video Time
mm	N	sec	mm/mm	sec
5.95586016061134E-05	-2.31691193580627	0.112999998033047	-3.01479994959664E-05	4.19990015029907
0.00053602741445502	-2.26763653755188	0.312999993562698	-2.13707007787889E-05	4.40000009536743
0.00232278534895158	-1.98448383808136	0.513000011444092	-7.79890979174525E-05	4.49989986419678
0.00446689500677167	-1.54676902294159	0.712999999523163	2.21515001612715E-05	4.69990015029907
0.0065514459492988	-1.14484775066376	0.912999987602234	4.80060989502817E-05	4.89989995956421
0.00857643863128033	-0.712656259536743	1.11300003528595	6.25596003374085E-05	5.09989976882935
0.0103631964520901	-0.302603632211685	1.31299996376038	0.000142737000714988	5.39989995956421
0.0120903960123542	0.0307114832103252	1.51300001144409	0.000144178993650712	5.59999990463257
0.0141153886943357	0.401121228933334	1.71300005912781	0.000192884996067733	5.69990015029907
0.0158425882545998	0.738386690616608	1.91299998760223	0.000203232993953861	5.89989995956421
0.0174506694747834	1.11159574985504	2.11299991607666	0.000202399998670444	6.09989976882935
0.018999193343916	1.42172026634216	2.31299996376038	0.000321945000905544	6.29990005493164
0.0207263929041801	1.71975696086884	2.51300001144409	0.000340388010954484	6.59989976882935
0.022691827325616	2.06550812721252	2.71300005912781	0.000382633996196091	6.79990005493164
0.0242999085457996	2.40926313400269	2.91300010681152	0.000333142990712076	6.89989995956421
0.0256697567238007	2.69683623313904	3.11299991607666	0.00039425099384971	7.09980010986328
0.027516072805156	3.03038716316223	3.31299996376038	0.000456948997452855	7.29979991912842
0.0293028315354604	3.33728551864624	3.51300001144409	0.000485752010717988	7.49980020523071
0.0309109127556439	3.64595103263855	3.71300005912781	0.000504460011143237	7.69980001449585
0.0326976733049378	4.02787017822266	3.91300010681152	0.000505823991261423	7.90000009536743
0.0341270788339898	4.32883548736572	4.11299991607666	0.000559696985874325	8.19989967346191
0.0358542783942539	4.63639259338379	4.31300020217896	0.00059853499988094	8.29979991912842
0.0374623596144374	4.91359186172485	4.51300001144409	0.000601652020122856	8.49979972839355
0.0393086775147822	5.26071166992188	4.71299982070923	0.000752654974348843	8.69989967346191
0.0408572013839148	5.6046142578125	4.91300010681152	0.000719266012310982	8.89980030059814
0.0424652826040983	5.89317989349365	5.11299991607666	0.000785210984759033	9.19979953765869
0.0440138064732309	6.13745594024658	5.31300020217896	0.000677324016578496	9.39980030059814
0.045800563384546	6.43046379089355	5.51300001144409	0.000672105001285672	9.49979972839355
0.0475277629448101	6.79694700241089	5.71299982070923	0.000854535028338432	9.69979953765869
0.0491358441649936	7.10498285293579	5.91300010681152	0.000858740997500718	9.89980030059814
0.0508630437252577	7.38709735870361	6.11299991607666	0.000767840014304966	10.1149997711182
0.0523520102433395	7.6340389251709	6.31300020217896	0.00081809499533847	10.3997001647949
0.0540792098036036	7.9665699005127	6.51300001144409	0.000861319014802575	10.4997997283936
0.0559850850549992	8.33760356903076	6.71299982070923	0.000886360998265445	10.6997995376587
0.0574740515730809	8.64205360412598	6.91300010681152	0.000903134990949184	10.8998003005981
0.0590821327932645	8.89474391937256	7.11299991607666	0.000929635018110275	11.0996999740601
0.0608688897045795	9.17189598083496	7.31300020217896	0.000962431018706411	11.2996997833252
0.0625365282758139	9.47374725341797	7.51300001144409	0.00100846996065229	11.5998001098633
0.0643828461761586	9.85120391845703	7.71299982070923	0.00100692000705749	11.7996997833252
0.0659909273963422	10.1429862976074	7.91300010681152	0.00105355004779994	11.8997001647949
0.0676585696055554	10.3647718429565	8.11299991607666	0.00107708002906293	12.0998001098633
0.0692070971126668	10.6208381652832	8.3129997253418	0.00112695002462715	12.2996997833252
0.0707556173438206	10.9128122329712	8.51299953460693	0.00112042005639523	12.4997997283936
0.0725423742551357	11.2748260498047	8.71300029754639	0.00110469001810998	12.6997995376587
0.0742100164643489	11.5593709945679	8.91300010681152	0.00124280003365129	12.9996995925903
0.0759372196625918	11.8206090927124	9.11299991607666	0.00126112997531891	13.1152000427246
0.0776644155848771	12.1118192672729	9.3129997253418	0.00125361001119018	13.2997999191284
0.0793916115071625	12.4652709960938	9.51299953460693	0.00125660002231598	13.4996995925903
0.0809997000033036	12.7475395202637	9.71300029754639	0.00135372998192906	13.6997995376587
0.0827268959255889	13.005805015564	9.91300010681152	0.00138646003324538	13.8999996185303
0.0841563014546409	13.2026796340942	10.1129999160767	0.00154225004371256	14.1997003555298
0.0857643826748244	13.4978008270264	10.3129997253418	0.00147330004256219	14.2997999191284
0.0876702615641989	13.8556537628174	10.5129995346069	0.00144540995825082	14.4996004104614
0.0893379037734121	14.1116924285889	10.7130002975464	0.00188469002023339	14.6997003555298
0.0907673093024641	14.2920875549316	10.9130001068115	0.00168787001166493	14.8997001647949
0.0924349515116774	14.5601949691772	11.1129999160767	0.00168533995747566	15.1997003555298
0.094459937827196	14.9509763717651	11.3129997253418	0.00168016005773097	15.3997001647949
0.0958893506322056	15.1963672637939	11.5129995346069	0.00170408003032207	15.4996995925903
0.0974378708633594	15.4084224700928	11.7130002975464	0.0017606399487704	15.7079000473022
0.0991650740616024	15.6632680892944	11.9130001068115	0.00177991995587945	15.8997001647949
0.100832708994858	15.9478874206543	12.1129999160767	0.00179454998578876	16.0997009277344
0.102619465906173	16.2684268951416	12.3129997253418	0.0018260000506416	16.2996997833252
0.104406230093446	16.5601558685303	12.5129995346069	0.00191116996575147	16.6007995605469
0.106014311313629	16.7901477813721	12.7130002975464	0.00196211994625628	16.7996997833252
0.107562831544783	16.9871311187744	12.9130001068115	0.00196916004642844	16.9083003997803
0.109170912764966	17.2763195037842	13.1129999160767	0.00197937991470098	17.0995998382568
0.110898115963209	17.5592174530029	13.3129997253418	0.00203854008577764	17.2996997833252
0.112863548565656	17.8529033660889	13.5129995346069	0.00204120995476842	17.4997005462646
0.114173839392606	18.0108089447021	13.7130002975464	0.00209631002508104	17.7996006011963
0.115662805910688	18.2631301879883	13.9130001068115	0.00209731003269553	17.9995994567871
0.117509116535075	18.5745334625244	14.1129999160767	0.00208470993675292	18.0998001098633
0.11935543443542	18.876070022583	14.3129997253418	0.00211899005807936	18.2996006011963
0.121023076644633	19.1049003601074	14.5129995346069	0.00223746011033654	18.4997005462646
0.122631157864816	19.3229751586914	14.7130002975464	0.00226111011579633	18.6996994018555
0.124120124382898	19.5867671966553	14.9130001068115	0.00226502004079521	18.9995994567871
0.126026003272273	19.9147853851318	15.1129999160767	0.00229062000289559	19.1996994018555
0.127693638205528	20.1468601226807	15.3129997253418	0.00237104995176196	19.2996006011963
0.129539956105873	20.3709716796875	15.5129995346069	0.00227075000293553	19.4995994567871
0.131088483612984	20.5942325592041	15.7130002975464	0.00229364004917443	19.6996002197266
0.13269655755721	20.8847141265869	15.9130001068115	0.00248044007457793	19.9018001556396
0.134483314468525	21.1392669677734	16.113000869751	0.00246822996996343	20.0995998382568
0.136270085931756	21.3526306152344	16.3129997253418	0.00257471995428205	20.3995990753174
0.137818598886952	21.4636268615723	16.5130004882813	0.00248644989915192	20.5995998382568
0.139367126394063	21.72829246521	16.7129993438721	0.00252225995063782	20.6996002197266
0.140915653901175	21.9876594543457	16.9130001068115	0.00279024988412857	20.8995990753174
0.14264284982346	22.2712841033936	17.113000869751	0.00258076004683971	21.0995006561279
0.144429606734775	22.4953098297119	17.3129997253418	0.00262480997480452	21.2994995117188
0.146097241668031	22.7187881469727	17.5130004882813	0.00264313002116978	21.5995998382568
0.147526661748998	22.9602584838867	17.7129993438721	0.00271964003331959	21.7994995117188
0.149134735693224	23.1966533660889	17.9130001068115	0.00269675999879837	21.8995990753174
0.150802370626479	23.423303604126	18.113000869751	0.00273600989021361	22.0997009277344
0.15258914208971	23.6423091888428	18.3129997253418	0.0027895700186491	22.2996006011963
0.154137655044906	23.8541851043701	18.5130004882813	0.0028249800670892	22.4995002746582
0.155686182552017	24.1272773742676	18.7129993438721	0.00282058003358543	22.699499130249
0.157294271048158	24.3593292236328	18.9130001068115	0.00287024001590908	22.9995002746582
0.159021466970444	24.5770893096924	19.113000869751	0.00292441993951797	23.0995006561279
0.160569994477555	24.7470092773438	19.3129997253418	0.00294606992974877	23.2994995117188
0.16235675138887	25.03005027771	19.5130004882813	0.00296840001828969	23.4995002746582
0.164024386322126	25.3206748962402	19.7129993438721	0.0030425600707531	23.699499130249
0.165513352840208	25.4960956573486	19.9130001068115	0.00306093995459378	23.8995990753174
0.167359670740552	25.7151279449463	20.113000869751	0.0030947900377214	24.199499130249
0.169146427651867	25.9670543670654	20.3129997253418	0.00314444000832736	24.4020004272461
0.170814062585123	26.2507038116455	20.5130004882813	0.00311603001318872	24.4995994567871
0.172541273059323	26.5362720489502	20.7129993438721	0.00315034994855523	24.699499130249
0.174268468981609	26.7345523834229	20.9130001068115	0.00321806990541518	24.8994007110596
0.176114786881953	26.9793510437012	21.113000869751	0.00325532001443207	25.0995006561279
0.178020651219413	27.2575511932373	21.3129997253418	0.00331530999392271	25.3994998931885
0.179569178726524	27.4801502227783	21.5130004882813	0.00336347008123994	25.6093997955322
0.181117706233636	27.6919918060303	21.7129993438721	0.00338231003843248	25.699499130249
0.182904463144951	27.9075927734375	21.9130001068115	0.00346472999081016	25.8994998931885
0.184572098078206	28.1094818115234	22.113000869751	0.00354873994365335	26.0995998382568
0.186180186574347	28.3433094024658	22.3129997253418	0.00355972000397742	26.2994003295898
0.187609592103399	28.5608234405518	22.5130004882813	0.00354648008942604	26.5995006561279
0.189277227036655	28.7690029144287	22.7129993438721	0.00365457008592784	26.7994995117188
0.190885315532796	28.9380302429199	22.9130001068115	0.00366189004853368	26.8994998931885
0.192612511455081	29.1551742553711	23.113000869751	0.00369493989273906	27.0995006561279
0.194399268366396	29.4488162994385	23.3129997253418	0.00372840999625623	27.2994003295898
0.196007356862538	29.6671714782715	23.5130004882813	0.00370616000145674	27.4993991851807
0.197555884369649	29.8241539001465	23.7129993438721	0.00376566988416016	27.699499130249
0.199223519302905	30.0130043029785	23.9130001068115	0.00383605994284153	27.9993991851807
0.200831607799046	30.2341594696045	24.113000869751	0.0038105899002403	28.0995006561279
0.202737472136505	30.528829574585	24.3129997253418	0.00389022007584572	28.2994003295898
0.204047770239413	30.6678810119629	24.5130004882813	0.00389473000541329	28.4993991851807
0.205715405172668	30.8530502319336	24.7129993438721	0.00392598984763026	28.6993999481201
0.20714481070172	31.0015392303467	24.9130001068115	0.00398975005373359	28.8994007110596
0.209288918995298	31.3717403411865	25.113000869751	0.00403376016765833	29.0993995666504
0.21089700749144	31.6039390563965	25.3129997253418	0.00404206989333034	29.3994007110596
0.212564642424695	31.7712001800537	25.5130004882813	0.00407597981393337	29.4993991851807
0.214113169931807	31.9151782989502	25.7129993438721	0.00390098989009857	29.6993999481201
0.215840365854092	32.1370735168457	25.9130001068115	0.00414359988644719	29.899299621582
0.217686683754437	32.4303321838379	26.113000869751	0.00418070983141661	30.0993995666504
0.219473440665752	32.6805877685547	26.3129997253418	0.00420635007321835	30.2992992401123
0.221021968172863	32.8235397338867	26.5130004882813	0.00415530009195209	30.5993003845215
0.222570495679975	32.9774894714355	26.7129993438721	0.00413304986432195	30.6993999481201
0.224416813580319	33.2636337280273	26.9130001068115	0.00429800013080239	30.8994007110596
0.226084448513575	33.5039482116699	27.113000869751	0.0043854801915586	31.0993003845215
0.227632976020686	33.6755599975586	27.3129997253418	0.00430055009201169	31.2992992401123
0.229300610953942	33.8403053283691	27.5130004882813	0.00436982000246644	31.4993991851807
0.230789577472024	34.026123046875	27.7129993438721	0.00438824994489551	31.7992992401123
0.232576334383339	34.2967529296875	27.9130001068115	0.00453263986855745	31.899299621582
0.234303530305624	34.5157890319824	28.113000869751	0.00459414999932051	32.0993003845215
0.235971179790795	34.6821746826172	28.3129997253418	0.00451330980286002	32.2994003295898
0.237519707297906	34.8345336914063	28.5130004882813	0.00458385981619358	32.4992980957031
0.239187342231162	35.070198059082	28.7129993438721	0.00456923991441727	32.6994018554688
0.241093221120536	35.3440551757813	28.9130001068115	0.00460910983383656	32.9994010925293
0.242760856053792	35.5336570739746	29.113000869751	0.00465591019019485	33.1992988586426
0.244309369008988	35.6672515869141	29.3129997253418	0.0047061201184988	33.2993011474609
0.245977018494159	35.8620834350586	29.5130004882813	0.00470564002171159	33.4994010925293
0.247585092438385	36.0918579101563	29.7129993438721	0.00475030997768044	33.6992988586426
0.24943141033873	36.3590927124023	29.9130001068115	0.00477857980877161	33.899299621582
0.251039513386786	36.5082893371582	30.113000869751	0.0048022698611021	34.1992988586426
0.252409343374893	36.6158638000488	30.3129997253418	0.0048710098490119	34.399299621582
0.254136539297178	36.8223495483398	30.5130004882813	0.0049108499661088	34.4991989135742
0.255923310760409	37.0873489379883	30.7129993438721	0.00494791008532047	34.6992988586426
0.257769628660753	37.3265800476074	30.9130001068115	0.00497727002948523	34.8993988037109
0.259437278145924	37.4759368896484	31.113000869751	0.00499803991988301	35.0992012023926
0.260985776549205	37.6179428100586	31.3129997253418	0.00506485998630524	35.3992004394531
0.262593879597262	37.8282203674316	31.5130004882813	0.00508406991139054	35.5992012023926
0.264201953541487	38.0578918457031	31.7129993438721	0.00509636988863349	35.7994003295898
0.266048271441832	38.2563209533691	31.9130001068115	0.00516367005184293	35.899299621582
0.267656345386058	38.3935623168945	32.1129989624023	0.00516984984278679	36.0992012023926
0.269145326456055	38.5397338867188	32.3129997253418	0.00518351001664996	36.2991981506348
0.270574731985107	38.7327156066895	32.5130004882813	0.00522186979651451	36.4992980957031
0.272361474344507	38.9779014587402	32.7130012512207	0.00527038984000683	36.6994018554688
0.27444603620097	39.2097587585449	32.9129981994629	0.00535691017284989	36.9992980957031
0.275696773314849	39.282901763916	33.1129989624023	0.0054368800483644	37.0993003845215
0.27724530082196	39.4689521789551	33.3129997253418	0.00538913998752832	37.2991981506348
0.278853374766186	39.6786804199219	33.5130004882813	0.00541430991142988	37.4991989135742
0.28081881464459	39.9279975891113	33.7130012512207	0.00547744007781148	37.6991996765137
0.282665132544935	40.0861282348633	33.9129981994629	0.00556180998682976	37.899299621582
0.284273206489161	40.245361328125	34.1129989624023	0.00564613007009029	38.0992012023926
0.285821733996272	40.4309997558594	34.3129997253418	0.0056699002161622	38.2991981506348
0.287489354377612	40.6358489990234	34.5130004882813	0.00563356978818774	38.4991989135742
0.289216579403728	40.818058013916	34.7130012512207	0.00573064992204309	38.6991996765137
0.290884199785069	40.9555587768555	34.9129981994629	0.00574776995927095	38.899299621582
0.292611395707354	41.1672439575195	35.1129989624023	0.0058289198204875	39.0993003845215
0.294517289148644	41.4404830932617	35.3129997253418	0.00584390014410019	39.3992004394531
0.295827572699636	41.5582466125488	35.5130004882813	0.00589445000514388	39.4991989135742
0.297495222184807	41.7127914428711	35.7130012512207	0.00593905989080667	39.6991996765137
0.29957975493744	41.9254341125488	35.9129981994629	0.00596346985548735	39.8992004394531
0.301187857985497	42.140754699707	36.1129989624023	0.00599063979461789	40.0992012023926
0.302617263514549	42.2956886291504	36.3129997253418	0.00602190988138318	40.2991981506348
0.304284883895889	42.4400672912598	36.5130004882813	0.00607830984517932	40.5990982055664
0.306071655359119	42.5833511352539	36.7130012512207	0.0059714000672102	40.7990989685059
0.307798851281404	42.7899627685547	36.9129981994629	0.00593477999791503	40.8992004394531
0.309347378788516	42.9704437255859	37.1129989624023	0.00614657020196319	41.0990982055664
0.310836330754682	43.1315841674805	37.3129997253418	0.00622608978301287	41.2991981506348
0.312563526676968	43.3125114440918	37.5130004882813	0.00615774001926184	41.4990997314453
0.314231176162139	43.4481391906738	37.7130012512207	0.00623020017519593	41.7990989685059
0.316017947625369	43.6724662780762	37.9129981994629	0.00625695008784533	41.9990997314453
0.31756644602865	43.8712120056152	38.1129989624023	0.00634470023214817	42.0990982055664
0.319174549076706	44.0023803710938	38.3129997253418	0.00627710996195674	42.2990989685059
0.320842169458047	44.1694145202637	38.5130004882813	0.00636600004509091	42.4990997314453
0.322807609336451	44.3815116882324	38.7130012512207	0.00639799004420638	42.6991996765137
0.324475258821622	44.5745239257813	38.9129981994629	0.00643950002267957	42.9990997314453
0.325964210787788	44.7391395568848	39.1129989624023	0.00646569021046162	43.1991996765137
0.327631860272959	44.8861427307129	39.3129997253418	0.00648395996540785	43.2990989685059
0.32918038778007	44.9792671203613	39.5130004882813	0.00660576019436121	43.4990997314453
0.330967159243301	45.1669692993164	39.7130012512207	0.00661625992506742	43.6991004943848
0.332634779624641	45.4031105041504	39.9129981994629	0.00667101005092263	43.8991012573242
0.334123760694638	45.5496139526367	40.1129989624023	0.00671610003337264	44.0990982055664
0.335672288201749	45.6670303344727	40.3129997253418	0.00674383994191885	44.3991012573242
0.337399484124035	45.8286895751953	40.5130004882813	0.00680402992293239	44.4990005493164
0.339364894898608	46.0727005004883	40.7130012512207	0.00682371016591787	44.6990013122559
0.34091342240572	46.2546005249023	40.9129981994629	0.0068744900636375	44.898998260498
0.342521525453776	46.3902969360352	41.1129989624023	0.00689150020480156	45.0989990234375
0.344070023857057	46.4907417297363	41.3129997253418	0.00694755977019668	45.298999786377
0.345856795320287	46.6764259338379	41.5130004882813	0.0069680898450315	45.5989990234375
0.347583991242573	46.8647117614746	41.7130012512207	0.00699293008074164	45.798999786377
0.349311187164858	47.0624351501465	41.9129981994629	0.00705868005752563	45.898998260498
0.350800168234855	47.1561889648438	42.1129989624023	0.0071275900118053	46.0992012023926
0.352289120201021	47.2423324584961	42.3129997253418	0.00710181007161736	46.298999786377
0.354135438101366	47.4660949707031	42.5130004882813	0.00715522980317473	46.4990005493164
0.355862634023651	47.6973533630371	42.7130012512207	0.00720717012882233	46.798999786377
0.357589829945937	47.8620872497559	42.9129981994629	0.0072592101059854	46.9990997314453
0.359197932993993	47.9650344848633	43.1129989624023	0.00730428984388709	47.0989990234375
0.360925128916278	48.1390495300293	43.3129997253418	0.0073113702237606	47.298999786377
0.36247365642339	48.3100547790527	43.5130004882813	0.00733682978898287	47.4990005493164
0.364558189176023	48.5683708190918	43.7130012512207	0.00737845012918115	47.6990013122559
0.366106716683134	48.6727409362793	43.9129981994629	0.00748019991442561	47.9990005493164
0.367476575775072	48.7658958435059	44.1129989624023	0.00748131982982159	48.1991004943848
0.369203771697357	48.9215393066406	44.3129997253418	0.00755714997649193	48.298999786377
0.371228758012876	49.1928215026855	44.5130004882813	0.00755668012425303	48.4990005493164
0.372955953935161	49.3522109985352	44.7130012512207	0.00765431998297572	48.6990013122559
0.374444935005158	49.4579544067383	44.9129981994629	0.00779516017064452	48.8988990783691
0.375993433408439	49.5530662536621	45.1129989624023	0.00779700977727771	49.0992012023926
0.37766108289361	49.7425193786621	45.3129997253418	0.00778792984783649	49.298999786377
0.379388278815895	49.9328231811523	45.5130004882813	0.00782578997313976	49.4990005493164
0.381175050279126	50.1011161804199	45.7130012512207	0.00788213033229113	49.6990013122559
0.382604455808178	50.1630630493164	45.9129981994629	0.00791660044342279	49.898998260498
0.384212529752403	50.3056144714355	46.1129989624023	0.00794878974556923	50.0989990234375
0.385999301215634	50.5230522155762	46.3129997253418	0.00796250998973846	50.298900604248
0.387666921596974	50.699951171875	46.5130004882813	0.00803445000201464	50.5988998413086
0.389215449104086	50.784595489502	46.7130012512207	0.00806090980768204	50.6988983154297
0.391002220567316	50.9270706176758	46.9129981994629	0.00811596028506756	50.898998260498
0.392550748074427	51.0447387695313	47.1129989624023	0.00816958956420422	51.0989990234375
0.394218368455768	51.240348815918	47.3129997253418	0.00814507994800806	51.298900604248
0.395945593481883	51.3884696960449	47.5130004882813	0.00820162985473871	51.4990005493164
0.397553667426109	51.4833030700684	47.7130012512207	0.00828752014786005	51.6988983154297
0.399102194933221	51.5940628051758	47.9129981994629	0.00832203030586243	51.9989013671875
0.400710268877447	51.7606086730957	48.1129989624023	0.00833091977983713	52.0989990234375
0.402377918362617	51.951789855957	48.3129997253418	0.00838060025125742	52.298999786377
0.404164660722017	52.1118316650391	48.5130004882813	0.00840902980417013	52.4990005493164
0.406070554163307	52.263542175293	48.7130012512207	0.00834398996084929	52.6990013122559
0.407619052566588	52.3552169799805	48.9129981994629	0.00842154026031494	52.9084014892578
0.409227155614644	52.5546951293945	49.1129989624023	0.00849412009119987	53.1987991333008
0.410894775995985	52.716064453125	49.3129997253418	0.00854060985147953	53.298900604248
0.412860215874389	52.8740158081055	49.5130004882813	0.00851019006222486	53.4989013671875
0.4144087433815	52.9770431518555	49.7130012512207	0.00855723023414612	53.6988983154297
0.416076392866671	53.1346702575684	49.9129981994629	0.00861341971904039	53.8988990783691
0.417684466810897	53.296760559082	50.1129989624023	0.00879362039268017	54.0988998413086
0.419411662733182	53.4516372680664	50.3129997253418	0.00867404974997044	54.298900604248
0.421198434196413	53.5680160522461	50.5130004882813	0.00877200998365879	54.5988998413086
0.422925630118698	53.7216491699219	50.7130012512207	0.00882256031036377	54.7070999145508
0.424116791691631	53.7953071594238	50.9129981994629	0.00885675009340048	54.8988990783691
0.425843987613916	53.9656448364258	51.1129989624023	0.00901168026030064	55.0988006591797
0.427511637099087	54.0916862487793	51.3129997253418	0.0089578703045845	55.298900604248
0.429298408562317	54.2261276245117	51.5130004882813	0.00898979976773262	55.5988006591797
0.430966028943658	54.3598136901855	51.7130012512207	0.00902345962822437	55.798900604248
0.43239543447271	54.4662284851074	51.9129981994629	0.00904791988432407	55.8988990783691
0.434003537520766	54.6173934936523	52.1129989624023	0.0090893404558301	56.0988998413086
0.435909401858225	54.7684020996094	52.3129997253418	0.00915475003421307	56.298900604248
0.437577051343396	54.8646469116211	52.5130004882813	0.00912549998611212	56.4987983703613
0.439185125287622	55.0085868835449	52.7130012512207	0.0092053497210145	56.7988014221191
0.440852774772793	55.1899375915527	52.9129981994629	0.00923328008502722	56.9987983703613
0.442401302279904	55.2777404785156	53.1129989624023	0.00926887989044189	57.0988006591797
0.444247591076419	55.4186859130859	53.3129997253418	0.00928984954953194	57.2988014221191
0.446034362539649	55.5875015258789	53.5130004882813	0.00930648017674685	57.4987983703613
0.44770201202482	55.7543907165527	53.7130012512207	0.00938711035996675	57.6987991333008
0.449190963990986	55.8510055541992	53.9129981994629	0.00944733992218971	57.9987983703613
0.450799037935212	55.9514389038086	54.1129989624023	0.0094606801867485	58.1987991333008
0.452585809398443	56.0945701599121	54.3129997253418	0.00949400011450052	58.3026008605957
0.454372580861673	56.2496795654297	54.5130004882813	0.00951709970831871	58.4987983703613
0.456218869658187	56.4751968383789	54.7130012512207	0.00958366971462965	58.6987991333008
0.457588728750125	56.5131378173828	54.9129981994629	0.00963686965405941	58.8987007141113
0.458839465864003	56.5273246765137	55.1129989624023	0.00966682005673647	59.1987991333008
0.461043120594695	56.7278480529785	55.3129997253418	0.00968618039041758	59.3987007141113
0.462710770079866	56.912841796875	55.5130004882813	0.0096949003636837	59.4986991882324
0.464437966002151	57.0720329284668	55.7130012512207	0.00969981029629707	59.6986999511719
0.465807825094089	57.1077346801758	55.9129981994629	0.00975271034985781	59.8987998962402
0.467594567453489	57.2106895446777	56.1129989624023	0.00992592982947826	60.0987014770508
0.469321763375774	57.3709678649902	56.3129997253418	0.00996799021959305	60.3987007141113
0.47104898840189	57.5455513000488	56.5130004882813	0.00994512997567654	60.5987014770508
0.472597486805171	57.6620635986328	56.7130012512207	0.0100071998313069	60.6986999511719
0.474146014312282	57.7062568664551	56.9129981994629	0.010118099860847	60.8987007141113
0.475873210234568	57.8441123962402	57.1129989624023	0.0102123003453016	61.0987014770508
0.477481313282624	57.9900283813477	57.3129997253418	0.0102543001994491	61.2985992431641
0.47908938722685	58.1274909973145	57.5130004882813	0.0102441003546119	61.4986991882324
0.480935705127195	58.2694396972656	57.7130012512207	0.0102513004094362	61.798698425293
0.482484232634306	58.3206901550293	57.9129981994629	0.0103040002286434	61.8987007141113
0.484151853015646	58.4399948120117	58.1129989624023	0.0103756003081799	62.0987014770508
0.485998170915991	58.6370048522949	58.3129997253418	0.010394399985671	62.298698425293
0.487784942379221	58.8178863525391	58.5130004882813	0.0104291997849941	62.4986991882324
0.489214377012104	58.8655700683594	58.7130012512207	0.0104604000225663	62.6986999511719
0.49070332897827	58.9149436950684	58.9129981994629	0.0105026997625828	62.9986000061035
0.492609164211899	59.1085586547852	59.1129989624023	0.0105408998206258	63.1986999511719
0.49439596477896	59.3023490905762	59.3129997253418	0.0105541003867984	63.2985992431641
0.496123160701245	59.425537109375	59.5130004882813	0.0106464000418782	63.4986991882324
0.497612112667412	59.5009269714355	59.7130012512207	0.0106953997164965	63.698600769043
0.499279762152582	59.588493347168	59.9129981994629	0.0107316002249718	63.8986015319824
0.501245202030987	59.8113594055176	60.1129989624023	0.0107795000076294	64.198600769043
0.502972397953272	59.975715637207	60.3129997253418	0.0107835000380874	64.3985977172852
0.504699593875557	60.0616226196289	60.5130004882813	0.0108479997143149	64.4985961914063
0.506188545841724	60.1110153198242	60.7130012512207	0.0107990000396967	64.698600769043
0.507617951370776	60.1913452148438	60.9129981994629	0.010929100215435	64.8986968994141
0.509345147293061	60.3791275024414	61.1129989624023	0.0109772998839617	65.0986022949219
0.510893703904003	60.4785385131836	61.3129997253418	0.0110354004427791	65.3984985351563
0.512501748744398	60.5505447387695	61.5130004882813	0.01102240011096	65.5987014770508
0.513990700710565	60.6217994689941	61.7130012512207	0.0110882995650172	65.6986999511719
0.515539257321507	60.7319183349609	61.9129981994629	0.0111494995653629	65.8986968994141
0.517266453243792	60.912296295166	62.1129989624023	0.0111645003780723	66.0986022949219
0.519112742040306	61.0548248291016	62.3129997253418	0.01117969956249	66.2985992431641
0.520839937962592	61.1466484069824	62.5130004882813	0.0112281003966928	66.5986022949219
0.522448041010648	61.2342147827148	62.7130012512207	0.0112396003678441	66.798698425293
0.5238774465397	61.3498344421387	62.9129981994629	0.0112699996680021	66.8988037109375
0.526021583937109	61.5816917419434	63.1129989624023	0.0112936003133655	67.0986022949219
0.527689233422279	61.6397743225098	63.3129997253418	0.0113676004111767	67.2985992431641
0.52923773182556	61.7150840759277	63.5130004882813	0.011443099938333	67.4984970092773
0.530905381310731	61.8282089233398	63.7130012512207	0.0114521002396941	67.7985992431641
0.532513426151127	61.9854011535645	63.9129981994629	0.0114546995609999	67.8985977172852
0.534300226718187	62.1276092529297	64.1129989624023	0.0115427002310753	68.0986022949219
0.536086969077587	62.2309646606445	64.3130035400391	0.0115881003439426	68.2985000610352
0.537635467480868	62.2972717285156	64.5130004882813	0.0116327004507184	68.4984970092773
0.539303116966039	62.4471702575684	64.7129974365234	0.0116343004629016	68.6985015869141
0.54097076645121	62.5796318054199	64.9130020141602	0.0116929998621345	68.8984985351563
0.542638415936381	62.6780471801758	65.1129989624023	0.0116897001862526	69.1985015869141
0.54442515829578	62.7843360900879	65.3130035400391	0.0117370001971722	69.3984985351563
0.546152354218066	62.9083442687988	65.5130004882813	0.0118038998916745	69.4984970092773
0.547462666872889	62.9715194702148	65.7129974365234	0.011829299852252	69.698600769043
0.549487653188407	63.1697845458984	65.9130020141602	0.0118872001767159	69.8985977172852
0.550976605154574	63.2055473327637	66.1129989624023	0.0119436997920275	70.1985015869141
0.552822952158749	63.316722869873	66.3130035400391	0.0119735999032855	70.3984985351563
0.554252357687801	63.4063835144043	66.5130004882813	0.011986400000751	70.4984970092773
0.555741309653968	63.5302276611328	66.7129974365234	0.0120449000969529	70.6985015869141
0.557587598450482	63.6595878601074	66.9130020141602	0.012079999782145	70.8984985351563
0.559195701498538	63.7109985351563	67.1129989624023	0.0122050996869802	71.098503112793
0.560803804546595	63.7814445495605	67.3130035400391	0.0122237000614405	71.3985977172852
0.56241184938699	63.9232444763184	67.5130004882813	0.0122429002076387	71.4984970092773
0.563900859560817	64.0206604003906	67.7129974365234	0.0121860997751355	71.698600769043
0.565925845876336	64.1924743652344	67.9130020141602	0.0123578999191523	71.8985977172852
0.567593495361507	64.2332000732422	68.1129989624023	0.0124201001599431	72.098503112793
0.569022900890559	64.297737121582	68.3130035400391	0.0124768996611238	72.2985000610352
0.57057139929384	64.4077453613281	68.5130004882813	0.012542299926281	72.4984970092773
0.57247729273513	64.5584487915039	68.7129974365234	0.0125197004526854	72.7985000610352
0.574025791138411	64.5894393920898	68.9130020141602	0.0125356996431947	72.8984985351563
0.5759316845797	64.7131958007813	69.1129989624023	0.0125743001699448	73.0986022949219
0.577599334064871	64.8352584838867	69.3130035400391	0.0126350997015834	73.2985000610352
0.579028739593923	64.9087677001953	69.5130004882813	0.0127052003517747	73.4984970092773
0.580755935516208	64.992561340332	69.7129974365234	0.012755099684	73.6985015869141
0.582602224312723	65.0759048461914	69.9130020141602	0.0127951996400952	73.8983993530273
0.584567664191127	65.2113952636719	70.1129989624023	0.0127959996461868	74.1985015869141
0.586175767239183	65.261589050293	70.3130035400391	0.0127480002120137	74.2985000610352
0.587902963161469	65.2554168701172	70.5130004882813	0.0128181995823979	74.4983978271484
0.589511008001864	-42.5804252624512	70.7099990844727	0.0127902999520302	74.6985015869141