File: CSVs/24-01-08_Tensile_paper-PDMS/na_Uncoated_2/asdf.txt
File Path: C:\Users\apk5101\Desktop\Sandra\Uncoated_2 01-8-24 11 12 58 AM\DAQ- Crosshead, … - (Timed).txt
Test: MTS EM Tension (Simplified) with Video Extensometer apk5101 25
Test Run: Uncoated_2
Date: 1/8/2024 10:17:22 AM


Crosshead 	Load 	Time 	Strain 1 	Video Time
mm	N	sec	mm/mm	sec
-5.95586016061134E-05	2.66770958900452	0.112999998033047	-2.40163008129457E-05	4.99989986419678
0.000297793008030567	2.68688344955444	0.312999993562698	7.5436200859258E-06	5.19990015029907
0.00226322686103231	2.81629848480225	0.513000011444092	-8.69681025505997E-06	5.39989995956421
0.00434777803093311	2.86050724983215	0.712999999523163	2.11755996133434E-05	5.59989976882935
0.00643232897346024	2.96598267555237	0.912999987602234	3.20701001328416E-05	5.79990005493164
0.00863599689182593	3.10432386398315	1.11300003528595	6.07180008955766E-05	5.99980020523071
0.0103631964520901	3.21168446540833	1.31299996376038	7.69734979257919E-05	6.19980001449585
0.0121499542728998	3.28097796440125	1.51300001144409	0.000108776002889499	6.39979982376099
0.0139367130032042	3.32634139060974	1.71300005912781	0.000126604005345143	6.59999990463257
0.0157830290845595	3.42637658119202	1.91299998760223	0.000144667006679811	6.79990005493164
0.0176293451659149	3.5596227645874	2.11299991607666	0.000213792998692952	6.99989986419678
0.0191183116839966	3.6548478603363	2.31299996376038	0.000166323996381834	7.19990015029907
0.0207859520742204	3.70407629013062	2.51300001144409	0.000344483996741474	7.40000009536743
0.0224535924644442	3.76825428009033	2.71300005912781	0.000250521989073604	7.59980010986328
0.0241807920247084	3.88577628135681	2.91300010681152	0.000389016000553966	7.79979991912842
0.0259079915849725	4.02227830886841	3.11299991607666	0.000301508989650756	7.99989986419678
0.027516072805156	4.09531259536743	3.31299996376038	0.000341339007718489	8.19979953765869
0.0290645966742886	4.15823030471802	3.51300001144409	0.000490521022584289	8.39980030059814
0.0309704737446737	4.26243829727173	3.71300005912781	0.000354997988324612	8.59980010986328
0.0326976733049378	4.40757274627686	3.91300010681152	0.000384390994440764	8.79979991912842
0.0343653118761722	4.50788021087646	4.11299991607666	0.000411654007621109	8.99979972839355
0.0356160417140927	4.56900548934937	4.31300020217896	0.000439513009041548	9.19979953765869
0.0374028022633865	4.62400054931641	4.51300001144409	0.000459795992355794	9.39980030059814
0.0391895591747016	4.74829339981079	4.71299982070923	0.000470308004878461	9.59980010986328
0.0410954344260972	4.92299699783325	4.91300010681152	0.000503571005538106	9.79979991912842
0.0426439582952298	5.01641798019409	5.11299991607666	0.000528934993781149	9.99979972839355
0.0441924821643624	5.05822515487671	5.31300020217896	0.000541976012755185	10.1997003555298
0.045800563384546	5.14045333862305	5.51300001144409	0.000536406994797289	10.3997001647949
0.0475873239338398	5.30059623718262	5.71299982070923	0.000529508979525417	10.5998001098633
0.0492549625050742	5.45661687850952	5.91300010681152	0.000542735971976072	10.7996997833252
0.0511012804054189	5.54134607315063	6.11299991607666	0.000557560997549444	10.9997997283936
0.0525902432855219	5.58793926239014	6.31300020217896	0.00057280802866444	11.1997995376587
0.0541387671546545	5.70555210113525	6.51300001144409	0.000553013000171632	11.3998003005981
0.0556277336727362	5.86018800735474	6.71299982070923	0.000686531013343483	11.5996999740601
0.0578314029553439	6.00953388214111	6.91300010681152	0.0007010159897618	11.7997999191284
0.0593799268244766	6.08992481231689	7.11299991607666	0.000695855997037143	11.9996995925903
0.0610475690336898	6.1663236618042	7.31300020217896	0.000703081022948027	12.1997003555298
0.0624769745627418	6.28097486495972	7.51300001144409	0.000741478987038136	12.3997001647949
0.0642041704850271	6.45072412490845	7.71299982070923	0.000891626987140626	12.5998001098633
0.0661100493744016	6.59949254989624	7.91300010681152	0.000911156996153295	12.7996997833252
0.0677181305945851	6.6646900177002	8.11299991607666	0.000953404989559203	12.9996995925903
0.0693262118147686	6.78839111328125	8.3129997253418	0.000983159989118576	13.1997003555298
0.0709342930349521	6.93700218200684	8.51299953460693	0.00102501001674682	13.3997001647949
0.0727806109352969	7.10726594924927	8.71300029754639	0.000932922004722059	13.5996999740601
0.0745078068575822	7.21503591537476	8.91300010681152	0.00103421998210251	13.7996997833252
0.0761158953537233	7.28394603729248	9.11299991607666	0.00107083003968	13.9996995925903
0.0777835302869789	7.42556285858154	9.3129997253418	0.000985894002951682	14.1997003555298
0.0793320577940904	7.6077561378479	9.51299953460693	0.0010130200535059	14.4003000259399
0.0811783756944351	7.73648881912231	9.71300029754639	0.00103795004542917	14.5996999740601
0.0829055716167204	7.82810306549072	9.91300010681152	0.00108416995499283	14.799599647522
0.0843349771457724	7.90855264663696	10.1129999160767	0.00111207005102187	14.9996995925903
0.0858835046528839	8.0514612197876	10.3129997253418	0.00119225995149463	15.1997003555298
0.0874320248840377	8.22423839569092	10.5129995346069	0.00118502997793257	15.3997001647949
0.0892783427843824	8.36172962188721	10.7130002975464	0.00118436000775546	15.5995998382568
0.0908268630155362	8.4575719833374	10.9130001068115	0.00125922996085137	15.7996997833252
0.0924945052247494	8.57382965087891	11.1129999160767	0.0013144799740985	15.9996004104614
0.094102586444933	8.75052738189697	11.3129997253418	0.00133209000341594	16.1996002197266
0.0957702286541462	8.89248085021973	11.5129995346069	0.00139444996602833	16.3995990753174
0.0976761075435206	9.02498340606689	11.7130002975464	0.00140939000993967	16.5995998382568
0.0992246277746744	9.11069297790527	11.9130001068115	0.00146168994251639	16.7996006011963
0.100892269983888	9.26160907745361	12.1129999160767	0.00158498995006084	16.9995994567871
0.102738587884232	9.46928405761719	12.3129997253418	0.00162068998906761	17.1996002197266
0.104406230093446	9.57855129241943	12.5129995346069	0.00155301997438073	17.3995990753174
0.106192987004761	9.69440078735352	12.7130002975464	0.00166443001944572	17.5995998382568
0.107979743916076	9.84123992919922	12.9130001068115	0.00161189003847539	17.7996006011963
0.109349588456098	10.009256362915	13.1129999160767	0.00162128999363631	17.9995994567871
0.111076791654341	10.1922779083252	13.3129997253418	0.00168355996720493	18.1996002197266
0.112803987576626	10.3146028518677	13.5129995346069	0.00163936999160796	18.3995990753174
0.11476942745503	10.4469289779663	13.7130002975464	0.0016793500399217	18.5995998382568
0.116437062388286	10.6069183349609	13.9130001068115	0.00169951003044844	18.7996006011963
0.117985589895397	10.7786703109741	14.1129999160767	0.00173789996188134	18.9995994567871
0.119534110126551	10.920111656189	14.3129997253418	0.00179471005685627	19.2000007629395
0.121320867037866	11.0552778244019	14.5129995346069	0.00179908995050937	19.3995990753174
0.123048070236109	11.1736717224121	14.7130002975464	0.00187556003220379	19.5995998382568
0.124298807349987	11.3201274871826	14.9130001068115	0.00193330005276948	19.7994995117188
0.125847320305184	11.4785604476929	15.1129999160767	0.00198908988386393	19.9995994567871
0.127217164845206	11.5477313995361	15.3129997253418	0.00192022998817265	20.199499130249
0.129003936308436	11.6957311630249	15.5129995346069	0.00202818005345762	20.3995990753174
0.130731132230721	11.8476696014404	15.7130002975464	0.00209841993637383	20.5995006561279
0.132160537759773	12.0057668685913	15.9130001068115	0.00209127995185554	20.7994995117188
0.133887733682059	12.1765470504761	16.113000869751	0.00208829995244741	20.9995002746582
0.13543626118917	12.2867670059204	16.3129997253418	0.00211711996234953	21.199499130249
0.137103896122426	12.4234533309937	16.5130004882813	0.00217926991172135	21.3994998931885
0.1390097750118	12.6332225799561	16.7129993438721	0.00218648998998106	21.5995006561279
0.140677409945056	12.8016405105591	16.9130001068115	0.00215181009843946	21.7994995117188
0.142464166856371	12.9798974990845	17.113000869751	0.00210387003608048	21.9995002746582
0.144072255352512	13.0797462463379	17.3129997253418	0.00220483005978167	22.199499130249
0.145501660881564	13.1992216110229	17.5130004882813	0.002507199998945	22.3994998931885
0.147764891153201	13.4784059524536	17.7129993438721	0.00228593009524047	22.5995006561279
0.149492087075487	13.6682119369507	17.9130001068115	0.00229204003699124	22.7994995117188
0.151040614582598	13.7834501266479	18.113000869751	0.00231394008733332	22.9995002746582
0.152827371493913	13.9134683609009	18.3129997253418	0.00235643004998565	23.199499130249
0.154495006427169	14.1055908203125	18.5130004882813	0.00242329994216561	23.3994998931885
0.156222216901369	14.3356227874756	18.7129993438721	0.002453220076859	23.5995006561279
0.157770729856566	14.4908437728882	18.9130001068115	0.00251914002001286	23.7994995117188
0.159438379341736	14.6103792190552	19.113000869751	0.0024713899474591	23.9995002746582
0.160986892296933	14.7524604797363	19.3129997253418	0.00250404002144933	24.199499130249
0.162833210197277	14.9628934860229	19.5130004882813	0.00264276005327702	24.3994998931885
0.164560420671478	15.1968584060669	19.7129993438721	0.00260787992738187	24.5995006561279
0.166168494615704	15.358154296875	19.9130001068115	0.00271006999537349	24.7994995117188
0.167657461133786	15.4470243453979	20.113000869751	0.00263513997197151	24.9995002746582
0.169325096067041	15.6291246414185	20.3129997253418	0.00269468990154564	25.199499130249
0.171290535945445	15.8913259506226	20.5130004882813	0.00268755992874503	25.3994998931885
0.172839063452557	16.0861396789551	20.7129993438721	0.0026965900324285	25.5995006561279
0.174328029970638	16.1962108612061	20.9130001068115	0.0026354999281466	25.7994003295898
0.175995664903894	16.3437271118164	21.113000869751	0.00262795994058251	25.9995002746582
0.177425070432946	16.5058746337891	21.3129997253418	0.00265679997391999	26.1993999481201
0.17945007130038	16.7869853973389	21.5130004882813	0.00264534004963934	26.3994998931885
0.181058145244606	16.9613914489746	21.7129993438721	0.00267651001922786	26.5995006561279
0.182547111762688	17.0920028686523	21.9130001068115	0.00270200008526444	26.7994995117188
0.184155200258829	17.2589149475098	22.113000869751	0.00273666996508837	26.9993991851807
0.185882396181114	17.4871883392334	22.3129997253418	0.00275689992122352	27.199499130249
0.187788275070488	17.7440128326416	22.5130004882813	0.00276539009064436	27.3994007110596
0.189396349014714	17.9286308288574	22.7129993438721	0.0028214599005878	27.5993995666504
0.190766193554737	18.0090045928955	22.9130001068115	0.00298053002916276	27.7994003295898
0.192612511455081	18.242208480835	23.113000869751	0.00352146988734603	27.9993991851807
0.194280160940252	18.4951839447021	23.3129997253418	0.00276435003615916	28.1993999481201
0.196126478840597	18.7378921508789	23.5130004882813	0.00278641004115343	28.3994998931885
0.197734552784823	18.8761692047119	23.7129993438721	0.00281006004661322	28.5993995666504
0.199283080291934	19.0499591827393	23.9130001068115	0.00283576990477741	28.7994003295898
0.20095071522519	19.2945938110352	24.113000869751	0.00301941996440291	28.9993991851807
0.202737472136505	19.5455532073975	24.3129997253418	0.00300983991473913	29.1993999481201
0.204405121621676	19.7501850128174	24.5130004882813	0.00294820009730756	29.3994998931885
0.206132317543961	19.9144153594971	24.7129993438721	0.0030137300491333	29.5993995666504
0.207621284062043	20.0813617706299	24.9130001068115	0.00301963998936117	29.7992992401123
0.209288918995298	20.3455696105957	25.113000869751	0.00318384007550776	29.9993991851807
0.211075675906613	20.5834121704102	25.3129997253418	0.00310236006043851	30.1993999481201
0.212862432817928	20.7998828887939	25.5130004882813	0.00317551009356976	30.3994007110596
0.214291852898896	20.9544849395752	25.7129993438721	0.00329195009544492	30.5993003845215
0.216078609810211	21.2039546966553	25.9130001068115	0.00322420010343194	30.7992992401123
0.217150663957	21.3633823394775	26.113000869751	0.00322500988841057	30.9993991851807
0.219354333239608	21.6925868988037	26.3129997253418	0.00326551008038223	31.1993007659912
0.221141090150923	21.8951854705811	26.5130004882813	0.00328600988723338	31.399299621582
0.222510934690945	22.0628471374512	26.7129993438721	0.00340444990433753	31.5993003845215
0.22423813061323	22.3242340087891	26.9130001068115	0.0033406401053071	31.7994003295898
0.225905780098401	22.5563373565674	27.113000869751	0.00337167992256582	31.9993991851807
0.22781164443586	22.8167209625244	27.3129997253418	0.00336272991262376	32.1992988586426
0.229538854910061	23.0250587463379	27.5130004882813	0.00341055006720126	32.399299621582
0.231087367865257	23.2117481231689	27.7129993438721	0.003648960031569	32.5993995666504
0.233112368732691	23.5204944610596	27.9130001068115	0.00368798989802599	32.7993011474609
0.234303530305624	23.6658935546875	28.113000869751	0.00369997997768223	32.9992980957031
0.235911618801765	23.8747615814209	28.3129997253418	0.00369505002163351	33.1992988586426
0.237996166106313	24.1557788848877	28.5130004882813	0.00370633997954428	33.3992004394531
0.239306464209221	24.3375186920166	28.7129993438721	0.00373614998534322	33.5993003845215
0.240914538153447	24.5911808013916	28.9130001068115	0.00380859989672899	33.7991981506348
0.242522626649588	24.8096256256104	29.113000869751	0.00381147000007331	33.9992980957031
0.244190276134759	24.9979572296143	29.3129997253418	0.00383717007935047	34.1991996765137
0.245917472057045	25.2361907958984	29.5130004882813	0.00388052989728749	34.399299621582
0.247346877586097	25.4605560302734	29.7129993438721	0.00420774985104799	34.5993003845215
0.248954951530322	25.6981048583984	29.9130001068115	0.00385726010426879	34.7993011474609
0.250741722993553	25.9054679870605	30.113000869751	0.00395214976742864	34.9991989135742
0.252588040893897	26.124698638916	30.3129997253418	0.00395885994657874	35.1992988586426
0.254196114838123	26.3520641326904	30.5130004882813	0.00387993990443647	35.3992004394531
0.25568506680429	26.5972442626953	30.7129993438721	0.00389084010384977	35.5992012023926
0.257293169852346	26.8166770935059	30.9130001068115	0.00392886996269226	35.7993011474609
0.259020365774632	27.0193157196045	31.113000869751	0.00394238019362092	35.9991989135742
0.260807108134031	27.2464084625244	31.3129997253418	0.0039899698458612	36.1992988586426
0.262534304056317	27.5318069458008	31.5130004882813	0.00401713978499174	36.3992004394531
0.264261499978602	27.79807472229	31.7129993438721	0.00408567022532225	36.5992012023926
0.265810027485713	27.9783248901367	31.9130001068115	0.00408850004896522	36.7991981506348
0.267656345386058	28.2053718566895	32.1129989624023	0.00409092009067535	36.9991989135742
0.269443116849288	28.4716510772705	32.3129997253418	0.00411750003695488	37.1991004943848
0.271170312771574	28.7511539459229	32.5130004882813	0.00426163012161851	37.3992004394531
0.272361474344507	28.903491973877	32.7130012512207	0.00422198977321386	37.5992012023926
0.274386460660025	29.1448669433594	32.9129981994629	0.00422031991183758	37.7991981506348
0.276113685686141	29.3688907623291	33.1129989624023	0.0042885597795248	37.9991989135742
0.278079096460715	29.658634185791	33.3129997253418	0.00439787982031703	38.1991996765137
0.279568077530712	29.8730564117432	33.5130004882813	0.00443698978051543	38.3992004394531
0.280937907518819	30.0578346252441	33.7130012512207	0.0044126701541245	38.5992012023926
0.28260555700399	30.2470951080322	33.9129981994629	0.0044536697678268	38.7991981506348
0.284451874904335	30.5154495239258	34.1129989624023	0.00447057979181409	38.9991989135742
0.28617907082662	30.7827110290527	34.3129997253418	0.00454082014039159	39.1991996765137
0.287727598333731	31.027135848999	34.5130004882813	0.00453134998679161	39.3992004394531
0.289335672277957	31.2076435089111	34.7130012512207	0.00456729996949434	39.5992012023926
0.290943775326014	31.3717041015625	34.9129981994629	0.00460149999707937	39.7991981506348
0.292968761641532	31.667552947998	35.1129989624023	0.00460417987778783	39.9991989135742
0.294576835585758	31.9337940216064	35.3129997253418	0.00465688994154334	40.1991004943848
0.296184909529984	32.1418800354004	35.5130004882813	0.00466948002576828	40.3992004394531
0.29779301257804	32.3018913269043	35.7130012512207	0.00469915987923741	40.5990982055664
0.299460632959381	32.5152931213379	35.9129981994629	0.00472821015864611	40.7991981506348
0.301306950859725	32.7882041931152	36.1129989624023	0.00474982988089323	40.9991989135742
0.302855478366837	33.0288887023926	36.3129997253418	0.00481978012248874	41.1991996765137
0.304344459436834	33.2078399658203	36.5130004882813	0.0048103597946465	41.3992004394531
0.30595253338106	33.3943214416504	36.7130012512207	0.00483410013839602	41.5990982055664
0.307143694953993	33.5317878723145	36.9129981994629	0.00489956978708506	41.7990989685059
0.309347378788516	33.8695411682129	37.1129989624023	0.00490360986441374	41.9990997314453
0.310955452732742	34.1171112060547	37.3129997253418	0.00495941983535886	42.1991004943848
0.312444433802739	34.2608833312988	37.5130004882813	0.00497280992567539	42.3991012573242
0.314052507746965	34.4373664855957	37.7130012512207	0.00497830985113978	42.5990982055664
0.31577970366925	34.6866989135742	37.9129981994629	0.00503933010622859	42.798999786377
0.317506899591535	34.9645156860352	38.1129989624023	0.00510672014206648	42.9990997314453
0.319293671054766	35.1941757202148	38.3129997253418	0.00508025009185076	43.1991004943848
0.320723076583818	35.3262138366699	38.5130004882813	0.00510868011042476	43.3991012573242
0.322450272506103	35.5310592651367	38.7130012512207	0.00512129021808505	43.5990982055664
0.324296590406448	35.8285903930664	38.9129981994629	0.00514345010742545	43.798999786377
0.326023786328733	36.065673828125	39.1129989624023	0.00519258994609118	43.9990997314453
0.32739361631684	36.2155570983887	39.3129997253418	0.00524184992536902	44.1991004943848
0.329239934217185	36.4311981201172	39.5130004882813	0.00521236006170511	44.398998260498
0.330967159243301	36.6568565368652	39.7130012512207	0.00522053986787796	44.5990982055664
0.332813448039815	36.9526710510254	39.9129981994629	0.00528735993430018	44.7990989685059
0.334421551087871	37.1595191955566	40.1129989624023	0.00530658010393381	44.9990005493164
0.336089171469212	37.3259315490723	40.3129997253418	0.00535146007314324	45.1991004943848
0.337697274517268	37.5031890869141	40.5130004882813	0.00508463010191917	45.3991012573242
0.339186226483434	37.6946411132813	40.7130012512207	0.00531045999377966	45.5989990234375
0.341092119924724	38.0024299621582	40.9129981994629	0.00540192006155849	45.798999786377
0.342759740306064	38.2007827758789	41.1129989624023	0.00544806988909841	45.9990005493164
0.344546511769295	38.3776168823242	41.3129997253418	0.00546478014439344	46.1990013122559
0.345916341757402	38.5490074157715	41.5130004882813	0.0054892199113965	46.3992004394531
0.347583991242573	38.7998466491699	41.7130012512207	0.00554312020540237	46.5989990234375
0.349430309142917	39.0531272888184	41.9129981994629	0.0055469898506999	46.798999786377
0.351157505065203	39.2500915527344	42.1129989624023	0.0055706799030304	46.9990005493164
0.352706032572314	39.4172172546387	42.3129997253418	0.00559727987274528	47.1990013122559
0.354254560079426	39.6009063720703	42.5130004882813	0.00562877999618649	47.398998260498
0.355683965608478	39.7813453674316	42.7130012512207	0.00566639984026551	47.5989990234375
0.357768527464941	40.0931396484375	42.9129981994629	0.00568869011476636	47.798999786377
0.359317025868222	40.241283416748	43.1129989624023	0.00576137006282806	47.9990005493164
0.361044250894338	40.429069519043	43.3129997253418	0.00575217977166176	48.1988983154297
0.362414080882445	40.6314811706543	43.5130004882813	0.00579709000885487	48.398998260498
0.36426039878279	40.87451171875	43.7130012512207	0.00579763017594814	48.5988998413086
0.36604717024602	41.0822830200195	43.9129981994629	0.00579315982758999	48.798999786377
0.367774366168305	41.2677688598633	44.1129989624023	0.00584489991888404	48.9990005493164
0.369322893675417	41.4663391113281	44.3129997253418	0.00589442998170853	49.1990013122559
0.370811845641583	41.6702880859375	44.5130004882813	0.00595394987612963	49.398998260498
0.372539041563869	41.8888130187988	44.7130012512207	0.00592966005206108	49.5989990234375
0.374504481442273	42.1152114868164	44.9129981994629	0.00594886997714639	49.798900604248
0.376112555386499	42.2897872924805	45.1129989624023	0.00598071003332734	49.9989013671875
0.37766108289361	42.4778785705566	45.3129997253418	0.00609801989048719	50.1990013122559
0.379269156837836	42.7236747741699	45.5130004882813	0.00609852001070976	50.398998260498
0.380877259885892	42.8987045288086	45.7130012512207	0.00614529987797141	50.5988998413086
0.382604455808178	43.0507621765137	45.9129981994629	0.00614908011630177	50.798999786377
0.384391198167577	43.2867393493652	46.1129989624023	0.00618606992065907	50.9989013671875
0.385939725674689	43.4820213317871	46.3129997253418	0.00620643002912402	51.1988983154297
0.387666921596974	43.7128028869629	46.5130004882813	0.00626744003966451	51.3988990783691
0.389334571082145	43.8884735107422	46.7130012512207	0.00629513990134001	51.5988006591797
0.39118088898249	44.0756721496582	46.9129981994629	0.00632190983742476	51.7988014221191
0.392788962926716	44.2872695922852	47.1129989624023	0.00638754013925791	51.9989013671875
0.39475440280512	44.5754165649414	47.3129997253418	0.00628456007689238	52.1988983154297
0.396005139918998	44.6886520385742	47.5130004882813	0.00624097976833582	52.3988990783691
0.397494091885164	44.8178672790527	47.7130012512207	0.00640275981277227	52.5988998413086
0.399638200178742	45.0953483581543	47.9129981994629	0.00642090989276767	52.7988014221191
0.401186727685854	45.3033027648926	48.1129989624023	0.00636916980147362	52.9989013671875
0.402735255192965	45.4900741577148	48.3129997253418	0.00643558986485004	53.1987991333008
0.404224236262962	45.6363372802734	48.5130004882813	0.00660976022481918	53.3988990783691
0.406249222578481	45.8568115234375	48.7130012512207	0.00659532006829977	53.5988998413086
0.407797750085592	46.0398941040039	48.9129981994629	0.00644110981374979	53.798900604248
0.409465370466933	46.254207611084	49.1129989624023	0.00653599016368389	53.9989013671875
0.41095435153693	46.4221000671387	49.3129997253418	0.00656718015670776	54.1988983154297
0.412562425481156	46.5526237487793	49.5130004882813	0.0065662101842463	54.3987998962402
0.414349196944386	46.7525062561035	49.7130012512207	0.00660332012921572	54.5988998413086
0.415897724451497	46.9424362182617	49.9129981994629	0.00665629981085658	54.7988014221191
0.417267554439604	47.1207008361816	50.1129989624023	0.00649465993046761	54.9987983703613
0.419054325902835	47.314022064209	50.3129997253418	0.00663605006411672	55.1987991333008
0.420721946284175	47.453685760498	50.5130004882813	0.00668566999956965	55.3987998962402
0.422508717747405	47.6631088256836	50.7130012512207	0.00671932008117437	55.5988006591797
0.424295460106805	47.9040908813477	50.9129981994629	0.00685615977272391	55.798698425293
0.425843987613916	48.116397857666	51.1129989624023	0.00688590994104743	55.9987983703613
0.427511637099087	48.2481384277344	51.3129997253418	0.00686497008427978	56.1987991333008
0.429119711043313	48.4008827209473	51.5130004882813	0.00694483984261751	56.3987998962402
0.431085150921717	48.6393508911133	51.7130012512207	0.00694135995581746	56.5988006591797
0.432693224865943	48.8655815124512	51.9129981994629	0.00697162980213761	56.7988014221191
0.434360874351114	49.0673065185547	52.1129989624023	0.00699899019673467	56.9987983703613
0.436028523836285	49.2087898254395	52.3129997253418	0.0070027899928391	57.1987991333008
0.437696144217625	49.3626022338867	52.5130004882813	0.00706634996458888	57.3987998962402
0.439304247265682	49.5968437194824	52.7130012512207	0.0070672701112926	57.5987014770508
0.440912321209908	49.7900466918945	52.9129981994629	0.00707542011514306	57.7988014221191
0.442460848717019	49.913459777832	53.1129989624023	0.0070881200954318	57.9986991882324
0.444247591076419	50.0911979675293	53.3129997253418	0.00714167999103665	58.1986999511719
0.44579611858353	50.2690811157227	53.5130004882813	0.00716667994856834	58.3987998962402
0.447642436483875	50.5060119628906	53.7130012512207	0.00722065987065434	58.5988006591797
0.449250539531931	50.6972961425781	53.9129981994629	0.00725241005420685	58.798698425293
0.450918159913272	50.8472671508789	54.1129989624023	0.00723069999366999	58.9987983703613
0.452585809398443	50.9689483642578	54.3129997253418	0.00727620022371411	59.1987991333008
0.454253458883613	51.1499443054199	54.5130004882813	0.00734339002519846	59.3987998962402
0.456040201243013	51.4110488891602	54.7130012512207	0.00734385987743735	59.5987014770508
0.457588728750125	51.5523262023926	54.9129981994629	0.0073776300996542	59.798698425293
0.45919680269435	51.6697082519531	55.1129989624023	0.00741061009466648	59.9986991882324
0.460923998616636	51.8614349365234	55.3129997253418	0.00740652019158006	60.1986999511719
0.462234311271459	52.0285339355469	55.5130004882813	0.00738641014322639	60.3987007141113
0.464437966002151	52.3217735290527	55.7130012512207	0.0074066398665309	60.5987014770508
0.465986493509263	52.4470176696777	55.9129981994629	0.00742697017267346	60.798698425293
0.467713689431548	52.5933494567871	56.1129989624023	0.00749125983566046	60.9986991882324
0.469500460894778	52.8030776977539	56.3129997253418	0.00730716018006206	61.1986999511719
0.471346778795123	53.0582847595215	56.5130004882813	0.00737167987972498	61.3987007141113
0.473193096695468	53.2937812805176	56.7130012512207	0.00706735998392105	61.5987014770508
0.474860717076808	53.4057807922363	56.9129981994629	0.00770328007638454	61.798698425293
0.476349698146805	53.5355033874512	57.1129989624023	0.00787580013275146	61.9986991882324
0.478017318528146	53.7211990356445	57.3129997253418	0.00775498989969492	62.1986999511719
0.479565846035257	53.8950042724609	57.5130004882813	0.00772101990878582	62.3987007141113
0.481173949083313	54.0434722900391	57.7130012512207	0.00769466022029519	62.5987014770508
0.482782023027539	54.1558723449707	57.9129981994629	0.00773310009390116	62.798698425293
0.484032760141417	54.242488861084	58.1129989624023	0.00777200981974602	62.9986991882324
0.485640834085643	54.4579887390137	58.3129997253418	0.00778710003942251	63.1986999511719
0.487487151985988	54.6810455322266	58.5130004882813	0.00772796990349889	63.3987007141113
0.488678342662752	54.7194175720215	58.7130012512207	0.00780965015292168	63.5987014770508
0.490822421852499	54.9536781311035	58.9129981994629	0.00782484002411366	63.798698425293
0.492430524900556	55.1032829284668	59.1129989624023	0.00782296992838383	63.9986991882324
0.494157720822841	55.3270149230957	59.3129997253418	0.00781391002237797	64.1986999511719
0.496123160701245	55.5563583374023	59.5130004882813	0.00785673037171364	64.3985977172852
0.49785035662353	55.6824111938477	59.7130012512207	0.00784896034747362	64.5986022949219
0.499458401463926	55.8124961853027	59.9129981994629	0.00789923965930939	64.7985992431641
0.501066504511982	55.994945526123	60.1129989624023	0.00794658996164799	64.9985961914063
0.502615061122924	56.1632614135742	60.3129997253418	0.00796603970229626	65.198600769043
0.504699593875557	56.38720703125	60.5130004882813	0.00797806959599257	65.3986968994141
0.506069452967495	56.4757385253906	60.7130012512207	0.00800574012100697	65.5986022949219
0.507617951370776	56.6169052124023	60.9129981994629	0.00804091989994049	65.7985000610352
0.509166507981718	56.7784309387207	61.1129989624023	0.00833034981042147	65.9985961914063
0.511012796778232	56.9992599487305	61.3129997253418	0.00857609044760466	66.198600769043
0.512680446263403	57.1213798522949	61.5130004882813	0.00823760032653809	66.3985977172852
0.514348095748574	57.2708854675293	61.7130012512207	0.0078619197010994	66.5986022949219
0.515896594151855	57.4133110046387	61.9129981994629	0.00852103997021914	66.7985992431641
0.517564243637025	57.6040534973145	62.1129989624023	0.00765996007248759	66.9985961914063
0.519172346685082	57.7553405761719	62.3129997253418	0.00816045980900526	67.198600769043
0.521137786563486	57.9184417724609	62.5130004882813	0.00862636975944042	67.3985977172852
0.522626738529652	58.0508117675781	62.7130012512207	0.00878981035202742	67.5986022949219
0.524175236932933	58.2064476013184	62.9129981994629	0.00898133963346481	67.7985000610352
0.52578333998099	58.3813018798828	63.1129989624023	0.00900494027882814	67.9985961914063
0.527629628777504	58.5256958007813	63.3129997253418	0.00837540999054909	68.198600769043
0.52923773182556	58.6687278747559	63.5130004882813	0.00878665037453175	68.3983993530273
0.530964927747846	58.8570518493652	63.7130012512207	0.00905708037316799	68.5983963012695
0.532513426151127	59.0172882080078	63.9129981994629	0.00910232029855251	68.7985000610352
0.534240622073412	59.1885871887207	64.1129989624023	0.00913652963936329	68.9984970092773
0.535908271558583	59.2756690979004	64.3130035400391	0.00916806980967522	69.1985015869141
0.537754618562758	59.4675140380859	64.5130004882813	0.00917533040046692	69.3984985351563
0.539362663403153	59.6417999267578	64.7129974365234	0.00921228993684053	69.598503112793
0.5410899175331	59.834774017334	64.9130020141602	0.00918836984783411	69.7985000610352
0.542697962373495	59.9419288635254	65.1129989624023	0.00923573039472103	69.9984970092773
0.544186914339662	60.010311126709	65.3130035400391	0.00927450973540545	70.1985015869141
0.546152354218066	60.2570266723633	65.5130004882813	0.00931948982179165	70.3984985351563
0.547700910829008	60.4249534606934	65.7129974365234	0.00933920033276081	70.598503112793
0.549428106751293	60.6299209594727	65.9130020141602	0.00932976044714451	70.7985000610352
0.551036151591688	60.7138328552246	66.1129989624023	0.00936647970229387	70.9984970092773
0.552644254639745	60.8364143371582	66.3130035400391	0.00939358957111835	71.1985015869141
0.554311904124916	61.0068778991699	66.5130004882813	0.00944168958812952	71.3984985351563
0.556098646484315	61.2125473022461	66.7129974365234	0.0094300601631403	71.598503112793
0.557647203095257	61.3244285583496	66.9130020141602	0.00946290045976639	71.7985000610352
0.559195701498538	61.4136390686035	67.1129989624023	0.00949584972113371	71.9984970092773
0.561101594939828	61.5891304016113	67.3130035400391	0.00953525956720114	72.1985015869141
0.562650093343109	61.750862121582	67.5130004882813	0.00953118968755007	72.3983993530273
0.564377289265394	61.9319076538086	67.7129974365234	0.00956609006971121	72.5983963012695
0.565925845876336	61.9996109008789	67.9130020141602	0.00958866998553276	72.7984008789063
0.567712588235736	62.1432647705078	68.1129989624023	0.00960193015635014	72.9983978271484
0.569439784158021	62.3277854919434	68.3130035400391	0.00903376005589962	73.1984024047852
0.571107433643192	62.4889183044434	68.5130004882813	0.00938975997269154	73.3983993530273
0.572536839172244	62.5983963012695	68.7129974365234	0.00973918009549379	73.5983963012695
0.574204488657415	62.69970703125	68.9130020141602	0.00971233006566763	73.7984008789063
0.576169928535819	62.8869705200195	69.1129989624023	0.00994906015694141	73.9983978271484
0.577658880501986	63.0136680603027	69.3130035400391	0.00986338034272194	74.1984024047852
0.579088286031038	63.155590057373	69.5130004882813	0.00986518990248442	74.3983993530273
0.580994179472327	63.3301429748535	69.7129974365234	0.00987161044031382	74.5983963012695
0.582542677875608	63.4054183959961	69.9130020141602	0.0106900995597243	74.7984008789063
0.584329420235008	63.5529747009277	70.1129989624023	0.00998327042907476	74.9983978271484
0.586235313676298	63.7971839904785	70.3130035400391	0.00997294019907713	75.1984024047852
0.587902963161469	63.9337921142578	70.5130004882813	0.00994602032005787	75.3983993530273
0.589391915127635	63.9998359680176	70.7129974365234	0.0099983299151063	75.5982971191406
0.591178657487035	64.1613693237305	70.9130020141602	0.0100424000993371	75.7984008789063
0.592846306972206	64.3228759765625	71.1129989624023	0.0100311003625393	75.9983978271484
0.594752200413495	64.5512084960938	71.3130035400391	0.0100573999807239	76.1983032226563
0.596181605942547	64.6193389892578	71.5130004882813	0.0102051999419928	76.3983993530273
0.597730104345828	64.7119979858398	71.7129974365234	0.0101316999644041	76.5982971191406
0.598861719481647	64.7228088378906	71.9130020141602	0.0101448995992541	76.7983016967773
0.60106540331617	65.0179214477539	72.1129989624023	0.010134999640286	76.9982986450195
0.602673506364226	65.176628112793	72.3130035400391	0.0101479003205895	77.1983032226563
0.604162458330393	65.2174758911133	72.5130004882813	0.0102174002677202	77.3983001708984
0.605710956733674	65.2963485717773	72.7129974365234	0.01021150033921	77.5982971191406
0.607140362262726	65.411491394043	72.9130020141602	0.0102524999529123	77.7983016967773
0.609046255704015	65.6316986083984	73.1129989624023	0.0102621000260115	77.9982986450195
0.610773451626301	65.7771301269531	73.3130035400391	0.0102939000353217	78.1983032226563
0.612500647548586	65.879508972168	73.5130004882813	0.0103141004219651	78.3983001708984
0.613989599514753	65.9796829223633	73.7129974365234	0.0103781996294856	78.5982971191406
0.615835946518928	66.1940231323242	73.9130020141602	0.0104796001687646	78.7983016967773
0.617741781752557	66.3989868164063	74.1129989624023	0.010495999827981	78.9982986450195
0.619469035882503	66.5380859375	74.3130035400391	0.0104214996099472	79.1983032226563
0.621196231804788	66.625244140625	74.5130004882813	0.01044060010463	79.3983993530273
0.62262563733384	66.7243957519531	74.7129974365234	0.0104732997715473	79.5982971191406
0.624352833256125	66.880256652832	74.9130020141602	0.0105547001585364	79.7983016967773
0.626080029178411	67.0610580444336	75.1129989624023	0.010589100420475	79.9982986450195
0.627747678663582	67.1534805297852	75.3130035400391	0.010619199834764	80.1981964111328
0.629296177066863	67.2216033935547	75.5130004882813	0.010644800029695	80.3983001708984
0.630785129033029	67.3470230102539	75.7129974365234	0.0106640998274088	80.5982971191406
0.63257192960009	67.5339889526367	75.9130020141602	0.0106883998960257	80.7982025146484
0.63435867195949	67.6839294433594	76.1129989624023	0.0107607003301382	80.9981994628906
0.635966716799885	67.7627105712891	76.3130035400391	0.0107559999451041	81.1981964111328
0.63769391272217	67.9002685546875	76.5130004882813	0.0107773002237082	81.3982009887695
0.639123318251222	68.0163269042969	76.7129974365234	0.0107605997473001	81.5981979370117
0.641029211692512	68.2251434326172	76.9130020141602	0.0108121000230312	81.7982025146484
0.642756407614797	68.3450927734375	77.1129989624023	0.0112493000924587	81.9981994628906
0.644364510662854	68.41455078125	77.3130035400391	0.011069499887526	82.1981964111328
0.646091706585139	68.5838165283203	77.5130004882813	0.0109053999185562	82.3982009887695
0.647521112114191	68.6825866699219	77.7129974365234	0.0109107000753284	82.5981979370117
0.649486551992595	68.8821792602539	77.9130020141602	0.0109278000891209	82.7982025146484
0.651154201477766	68.9694290161133	78.1129989624023	0.0109742004424334	82.9981994628906
0.652821850962937	69.0658493041992	78.3130035400391	0.0109965996816754	83.1981964111328
0.654370349366218	69.1754684448242	78.5130004882813	0.0109756998717785	83.3982009887695
0.656097545288503	69.3587875366211	78.7129974365234	0.0109949000179768	83.5981979370117
0.657824741210788	69.4742279052734	78.9130020141602	0.0109986001625657	83.7982025146484
0.659492390695959	69.5570526123047	79.1129989624023	0.0110457995906472	83.9981994628906
0.66104088909924	69.6480026245117	79.3130035400391	0.0110548995435238	84.1981964111328
0.662589445710182	69.8012771606445	79.5130004882813	0.0111744003370404	84.3982009887695
0.664197490550578	69.8984909057617	79.7129974365234	0.0111734997481108	84.5981979370117
0.665924744680524	70.0091552734375	79.9130020141602	0.0111132003366947	84.7982025146484
0.667532789520919	70.1002197265625	80.1129989624023	0.0110740000382066	84.9981994628906
0.669379136525095	70.2895812988281	80.3130035400391	0.0112771997228265	85.1981964111328
0.670570298098028	70.3146743774414	80.5130004882813	0.0113006997853518	85.3982009887695
0.672476191539317	70.494499206543	80.7129974365234	0.0113287996500731	85.5981979370117
0.674322480335832	70.5892105102539	80.9130020141602	0.011353200301528	85.7982025146484
0.676049676258117	70.6981201171875	81.1129989624023	0.0113485995680094	85.9981994628906
0.677776872180402	70.8605499267578	81.3130035400391	0.0114230997860432	86.1981964111328
0.67914673127234	70.9669418334961	81.5130004882813	0.0114011000841856	86.3982009887695
0.680873927194625	71.0878295898438	81.7129974365234	0.0114129995927215	86.5981979370117
0.682779820635915	71.222412109375	81.9130020141602	0.0114679001271725	86.7982025146484
0.68438786547631	71.3407897949219	82.1129989624023	0.0114144999533892	86.9981002807617
0.6862937589176	71.5820693969727	82.3130035400391	0.0114200003445148	87.1980972290039
0.687723164446652	71.6334686279297	82.5130004882813	0.0114344004541636	87.3981018066406
0.689152569975704	71.6884689331055	82.7129974365234	0.0114690000191331	87.5999984741211
0.691237102728337	71.8691940307617	82.9130020141602	0.0114775002002716	87.7981033325195
0.693023903295398	72.0221939086914	83.1129989624023	0.0115938000380993	87.9981002807617
0.69445330882445	72.111083984375	83.3130035400391	0.0115729002282023	88.1980972290039
0.69612090010196	72.1859436035156	83.5130004882813	0.0115547003224492	88.3981018066406
0.697669456712902	72.2615966796875	83.7129974365234	0.01157489977777	88.5980987548828
0.699575350154191	72.4275970458984	83.9130020141602	0.0116696003824472	88.7981033325195
0.701123848557472	72.5366668701172	84.1129989624023	0.0115799000486732	88.9981002807617
0.702731951605529	72.6534271240234	84.3130035400391	0.0115724001079798	89.1980972290039
0.704220903571695	72.7120208740234	84.5130004882813	0.0119802001863718	89.3981018066406
0.705829006619751	72.7659683227539	84.7129974365234	0.0120559995993972	89.5980987548828
0.707675295416266	72.9521102905273	84.9130020141602	0.0119315003976226	89.7981033325195
0.709283398464322	73.0932388305664	85.1129989624023	0.0117301000282168	89.9981002807617
0.710772350430489	73.1503524780273	85.3130035400391	0.0120831998065114	90.1980972290039
0.712380453478545	73.2262115478516	85.5130004882813	0.0122956000268459	90.3980026245117
0.71410764940083	73.3380126953125	85.7129974365234	0.0123846996575594	90.5980987548828
0.716013484634459	73.5336074829102	85.9130020141602	0.0124923996627331	90.7979965209961
0.717562041245401	73.6216583251953	86.1129989624023	0.0124974995851517	90.9980010986328
0.719110539648682	73.669563293457	86.3130035400391	0.0124230002984405	91.197998046875
0.720718642696738	73.726188659668	86.5130004882813	0.0124399997293949	91.3981018066406
0.722505385056138	73.8656921386719	86.7129974365234	0.0125588001683354	91.5980987548828
0.724470824934542	74.0934524536133	86.9130020141602	0.0127018997445703	91.7979965209961
0.72572153294459	74.1262664794922	87.1129989624023	0.0126243000850081	91.9980010986328
0.727567879948765	74.2269744873047	87.3130035400391	0.01264030020684	92.197998046875
0.72917592478916	74.2743530273438	87.5130004882813	0.0126345995813608	92.3980026245117
0.73108181823045	74.4657974243164	87.7129974365234	0.0125812999904156	92.5979995727539
0.73298771167174	74.6447601318359	87.9130020141602	0.0126841999590397	92.7979965209961
0.734357570763677	74.6799087524414	88.1129989624023	0.0127090997993946	92.9980010986328
0.736144313123077	74.7406997680664	88.3130035400391	0.0127822002395988	93.197998046875
0.737692811526358	74.8096389770508	88.5130004882813	0.0127165000885725	93.3980026245117
0.739598704967648	74.9778747558594	88.7129974365234	0.0127323996275663	93.5979995727539
0.741445051971823	75.1174163818359	88.9130020141602	0.0127552002668381	93.7979965209961
0.742755306418985	75.0919494628906	89.1129989624023	0.0127702997997403	94.0000991821289
0.744244258385152	75.1088333129883	89.3130035400391	0.0127950003370643	94.197998046875
0.745852361433208	75.189079284668	89.5130004882813	0.012767200358212	94.3980026245117
0.747520010918379	75.2926559448242	89.7129974365234	0.0127523997798562	94.5979995727539
0.749366299714893	75.4291534423828	89.9130020141602	0.0126558998599648	94.7979965209961
0.750795705243945	75.4314193725586	90.1129989624023	0.0124923000112176	94.9980010986328
0.752344261854887	75.4808731079102	90.3130035400391	0.0125836003571749	95.197998046875
0.754071457777172	75.6128845214844	90.5130004882813	0.0128135997802019	95.3980026245117
0.755858200136572	75.7126388549805	90.7129974365234	0.0130911003798246	95.5979995727539
0.757525849621743	75.7900009155273	90.9130020141602	0.0128194997087121	95.7979965209961
0.759372138418257	75.8190612792969	91.1129989624023	0.0128613002598286	95.9980010986328
0.760503753554076	75.755989074707	91.3130035400391	0.0127681000158191	96.1978988647461
0.762647890951484	75.8818206787109	91.5130004882813	0.0129225999116898	96.3980026245117
0.764553784392774	75.7374877929688	91.7129974365234	0.0128686996176839	96.597900390625
0.766221375670284	75.247428894043	91.9130020141602	0.0130086001008749	96.7978973388672
0.766995653975755	-9.23429298400879	92.0169982910156	0.0130473002791405	96.8979034423828