File: CSVs/oven-laser_combinations/laser-oven_3.txt
File Path: C:\Users\apk5101\Desktop\220114_cbPDMS_Oven_and_Laser\220114_cbPDMS_laser_808nm_1k3k_Oven_100C_3_real3 01-14-22 17 37 09 PM\DAQ- Crosshead, … - (Timed).txt
Test: MTS EM Tension (Simplified) with Video Extensometer apk5101 6
Test Run: 220114_cbPDMS_laser_808nm_1k3k_Oven_100C_3_real3
Date: 1/14/2022 5:25:34 PM


Crosshead 	Load 	Time 	Strain 1 	Video Time
mm	N	sec	mm/mm	sec
0.0858835046528839	0.847458600997925	0.112000003457069	-1.24377002066467E-05	4.09999990463257
0.170218481798656	0.664454340934753	0.211999997496605	0.000904210028238595	4.19990015029907
0.253540958510712	0.00367436790838838	0.312000006437302	0.00337577005848289	4.29990005493164
0.337637698976323	-0.678850650787354	0.412000000476837	0.00580359017476439	4.40140008926392
0.421257980633527	0.0708282366394997	0.512000024318695	0.00818635988980532	4.49989986419678
0.50499738426879	1.05323374271393	0.611999988555908	0.0105280000716448	4.69980001449585
0.588438997510821	0.410049706697464	0.712000012397766	0.0127001004293561	4.69980001449585
0.672059250064194	0.150660917162895	0.811999976634979	0.0147940004244447	4.79990005493164
0.755560409743339	0.601396322250366	0.912000000476837	0.0167418997734785	4.89989995956421
0.838882871903479	0.707618296146393	1.01199996471405	0.0187429003417492	4.99989986419678
0.922324485145509	0.577958047389984	1.11199998855591	0.0205144006758928	5.09989976882935
1.00564700551331	0.219250872731209	1.21200001239777	0.0222701001912355	5.19980001449585
1.0893268045038	0.322262048721313	1.31200003623962	0.0238738004118204	5.29990005493164
1.17270881310105	0.220729038119316	1.41199994087219	0.0256529003381729	5.39989995956421
1.25603133346885	0.0739285722374916	1.51199996471405	0.0273052006959915	5.49989986419678
1.33965164422989	0.803033471107483	1.61199998855591	0.0273052006959915	5.59999990463257
1.42273586243391	1.37080752849579	1.71200001239777	0.0303803998976946	5.69980001449585
1.50605838280171	0.492888689041138	1.81200003623962	0.0319001004099846	5.79990005493164
1.58961908891797	0.716682553291321	1.91199994087219	0.0334604009985924	5.89979982376099
1.67276291176677	1.07887673377991	2.01200008392334	0.0350962989032269	5.99989986419678
1.75638310611248	0.714790761470795	2.11199998855591	0.0366802997887135	6.09980010986328
1.83970562648028	1.14766061306	2.21199989318848	0.0382881984114647	6.19980001449585
1.92314723972231	1.16125214099884	2.31200003623962	0.039802398532629	6.29990005493164
2.00652936473489	0.688366651535034	2.41199994087219	0.0413084998726845	6.39979982376099
2.08955397829413	1.75479996204376	2.51200008392334	0.0427486002445221	6.59980010986328
2.17293598689139	0.750150978565216	2.61199998855591	0.0443827994167805	6.59980010986328
2.25625839084387	1.18453907966614	2.71199989318848	0.045941099524498	6.69980001449585
2.33940221369267	1.26418042182922	2.81200003623962	0.0473727993667126	6.80159997940063
2.42332043126225	0.62139493227005	2.91199994087219	0.0488216988742352	6.89979982376099
2.50658323056996	1.06766617298126	3.01200008392334	0.0503316000103951	6.99989986419678
2.58996523916721	1.48760604858398	3.11199998855591	0.0517886988818645	7.10020017623901
2.6729900855571	1.78999900817871	3.21199989318848	0.0533334016799927	7.19980001449585
2.75655067525804	1.58630764484406	3.31200003623962	0.0548540018498898	7.29979991912842
2.83951591700315	0.69639790058136	3.41199994087219	0.0564000010490417	7.40150022506714
2.92313611134887	1.11311841011047	3.51200008392334	0.0577856004238129	7.49980020523071
3.00663732923567	1.40786218643188	3.61199998855591	0.0592187009751797	7.59980010986328
3.08978115208447	1.35245990753174	3.71199989318848	0.0607293993234634	7.69980001449585
3.17310355603695	1.31952154636383	3.81200003623962	0.0621910989284515	7.79990005493164
3.25654516927898	1.47460901737213	3.91199994087219	0.0636795982718468	7.89979982376099
3.33986757323146	1.23554491996765	4.01200008392334	0.0651893019676208	7.99980020523071
3.42319021001458	1.26602947711945	4.11199998855591	0.0667010992765427	8.09980010986328
3.5062744282186	1.40257358551025	4.21199989318848	0.0681786984205246	8.19979953765869
3.58995422720909	1.73191142082214	4.31199979782104	0.0687860995531082	8.29979991912842
3.67303844541311	1.96749079227448	4.41200017929077	0.0718106031417847	8.50010013580322
3.75648005865514	1.80984604358673	4.51200008392334	0.0731116011738777	8.50010013580322
3.83974309079349	2.32771897315979	4.61199998855591	0.0745514035224915	8.60190010070801
3.92276747152209	2.04413437843323	4.71199989318848	0.0759920999407768	8.70230007171631
4.00638813152909	2.67519021034241	4.81199979782104	0.0773957967758179	8.79979991912842
4.08988911658525	1.40462112426758	4.91200017929077	0.0788810029625893	8.99979972839355
4.17303293943405	1.19008421897888	5.01200008392334	0.0802579000592232	8.99979972839355
4.25665313377976	1.83541178703308	5.11199998855591	0.0818156972527504	9.09980010986328
4.33973735198379	1.9177770614624	5.21199989318848	0.083279199898243	9.19979953765869
4.42294077947736	2.11269807815552	5.31199979782104	0.0848146006464958	9.29979991912842
4.50608460232615	1.86321318149567	5.41200017929077	0.0864055007696152	9.39980030059814
4.58970479667187	1.45765161514282	5.51200008392334	0.0878382995724678	9.49979972839355
4.67278901487589	1.2522394657135	5.61199998855591	0.0895178020000458	9.59980010986328
4.75658802315593	1.62411332130432	5.71199989318848	0.091026596724987	9.69989967346191
4.83985105529428	1.84172260761261	5.81199979782104	0.0924037024378777	9.79979991912842
4.9229352734983	1.46339583396912	5.91200017929077	0.0938732996582985	9.89970016479492
5.00655546784401	1.93961584568024	6.01200008392334	0.0952915027737617	9.99979972839355
5.08981849998236	1.91024649143219	6.11199998855591	0.0968054011464119	10.1997995376587
5.17272390425205	1.79664981365204	6.21199989318848	0.0981955975294113	10.1997995376587
5.25652291253209	1.88146865367889	6.31199979782104	0.0996896997094154	10.2997999191284
5.33978594467044	1.97821116447449	6.41200017929077	0.101318001747131	10.3999004364014
5.42298937216401	2.06789493560791	6.51200008392334	0.10283900052309	10.4996995925903
5.50654996186495	1.93048083782196	6.61199998855591	0.104409001767635	10.6997003555298
5.58957457542419	1.54235661029816	6.71199989318848	0.106118999421597	10.6997003555298
5.67313563078642	2.03280854225159	6.81199979782104	0.107649996876717	10.7997999191284
5.75639819726348	2.17694354057312	6.91200017929077	0.109012000262737	10.8998003005981
5.84001839160919	2.13410687446594	7.01200008392334	0.110413998365402	10.9996995925903
5.92298386618495	2.44760513305664	7.11199998855591	0.111897997558117	11.0998001098633
6.00594887509942	2.70804977416992	7.21199989318848	0.113375999033451	11.1997003555298
6.08939025551081	2.24022221565247	7.31199979782104	0.115091003477573	11.3997001647949
6.17289170622826	1.95696651935577	7.41200017929077	0.116599999368191	11.3997001647949
6.25639269128442	2.61806297302246	7.51200008392334	0.118141002953053	11.5003004074097
6.33989414200187	2.42788052558899	7.61199998855591	0.119814001023769	11.5996999740601
6.42333552241325	2.18571758270264	7.71199989318848	0.121212996542454	11.6997003555298
6.50665815919638	2.22704005241394	7.81199979782104	0.122639000415802	11.7996997833252
6.58956356346607	2.18252086639404	7.91200017929077	0.124347001314163	11.8997001647949
6.6728862002492	2.14603567123413	8.01200008392334	0.125662997364998	12.1023998260498
6.75597041845322	2.63940501213074	8.11200046539307	0.127105996012688	12.1023998260498
6.83982903137803	2.81251454353333	8.21199989318848	0.128604993224144	12.1997003555298
6.92327041178942	2.38125205039978	8.3120002746582	0.130192995071411	12.2996997833252
7.00647383928299	2.58156895637512	8.41199970245361	0.133309006690979	12.4003000259399
7.08991521969438	2.47655963897705	8.51200008392334	0.132844999432564	12.4996995925903
7.17311864718795	1.92296671867371	8.61200046539307	0.135813996195793	12.5996999740601
7.25632207468152	2.8145227432251	8.71199989318848	0.136612996459007	12.6997003555298
7.33994226902723	2.17780900001526	8.8120002746582	0.138171002268791	12.7996997833252
7.42272892966866	2.20565700531006	8.91199970245361	0.139511004090309	12.8997001647949
7.5065279379487	2.35570931434631	9.01200008392334	0.140759006142616	12.9996995925903
7.58985010907054	2.079838514328	9.11200046539307	0.142269998788834	13.0996999740601
7.67317274585366	2.68634271621704	9.21199989318848	0.143745005130768	13.2996997833252
7.75643577799201	2.51309490203857	9.3120002746582	0.145227998495102	13.2996997833252
7.83951953053474	2.51115584373474	9.41199970245361	0.146690994501114	13.3997001647949
7.92296137660742	2.07644891738892	9.51200008392334	0.148044005036354	13.4996995925903
8.00634361803532	2.47516202926636	9.61200046539307	0.150141999125481	13.5996999740601
8.08990467339754	2.58075428009033	9.71199989318848	0.151713997125626	13.6996002197266
8.17346479743719	2.53328371047974	9.8120002746582	0.15361599624157	13.799599647522
8.25648941099644	2.40986967086792	9.91199970245361	0.155204996466637	13.8997001647949
8.33981204777956	2.71160793304443	10.0120000839233	0.156488001346588	13.9997997283936
8.42277705669403	2.58894062042236	10.1120004653931	0.157792001962662	14.0996999740601
8.50651692599058	2.25377464294434	10.2119998931885	0.158962994813919	14.1996002197266
8.58954153954983	2.64399838447571	10.3120002746582	0.160365000367165	14.299599647522
8.6732804775238	2.5385365486145	10.4119997024536	0.161972999572754	14.4996004104614
8.7566627189517	2.99337196350098	10.5120000839233	0.163227006793022	14.4996004104614
8.83962772786617	3.12378144264221	10.6120004653931	0.164728999137878	14.5995998382568
8.92312917858362	1.9932028055191	10.7119998931885	0.166207998991013	14.6997003555298
9.0065710246563	2.35991740226746	10.8120002746582	0.167607992887497	14.799599647522
9.08935721963644	2.99024128913879	10.9119997024536	0.169339001178741	14.8996000289917
9.17315576225519	2.84486222267151	11.0120000839233	0.170654997229576	14.9996004104614
9.25647839903831	3.0863094329834	11.1120004653931	0.172505006194115	15.1996002197266
9.33997984975576	2.6131055355072	11.2119998931885	0.174269005656242	15.1996002197266
9.42342169582844	3.24886584281921	11.3120002746582	0.175632998347282	15.299599647522
9.50632710009813	3.7176878452301	11.4119997024536	0.177102997899055	15.3996000289917
9.58970934152603	2.71936941146851	11.5120000839233	0.178523004055023	15.4997997283936
9.67279355973005	3.56356382369995	11.6120004653931	0.181921005249023	15.6000003814697
9.75653249770403	3.17552185058594	11.7119998931885	0.181422993540764	15.6996002197266
9.8394975066185	2.87399053573608	11.8120002746582	0.184676006436348	15.8020000457764
9.92299895733595	3.26549315452576	11.9119997024536	0.186194002628326	15.8996000289917
10.0063215941191	3.28519582748413	12.0120000839233	0.187610000371933	15.9996004104614
10.0897634401917	2.98129868507385	12.1120004653931	0.189000993967056	16.0995998382568
10.1732043549418	3.29885149002075	12.2119998931885	0.190628007054329	16.2001991271973
10.256526991725	3.42354035377502	12.3120002746582	0.19241900742054	16.2996006011963
10.3397900238633	3.46964025497437	12.4119997024536	0.193691000342369	16.3995990753174
10.4230530560017	3.68688821792603	12.5120000839233	0.195030003786087	16.4995994567871
10.5059584602714	3.34471297264099	12.6120004653931	0.196383997797966	16.5995998382568
10.5895791202784	2.8843994140625	12.7119998931885	0.197744995355606	16.6996002197266
10.6728421524167	3.81641030311584	12.8120002746582	0.199294999241829	16.7996006011963
10.7565214857459	2.96187734603882	12.9119997024536	0.200508996844292	16.8995990753174
10.8400825411081	3.28461098670959	13.0120000839233	0.201949000358582	17.0995998382568
10.9231071546674	3.41442704200745	13.1120004653931	0.20532700419426	17.0995998382568
11.006667278707	3.48670077323914	13.2119998931885	0.204431995749474	17.1996002197266
11.0896332189441	3.40448689460754	13.3120002746582	0.208152994513512	17.2996006011963
11.1727770417929	3.28093361854553	13.4119997024536	0.208431005477905	17.3995990753174
11.2563967704773	3.25503945350647	13.5120000839233	0.211797997355461	17.4997005462646
11.3393617793918	3.69166445732117	13.6120004653931	0.212095007300377	17.5995998382568
11.4231016486883	4.03721570968628	13.7119998931885	0.213670000433922	17.7996997833252
11.5064838901162	3.73044276237488	13.8120002746582	0.215115994215012	17.7996997833252
11.5898652002215	3.58832454681396	13.9119997024536	0.216232001781464	17.8995990753174
11.6734262555838	3.70109677314758	14.0120000839233	0.218000993132591	17.9995002746582
11.7565104737878	3.52384328842163	14.1120004653931	0.219326004385948	18.1023998260498
11.8395946919918	3.33699250221252	14.2119998931885	0.220493003726006	18.1996002197266
11.9228577241302	3.58203125	14.3120002746582	0.222120001912117	18.2994995117188
12.0063591748476	4.24398326873779	14.4119997024536	0.223388001322746	18.3995990753174
12.0899192988873	3.29057478904724	14.5120000839233	0.224937006831169	18.4995994567871
12.1729439124465	3.65895795822144	14.6120004653931	0.226799994707108	18.5997009277344
12.2567433863878	4.11536264419556	14.7119998931885	0.22791999578476	18.699499130249
12.3396487906575	4.59619092941284	14.8120002746582	0.229296997189522	18.7994995117188
12.423150241375	3.97019267082214	14.9119997024536	0.230818003416061	18.9995002746582
12.5064132735133	3.61264061927795	15.0120000839233	0.23191000521183	18.9995002746582
12.5899137929082	3.70833301544189	15.1120004653931	0.233678996562958	19.0995006561279
12.6731172204018	3.6280198097229	15.2119998931885	0.234942004084587	19.1996002197266
12.7560822293162	4.09392642974854	15.3120002746582	0.236617997288704	19.2994995117188
12.839762493968	3.72075247764587	15.4119997024536	0.238360002636909	19.3994998931885
12.9233226180077	4.19934463500977	15.5120000839233	0.239466995000839	19.4995002746582
13.0060501396656	3.90821170806885	15.6120004653931	0.2413360029459	19.699499130249
13.0900274962187	4.37731552124023	15.7119998931885	0.242541998624802	19.699499130249
13.1731713190675	3.97781872749329	15.8120002746582	0.243919998407364	19.7994995117188
13.2567323744297	4.25459861755371	15.9119997024536	0.245149001479149	19.8995990753174
13.3400550112128	4.402587890625	16.011999130249	0.246508002281189	19.9995994567871
13.4231988340616	3.87902545928955	16.1119995117188	0.248246997594833	20.1000003814697
13.5063417255878	3.64570307731628	16.2119998931885	0.249208003282547	20.199499130249
13.5896047577262	4.53786134719849	16.3120002746582	0.250633001327515	20.2994995117188
13.6734042316675	4.40849256515503	16.4120006561279	0.252088010311127	20.3994998931885
13.7564884498715	4.48345184326172	16.511999130249	0.253304988145828	20.4995002746582
13.8395130634308	4.74575424194336	16.6119995117188	0.255059987306595	20.5995006561279
13.9230145141482	4.15853691101074	16.7119998931885	0.256130009889603	20.699499130249
14.0063958242536	4.07490730285645	16.8120002746582	0.257494002580643	20.8994998931885
14.0895992517471	5.17907333374023	16.9120006561279	0.258946001529694	20.8994998931885
14.1730410978198	4.19082641601563	17.011999130249	0.260473012924194	20.9995002746582
14.2561253160238	3.97106575965881	17.1119995117188	0.262656986713409	21.1002006530762
14.3396863713861	4.61189413070679	17.2119998931885	0.263478994369507	21.199499130249
14.4226513803005	3.87737464904785	17.3120002746582	0.265168011188507	21.2994995117188
14.5065691322088	4.76965761184692	17.4120006561279	0.266187995672226	21.3994998931885
14.5896533504128	4.65484857559204	17.511999130249	0.267255991697311	21.4995002746582
14.6731548011303	4.06598567962646	17.6119995117188	0.269050002098083	21.5995998382568
14.756953343749	4.4252495765686	17.7119998931885	0.269773989915848	21.699499130249
14.8397404700518	4.89790344238281	17.8120002746582	0.27131000161171	21.7994995117188
14.9231217801571	5.24263668060303	17.9120006561279	0.273259997367859	21.8994998931885
15.0063848122954	4.91363954544067	18.011999130249	0.27564600110054	22.0014991760254
15.0896478444338	4.51744794845581	18.1119995117188	0.276895999908447	22.0995006561279
15.1732685044408	4.60053730010986	18.2119998931885	0.279226005077362	22.199499130249
15.2561739087105	4.61859273910522	18.3120002746582	0.281165987253189	22.2994995117188
15.3397945687175	5.10395288467407	18.4120006561279	0.282375007867813	22.3994998931885
15.4232950881124	4.75154256820679	18.511999130249	0.283724009990692	22.4995002746582
15.5064389109612	4.55921697616577	18.6119995117188	0.28514900803566	22.5995006561279
15.5899999663234	4.55717039108276	18.7119998931885	0.286292999982834	22.7994003295898
15.6732629984617	5.27177810668945	18.8120002746582	0.287476003170013	22.7994003295898
15.7563462853432	4.70856714248657	18.9120006561279	0.288736999034882	22.8994007110596
15.8396102488041	5.06528377532959	19.011999130249	0.290046006441116	23.0002994537354
15.923110768199	5.23292970657349	19.1119995117188	0.291974991559982	23.0993995666504
16.006613150239	4.14939451217651	19.2119998931885	0.29381200671196	23.1993999481201
16.0895772278309	4.91529750823975	19.3120002746582	0.295215010643005	23.2994995117188
16.173554584384	4.81118297576904	19.4120006561279	0.296400994062424	23.3994998931885
16.2564013153315	4.47893095016479	19.511999130249	0.296400994062424	23.4995002746582
16.3397826254368	4.64401912689209	19.6119995117188	0.298864990472794	23.5995006561279
16.4229273796082	5.33436155319214	19.7119998931885	0.298864990472794	23.699499130249
16.5066663175821	5.26789712905884	19.8120002746582	0.301827996969223	23.7994995117188
16.589691862464	5.23288869857788	19.9120006561279	0.302769005298615	23.8994998931885
16.6729539632797	5.43808221817017	20.011999130249	0.303820997476578	23.9993991851807
16.7563948780298	4.67850780487061	20.1119995117188	0.306145012378693	24.0993995666504
16.8399568647146	5.00671100616455	20.2119998931885	0.306145012378693	24.2014999389648
16.9227421283722	4.56127691268921	20.3120002746582	0.308770000934601	24.2999000549316
17.0068386942148	5.00273275375366	20.4120006561279	0.308770000934601	24.3994998931885
17.0897450298071	5.03920459747314	20.511999130249	0.312673002481461	24.4995002746582
17.1731263399124	5.10171556472778	20.6119995117188	0.314045011997223	24.5993995666504
17.2566883265972	4.58850431442261	20.7119998931885	0.314045011997223	24.7017993927002
17.3397716134787	4.73836183547974	20.8120002746582	0.318316996097565	24.8003005981445
17.42291636765	4.45232963562012	20.9120006561279	0.31953901052475	24.8994998931885
17.5061784684658	4.33396577835083	21.011999130249	0.320885002613068	24.9993991851807
17.5896789878607	4.9397988319397	21.1119995117188	0.322109997272491	25.0993995666504
17.6729429513216	4.55611038208008	21.2119998931885	0.323435008525848	25.1993999481201
17.7561454474926	4.93604183197021	21.3120002746582	0.324710994958878	25.3994007110596
17.8397074341774	5.16892433166504	21.4120006561279	0.326097011566162	25.3994007110596
17.9230291396379	6.08309078216553	21.511999130249	0.327372997999191	25.4993991851807
18.0063527077436	5.24010610580444	21.6119995117188	0.329160004854202	25.5993995666504
18.0896744132042	4.77938556671143	21.7119998931885	0.330565005540848	25.6993999481201
18.17293651402	5.23973655700684	21.8120002746582	0.331651985645294	25.7994003295898
18.2562600821257	5.12291049957275	21.9120006561279	0.333420008420944	25.8994007110596
18.3393433690071	5.64944505691528	22.011999130249	0.334677994251251	25.9995002746582
18.4232611209154	5.78191089630127	22.1119995117188	0.336062997579575	26.0993995666504
18.5065846890211	5.73053550720215	22.2119998931885	0.33763000369072	26.1993999481201
18.5898467898369	5.68215990066528	22.3120002746582	0.339365005493164	26.300199508667
18.6733491718769	5.30238485336304	22.4120006561279	0.340541988611221	26.399299621582
18.7561344355345	5.24118566513062	22.511999130249	0.341742008924484	26.6018009185791
18.8394580036402	5.1281304359436	22.6119995117188	0.343001991510391	26.6018009185791
18.9230181276798	4.97360849380493	22.7119998931885	0.344386994838715	26.6993007659912
19.0063994377851	5.5287618637085	22.8120002746582	0.346224993467331	26.7998008728027
19.0898422151804	5.59064912796021	22.9120006561279	0.347506999969482	26.899299621582
19.1728658974171	5.64938068389893	23.011999130249	0.348906010389328	26.9993000030518
19.2564874887466	4.79317617416382	23.1119995117188	0.350138992071152	27.0993003845215
19.3397495895624	5.59819936752319	23.2119998931885	0.351514011621475	27.1993999481201
19.4228943437338	5.11915254592896	23.3120002746582	0.352705985307693	27.2992992401123
19.5065140724182	5.69701337814331	23.4120006561279	0.354241013526917	27.3994007110596
19.5898357778788	5.98478364944458	23.511999130249	0.356025010347366	27.5000991821289
19.6730997413397	6.02876377105713	23.6119995117188	0.357596009969711	27.5993995666504
19.7563618421555	5.96603775024414	23.7119998931885	0.360011011362076	27.7992992401123
19.8397450149059	5.81699419021606	23.8120002746582	0.361187011003494	27.7992992401123
19.9232455343008	5.84140300750732	23.9120006561279	0.362385004758835	27.899299621582
20.0063288211823	6.12516975402832	24.011999130249	0.36362299323082	27.9993991851807
20.0901292264462	6.1126823425293	24.1119995117188	0.364946007728577	28.0993003845215
20.1731529086828	6.09809160232544	24.2119998931885	0.366113990545273	28.1993999481201
20.2564168721437	5.98248100280762	24.3120002746582	0.367651998996735	28.2994003295898
20.33955976367	5.32457304000854	24.4120006561279	0.368766009807587	28.4993000030518
20.4230602830648	6.23104667663574	24.511999130249	0.370261996984482	28.4993000030518
20.5061454325914	5.98394680023193	24.6119995117188	0.371493011713028	28.5993003845215
20.5895863473415	5.919508934021	24.7119998931885	0.373023986816406	28.6993999481201
20.6731483340263	5.72776985168457	24.8120002746582	0.374163001775742	28.7992992401123
20.756708458066	6.65544939041138	24.9120006561279	0.375788003206253	28.9995002746582
20.8395551890135	6.54654979705811	25.011999130249	0.377066999673843	28.9995002746582
20.9236517548561	5.75183296203613	25.1119995117188	0.378309011459351	29.0995006561279
21.0063774138689	5.71779775619507	25.2119998931885	0.379664987325668	29.1998996734619
21.0895221680403	6.0194411277771	25.3120002746582	0.380993992090225	29.2992992401123
21.1730822920799	6.48950481414795	25.4120006561279	0.382331013679504	29.399299621582
21.2564058601856	6.31244087219238	25.511999130249	0.383760988712311	29.4993000030518
21.3396083563566	6.02828693389893	25.6119995117188	0.385161995887756	29.5993003845215
21.4231088757515	6.01957893371582	25.7119998931885	0.386633992195129	29.6993007659912
21.5066708624363	6.1955418586731	25.8120002746582	0.38815900683403	29.7992992401123
21.5897541493177	6.67380380630493	25.9120006561279	0.389360010623932	29.899299621582
21.6730777174234	6.08779668807983	26.011999130249	0.390688985586166	29.9993000030518
21.7564590275288	6.99992656707764	26.1119995117188	0.392033994197845	30.1993007659912
21.8398403376341	7.04062938690186	26.2119998931885	0.393451005220413	30.1993007659912
21.9232831150293	6.09024238586426	26.3120002746582	0.394901007413864	30.2992992401123
22.0065452158451	6.51965808868408	26.4120006561279	0.396465003490448	30.399299621582
22.089809179306	5.96359348297119	26.511999130249	0.397819995880127	30.5
22.173011675477	6.52302646636963	26.6119995117188	0.399158000946045	30.5993995666504
22.2560968250036	6.21373224258423	26.7119998931885	0.400557011365891	30.6993007659912
22.3398357629776	6.62942695617676	26.8120002746582	0.402042001485825	30.899299621582
22.4230978637934	6.26522207260132	26.9120006561279	0.403223991394043	30.899299621582
22.5063618272543	6.09118127822876	27.011999130249	0.404437005519867	30.9992008209229
22.5900411605835	6.5982084274292	27.1119995117188	0.405970990657806	31.0993003845215
22.6730071008205	6.62880897521973	27.2119998931885	0.407207995653152	31.1993007659912
22.7562692016363	6.57744264602661	27.3120002746582	0.40871199965477	31.2992992401123
22.839592769742	6.4162449836731	27.4120006561279	0.409992009401321	31.3992004394531
22.9231528937817	6.21830463409424	27.511999130249	0.411547988653183	31.5991992950439
23.0064745992422	6.62610292434692	27.6119995117188	0.41288098692894	31.5991992950439
23.0896193534136	6.3344931602478	27.7119998931885	0.414285987615585	31.6991996765137
23.1730602681637	6.31178092956543	27.8120002746582	0.415701001882553	31.7992992401123
23.2562050223351	6.62090301513672	27.9120006561279	0.416850000619888	31.899299621582
23.3397055417299	7.1390323638916	28.011999130249	0.418336004018784	32.0019989013672
23.4233252704144	6.83584356307983	28.1119995117188	0.419461995363235	32.0998001098633
23.5065892338753	6.55613994598389	28.2119998931885	0.420998007059097	32.1992988586426
23.5900897532701	6.80307054519653	28.3120002746582	0.42230299115181	32.2991981506348
23.6732922494411	6.54119729995728	28.4120006561279	0.423987001180649	32.3992004394531
23.7565562129021	6.54329204559326	28.511999130249	0.4254370033741	32.4991989135742
23.8398183137178	6.72896671295166	28.6119995117188	0.426753997802734	32.5992012023926
23.9227842539549	6.64472675323486	28.7119998931885	0.427976995706558	32.7993011474609
24.0065827965736	6.3155779838562	28.8120002746582	0.428929001092911	32.7993011474609
24.0898467600346	6.42019844055176	28.9120006561279	0.430341988801956	32.8992004394531
24.1731088608503	6.95545816421509	29.011999130249	0.431329011917114	32.9991989135742
24.2563709616661	7.45393562316895	29.1119995117188	0.433192014694214	33.0992012023926
24.3397541344166	7.00873947143555	29.2119998931885	0.434161990880966	33.1991996765137
24.4228970259428	6.95366239547729	29.3120002746582	0.435662001371384	33.2991981506348
24.5061013847589	6.95065116882324	29.4120006561279	0.436755001544952	33.4992980957031
24.5897807180882	6.29226160049438	29.511999130249	0.438443005084991	33.4992980957031
24.6730446815491	6.57141542434692	29.6119995117188	0.43987700343132	33.5993003845215
24.7562471777201	7.30963087081909	29.7119998931885	0.441345989704132	33.6991996765137
24.8402841389179	7.07060766220093	29.8120002746582	0.442640006542206	33.7991981506348
24.922713637352	6.78740978240967	29.9120006561279	0.443908005952835	34.0010986328125
25.006452575326	7.18816947937012	30.011999130249	0.445196986198425	34.0010986328125
25.0898357480764	7.13244962692261	30.1119995117188	0.446473002433777	34.0992012023926
25.1733362674713	7.14597940444946	30.2119998931885	0.447874009609222	34.1991996765137
25.2564195543528	6.77030277252197	30.3120002746582	0.449232995510101	34.2991981506348
25.3401007503271	7.22575807571411	30.4120006561279	0.450767010450363	34.3992004394531
25.4231840372086	6.97394609451294	30.511999130249	0.451945006847382	34.4991989135742
25.5062691867352	6.37613534927368	30.6119995117188	0.4531170129776	34.6991996765137
25.5895312875509	7.14497375488281	30.7119998931885	0.454791009426117	34.6991996765137
25.6730914115906	6.80140924453735	30.8120002746582	0.456162005662918	34.7991981506348
25.7563553750515	7.51618480682373	30.9120006561279	0.457064002752304	34.8992004394531
25.8399154990911	6.80826568603516	31.011999130249	0.458490997552872	34.9998016357422
25.9232390671968	7.89154767990112	31.1119995117188	0.45974999666214	35.1016006469727
26.0063819587231	7.29925060272217	31.2119998931885	0.461277991533279	35.1991004943848
26.0898824781179	7.48540592193604	31.3120002746582	0.462339013814926	35.3992004394531
26.1726099997759	7.61077165603638	31.4120006561279	0.46399199962616	35.3992004394531
26.2561701238155	6.8143892288208	31.511999130249	0.465187013149261	35.4990997314453
26.3394340872765	7.33057641983032	31.6119995117188	0.466356009244919	35.6012001037598
26.4230538159609	7.41078615188599	31.7119998931885	0.467999011278152	35.6991996765137
26.5065561980009	7.07541418075562	31.8120002746582	0.469222992658615	35.7991981506348
26.5897586941719	6.66129732131958	31.9120006561279	0.470681995153427	35.8991012573242
26.6730803996325	7.62137460708618	32.0120010375977	0.471522003412247	35.9991989135742
26.7563443630934	7.58612442016602	32.1119995117188	0.473008006811142	36.0992012023926
26.8399640917778	8.35533332824707	32.2120018005371	0.47427698969841	36.1991996765137
26.9230492413044	7.96779346466064	32.3120002746582	0.475746989250183	36.2991981506348
27.0062517374754	7.00827741622925	32.4119987487793	0.477113008499146	36.3992004394531
27.0897522568703	8.11469554901123	32.5120010375977	0.478646010160446	36.4990997314453
27.1729566156864	8.02539443969727	32.6119995117188	0.479618012905121	36.5990982055664
27.2563975304365	8.05444526672363	32.7120018005371	0.481025993824005	36.6991004943848
27.3400191217661	8.00339889526367	32.8120002746582	0.482239007949829	36.7991981506348
27.4232216179371	8.34671306610107	32.9119987487793	0.483788996934891	36.8991012573242
27.5066029280424	7.76093149185181	33.0120010375977	0.485134989023209	37.0990982055664
27.5898072868586	7.46659564971924	33.1119995117188	0.486221998929977	37.0990982055664
27.67289057374	7.61621046066284	33.2120018005371	0.487421989440918	37.1991996765137
27.7562141418457	7.89125776290894	33.3120002746582	0.488503009080887	37.2994995117188
27.8395358473063	7.72994804382324	33.4119987487793	0.489594995975494	37.3991012573242
27.9233362525702	7.189040184021	33.5120010375977	0.491147011518478	37.5
28.0063599348068	7.35082578659058	33.6119995117188	0.49236598610878	37.5990982055664
28.0898604542017	7.70581388473511	33.7120018005371	0.493616998195648	37.7990989685059
28.1731244176626	7.57788038253784	33.8120002746582	0.4949089884758	37.7990989685059
28.2564461231232	7.29964065551758	33.9119987487793	0.496313005685806	37.8992004394531
28.3395908772945	7.90227651596069	34.0120010375977	0.497754007577896	37.9999008178711
28.4227337688208	7.41395950317383	34.1119995117188	0.498584985733032	38.0990982055664
28.5064149647951	7.84160184860229	34.2120018005371	0.499956995248795	38.1991004943848
28.5896770656109	7.71737289428711	34.3120002746582	0.501219987869263	38.2990989685059
28.6730583757162	8.10239505767822	34.4119987487793	0.502627015113831	38.3991012573242
28.7569779902697	7.56901741027832	34.5120010375977	0.50381600856781	38.4990997314453
28.8396440446377	8.15878772735596	34.6119995117188	0.505626022815704	38.5990982055664
28.9232656359673	8.02527332305908	34.7120018005371	0.506420016288757	38.6991004943848
29.0063489228487	6.98363780975342	34.8120002746582	0.508467018604279	38.7993011474609
29.089730232954	8.10563659667969	34.9119987487793	0.508882999420166	38.8991012573242
29.1729941964149	8.44572734832764	35.0120010375977	0.509827017784119	38.9991989135742
29.2566139250994	8.23975944519043	35.1119995117188	0.511186003684998	39.0990982055664
29.3397586792707	7.3063907623291	35.2120018005371	0.512158989906311	39.1991004943848
29.422901570797	7.9507474899292	35.3120002746582	0.513701021671295	39.2990989685059
29.5062847435474	7.63360834121704	35.4119987487793	0.514533996582031	39.3992004394531
29.5900236815214	7.95852041244507	35.5120010375977	0.515808999538422	39.4991989135742
29.6730473637581	8.33391571044922	35.6119995117188	0.517054975032806	39.6991004943848
29.7566689550877	8.7498893737793	35.7120018005371	0.518401980400085	39.6991004943848
29.8397522419691	8.36560916900635	35.8120002746582	0.519894003868103	39.7990989685059
29.9231354147196	8.15938758850098	35.9119987487793	0.520770013332367	39.898998260498
30.0062783062458	7.5724024772644	36.0120010375977	0.521624028682709	39.9992980957031
30.089421197772	7.58308887481689	36.1119995117188	0.522871971130371	40.0992012023926
30.1731619983912	7.99017572402954	36.2120018005371	0.524258971214294	40.1991004943848
30.2564837038517	8.61470222473145	36.3120002746582	0.525349974632263	40.2990989685059
30.3399860858917	8.24271011352539	36.4119987487793	0.526929974555969	40.3991012573242
30.4234270006418	8.23905467987061	36.5120010375977	0.527966976165771	40.4998016357422
30.506569892168	8.05443859100342	36.6119995117188	0.529246985912323	40.5990982055664
30.589833855629	7.81755685806274	36.7120018005371	0.530507028102875	40.6991004943848
30.6727979332209	8.09555530548096	36.8120002746582	0.532087981700897	40.8991012573242
30.7562407106161	8.37765026092529	36.9119987487793	0.532913982868195	40.8991012573242
30.8396220207214	7.83181047439575	37.0120010375977	0.534092009067535	40.9998016357422
30.9228263795376	8.81111812591553	37.1119995117188	0.535367012023926	41.0990982055664
31.0066249221563	8.19614791870117	37.2120018005371	0.536300003528595	41.1991004943848
31.0895889997482	8.02339267730713	37.3120002746582	0.537539005279541	41.298999786377
31.1729721724987	8.48135375976563	37.4119987487793	0.538773000240326	41.3991012573242
31.2567129731178	8.33895969390869	37.5120010375977	0.540251970291138	41.5990982055664
31.3397347927094	8.57761001586914	37.6119995117188	0.541328012943268	41.5990982055664
31.4231179654598	8.69798183441162	37.7120018005371	0.542867004871368	41.6991004943848
31.5061435103416	8.61768627166748	37.8120002746582	0.544354975223541	41.7999000549316
31.5897017717361	8.61263084411621	37.9119987487793	0.545597016811371	41.8991012573242
31.6730253398418	9.15567207336426	38.0120010375977	0.546117007732391	41.9990005493164
31.7562893033028	9.33208084106445	38.1119995117188	0.547838985919952	42.0990982055664
31.8399667739868	8.55109882354736	38.2120018005371	0.549106001853943	42.1990013122559
31.9231115281582	8.46627235412598	38.3120002746582	0.550274014472961	42.2990989685059
32.0066139101982	8.8715295791626	38.4119987487793	0.551034986972809	42.3991012573242
32.0898182690144	9.0842456817627	38.5120010375977	0.55239200592041	42.4995002746582
32.1731977164745	8.5310583114624	38.6119995117188	0.553839981555939	42.5990982055664
32.2563424706459	9.07231426239014	38.7120018005371	0.554751992225647	42.7997016906738
32.3395468294621	9.03861808776855	38.8120002746582	0.556307971477509	42.7997016906738
32.4231646955013	8.92239570617676	38.9119987487793	0.557654023170471	42.8991012573242
32.5064286589622	9.24611949920654	39.0120010375977	0.559221029281616	42.9990005493164
32.5895138084888	8.54911613464355	39.1119995117188	0.560145020484924	43.0990982055664
32.6734893023968	9.03419494628906	39.2120018005371	0.561722993850708	43.1990013122559
32.7562168240547	9.47837924957275	39.3120002746582	0.564657986164093	43.2994995117188
32.8397788107395	9.51603317260742	39.4119987487793	0.565994024276733	43.3991012573242
32.9228043556213	9.02081203460693	39.5120010375977	0.567430973052979	43.4990997314453
33.0063030123711	9.67424869537354	39.6119995117188	0.568274021148682	43.5989990234375
33.0898053944111	9.10209178924561	39.7120018005371	0.569172978401184	43.6990013122559
33.1731885671616	9.58360481262207	39.8120002746582	0.57033097743988	43.798999786377
33.2564525306225	9.49029922485352	39.9119987487793	0.5710129737854	43.898998260498
33.3397723734379	8.42459392547607	40.0120010375977	0.572521984577179	43.9990005493164
33.422976732254	10.1801977157593	40.1119995117188	0.573574006557465	44.0989990234375
33.5065983235836	9.11418342590332	40.2120018005371	0.574684977531433	44.1990013122559
33.5897989571095	9.49726104736328	40.3120002746582	0.576134026050568	44.298999786377
33.673420548439	9.67006683349609	40.4119987487793	0.576318979263306	44.398998260498
33.7565056979656	10.1096515655518	40.5120010375977	0.575715005397797	44.4990005493164
33.8399447500706	9.36731147766113	40.6119995117188	0.57729697227478	44.6990013122559
33.923327922821	9.83945560455322	40.7120018005371	0.579963028430939	44.6990013122559
34.0065322816372	9.93298625946045	40.8120002746582	0.582077026367188	44.798999786377
34.0894386172295	9.98998641967773	40.9119987487793	0.583132982254028	44.8988990783691
34.1729372739792	9.73588562011719	41.0120010375977	0.585492014884949	44.9990005493164
34.2564396560192	9.69594955444336	41.1119995117188	0.587321996688843	45.0988998413086
34.3398228287697	10.009391784668	41.2120018005371	0.590142011642456	45.1988983154297
34.422904253006	10.2968893051147	41.3120002746582	0.592317998409271	45.298900604248
34.5063470304012	9.60749912261963	41.4119987487793	0.593171000480652	45.398998260498
34.5892533659935	10.035231590271	41.5120010375977	0.594453990459442	45.4990005493164
34.6729345619678	10.036810874939	41.6119995117188	0.595488011837006	45.5989990234375
34.7563736140728	10.1128253936768	41.7120018005371	0.596816003322601	45.6991004943848
34.8392799496651	10.4785327911377	41.8120002746582	0.597976982593536	45.898998260498
34.923080354929	10.6175746917725	41.9119987487793	0.599157989025116	45.898998260498
35.0064598023891	9.87645149230957	42.0120010375977	0.600217998027802	45.9990005493164
35.0897237658501	10.5346403121948	42.1119995117188	0.600450992584229	46.0989990234375
35.1732261478901	10.2663707733154	42.2120018005371	0.60145902633667	46.1990013122559
35.2563671767712	10.421817779541	42.3120002746582	0.60268497467041	46.2991981506348
35.3396907448769	9.9914665222168	42.4119987487793	0.60394299030304	46.3988990783691
35.4228354990482	10.3940229415894	42.5120010375977	0.605170011520386	46.4989013671875
35.506397485733	10.5092458724976	42.6119995117188	0.606257975101471	46.5988998413086
35.5897769331932	10.0824823379517	42.7120018005371	0.608532011508942	46.6988983154297
35.6732197105885	9.9547872543335	42.8120002746582	0.608479022979736	46.798900604248
35.7569009065628	10.8147239685059	42.9119987487793	0.609763026237488	46.898998260498
35.8399227261543	10.2601957321167	43.0120010375977	0.611944973468781	47.0989990234375
35.9230674803257	10.3738765716553	43.1119995117188	0.612214982509613	47.0989990234375
36.0062122344971	10.0025157928467	43.2120018005371	0.612735986709595	47.1988983154297
36.0896550118923	10.6868906021118	43.3120002746582	0.614507019519806	47.298900604248
36.1730344593525	10.1306953430176	43.4119987487793	0.615136027336121	47.3988990783691
36.2561792135239	10.6503658294678	43.5120010375977	0.616461992263794	47.5988998413086
36.3397412002087	10.2410335540771	43.6119995117188	0.617919981479645	47.5988998413086
36.4230610430241	10.7544450759888	43.7120018005371	0.618254005908966	47.6988983154297
36.5063846111298	11.0760555267334	43.8120002746582	0.619921982288361	47.7994003295898
36.5901254117489	10.8561954498291	43.9119987487793	0.621210992336273	47.8988990783691
36.6727337241173	10.6015758514404	44.0120010375977	0.62253600358963	47.9989013671875
36.7565304040909	10.8398561477661	44.1119995117188	0.62354302406311	48.0988998413086
36.8396155536175	11.2316484451294	44.2120018005371	0.624791026115417	48.298900604248
36.9230583310127	10.4953594207764	44.3120002746582	0.625963985919952	48.298900604248
37.0065569877625	10.5414772033691	44.4119987487793	0.627077996730804	48.3988990783691
37.0898209512234	10.5176258087158	44.5120010375977	0.62754100561142	48.4989013671875
37.1731445193291	10.4459314346313	44.6119995117188	0.629185974597931	48.5989990234375
37.2566431760788	11.1778755187988	44.7120018005371	0.62931901216507	48.798900604248
37.3398475348949	10.6520881652832	44.8120002746582	0.630725026130676	48.798900604248
37.4232903122902	10.9067735671997	44.9119987487793	0.631636023521423	48.8988990783691
37.5065542757511	10.8760757446289	45.0120010375977	0.633282005786896	48.9989013671875
37.5900529325008	11.041241645813	45.1119995117188	0.634135007858276	49.0988998413086
37.6728996634483	10.6712846755981	45.2120018005371	0.635070979595184	49.1988983154297
37.7565212547779	10.4940376281738	45.3120002746582	0.635841012001038	49.298900604248
37.8397218883038	10.7449340820313	45.4119987487793	0.636711001396179	49.4989013671875
37.9229858517647	11.6926078796387	45.5120010375977	0.638009011745453	49.4989013671875
38.0063690245152	11.5218000411987	45.6119995117188	0.639182984828949	49.5988998413086
38.0896925926208	11.1310091018677	45.7120018005371	0.640016973018646	49.6988983154297
38.1731316447258	11.5531272888184	45.8120002746582	0.640977025032043	49.7988014221191
38.2563956081867	11.3509731292725	45.9119987487793	0.642359972000122	49.8988990783691
38.3396595716476	11.4983386993408	46.0120010375977	0.643440008163452	49.9990997314453
38.4233370423317	10.9990673065186	46.1119995117188	0.643567025661469	50.0988998413086
38.5064221918583	11.1491746902466	46.2120018005371	0.64487898349762	50.1988983154297
38.5306030511856	-1.10263323783875	46.2410011291504	0.64487898349762	50.1988983154297