File: CSVs/oven-laser_combinations/laser_1.txt
File Path: C:\Users\apk5101\Desktop\220114_cbPDMS_Oven_and_Laser\220114_cbPDMS_laser_808nm_1k3k_1 01-14-22 17 37 09 PM\DAQ- Crosshead, … - (Timed).txt
Test: MTS EM Tension (Simplified) with Video Extensometer apk5101 6
Test Run: 220114_cbPDMS_laser_808nm_1k3k_1
Date: 1/14/2022 5:34:35 PM


Crosshead 	Load 	Time 	Strain 1 	Video Time
mm	N	sec	mm/mm	sec
0.0862408560351469	-0.268700301647186	0.112000003457069	-0.000124860001960769	4.19990015029907
0.169682447449304	0.627752721309662	0.211999997496605	-9.69952016021125E-05	4.19990015029907
0.253957870882004	-0.22639773786068	0.312000006437302	0.0020705999340862	4.40000009536743
0.337518606102094	0.4252048432827	0.412000000476837	0.00398048991337419	4.40000009536743
0.421079312218353	-0.0823405608534813	0.512000024318695	0.00607354007661343	4.49989986419678
0.505056930705905	0.0361814759671688	0.611999988555908	0.00799562036991119	4.69999980926514
0.588438997510821	0.479228168725967	0.712000012397766	0.00953823979943991	4.69999980926514
0.671940157189965	0.342475026845932	0.811999976634979	0.0115184001624584	4.89989995956421
0.755500863306224	0.346350580453873	0.912000000476837	0.0131091000512242	4.89989995956421
0.839180662296712	1.20233631134033	1.01199996471405	0.0148074999451637	5.09989976882935
0.922562729101628	0.233696505427361	1.11199998855591	0.0164668001234531	5.19990015029907
1.006004284136	0.514159679412842	1.21200001239777	0.0180760007351637	5.19990015029907
1.08956499025226	-0.272214233875275	1.31200003623962	0.0198810994625092	5.39989995956421
1.17270881310105	0.250616490840912	1.41199994087219	0.0214831996709108	5.39989995956421
1.25615042634308	0.578286170959473	1.51199996471405	0.0227674003690481	5.59989976882935
1.33935385383666	0.0639437288045883	1.61199998855591	0.0244638994336128	5.59989976882935
1.42303365282714	0.268042773008347	1.71200001239777	0.0259815994650126	5.79990005493164
1.5064156614244	0.417174220085144	1.81200003623962	0.027140099555254	5.89989995956421
1.58944039139897	0.153202325105667	1.91199994087219	0.0288503002375364	5.89989995956421
1.67317979503423	0.49852979183197	2.01200008392334	0.0301207005977631	6.09989976882935
1.75632361788303	0.552107930183411	2.11199998855591	0.0314655005931854	6.09989976882935
1.83928874321282	0.721457004547119	2.21199989318848	0.0328375995159149	6.29990005493164
1.92362372763455	0.593856871128082	2.31200003623962	0.0342629998922348	6.29990005493164
2.00641015544534	1.0273152589798	2.41199994087219	0.0357072986662388	6.39989995956421
2.09008995443583	0.489497721195221	2.51200008392334	0.0371229015290737	6.59989976882935
2.17311456799507	1.05189502239227	2.61199998855591	0.038383599370718	6.59989976882935
2.25685397163033	0.022936524823308	2.71199989318848	0.0399793982505798	6.79990005493164
2.33981921337545	0.532382249832153	2.81200003623962	0.0414502993226051	6.79990005493164
2.42308201268315	0.492015480995178	2.91199994087219	0.0428044013679028	6.99989986419678
2.50664283521473	0.954483449459076	3.01200008392334	0.0442382991313934	7.09989976882935
2.58990586735308	1.16210627555847	3.11199998855591	0.0454326011240482	7.09989976882935
2.67293048091233	0.829929769039154	3.21199989318848	0.0470304004848003	7.30000019073486
2.75666988454759	0.596885561943054	3.31200003623962	0.0485531017184258	7.30000019073486
2.84005189314485	0.687402665615082	3.41199994087219	0.0496787987649441	7.49989986419678
2.92325532063842	1.05406820774078	3.51200008392334	0.0513672009110451	7.49989986419678
3.00645851530135	1.13060653209686	3.61199998855591	0.0527988001704216	7.69990015029907
3.0900789424777	0.737807512283325	3.71199989318848	0.0538181997835636	7.79990005493164
3.17310355603695	1.19969749450684	3.81200003623962	0.0551482997834682	7.79990005493164
3.25618777424097	0.807535707950592	3.91199994087219	0.0565741993486881	7.99989986419678
3.33986757323146	1.58053839206696	4.01200008392334	0.0579443983733654	7.99989986419678
3.42283281497657	0.346432119607925	4.11199998855591	0.0590214990079403	8.19989967346191
3.50651261396706	0.391535192728043	4.21199989318848	0.0603719018399715	8.19989967346191
3.59013280831277	0.353392243385315	4.31199979782104	0.0620216988027096	8.29990005493164
3.67291946895421	0.872976660728455	4.41200017929077	0.0631688982248306	8.49989986419678
3.75653966329992	0.136116653680801	4.51200008392334	0.0645060986280441	8.49989986419678
3.83968348614872	0.932176172733307	4.61199998855591	0.0663821026682854	8.70009994506836
3.92288668081164	0.777664721012115	4.71199989318848	0.0674614980816841	8.70009994506836
4.00626892223954	1.54919707775116	4.81199979782104	0.068874903023243	8.89980030059814
4.08935314044356	1.35856926441193	4.91200017929077	0.0701946020126343	8.99989986419678
4.17303293943405	1.31593728065491	5.01200008392334	0.0716153979301453	8.99989986419678
4.25671273842454	1.34163022041321	5.11199998855591	0.0729203000664711	9.19979953765869
4.33997577056289	1.28361880779266	5.21199989318848	0.0740012973546982	9.19979953765869
4.42341715097427	0.807018220424652	5.31199979782104	0.0755250975489616	9.39990043640137
4.50656097382307	0.932987630367279	5.41200017929077	0.0768816024065018	9.39990043640137
4.58976440131664	1.33095622062683	5.51200008392334	0.0780265033245087	9.49989986419678
4.67302743345499	1.36787152290344	5.61199998855591	0.0793785005807877	9.69979953765869
4.75635007023811	1.60692238807678	5.71199989318848	0.0810957029461861	9.69979953765869
4.8397914506495	1.1156986951828	5.81199979782104	0.0822841972112656	9.89980030059814
4.92305448278785	1.7866632938385	5.91200017929077	0.0835705995559692	9.89980030059814
5.00661507248878	1.99466717243195	6.01200008392334	0.0849594995379448	10.0998001098633
5.08963968604803	1.80875027179718	6.11199998855591	0.0864342004060745	10.0998001098633
5.17314113676548	1.60469734668732	6.21199989318848	0.087406799197197	10.1997995376587
5.25628495961428	1.30376148223877	6.31199979782104	0.0891757979989052	10.3998003005981
5.33996475860476	1.54801154136658	6.41200017929077	0.090666800737381	10.3998003005981
5.42322732508183	0.980579495429993	6.51200008392334	0.0917181000113487	10.5998001098633
5.50595438107848	0.71332448720932	6.61199998855591	0.0942135006189346	10.5998001098633
5.58963418006897	1.61112606525421	6.71199989318848	0.0953700989484787	10.7997999191284
5.67295681685209	1.48468852043152	6.81199979782104	0.0962075963616371	10.8998003005981
5.75621984899044	1.38605535030365	6.91200017929077	0.0974415987730026	10.8998003005981
5.84013760089874	1.72443640232086	7.01200008392334	0.098957397043705	11.0998001098633
5.92304347082973	1.41635501384735	7.11199998855591	0.100406996905804	11.0998001098633
6.00666366517544	1.51643943786621	7.21199989318848	0.101558998227119	11.2997999191284
6.08998583629727	2.47772192955017	7.31199979782104	0.102549999952316	11.2997999191284
6.17318926379085	1.25235319137573	7.41200017929077	0.104806996881962	11.4997997283936
6.25609513372183	1.4102885723114	7.51200008392334	0.105764999985695	11.5998001098633
6.33989414200187	1.72399985790253	7.61199998855591	0.106605999171734	11.5998001098633
6.42315670847893	1.70346403121948	7.71199989318848	0.108285002410412	11.7997999191284
6.5065985545516	1.2957946062088	7.81199979782104	0.109343998134136	11.7997999191284
6.58980198204517	0.990948975086212	7.91200017929077	0.110532000660896	11.9997997283936
6.67354138568044	0.877514362335205	8.01200008392334	0.111730001866817	12.0998001098633
6.75656599923968	1.50436425209045	8.11200046539307	0.11328399926424	12.0998001098633
6.83994777500629	0.984578013420105	8.21199989318848	0.114799000322819	12.2997999191284
6.92285364493728	1.47781121730804	8.3120002746582	0.115887001156807	12.2997999191284
7.00641423463821	0.426884859800339	8.41199970245361	0.117581002414227	12.4997997283936
7.08979647606611	1.35625004768372	8.51200008392334	0.118753999471664	12.4997997283936
7.17305904254317	1.92387640476227	8.61200046539307	0.120085999369621	12.6997995376587
7.2566200979054	2.92966651916504	8.71199989318848	0.121478997170925	12.7997999191284
7.33958510681987	2.01432418823242	8.8120002746582	0.123241998255253	12.7997999191284
7.42308609187603	1.90522158145905	8.91199970245361	0.124387003481388	12.9996995925903
7.50676589086652	1.65483260154724	9.01200008392334	0.125523999333382	12.9996995925903
7.58979097008705	1.34101736545563	9.11200046539307	0.127050995826721	13.1997003555298
7.67329195514321	2.51012945175171	9.21199989318848	0.128464996814728	13.1997003555298
7.75649538263679	1.82573342323303	9.3120002746582	0.12984399497509	13.2996997833252
7.83969834446907	1.88012170791626	9.41199970245361	0.131020992994308	13.4996995925903
7.92290177196264	1.84442281723022	9.51200008392334	0.132622003555298	13.4996995925903
8.00628401339054	2.27831506729126	9.61200046539307	0.133853003382683	13.6997003555298
8.08966625481844	1.92246568202972	9.71199989318848	0.135236993432045	13.6997003555298
8.17334558814764	2.23426246643066	9.8120002746582	0.136925995349884	13.8997001647949
8.25684703886509	2.50034189224243	9.91199970245361	0.137952998280525	13.9996995925903
8.34016967564821	2.43161940574646	10.0120000839233	0.139211997389793	13.9996995925903
8.42307507991791	1.79628908634186	10.1120004653931	0.140493005514145	14.1997003555298
8.50627850741148	2.27707672119141	10.2119998931885	0.141619995236397	14.1997003555298
8.58972035348415	2.35872411727905	10.3120002746582	0.143636003136635	14.3997001647949
8.67304299026728	2.50014400482178	10.4119997024536	0.144372001290321	14.3997001647949
8.75660311430693	2.47256708145142	10.5120000839233	0.145636007189751	14.5996999740601
8.84010456502438	1.81016433238983	10.6120004653931	0.147139996290207	14.6997003555298
8.92354641109705	3.01671028137207	10.7119998931885	0.148729994893074	14.6997003555298
9.00639221072197	2.29505038261414	10.8120002746582	0.149698004126549	14.8997001647949
9.08977445214987	2.36255216598511	10.9119997024536	0.151094004511833	14.8997001647949
9.17285867035389	1.62291789054871	11.0120000839233	0.152208000421524	15.0996999740601
9.25641879439354	1.80057597160339	11.1120004653931	0.153927996754646	15.1997003555298
9.33968182653189	2.58539128303528	11.2119998931885	0.155028000473976	15.1997003555298
9.42294485867023	1.75207841396332	11.3120002746582	0.156182006001472	15.3997001647949
9.50656551867723	2.48137211799622	11.4119997024536	0.157873004674911	15.3997001647949
9.58988815546036	2.19569325447083	11.5120000839233	0.15931099653244	15.5996999740601
9.67303104698658	2.86244535446167	11.6120004653931	0.160389006137848	15.5996999740601
9.75689012557268	2.05994176864624	11.7119998931885	0.161705002188683	15.7996997833252
9.83985513448715	1.99455213546753	11.8120002746582	0.163589000701904	15.8998003005981
9.9231181666255	2.71449947357178	11.9119997024536	0.164484992623329	15.8998003005981
10.0064408034086	2.62436699867249	12.0120000839233	0.165485993027687	16.0997009277344
10.0896442309022	2.72493410110474	12.1120004653931	0.166254997253418	16.0997009277344
10.172788053751	2.17322254180908	12.2119998931885	0.168142005801201	16.2996997833252
10.2566462010145	2.27984356880188	12.3120002746582	0.169358998537064	16.3995990753174
10.3399688377976	2.1407995223999	12.4119997024536	0.170677006244659	16.4995994567871
10.4231126606464	2.71995377540588	12.5120000839233	0.172310993075371	16.5995998382568
10.5066141113639	2.75958347320557	12.6120004653931	0.173841997981071	16.5995998382568
10.5899954214692	2.56501579284668	12.7119998931885	0.174976006150246	16.7996997833252
10.6729017570615	2.51470732688904	12.8120002746582	0.176063999533653	16.7996997833252
10.7565214857459	2.43340659141541	12.9119997024536	0.177240997552872	17.0009002685547
10.8393672853708	3.15939903259277	13.0120000839233	0.178730994462967	17.0995998382568
10.9231667593122	2.49786162376404	13.1120004653931	0.180352002382278	17.0995998382568
11.0064297914505	2.93974280357361	13.2119998931885	0.181445002555847	17.2996997833252
11.0899899154902	2.87815308570862	13.3120002746582	0.182852998375893	17.2996997833252
11.1735509708524	2.88177609443665	13.4119997024536	0.184581995010376	17.4995994567871
11.2565159797668	3.1528697013855	13.5120000839233	0.185586005449295	17.4995994567871
11.3396598026156	2.7883665561676	13.6120004653931	0.186792999505997	17.6996002197266
11.4232208579779	2.97380137443542	13.7119998931885	0.188767001032829	17.7996006011963
11.5063050761819	2.9411256313324	13.8120002746582	0.189835995435715	17.7996006011963
11.589745990932	1.73495256900787	13.9119997024536	0.190675005316734	17.9995994567871
11.6730090230703	2.9398148059845	14.0120000839233	0.192963004112244	17.9995994567871
11.7565700784326	3.10222268104553	14.1120004653931	0.19378699362278	18.1996002197266
11.8397139012814	2.9276123046875	14.2119998931885	0.194738000631332	18.1996002197266
11.9230961427093	3.14134478569031	14.3120002746582	0.19675900042057	18.2996006011963
12.0063591748476	3.47220683097839	14.4119997024536	0.1978600025177	18.4995994567871
12.0896808803082	3.06466937065125	14.5120000839233	0.198897004127502	18.4995994567871
12.1731227263808	1.89939332008362	14.6120004653931	0.201104000210762	18.6996002197266
12.2566241770983	3.07088255882263	14.7119998931885	0.201655000448227	18.6996002197266
12.3397679999471	1.99590015411377	14.8120002746582	0.202879995107651	18.8995990753174
12.4230310320854	2.84601092338562	14.9119997024536	0.20422500371933	18.9995994567871
12.5062940642238	2.8603253364563	15.0120000839233	0.205013006925583	18.9995994567871
12.589973397553	2.82150626182556	15.1120004653931	0.207102999091148	19.1996002197266
12.6732364296913	2.69412279129028	15.2119998931885	0.208177998661995	19.1996002197266
12.7567974850535	2.57777094841003	15.3120002746582	0.208773002028465	19.3995990753174
12.8401787951589	3.87988972663879	15.4119997024536	0.20974999666214	19.3995990753174
12.9231447353959	2.51425194740295	15.5120000839233	0.211351007223129	19.5995998382568
13.0065260455012	3.38518953323364	15.6120004653931	0.212948992848396	19.699499130249
13.0895506590605	2.83868169784546	15.7119998931885	0.213952004909515	19.699499130249
13.173290528357	3.1784451007843	15.8120002746582	0.214855000376701	19.8994998931885
13.2566727697849	3.45858001708984	15.9119997024536	0.218417003750801	19.8994998931885
13.3393993601203	2.96323227882385	16.011999130249	0.217269003391266	20.0995006561279
13.4230796247721	3.30409908294678	16.1119995117188	0.218877002596855	20.0995006561279
13.5065801441669	3.55412459373474	16.2119998931885	0.220887005329132	20.1996002197266
13.589664362371	3.20468831062317	16.3120002746582	0.221878007054329	20.3995990753174
13.6733446270227	3.13396739959717	16.4120006561279	0.223526000976563	20.3995990753174
13.7561904266477	3.38094091415405	16.511999130249	0.224370002746582	20.5995006561279
13.8396322727203	3.41854786872864	16.6119995117188	0.225948005914688	20.5995006561279
13.9228357002139	2.78123569488525	16.7119998931885	0.2275779992342	20.7996006011963
14.0066342428327	3.86205816268921	16.8120002746582	0.228826999664307	20.8995990753174
14.0895992517471	3.47615027427673	16.9120006561279	0.229890003800392	20.8995990753174
14.1731603071094	3.75990509986877	17.011999130249	0.232245996594429	21.0995998382568
14.2568405717611	2.88186526298523	17.1119995117188	0.232978001236916	21.0995998382568
14.3398055806756	3.04322648048401	17.2119998931885	0.234095007181168	21.2996006011963
14.4233657047153	3.93133878707886	17.3120002746582	0.234261006116867	21.2996006011963
14.5065691322088	2.9897255897522	17.4120006561279	0.235563993453979	21.3995990753174
14.5897725597024	2.78599500656128	17.511999130249	0.23751999437809	21.5995998382568
14.6733932197094	2.98617815971375	17.6119995117188	0.236431002616882	21.5995998382568
14.7562390193343	3.39394998550415	17.7119998931885	0.240512996912003	21.7996006011963
14.8398596793413	3.1216197013855	17.8120002746582	0.242844998836517	21.7996006011963
14.9232409894466	3.54074692726135	17.9120006561279	0.24414099752903	21.9995994567871
15.0067424401641	3.85977864265442	18.011999130249	0.246637001633644	22.0995998382568
15.090124681592	3.8505802154541	18.1119995117188	0.247342005372047	22.0995998382568
15.173208899796	3.53188490867615	18.2119998931885	0.248192995786667	22.2994995117188
15.2563527226448	3.70821952819824	18.3120002746582	0.250189989805222	22.2994995117188
15.3398532420397	3.61576724052429	18.4120006561279	0.251525014638901	22.4995994567871
15.423116274178	4.25217819213867	18.511999130249	0.25093400478363	22.4995994567871
15.5066773295403	3.55818605422974	18.6119995117188	0.25763401389122	22.5995998382568
15.5897615477443	3.97340726852417	18.7119998931885	0.254893004894257	22.7996006011963
15.6735014170408	3.86851072311401	18.8120002746582	0.256956994533539	22.7996006011963
15.756644308567	3.73073506355286	18.9120006561279	0.258549004793167	22.9995994567871
15.839908272028	3.64241003990173	19.011999130249	0.259743005037308	22.9995994567871
15.9227531403303	3.48423767089844	19.1119995117188	0.261180996894836	23.1996002197266
16.0063747316599	3.07705450057983	19.2119998931885	0.262205988168716	23.2994995117188
16.0897560417652	3.99674224853516	19.3120002746582	0.263776987791061	23.2994995117188
16.1731969565153	4.15973520278931	19.4120006561279	0.265168011188507	23.4995002746582
16.2565801292658	3.57877349853516	19.511999130249	0.266826003789902	23.4995002746582
16.3399018347263	3.79937219619751	19.6119995117188	0.267439007759094	23.699499130249
16.4229869842529	4.0986328125	19.7119998931885	0.268471986055374	23.699499130249
16.5067259222269	3.60573410987854	19.8120002746582	0.267931997776031	23.7996997833252
16.5898688137531	3.86264038085938	19.9120006561279	0.270318001508713	23.9995002746582
16.6732519865036	3.14170503616333	20.011999130249	0.272522002458572	23.9995002746582
16.7567525058985	4.4157452583313	20.1119995117188	0.274376004934311	24.1993999481201
16.8396588414907	3.93050909042358	20.2119998931885	0.275420993566513	24.1993999481201
16.9231593608856	3.80332350730896	20.3120002746582	0.276892989873886	24.3994998931885
17.006304115057	4.00926113128662	20.4120006561279	0.278378009796143	24.5000991821289
17.0896854251623	3.58008432388306	20.511999130249	0.279567003250122	24.5000991821289
17.173245549202	3.67263054847717	20.6119995117188	0.281551003456116	24.699499130249
17.2561518847942	4.36326169967651	20.7119998931885	0.282508999109268	24.699499130249
17.3397120088339	4.1623682975769	20.8120002746582	0.283807992935181	24.8994998931885
17.4231547862291	4.15735912322998	20.9120006561279	0.284541994333267	24.8994998931885
17.5063572824001	3.98828029632568	21.011999130249	0.285697996616364	25.0995006561279
17.5899770110846	4.02403259277344	21.1119995117188	0.287957012653351	25.199499130249
17.6730025559664	4.48380136489868	21.2119998931885	0.289063990116119	25.199499130249
17.7563242614269	4.26156568527222	21.3120002746582	0.290888994932175	25.3994998931885
17.8395286202431	4.41613626480103	21.4120006561279	0.292439997196198	25.3994998931885
17.9233867675066	4.46852684020996	21.511999130249	0.292355000972748	25.5995006561279
18.0066488683224	4.27924299240112	21.6119995117188	0.294142991304398	25.699499130249
18.0899128317833	4.37978744506836	21.7119998931885	0.296140998601913	25.699499130249
18.1734729558229	3.92767310142517	21.8120002746582	0.297573000192642	25.8994998931885
18.2562600821257	4.90321683883667	21.9120006561279	0.299481004476547	25.8994998931885
18.3397009968758	4.25452852249146	22.011999130249	0.300642997026443	26.0995006561279
18.4230245649815	3.84283947944641	22.1119995117188	0.30077999830246	26.0995006561279
18.5061674565077	4.35971832275391	22.2119998931885	0.302388995885849	26.2994995117188
18.5900256037712	4.77399492263794	22.3120002746582	0.304403007030487	26.2994995117188
18.673051148653	4.14252138137817	22.4120006561279	0.306304007768631	26.3994998931885
18.7565516680479	3.8757746219635	22.511999130249	0.307386994361877	26.5995006561279
18.8398752361536	4.06151247024536	22.6119995117188	0.308530986309052	26.5995006561279
18.9230777323246	4.49969863891602	22.7119998931885	0.308562010526657	26.7994995117188
19.0065782517195	4.19156169891357	22.8120002746582	0.310683012008667	26.7994995117188
19.0897826105356	3.79199910163879	22.9120006561279	0.312510997056961	26.8994007110596
19.1731043159962	4.07632446289063	23.011999130249	0.314045995473862	27.0993995666504
19.2564874887466	4.63439226150513	23.1119995117188	0.315438985824585	27.0993995666504
19.3397495895624	4.24058437347412	23.2119998931885	0.317142009735107	27.2994003295898
19.4235481321812	5.04286861419678	23.3120002746582	0.318516999483109	27.2994003295898
19.5063948631287	5.63374280929565	23.4120006561279	0.319328010082245	27.4995002746582
19.5900145918131	4.41629695892334	23.511999130249	0.320643991231918	27.5993995666504
19.6731593459845	4.78070974349976	23.6119995117188	0.322299003601074	27.5993995666504
19.7564214468002	4.72359895706177	23.7119998931885	0.323599010705948	27.7994003295898
19.8395662009716	5.01076745986938	23.8120002746582	0.325029999017715	27.7994003295898
19.9231263250113	4.46019220352173	23.9120006561279	0.325980007648468	27.9993991851807
20.0064480304718	4.32912683486938	24.011999130249	0.327089011669159	27.9993991851807
20.0897715985775	4.8612813949585	24.1119995117188	0.328790009021759	28.1993999481201
20.1733317226171	5.14251136779785	24.2119998931885	0.329836010932922	28.1993999481201
20.2567745000124	4.84885883331299	24.3120002746582	0.331037998199463	28.2994995117188
20.3392021358013	5.5136570930481	24.4120006561279	0.332540988922119	28.4993991851807
20.4231794923544	5.12861919403076	24.511999130249	0.333761990070343	28.4993991851807
20.5063838511705	4.65204906463623	24.6119995117188	0.335283011198044	28.6993999481201
20.5894075334072	5.08024215698242	24.7119998931885	0.336611986160278	28.6993999481201
20.6732079386711	3.76699447631836	24.8120002746582	0.33797699213028	28.8994007110596
20.7562316209078	5.37977743148804	24.9120006561279	0.33890900015831	28.9993991851807
20.8397340029478	4.62827491760254	25.011999130249	0.339718014001846	28.9993991851807
20.9231153130531	4.48967361450195	25.1119995117188	0.340770989656448	29.1993999481201
21.0065562278032	4.46044588088989	25.2119998931885	0.342972010374069	29.1993999481201
21.0898797959089	4.73319339752197	25.3120002746582	0.343971997499466	29.3994007110596
21.1730226874352	5.70088052749634	25.4120006561279	0.346412003040314	29.3994007110596
21.2565250694752	4.65676736831665	25.511999130249	0.346403002738953	29.4993991851807
21.3398467749357	5.2467942237854	25.6119995117188	0.348832011222839	29.699800491333
21.423228085041	4.91325521469116	25.7119998931885	0.349406003952026	29.699800491333
21.5068496763706	5.29145908355713	25.8120002746582	0.350912988185883	29.8994007110596
21.5897541493177	5.34994220733643	25.9120006561279	0.352351009845734	29.8994007110596
21.6730181127787	5.56164360046387	26.011999130249	0.354633986949921	30.0993995666504
21.7561013996601	5.05735778808594	26.1119995117188	0.355634987354279	30.1993007659912
21.8398403376341	5.06791877746582	26.2119998931885	0.357279002666473	30.1993007659912
21.9232235103846	5.21558952331543	26.3120002746582	0.358996987342834	30.3994007110596
22.0064856112003	5.33988332748413	26.4120006561279	0.359917014837265	30.3994007110596
22.0899283885956	4.72616910934448	26.511999130249	0.362044990062714	30.5993995666504
22.173011675477	5.30339050292969	26.6119995117188	0.362919986248016	30.5993995666504
22.2563352435827	5.01654720306396	26.7119998931885	0.364032000303268	30.7994003295898
22.3396569490433	5.49522542953491	26.8120002746582	0.364419996738434	30.8994007110596
22.422919049859	4.85543632507324	26.9120006561279	0.366232991218567	30.8994007110596
22.5066002458334	4.64765930175781	27.011999130249	0.367841988801956	31.0995006561279
22.5896835327148	5.08398771286011	27.1119995117188	0.369688987731934	31.0995006561279
22.6732455193996	5.33622932434082	27.2119998931885	0.37091800570488	31.2994003295898
22.7565076202154	4.95522689819336	27.3120002746582	0.372523993253708	31.3994007110596
22.8396505117416	5.74599981307983	27.4120006561279	0.376513987779617	31.3994007110596
22.9231528937817	5.7970666885376	27.511999130249	0.376911997795105	31.5993995666504
23.0065938085318	5.66801929473877	27.6119995117188	0.377627998590469	31.5993995666504
23.090036585927	6.0251293182373	27.7119998931885	0.377925008535385	31.7994003295898
23.1733582913876	5.89782238006592	27.8120002746582	0.37992000579834	31.7994003295898
23.2566799968481	5.01201772689819	27.9120006561279	0.380928009748459	31.9993991851807
23.3401823788881	5.27725601196289	28.011999130249	0.382348001003265	32.0993995666504
23.4229080379009	6.45017051696777	28.1119995117188	0.383929014205933	32.0993995666504
23.5064700245857	4.89567899703979	28.2119998931885	0.384566992521286	32.2993011474609
23.5897917300463	5.50969791412354	28.3120002746582	0.386087000370026	32.2993011474609
23.673115298152	4.89834213256836	28.4120006561279	0.387497991323471	32.4994010925293
23.7564966082573	6.50633573532104	28.511999130249	0.388431012630463	32.4994010925293
23.8399971276522	5.47960233688354	28.6119995117188	0.390222012996674	32.5993003845215
23.9230822771788	5.54312324523926	28.7119998931885	0.391434997320175	32.7994003295898
24.0063443779945	5.49714279174805	28.8120002746582	0.393436014652252	32.7994003295898
24.0897871553898	5.53204822540283	28.9120006561279	0.394300013780594	32.9992980957031
24.1732876747847	4.98539400100708	29.011999130249	0.395177006721497	32.9992980957031
24.2559555917978	5.29300975799561	29.1119995117188	0.398941993713379	33.1992988586426
24.3400521576405	5.31873893737793	29.2119998931885	0.399673014879227	33.1992988586426
24.4229566305876	5.33737945556641	29.3120002746582	0.400438994169235	33.2993011474609
24.5063994079828	5.14167594909668	29.4120006561279	0.401805013418198	33.4992980957031
24.5901979506016	5.30837345123291	29.511999130249	0.402637004852295	33.4992980957031
24.673281237483	5.65958690643311	29.6119995117188	0.404819995164871	33.6992988586426
24.7565452009439	5.34313440322876	29.7119998931885	0.404938012361526	33.6992988586426
24.8399265110493	5.45446252822876	29.8120002746582	0.41057500243187	33.899299621582
24.9231904745102	5.56492519378662	29.9120006561279	0.410106986761093	33.9992980957031
25.0063929706812	5.62430191040039	30.011999130249	0.410715013742447	33.9992980957031
25.0895973294973	5.88278913497925	30.1119995117188	0.410941004753113	34.1992988586426
25.1729786396027	5.40781545639038	30.2119998931885	0.412252008914948	34.1992988586426
25.2564791589975	5.36196708679199	30.3120002746582	0.413868010044098	34.399299621582
25.3399219363928	5.63511180877686	30.4120006561279	0.414766013622284	34.399299621582
25.423601269722	5.97721862792969	30.511999130249	0.416803002357483	34.5993003845215
25.5065076053143	5.59083604812622	30.6119995117188	0.417443007230759	34.6992988586426
25.58976970613	5.74019622802734	30.7119998931885	0.418954998254776	34.6992988586426
25.6726164370775	5.5307936668396	30.8120002746582	0.420401990413666	34.899299621582
25.7562361657619	6.17140197753906	30.9120006561279	0.422361999750137	34.899299621582
25.8397366851568	5.74693441390991	31.011999130249	0.423299014568329	35.0993003845215
25.9230602532625	6.09985542297363	31.1119995117188	0.424452990293503	35.0993003845215
26.0067991912365	5.86234951019287	31.2119998931885	0.426270008087158	35.1991996765137
26.0897651314735	5.62986850738525	31.3120002746582	0.427376002073288	35.3992004394531
26.1731464415789	5.91142272949219	31.4120006561279	0.427924007177353	35.3992004394531
26.2564681470394	5.7095251083374	31.511999130249	0.430462002754211	35.5992012023926
26.3397321105003	5.4219446182251	31.6119995117188	0.431757986545563	35.5992012023926
26.4231730252504	5.69083166122437	31.7119998931885	0.432130992412567	35.7993011474609
26.506258174777	6.1767201423645	31.8120002746582	0.433268994092941	35.8992004394531
26.5900567173958	6.40975522994995	31.9120006561279	0.4341099858284	35.8992004394531
26.6732592135668	5.76667451858521	32.0120010375977	0.434958010911942	36.0992012023926
26.7563443630934	6.56458759307861	32.1119995117188	0.436753988265991	36.0992012023926
26.839904487133	6.19249153137207	32.2120018005371	0.438713997602463	36.2991981506348
26.9232876598835	6.09489822387695	32.3120002746582	0.439422994852066	36.2991981506348
27.0064901560545	5.88994932174683	32.4119987487793	0.441105008125305	36.4991989135742
27.0899310708046	6.46314811706543	32.5120010375977	0.441592007875443	36.5992012023926
27.1730162203312	6.27278089523315	32.6119995117188	0.447019010782242	36.5992012023926
27.2565167397261	6.27878427505493	32.7120018005371	0.448520004749298	36.7991981506348
27.3396614938974	6.43654108047485	32.8120002746582	0.450020998716354	36.7991981506348
27.4232812225819	6.334557056427	32.9119987487793	0.451535999774933	36.9991989135742
27.5063067674637	6.16559457778931	33.0120010375977	0.452221989631653	36.9991989135742
27.5898072868586	6.11730289459229	33.1119995117188	0.453056991100311	37.0992012023926
27.6732482016087	6.93126440048218	33.2120018005371	0.454946011304855	37.2991981506348
27.7566909790039	6.44181394577026	33.3120002746582	0.456063002347946	37.2991981506348
27.8397146612406	6.19002342224121	33.4119987487793	0.457902014255524	37.4991989135742
27.9228594154119	6.32711553573608	33.5120010375977	0.459858000278473	37.4991989135742
28.006300330162	6.96222734451294	33.6119995117188	0.461165010929108	37.6991996765137
28.0898604542017	6.28754568099976	33.7120018005371	0.461825996637344	37.6991996765137
28.1728263944387	6.42041969299316	33.8120002746582	0.462267994880676	37.7991981506348
28.2568633556366	7.01338529586792	33.9119987487793	0.465057998895645	37.9991989135742
28.3399485051632	6.92121505737305	34.0120010375977	0.465041011571884	37.9991989135742
28.4232702106237	5.79142761230469	34.1119995117188	0.468293994665146	38.1991996765137
28.5066515207291	6.29957151412964	34.2120018005371	0.468042999505997	38.1991996765137
28.58991548419	7.03922653198242	34.3120002746582	0.471105009317398	38.3992004394531
28.6727603524923	6.85665035247803	34.4119987487793	0.471688985824585	38.4991989135742
28.7562627345324	7.19128608703613	34.5120010375977	0.47290500998497	38.4991989135742
28.8397632539272	6.85501575469971	34.6119995117188	0.472772985696793	38.6991996765137
28.9229080080986	6.79624223709106	34.7120018005371	0.475685000419617	38.6991996765137
29.0061105042696	6.94073295593262	34.8120002746582	0.475546002388	38.8992004394531
29.0899686515331	7.15240812301636	34.9119987487793	0.478632986545563	38.9991989135742
29.1731730103493	7.00340747833252	35.0120010375977	0.478563010692596	38.9991989135742
29.2563755065203	6.55066776275635	35.1119995117188	0.480388998985291	39.1991004943848
29.340174049139	6.32438516616821	35.2120018005371	0.482048988342285	39.1991004943848
29.4231399893761	6.94614696502686	35.3120002746582	0.482959985733032	39.3992004394531
29.5062847435474	6.64873886108398	35.4119987487793	0.485157012939453	39.3992004394531
29.5894872397184	7.18551635742188	35.5120010375977	0.486223012208939	39.5992012023926
29.6731665730476	7.04051876068115	35.6119995117188	0.487603008747101	39.6991996765137
29.7566093504429	7.15950155258179	35.7120018005371	0.487973988056183	39.6991996765137
29.840050265193	6.8744068145752	35.8120002746582	0.489455997943878	39.8992004394531
29.9235507845879	7.04104566574097	35.9119987487793	0.490584999322891	39.8992004394531
30.0064571201801	6.94712829589844	36.0120010375977	0.492085009813309	40.0990982055664
30.0897788256407	6.40348625183105	36.1119995117188	0.493604987859726	40.0990982055664
30.1729831844568	7.29491472244263	36.2120018005371	0.49523800611496	40.2991981506348
30.2563048899174	6.3279275894165	36.3120002746582	0.4966059923172	40.2991981506348
30.3397476673126	7.15250301361084	36.4119987487793	0.498127013444901	40.3992004394531
30.4228905588388	7.35860729217529	36.5120010375977	0.498582988977432	40.4991989135742
30.5066891014576	7.09720182418823	36.6119995117188	0.498582988977432	40.5992012023926
30.5898934602737	6.47255420684814	36.7120018005371	0.501106977462769	40.7990989685059
30.6729767471552	6.41572904586792	36.8120002746582	0.502682983875275	40.7990989685059
30.75653873384	7.18638563156128	36.9119987487793	0.504109025001526	40.8992004394531
30.8398604393005	7.09559440612793	37.0120010375977	0.505418002605438	40.9991989135742
30.9229455888271	6.79866695404053	37.1119995117188	0.50559002161026	41.0993003845215
31.006446108222	7.348464012146	37.2120018005371	0.507845997810364	41.2991981506348
31.0898870229721	6.74256086349487	37.3120002746582	0.508610010147095	41.2991981506348
31.1732105910778	7.38785552978516	37.4119987487793	0.511653006076813	41.4990997314453
31.2562957406044	6.9464316368103	37.5120010375977	0.51171600818634	41.5990982055664
31.3400328159332	6.99062347412109	37.6119995117188	0.512396991252899	41.5990982055664
31.4231775701046	7.36623811721802	37.7120018005371	0.514632999897003	41.7991981506348
31.5066203474998	7.01983642578125	37.8120002746582	0.514730989933014	41.7991981506348
31.58999979496	7.95461845397949	37.9119987487793	0.51765501499176	41.9995002746582
31.673502177	6.76280069351196	38.0120010375977	0.517614006996155	41.9995002746582
31.7565277218819	7.54695081710815	38.1119995117188	0.525569975376129	42.0990982055664
31.8396128714085	7.57274103164673	38.2120018005371	0.522529006004333	42.2990989685059
31.9231115281582	7.6946587562561	38.3120002746582	0.5276740193367	42.2990989685059
32.0064350962639	7.10053586959839	38.4119987487793	0.533612012863159	42.4990997314453
32.0894606411457	7.59150362014771	38.5120010375977	0.538505971431732	42.4990997314453
32.1736745536327	7.11244106292725	38.6119995117188	0.538318991661072	42.6991004943848
32.256580889225	8.03783416748047	38.7120018005371	0.539196014404297	42.7990989685059
32.3399640619755	7.79429340362549	38.8120002746582	0.540045022964478	42.7990989685059
32.4231646955013	8.19097518920898	38.9119987487793	0.54154497385025	42.9990997314453
32.5064286589622	7.4080638885498	39.0120010375977	0.542944014072418	42.9990997314453
32.5895734131336	7.22389316558838	39.1119995117188	0.545338988304138	43.2064018249512
32.6731950044632	7.81690502166748	39.2120018005371	0.545680999755859	43.2064018249512
32.7564552426338	8.05786991119385	39.3120002746582	0.546854972839355	43.3991012573242
32.8397192060947	7.07900619506836	39.4119987487793	0.54638797044754	43.4990997314453
32.9230427742004	7.64425945281982	39.5120010375977	0.549244999885559	43.4990997314453
33.0069586634636	7.88486576080322	39.6119995117188	0.550675988197327	43.6991004943848
33.0897457897663	7.7739725112915	39.7120018005371	0.550598978996277	43.6991004943848
33.1731885671616	7.98694610595703	39.8120002746582	0.553453028202057	43.8991012573242
33.2569256424904	7.29027843475342	39.9119987487793	0.560196995735168	43.8991012573242
33.3398915827274	7.69835758209229	40.0120010375977	0.608071029186249	43.9999008178711
33.4233343601227	7.64637279510498	40.1119995117188	0.595260977745056	44.0990982055664
33.5064195096493	8.70230293273926	40.2120018005371	0.543043971061707	44.1990013122559
33.5895605385303	7.90787601470947	40.3120002746582	0.537729024887085	44.2990989685059
33.6731225252151	8.35846519470215	40.4119987487793	0.537729024887085	44.3991012573242
33.7566249072552	8.34412002563477	40.5120010375977	0.556511998176575	44.5989990234375
33.8399447500706	7.82034492492676	40.6119995117188	0.554391980171204	44.5989990234375
33.9228510856628	8.24517059326172	40.7120018005371	0.555830001831055	44.6990013122559
34.0061746537685	8.39968109130859	40.8120002746582	0.555830001831055	44.798999786377
34.0893194079399	8.63152503967285	40.9119987487793	0.573062002658844	44.898998260498
34.1728180646896	8.28156852722168	41.0120010375977	0.570015013217926	45.0989990234375
34.2563800513744	8.1760311126709	41.1119995117188	0.565596997737885	45.0989990234375
34.3392863869667	8.76868343353271	41.2120018005371	0.551477015018463	45.1990013122559
34.4232022762299	8.21449375152588	41.3120002746582	0.549861013889313	45.298999786377
34.5066450536251	8.50460529327393	41.4119987487793	0.555007994174957	45.398998260498
34.589909017086	9.02769756317139	41.5120010375977	0.564172983169556	45.4990005493164
34.6732325851917	8.77867984771729	41.6119995117188	0.52894800901413	45.5990982055664
34.7564332187176	8.92932224273682	41.7120018005371	0.529466986656189	45.6990013122559
34.8397567868233	8.35644054412842	41.8120002746582	0.529466986656189	45.7990989685059
34.9229611456394	8.50367164611816	41.9119987487793	0.559843003749847	45.898998260498
35.0065194070339	8.56789302825928	42.0120010375977	0.559843003749847	45.9990005493164
35.0898429751396	8.1356201171875	42.1119995117188	0.560989022254944	46.0989990234375
35.1728685200214	8.40485572814941	42.2120018005371	0.579033970832825	46.2991981506348
35.2569036185741	8.76969528198242	42.3120002746582	0.552662014961243	46.2991981506348
35.3398099541664	8.83753967285156	42.4119987487793	0.552662014961243	46.2991981506348
35.4229547083378	8.5018138885498	42.5120010375977	0.57746297121048	46.4990005493164
35.506397485733	9.14788055419922	42.6119995117188	0.564081013202667	46.5989990234375
35.5897173285484	8.84963512420654	42.7120018005371	0.553617000579834	46.6991004943848
35.6729216873646	8.78771781921387	42.8120002746582	0.565567970275879	46.798999786377
35.7563644647598	8.68629455566406	42.9119987487793	0.570275008678436	46.898998260498
35.83974391222	8.60272979736328	43.0120010375977	0.570275008678436	46.9990997314453
35.9231270849705	8.75961494445801	43.1119995117188	0.568112015724182	47.0989990234375
36.0063910484314	8.1346435546875	43.2120018005371	0.572547018527985	47.298999786377
36.0903069376945	8.70028972625732	43.3120002746582	0.573198020458221	47.298999786377
36.1727960407734	8.98528671264648	43.4119987487793	0.582497000694275	47.398998260498
36.2565964460373	8.64981460571289	43.5120010375977	0.578004002571106	47.4990005493164
36.3398604094982	9.20581722259521	43.6119995117188	0.579649984836578	47.6990013122559
36.4230014383793	8.81460857391357	43.7120018005371	0.58576101064682	47.798999786377
36.5065634250641	9.11439323425293	43.8120002746582	0.58380401134491	47.798999786377
36.5900658071041	8.99076366424561	43.9119987487793	0.579042017459869	47.9989013671875
36.67326644063	8.77848720550537	44.0120010375977	0.582116007804871	47.9989013671875
36.75676882267	8.59359073638916	44.1119995117188	0.583489000797272	48.1988983154297
36.8398539721966	8.93384838104248	44.2120018005371	0.583288013935089	48.1988983154297
36.9235351681709	8.33018493652344	44.3120002746582	0.584882020950317	48.298999786377
37.0064377784729	8.71525192260742	44.4119987487793	0.588463008403778	48.398998260498
37.0897613465786	8.74290561676025	44.5120010375977	0.59026300907135	48.4990997314453
37.1731445193291	8.82095241546631	44.6119995117188	0.592691004276276	48.6990013122559
37.2564047574997	9.35111904144287	44.7120018005371	0.596325993537903	48.6990013122559
37.3397879302502	9.2825813293457	44.8120002746582	0.599539995193481	48.898998260498
37.4230518937111	9.97235679626465	44.9119987487793	0.596000015735626	48.898998260498
37.5063754618168	8.98786354064941	45.0120010375977	0.595664024353027	48.9990005493164
37.5896953046322	9.43066787719727	45.1119995117188	0.602433979511261	49.1990013122559
37.6733168959618	9.79753494262695	45.2120018005371	0.598043978214264	49.1990013122559
37.7567000687122	8.78460597991943	45.3120002746582	0.600323021411896	49.398998260498
37.8397218883038	9.60600662231445	45.4119987487793	0.607127010822296	49.398998260498
37.923164665699	9.85255336761475	45.5120010375977	0.612698972225189	49.5989990234375
38.006667047739	8.93295097351074	45.6119995117188	0.612004995346069	49.6988983154297
38.0898080766201	8.498122215271	45.7120018005371	0.610092997550964	49.6988983154297
38.1731912493706	9.64284133911133	45.8120002746582	0.613261997699738	49.8988990783691
38.2562763988972	8.81317520141602	45.9119987487793	0.616774022579193	49.8988990783691
38.3399575948715	9.30870532989502	46.0120010375977	0.615604996681213	50.0988998413086
38.4232774376869	9.29184818267822	46.1119995117188	0.616779029369354	50.0988998413086
38.5065414011478	9.21364593505859	46.2120018005371	0.618116021156311	50.1988983154297
38.5902225971222	9.95743560791016	46.3120002746582	0.621003985404968	50.3988990783691
38.6731252074242	9.59182167053223	46.4119987487793	0.619431972503662	50.3988990783691
38.756687194109	9.66380214691162	46.5120010375977	0.622515976428986	50.5988998413086
38.8397127389908	9.65944576263428	46.6119995117188	0.623847007751465	50.5988998413086
38.9230363070965	8.59953689575195	46.7120018005371	0.621962010860443	50.798900604248
39.0065349638462	8.51039028167725	46.8120002746582	0.62193900346756	50.798900604248
39.0898585319519	9.28171253204346	46.9119987487793	0.626938998699188	50.8988990783691
39.1734801232815	9.7355318069458	47.0120010375977	0.626739025115967	51.0988998413086
39.2563827335835	10.1206951141357	47.1119995117188	0.626923024654388	51.0988998413086
39.3396466970444	9.24382877349854	47.2120018005371	0.630003988742828	51.298900604248
39.4232086837292	9.73174095153809	47.3120002746582	0.631437003612518	51.298900604248
39.5065285265446	9.48775863647461	47.4119987487793	0.631094992160797	51.4992980957031
39.5896136760712	8.86095905303955	47.5120010375977	0.631940007209778	51.5988998413086
39.673175662756	8.92356586456299	47.6119995117188	0.634581029415131	51.5988998413086
39.756678044796	9.29918384552002	47.7120018005371	0.635213017463684	51.798900604248
39.8399382829666	9.53441524505615	47.8120002746582	0.637389004230499	51.798900604248
39.923083037138	10.3332786560059	47.9119987487793	0.638568997383118	51.9989013671875
40.0067642331123	10.2878265380859	48.0120010375977	0.639155983924866	51.9989013671875
40.0896668434143	9.68737411499023	48.1119995117188	0.639823973178864	52.0988998413086
40.1733480393887	10.0293464660645	48.2120018005371	0.642059028148651	52.298900604248
40.2567312121391	9.69074440002441	48.3120002746582	0.642441987991333	52.298900604248
40.3398759663105	9.62672519683838	48.4119987487793	0.643353998661041	52.4989013671875
40.4233746230602	9.58526611328125	48.5120010375977	0.645811975002289	52.4989013671875
40.5066981911659	9.58698177337646	48.6119995117188	0.64664900302887	52.5988998413086
40.5897237360477	10.4156465530396	48.7120018005371	0.646697998046875	52.798900604248
40.6730435788631	10.4733543395996	48.8120002746582	0.646538019180298	52.798900604248
40.756069123745	10.1314277648926	48.9119987487793	0.646937012672424	52.9989013671875
40.8398099243641	10.2817277908325	49.0120010375977	0.649668991565704	52.9989013671875
40.9228354692459	9.70677471160889	49.1119995117188	0.65031498670578	53.1988983154297
41.0063937306404	10.0182647705078	49.2120018005371	0.652728021144867	53.298900604248
41.0896576941013	10.7840614318848	49.3120002746582	0.652728021144867	53.298900604248
41.172981262207	10.5222272872925	49.4119987487793	0.652889013290405	53.4989013671875
41.256420314312	9.94780540466309	49.5120010375977	0.654262006282806	53.4989013671875
41.3398034870625	9.91168975830078	49.6119995117188	0.654335021972656	53.6988983154297
41.4231270551682	10.5670795440674	49.7120018005371	0.657115995883942	53.6988983154297
41.5063872933388	9.74032115936279	49.8120002746582	0.657149970531464	53.8987998962402
41.5898896753788	10.0845546722412	49.9119987487793	0.658681988716125	53.9987983703613
41.6735112667084	10.2375946044922	50.0120010375977	0.658603012561798	53.9987983703613
41.7564772069454	11.0546894073486	50.1119995117188	0.660115003585815	54.1987991333008
41.8397970497608	10.5681524276733	50.2120018005371	0.661297976970673	54.1987991333008
41.9231802225113	10.1042585372925	50.3120002746582	0.662153005599976	54.3988990783691
42.0065633952618	10.2288599014282	50.4119987487793	0.663037002086639	54.3988990783691
42.0898236334324	10.0720748901367	50.5120010375977	0.664613008499146	54.4989013671875
42.1727895736694	10.0826568603516	50.6119995117188	0.664524972438812	54.6988983154297
42.2562919557095	10.5280122756958	50.7120018005371	0.664727985858917	54.6988983154297
42.3396155238152	10.7993612289429	50.8120002746582	0.667611002922058	54.8988990783691
42.4230545759201	10.946475982666	50.9119987487793	0.667824983596802	54.8988990783691
42.5066761672497	10.4586477279663	51.0120010375977	0.669076025485992	55.0988998413086
42.5896421074867	10.1918392181396	51.1119995117188	0.671653985977173	55.1988983154297
42.6731407642365	10.6081695556641	51.2120018005371	0.671653985977173	55.1988983154297
42.7561663091183	10.4020471572876	51.3120002746582	0.672254979610443	55.3988990783691
42.8395494818687	10.6653633117676	51.4119987487793	0.673666000366211	55.3988990783691
42.9229885339737	10.6580648422241	51.5120010375977	0.674026012420654	55.5988006591797
43.0063121020794	10.1546964645386	51.6119995117188	0.675080001354218	55.5988006591797
43.0899932980537	10.3161687850952	51.7120018005371	0.676173985004425	55.6988983154297
43.1733168661594	10.6287755966187	51.8120002746582	0.677932024002075	55.8988990783691
43.2564578950405	10.3846387863159	51.9119987487793	0.67817097902298	55.8988990783691
43.3396622538567	10.6392908096313	52.0120010375977	0.678303003311157	56.0988006591797
43.4232838451862	10.6511173248291	52.1119995117188	0.679480016231537	56.0988006591797
43.5063652694225	10.6444301605225	52.2120018005371	0.679838001728058	56.2988014221191
43.5896888375282	10.4730424880981	52.3120002746582	0.681397974491119	56.3987998962402
43.673250824213	11.2874794006348	52.4119987487793	0.681397974491119	56.3987998962402
43.756514787674	11.2129688262939	52.5120010375977	0.684174001216888	56.5988006591797
43.839655816555	11.0707883834839	52.6119995117188	0.685213983058929	56.5988006591797
43.9233966171741	11.3005838394165	52.7120018005371	0.685603022575378	56.798900604248
44.006422162056	10.985255241394	52.8120002746582	0.687372028827667	56.798900604248
44.0899208188057	11.6647987365723	52.9119987487793	0.689019978046417	56.8987007141113
44.1734232008457	10.9884214401245	53.0120010375977	0.688893020153046	57.0988006591797
44.2566275596619	11.6435117721558	53.1119995117188	0.690222024917603	57.0988006591797
44.3398281931877	11.0436658859253	53.2120018005371	0.691285014152527	57.2988014221191
44.4230325520039	11.0794878005981	53.3120002746582	0.69166499376297	57.2988014221191
44.50623691082	11.2353830337524	53.4119987487793	0.693161010742188	57.4990997314453
44.5896796882153	11.5921783447266	53.5120010375977	0.693331003189087	57.4990997314453
44.6728207170963	10.9945096969604	53.6119995117188	0.694535970687866	57.5988006591797
44.756680727005	11.3420238494873	53.7120018005371	0.696012020111084	57.7988014221191
44.8401235044003	11.0879173278809	53.8120002746582	0.696087002754211	57.7988014221191
44.9236817657948	11.2041521072388	53.9119987487793	0.697597026824951	57.9987983703613
45.0066477060318	11.0302972793579	54.0120010375977	0.696223020553589	57.9987983703613
45.0897328555584	11.4219446182251	54.1119995117188	0.697602987289429	58.1990013122559
45.1730564236641	11.0311574935913	54.2120018005371	0.700725972652435	58.2988014221191
45.2563762664795	12.0700025558472	54.3120002746582	0.700725972652435	58.2988014221191
45.3396402299404	11.1618185043335	54.4119987487793	0.702225029468536	58.4987983703613
45.42326182127	11.2236270904541	54.5120010375977	0.702529013156891	58.4987983703613
45.460544526577	0.537597894668579	54.556999206543	0.702529013156891	58.5988006591797