File: CSVs/24-01-08_Tensile_paper-PDMS/Oven_Coated_1/asdf.txt
File Path: C:\Users\apk5101\Desktop\Sandra\Oven_Coated_1 01-8-24 11 12 58 AM\DAQ- Crosshead, … - (Timed).txt
Test: MTS EM Tension (Simplified) with Video Extensometer apk5101 25
Test Run: Oven_Coated_1
Date: 1/8/2024 11:02:21 AM


Crosshead 	Load 	Time 	Strain 1 	Video Time
mm	N	sec	mm/mm	sec
0	-0.140623539686203	0.112000003457069	-0.000129919993923977	4.09989976882935
0.00136984783694061	0.0467980727553368	0.412000000476837	-0.000154986002598889	4.39989995956421
0.00440733629147871	0.241117671132088	0.712000012397766	8.56378974276595E-05	4.69990015029907
0.00762350100558251	0.455715984106064	1.01199996471405	-7.51675979699939E-05	4.99989986419678
0.0103631964520901	0.737412929534912	1.31200003623962	1.40209003802738E-05	5.29990005493164
0.0132220093291835	0.935592114925385	1.61199998855591	0.00016675099323038	5.59989976882935
0.0157830290845595	1.08309209346771	1.91199994087219	0.00151695997919887	5.89989995956421
0.0182249314093497	1.32809793949127	2.21199989318848	9.46772997849621E-05	6.19990015029907
0.0210241869353922	1.5274566411972	2.51200008392334	0.000166640005772933	6.49989986419678
0.0235852057812735	1.67582547664642	2.81200003623962	0.000127852996229194	6.79990005493164
0.0257888750638813	1.87590909004211	3.11199998855591	9.58489035838284E-05	7.09999990463257
0.0283498939097626	2.06936597824097	3.41199994087219	4.18556992372032E-05	7.39989995956421
0.031268264137907	2.24452996253967	3.71199989318848	0.00107849994674325	7.69990015029907
0.0334123760694638	2.46128273010254	4.01200008392334	0.000654292991384864	8.0999002456665
0.0357351600541733	2.63957333564758	4.31199979782104	0.000672878988552839	8.29990005493164
0.0385344137612265	2.79020285606384	4.61199998855591	0.00100547005422413	8.5999002456665
0.0409167587349657	3.00226140022278	4.91200017929077	0.000885871006175876	8.89990043640137
0.0432991037087049	3.19031763076782	5.21199989318848	0.00072957098018378	9.19979953765869
0.0457410060334951	3.30817937850952	5.51200008392334	0.000801821995992213	9.49989986419678
0.0484211414004676	3.53451299667358	5.81199979782104	0.000799019006080925	9.79979991912842
0.0507439290231559	3.71884107589722	6.11199998855591	0.00120926997624338	10.0998001098633
0.0533645070390776	3.85940837860107	6.41200017929077	0.000890562019776553	10.3999004364014
0.0558659667149186	4.07345342636108	6.71199989318848	0.000900817976798862	10.6997995376587
0.0584269873797894	4.27625942230225	7.01200008392334	0.00105268997140229	10.9997997283936
0.0609880080446601	4.40987110137939	7.31199979782104	0.000993489986285567	11.2997999191284
0.0636085824226029	4.61027240753174	7.61199998855591	0.000909895985387266	11.5998001098633
0.0660504883853719	4.83019399642944	7.91200017929077	0.000941812992095947	11.8998003005981
0.0684328333591111	4.9255542755127	8.21199989318848	0.00100878998637199	12.1997995376587
0.0709342930349521	5.12054920196533	8.51200008392334	0.00206298008561134	12.4997997283936
0.0733761989977211	5.34467935562134	8.8120002746582	0.00234946003183722	12.7997999191284
0.0758180976845324	5.45446872711182	9.11200046539307	0.00231776991859078	13.0998001098633
0.0786173550295644	5.67537355422974	9.41199970245361	0.00214018998667598	13.3998003005981
0.0811188147054054	5.89210414886475	9.71199989318848	0.00230427994392812	13.6997995376587
0.0833820449770428	5.97786664962769	10.0120000839233	0.00218156003393233	13.9997997283936
0.0859430583659559	6.15915441513062	10.3120002746582	0.00215196004137397	14.2996997833252
0.0885040790308267	6.39691495895386	10.6120004653931	0.00217396998777986	14.5996999740601
0.0908864240045659	6.50139999389648	10.9119997024536	0.00223447009921074	14.8998003005981
0.0936856813495979	6.67810106277466	11.2119998931885	0.00205711997114122	15.1997003555298
0.0960084653343074	6.91639757156372	11.5120000839233	0.00224775006063282	15.4996004104614
0.0983908103080466	7.02092742919922	11.8120002746582	0.00225543999113142	15.7996997833252
0.100951830972917	7.16514301300049	12.1120004653931	0.00199812999926507	16.1996994018555
0.10357240535086	7.41764783859253	12.4119997024536	0.00220165005885065	16.3997001647949
0.106073865026701	7.53563165664673	12.7119998931885	0.00228697992861271	16.6996994018555
0.108396656287368	7.64839744567871	13.0120000839233	0.00206888001412153	16.9997005462646
0.110957676952239	7.87699699401855	13.3120002746582	0.0021875100210309	17.2996997833252
0.113578251330182	8.05611133575439	13.6120004653931	0.00218360009603202	17.5997009277344
0.115662805910688	8.13608169555664	13.9119997024536	0.00276081007905304	17.8997001647949
0.11840250226669	8.39153480529785	14.2119998931885	0.00282784993760288	18.1996994018555
0.121023076644633	8.53971385955811	14.5120000839233	0.00224596005864441	18.4997005462646
0.123345860629342	8.64816570281982	14.8120002746582	0.0024772600736469	18.7996997833252
0.125966442283243	8.88483619689941	15.1120004653931	0.00317476992495358	19.0997009277344
0.128706131363288	9.04869937896729	15.4119997024536	0.00223770993761718	19.3999996185303
0.131148044602014	9.13578033447266	15.7119998931885	0.00249369000084698	19.6996002197266
0.133649504277855	9.34999752044678	16.011999130249	0.00252533005550504	20.0076007843018
0.136210524942726	9.52785015106201	16.3120002746582	0.00260668992996216	20.2996006011963
0.138711984618567	9.64347171783447	16.6119995117188	0.00253459997475147	20.5995998382568
0.141034761327319	9.82539463043213	16.9120006561279	0.00255282991565764	20.9020004272461
0.14359578199219	9.99762153625488	17.2119998931885	0.00264613004401326	21.1996002197266
0.14615680265706	10.1067476272583	17.511999130249	0.00253354990854859	21.4995002746582
0.148360471939668	10.2805280685425	17.8120002746582	0.00250410009175539	21.7994995117188
0.150802370626479	10.4468784332275	18.1119995117188	0.00259166001342237	22.0995998382568
0.15348251326941	10.5534543991089	18.4120006561279	0.00242576003074646	22.3997001647949
0.155805304530077	10.7357349395752	18.7119998931885	0.00246533006429672	22.699499130249
0.158187642227858	10.9047365188599	19.011999130249	0.00250904005952179	22.9995994567871
0.160689101903699	11.0073537826538	19.3120002746582	0.0024478801060468	23.2994995117188
0.16319056157954	11.1904430389404	19.6119995117188	0.00245184008963406	23.5995998382568
0.165692021255381	11.3663158416748	19.9120006561279	0.00258297007530928	23.8995990753174
0.168312602909282	11.4601068496704	20.2119998931885	0.00245306990109384	24.2994995117188
0.170814062585123	11.650426864624	20.511999130249	0.00246577011421323	24.4995002746582
0.173434644239023	11.8451499938965	20.8120002746582	0.00252681993879378	24.7994995117188
0.176293455297127	11.9482564926147	21.1119995117188	0.0035226799082011	25.0995006561279
0.178794914972968	12.1190643310547	21.4120006561279	0.00418788008391857	25.4993991851807
0.181177267222665	12.3075971603394	21.7119998931885	0.00386487995274365	25.699499130249
0.183738287887536	12.3947954177856	22.011999130249	0.00380184990353882	25.9995002746582
0.186180186574347	12.5583257675171	22.3120002746582	0.00384358991868794	26.2994995117188
0.188502977835014	12.7459383010864	22.6119995117188	0.00383136002346873	26.5993995666504
0.190825754543766	12.8177347183228	22.9120006561279	0.00377858988940716	26.8994998931885
0.193565458175726	12.9749364852905	23.2119998931885	0.0037496299482882	27.1993999481201
0.196007356862538	13.1534328460693	23.511999130249	0.00396161992102861	27.4993991851807
0.198389694560319	13.2478914260864	23.8120002746582	0.00405362015590072	27.7994003295898
0.20095071522519	13.3881225585938	24.1119995117188	0.00435234000906348	28.0993995666504
0.203333067474887	13.565691947937	24.4120006561279	0.00400855019688606	28.3994007110596
0.205477175768465	13.649829864502	24.7119998931885	0.00416170991957188	28.6993999481201
0.208455108804628	13.8111238479614	25.011999130249	0.00406137993559241	28.9993991851807
0.211016129469499	14.0005645751953	25.3120002746582	0.00422914000228047	29.2994003295898
0.213398467167281	14.1089878082275	25.6119995117188	0.00389304989948869	29.5993995666504
0.215959487832151	14.1947107315063	25.9120006561279	0.00405091978609562	29.8994007110596
0.218639630475082	14.4134483337402	26.2119998931885	0.00406493991613388	30.1993999481201
0.221081529161893	14.5285663604736	26.511999130249	0.00425201002508402	30.4993000030518
0.223523427848704	14.6096315383911	26.8120002746582	0.00405946001410484	30.7992992401123
0.226203570491634	14.8316469192505	27.1119995117188	0.00426601013168693	31.0993003845215
0.228466786211357	14.9378976821899	27.4120006561279	0.00426869001239538	31.3994007110596
0.230908699450083	14.9983911514282	27.7119998931885	0.00472977990284562	31.6993999481201
0.233588827541098	15.2040796279907	28.011999130249	0.00486283004283905	31.9993000030518
0.235911618801765	15.333423614502	28.3120002746582	0.00437180977314711	32.2993011474609
0.238413078477606	15.3866233825684	28.6119995117188	0.00481203012168407	32.5993995666504
0.241152782109566	15.5974540710449	28.9120006561279	0.004731560125947	32.8993988037109
0.243594680796377	15.7470731735229	29.2119998931885	0.00434147007763386	33.1992988586426
0.245977018494159	15.7858924865723	29.511999130249	0.00470054009929299	33.4994010925293
0.248716707574204	15.9735460281372	29.8120002746582	0.00528451008722186	33.7993011474609
0.250741722993553	16.0913124084473	30.1119995117188	0.00581583008170128	34.0993003845215
0.253362290095538	16.161018371582	30.4120006561279	0.00474192993715405	34.399299621582
0.255863764323294	16.3367748260498	30.7119998931885	0.00449306983500719	34.6992988586426
0.258722575381398	16.4791393280029	31.011999130249	0.00529660983011127	34.9992980957031
0.260985776549205	16.5217723846436	31.3120002746582	0.00504956999793649	35.2993011474609
0.263487250776961	16.7054195404053	31.6119995117188	0.00608323002234101	35.5993003845215
0.266107817878947	16.8462619781494	31.9120006561279	0.00619718991219997	35.899299621582
0.268490170128644	16.8923416137695	32.2120018005371	0.00610309978947043	36.1991996765137
0.270753400400281	17.0285949707031	32.5120010375977	0.00600511999800801	36.4991989135742
0.273612211458385	17.2207336425781	32.8120002746582	0.00623875018209219	36.7993011474609
0.275994563708082	17.2736110687256	33.1119995117188	0.00602558022364974	37.0993995666504
0.278079096460715	17.3922863006592	33.4119987487793	0.00604431005194783	37.399299621582
0.280878361081704	17.5594539642334	33.7120018005371	0.00615580985322595	37.6991996765137
0.28349892818369	17.6108169555664	34.0120010375977	0.00605311011895537	37.9992980957031
0.285881280433387	17.7459659576416	34.3120002746582	0.00606960989534855	38.2991981506348
0.288323179120198	17.90869140625	34.6119995117188	0.00610983977094293	38.5992012023926
0.290884199785069	17.9674949645996	34.9119987487793	0.00616909004747868	38.8992004394531
0.293743010843173	18.131893157959	35.2120018005371	0.00608874997124076	39.2991981506348
0.295946694677696	18.2694664001465	35.5120010375977	0.00620881002396345	39.4991989135742
0.29868638375774	18.3476314544678	35.8120002746582	0.00597658986225724	39.7990989685059
0.301187857985497	18.4395885467529	36.1119995117188	0.00590704008936882	40.0992012023926
0.303570181131363	18.5996952056885	36.4119987487793	0.00617888988927007	40.4991989135742
0.306190777337179	18.6724376678467	36.7120018005371	0.00597449019551277	40.6991996765137
0.30863267602399	18.7784614562988	37.0120010375977	0.00596106005832553	40.9990997314453
0.311015028273687	18.9400272369385	37.3120002746582	0.006095290184021	41.2991981506348
0.313456926960498	18.9939098358154	37.6119995117188	0.00610376987606287	41.5990982055664
0.315958372084424	19.0877666473389	37.9119987487793	0.00596588011831045	41.8991012573242
0.318340724334121	19.2508735656738	38.2120018005371	0.00609399983659387	42.1991004943848
0.320961291436106	19.3158836364746	38.5120010375977	0.00602630991488695	42.4990997314453
0.323641434079036	19.4055500030518	38.8120002746582	0.00591769022867084	42.7991981506348
0.325964210787788	19.563117980957	39.1119995117188	0.00611292012035847	43.0990982055664
0.32840613857843	19.6204071044922	39.4119987487793	0.00615489017218351	43.3991012573242
0.331145827658474	19.7173347473145	39.7120018005371	0.00706997979432344	43.6991004943848
0.333349482389167	19.8516902923584	40.0120010375977	0.00737681984901428	43.9990997314453
0.335850956616923	19.9326019287109	40.3120002746582	0.0074321897700429	44.2990989685059
0.338411977281794	20.0008964538574	40.6119995117188	0.00696968007832766	44.5990982055664
0.341032544383779	20.1832981109619	40.9119987487793	0.00737599981948733	44.8991012573242
0.343355321092531	20.2441959381104	41.2120018005371	0.00746737979352474	45.298999786377
0.345856795320287	20.2897758483887	41.5120010375977	0.00712729012593627	45.4990997314453
0.348656059941277	20.467845916748	41.8120002746582	0.0072928499430418	45.798999786377
0.350859714671969	20.5418682098389	42.1119995117188	0.00745947007089853	46.0989990234375
0.353242066921666	20.5724773406982	42.4119987487793	0.00727117015048862	46.4990005493164
0.355922209564596	20.7331581115723	42.7120018005371	0.00737466011196375	46.6990013122559
0.358364108251408	20.8418769836426	43.0120010375977	0.00750999012961984	46.9990005493164
0.360865553375334	20.8633651733398	43.3120002746582	0.00799189973622561	47.298999786377
0.363724364433438	21.0321846008301	43.6119995117188	0.00812426954507828	47.5989990234375
0.366106716683134	21.1561298370361	43.9119987487793	0.0075364401564002	47.898998260498
0.368310400517657	21.1498165130615	44.2120018005371	0.00790075026452541	48.1990013122559
0.371169211575761	21.3214263916016	44.5120010375977	0.00796485971659422	48.4990005493164
0.373670656699687	21.4194774627686	44.8120002746582	0.00880588032305241	48.798999786377
0.376053008949384	21.4320545196533	45.1119995117188	0.00797175988554955	49.0989990234375
0.378494907636195	21.5580368041992	45.4119987487793	0.00796793028712273	49.398998260498
0.381055928301066	21.6901721954346	45.7120018005371	0.00836551003158092	49.6990013122559
0.383497826987877	21.7216033935547	46.0120010375977	0.00804037041962147	49.9990005493164
0.385761057259515	21.7938537597656	46.3120002746582	0.00797292031347752	50.298999786377
0.388441199902445	21.9566383361816	46.6119995117188	0.00813287030905485	50.5989990234375
0.391002220567316	21.9838829040527	46.9119987487793	0.00824647024273872	50.8988990783691
0.393384572817013	22.0578708648682	47.2120018005371	0.00817514024674892	51.1988983154297
0.396005139918998	22.2032451629639	47.5120010375977	0.00816044956445694	51.4989013671875
0.398387492168695	22.2063293457031	47.8120002746582	0.00829898007214069	51.798900604248
0.400829390855506	22.3167037963867	48.1119995117188	0.0080586401745677	52.1988983154297
0.403330835979432	22.4668445587158	48.4119987487793	0.00816494040191174	52.3988990783691
0.406070554163307	22.4962062835693	48.7120018005371	0.00817609019577503	52.6991004943848
0.408393330872059	22.5574569702148	49.0120010375977	0.00824770983308554	52.9989013671875
0.411013897974044	22.7351036071777	49.3120002746582	0.010058400221169	53.3988990783691
0.41363449417986	22.765438079834	49.6119995117188	0.00851976964622736	53.5988006591797
0.415957270888612	22.8127136230469	49.9119987487793	0.00968114007264376	53.8988990783691
0.418577837990597	22.9724025726318	50.2120018005371	0.0103850001469254	54.1988983154297
0.421257980633527	23.0241870880127	50.5120010375977	0.0103522995486856	54.5988006591797
0.423402088927105	23.0380744934082	50.8120002746582	0.00982529018074274	54.798900604248
0.425784441176802	23.1669178009033	51.1119995117188	0.00966901984065771	55.0988998413086
0.428524130256847	23.2435398101807	51.4119987487793	0.0114315003156662	55.3988990783691
0.430966028943658	23.287446975708	51.7120018005371	0.00987861957401037	55.6988983154297
0.433169712778181	23.3885173797607	52.0120010375977	0.0100116999819875	55.9989013671875
0.435909401858225	23.4626979827881	52.3120002746582	0.00978317018598318	56.298900604248
0.438589544501156	23.5062503814697	52.6119995117188	0.00963004026561975	56.5988006591797
0.440793199231848	23.6142597198486	52.9119987487793	0.00976330041885376	56.8987998962402
0.443532888311893	23.6965408325195	53.2120018005371	0.00978447031229734	57.1987991333008
0.446093908976763	23.7289562225342	53.5120010375977	0.00995013024657965	57.4987983703613
0.448535836767405	23.8583812713623	53.8120002746582	0.00993193034082651	57.8987998962402
0.450858613476157	23.9072666168213	54.1119995117188	0.00989248044788837	58.0988006591797
0.453598302556202	23.9505367279053	54.4119987487793	0.0100210001692176	58.3987998962402
0.455861532827839	24.0250911712646	54.7120018005371	0.00998955965042114	58.6987991333008
0.458005641121417	24.0874671936035	55.0120010375977	0.0100678997114301	59.0988006591797
0.46110269613564	24.1683197021484	55.3120002746582	0.00999798998236656	59.298698425293
0.463544594822451	24.2914066314697	55.6119995117188	0.0100589003413916	59.5987014770508
0.466046039946377	24.3285827636719	55.9119987487793	0.0100645003840327	59.8987998962402
0.468428392196074	24.3494853973389	56.2120018005371	0.00984155014157295	60.1986999511719
0.471168081276119	24.5014495849609	56.5120010375977	0.0106183001771569	60.4986991882324
0.473550433525816	24.54860496521	56.8120002746582	0.0100568998605013	60.7988014221191
0.475873210234568	24.5655612945557	57.1119995117188	0.010652500204742	61.0987014770508
0.478374684462324	24.667444229126	57.4119987487793	0.0100194998085499	61.3987007141113
0.48087615869008	24.7643222808838	57.7120018005371	0.0100899999961257	61.6986999511719
0.483496725792065	24.7622833251953	58.0120010375977	0.010644800029695	61.9986991882324
0.486057746456936	24.8686447143555	58.3120002746582	0.0109815001487732	62.298698425293
0.488440098706633	24.9690399169922	58.6119995117188	0.0114347999915481	62.5988006591797
0.491001119371504	24.9768028259277	58.9119987487793	0.010772000066936	62.8987007141113
0.49350259359926	25.0674304962158	59.2120018005371	0.0107364002615213	63.1986999511719
0.496123160701245	25.1945419311523	59.5120010375977	0.0109996004030108	63.4986000061035
0.498445937409997	25.1798648834229	59.8120002746582	0.0122744999825954	63.7985992431641
0.501245202030987	25.2867469787598	60.1119995117188	0.0116999996826053	64.0986022949219
0.503984862007201	25.4169864654541	60.4119987487793	0.0112167000770569	64.3985977172852
0.506248092278838	25.4029712677002	60.7120018005371	0.0117560001090169	64.7985992431641
0.508630473632365	25.4525756835938	61.0120010375977	0.0119326002895832	64.9985961914063
0.511012796778232	25.5630378723145	61.3120002746582	0.0118762999773026	65.2985992431641
0.513276027049869	25.5617980957031	61.6119995117188	0.0118281003087759	65.5986022949219
0.515598803758621	25.6161231994629	61.9119987487793	0.0119110001251101	65.9985961914063
0.518338521942496	25.7583255767822	62.2120018005371	0.0118984002619982	66.198600769043
0.520899542607367	25.7787780761719	62.5120010375977	0.0119660999625921	66.4984970092773
0.52298407536	25.7944412231445	62.8120002746582	0.0120253004133701	66.7985992431641
0.525902432855219	25.936990737915	63.1119995117188	0.012079699896276	67.1985015869141
0.528463453520089	25.9596042633057	63.4119987487793	0.0121184997260571	67.3984985351563
0.530845834873617	25.9913082122803	63.7120018005371	0.0120317004621029	67.6985015869141
0.533466401975602	26.1235675811768	64.0120010375977	0.0122571000829339	67.9985961914063
0.536086969077587	26.1737365722656	64.3119964599609	0.0122571000829339	68.3984985351563
0.538528896868229	26.1798496246338	64.6119995117188	0.0120861995965242	68.5986022949219
0.541030312888324	26.3087139129639	64.9120025634766	0.0122541999444366	68.8984985351563
0.543591333553195	26.3560028076172	65.2119979858398	0.0122905997559428	69.1985015869141
0.54621190065518	26.3870964050293	65.5120010375977	0.0121480999514461	69.4984970092773
0.548594282008708	26.4845905303955	65.8119964599609	0.0122894002124667	69.7985000610352
0.551333941984922	26.5465278625488	66.1119995117188	0.0122827002778649	70.098503112793
0.553597172256559	26.5397987365723	66.4120025634766	0.0122699998319149	70.3984985351563
0.555860402528197	26.634765625	66.7119979858398	0.0122779002413154	70.6985015869141
0.558361876755953	26.6910572052002	67.0120010375977	0.0123881995677948	70.9984970092773
0.560803804546595	26.6754856109619	67.3119964599609	0.0121251000091434	71.2985000610352
0.563126581255347	26.7728061676025	67.6119995117188	0.0123113999143243	71.5986022949219
0.565747148357332	26.8440952301025	67.9120025634766	0.0124821001663804	71.8984985351563
0.568189076147974	26.8451099395752	68.2119979858398	0.0123001001775265	72.1985015869141
0.570809643249959	26.9554386138916	68.5120010375977	0.0123519999906421	72.4984970092773
0.573311117477715	27.0247821807861	68.8119964599609	0.0124284001067281	72.7985000610352
0.57581253349781	27.0096454620361	69.1119995117188	0.0133386002853513	73.098503112793
0.578433158807456	27.1308631896973	69.4120025634766	0.013697300106287	73.3984985351563
0.580815481953323	27.1799011230469	69.7119979858398	0.0137878004461527	73.6984024047852
0.583733839448541	27.2173709869385	70.0120010375977	0.0136540997773409	73.9984970092773
0.586354406550527	27.3225040435791	70.3119964599609	0.0136868003755808	74.2985000610352
0.58855809038505	27.3790550231934	70.6119995117188	0.0138285998255014	74.5983963012695
0.591416901443154	27.3742237091064	70.9120025634766	0.013684400357306	74.8983993530273
0.59379922458902	27.4619579315186	71.2119979858398	0.0137831997126341	75.2984008789063
0.595943361986428	27.5004215240479	71.5120010375977	0.0138651002198458	75.4982986450195
0.59838528977707	27.5112476348877	71.8119964599609	0.0135995000600815	75.7984008789063
0.600946310441941	27.5913238525391	72.1119995117188	0.0138218002393842	76.0983963012695
0.603507331106812	27.6744766235352	72.4120025634766	0.0138617996126413	76.3983993530273
0.605949200689793	27.6552486419678	72.7119979858398	0.0150626003742218	76.6984024047852
0.608569767791778	27.7413139343262	73.0120010375977	0.0136374002322555	76.9983978271484
0.611071242019534	27.8252868652344	73.3119964599609	0.0139567004516721	77.2984008789063
0.613394018728286	27.833080291748	73.6119995117188	0.0144472997635603	77.5983963012695
0.616312376223505	27.9112186431885	73.9120025634766	0.0143930995836854	77.8983993530273
0.618694757577032	27.9814014434814	74.2119979858398	0.0138742001727223	78.1984024047852
0.621077080722898	27.9886341094971	74.5120010375977	0.0145453996956348	78.4983978271484
0.62351900851354	28.0272998809814	74.8119964599609	0.0151775004342198	78.7983016967773
0.625960878096521	28.1118850708008	75.1119995117188	0.0147275999188423	79.0982971191406
0.628283654805273	28.1098136901855	75.4120025634766	0.0146382004022598	79.3986968994141
0.630785129033029	28.1481781005859	75.7119979858398	0.0145482998341322	79.6984024047852
0.633405696135014	28.2625122070313	76.0120010375977	0.0166206005960703	79.9982986450195
0.635847623925656	28.2390174865723	76.3119964599609	0.0165100004523993	80.2984008789063
0.638229947071522	28.2605819702148	76.6119995117188	0.016500199213624	80.5983963012695
0.640671874862164	28.3673992156982	76.9120025634766	0.0151132997125387	80.8983001708984
0.643292441964149	28.3950634002686	77.2119979858398	0.0128269996494055	81.1983032226563
0.645734369754791	28.4066314697266	77.5120010375977	0.0152679998427629	81.5139999389648
0.648414483293891	28.5303707122803	77.8119964599609	0.0150491995736957	81.8049011230469
0.651094596832991	28.5563163757324	78.1119995117188	0.0149095999076962	82.1983032226563
0.653417431749403	28.5366401672363	78.4120025634766	0.0151497004553676	82.3983001708984
0.656157091725618	28.6793460845947	78.7119979858398	0.0150348003953695	82.6983032226563
0.658718112390488	28.6951007843018	79.0120010375977	0.0150496996939182	82.9982986450195
0.66104088909924	28.6748352050781	79.3119964599609	0.0150090996176004	83.2983016967773
0.663661514408886	28.8043174743652	79.6119995117188	0.01546819973737	83.5982971191406
0.666103383991867	28.8276119232178	79.9120025634766	0.0161435008049011	83.8983001708984
0.668485765345395	28.8133239746094	80.2119979858398	0.0162348002195358	84.1981964111328
0.671046786010265	28.9152927398682	80.5120010375977	0.0164537001401186	84.4982986450195
0.673726899549365	28.9583568572998	80.8119964599609	0.0165822003036737	84.7982025146484
0.676109222695231	28.9458923339844	81.1119995117188	0.0160674005746841	85.0981979370117
0.678491604048759	29.0278854370117	81.4120025634766	0.016711900010705	85.3982009887695
0.68093347363174	29.0553760528564	81.7119979858398	0.0165307000279427	85.6981964111328
0.68349449429661	29.0375995635986	82.0120010375977	0.0164340008050203	85.9981994628906
0.685995968524367	29.1535453796387	82.3119964599609	0.0165017005056143	86.2981033325195
0.688497442752123	29.2037830352783	82.6119995117188	0.0167330000549555	86.5981979370117
0.690939312335104	29.193244934082	82.9120025634766	0.0172886997461319	86.8982009887695
0.69344078656286	29.2840232849121	83.2119979858398	0.0167018994688988	87.1981964111328
0.695644470397383	29.3109092712402	83.5120010375977	0.016610199585557	87.4981002807617
0.698443735018373	29.3241653442383	83.8119964599609	0.0156682003289461	87.8982009887695
0.700945151038468	29.3854160308838	84.1119995117188	0.0169060006737709	88.0980987548828
0.703267985954881	29.4512634277344	84.4120025634766	0.0168613996356726	88.3981018066406
0.706007645931095	29.4402523040771	84.7119979858398	0.0174003001302481	88.6980972290039
0.708449573721737	29.5167388916016	85.0120010375977	0.0180121995508671	89.0980987548828
0.711010594386607	29.5922660827637	85.3119964599609	0.0190407000482082	89.2981033325195
0.713690707925707	29.6059379577637	85.6119995117188	0.0171140991151333	89.5981979370117
0.716192182153463	29.6645221710205	85.9120025634766	0.0174135006964207	89.8981018066406
0.718455412425101	29.72243309021	86.2119979858398	0.0169110000133514	90.1980972290039
0.721075979527086	29.734806060791	86.5120010375977	0.0174042992293835	90.4982986450195
0.723398756235838	29.7483577728271	86.8119964599609	0.0176248997449875	90.7981033325195
0.72584068402648	29.8343353271484	87.1119995117188	0.0173860993236303	91.0980987548828
0.728461251128465	29.8298397064209	87.4120025634766	0.0173528008162975	91.3981018066406
0.730843574274331	29.8442649841309	87.7119979858398	0.0175161007791758	91.6980972290039
0.733345048502088	29.9736499786377	88.0120010375977	0.0176325999200344	91.9981002807617
0.735786976292729	29.9530467987061	88.3119964599609	0.0175816006958485	92.3980026245117
0.738467089831829	29.9972076416016	88.6119995117188	0.0177123006433249	92.5979995727539
0.740789866540581	30.0759391784668	88.9120025634766	0.017671599984169	92.8981018066406
0.743231794331223	30.068868637085	89.2119979858398	0.017696799710393	93.197998046875
0.746090605389327	30.1208972930908	89.5120010375977	0.0173925999552011	93.4980010986328
0.748413382098079	30.204496383667	89.8119964599609	0.0199507996439934	93.7979965209961
0.750855309888721	30.1966323852539	90.1119995117188	0.0174187999218702	94.0980987548828
0.753654516302049	30.230541229248	90.4120025634766	0.0176309999078512	94.3980026245117
0.756155990529805	30.3333187103271	90.7119979858398	0.0171006005257368	94.697998046875
0.758478767238557	30.3492546081543	91.0120010375977	0.0177606008946896	94.9980010986328
0.761099334340543	30.3637924194336	91.3119964599609	0.0176813993602991	95.2979965209961
0.763660355005413	30.449914932251	91.6119995117188	0.0157782007008791	95.5979995727539
0.765983189921826	30.4451198577881	91.9120025634766	0.0178025998175144	95.8980026245117
0.768425059504807	30.4327697753906	92.2119979858398	0.0190591998398304	96.197998046875
0.771045626606792	30.5643272399902	92.5120010375977	0.0192629992961884	96.499397277832
0.77342800796032	30.5638847351074	92.8119964599609	0.0193150993436575	96.7979965209961
0.7758698775433	30.5568084716797	93.1119995117188	0.0192200001329184	97.097900390625
0.778550049290061	30.6508960723877	93.4120025634766	0.0192885994911194	97.3979034423828
0.780872825998813	30.694543838501	93.7119979858398	0.0193559993058443	97.697998046875
0.783493393100798	30.6888847351074	94.0120010375977	0.0192630998790264	98.0979995727539
0.786054413765669	30.7897701263428	94.3119964599609	0.0193499997258186	98.2981033325195
0.788674980867654	30.8333168029785	94.6119995117188	0.0194553006440401	98.5979995727539
0.791057362221181	30.7938175201416	94.9120025634766	0.0200175996869802	98.8979034423828
0.793558778241277	30.8785800933838	95.2119979858398	0.019403800368309	99.2978973388672
0.796119798906147	30.9437217712402	95.5120010375977	0.0194588992744684	99.4979019165039
0.798383029177785	30.8930110931396	95.8119964599609	0.0199140999466181	99.7977981567383
0.80100359627977	30.9680347442627	96.1119995117188	0.0191412009298801	100.097900390625
0.803505070507526	31.0543899536133	96.4120025634766	0.019564600661397	100.397903442383
0.805946998298168	30.9984741210938	96.7119979858398	0.0200248006731272	100.697898864746
0.808388867881149	31.0765190124512	97.0120010375977	0.0199250001460314	100.997901916504
0.81106903962791	31.1528663635254	97.3119964599609	0.0195268001407385	101.297897338867
0.813451362773776	31.1228122711182	97.6119995117188	0.0200217999517918	101.597999572754
0.815833744127303	31.1689376831055	97.9120025634766	0.020066799595952	101.897903442383
0.818513857666403	31.2633781433105	98.2119979858398	0.020228199660778	102.197799682617
0.820836634375155	31.2235374450684	98.5120010375977	0.0200676992535591	102.497901916504
0.823278562165797	31.2818202972412	98.8119964599609	0.0201265998184681	102.797798156738
0.825779978185892	31.3503723144531	99.1119995117188	0.0202127993106842	103.097801208496
0.828638789243996	31.3683815002441	99.4120025634766	0.0201843995600939	103.397796630859
0.831021170597523	31.3874225616455	99.7119979858398	0.020150700584054	103.797798156738
0.83352264482528	31.4948596954346	100.012001037598	0.0202753003686666	103.997802734375
0.836500548757613	31.4679527282715	100.311996459961	0.0202569998800755	104.297798156738
0.838585081510246	31.4963283538818	100.611999511719	0.0201216991990805	104.597801208496
0.840848311781883	31.5442924499512	100.912002563477	0.0203939005732536	104.997802734375
0.843528483528644	31.5671463012695	101.21199798584	0.0203022006899118	105.197799682617
0.846029899548739	31.5919227600098	101.512001037598	0.0203545000404119	105.497802734375
0.848352734465152	31.6719436645508	101.811996459961	0.0204722993075848	105.797798156738
0.851151940878481	31.6961479187012	102.111999511719	0.0204817000776529	106.097702026367
0.853712961543351	31.7032279968262	102.412002563477	0.0204805992543697	106.39769744873
0.856035796459764	31.7872619628906	102.71199798584	0.0205304995179176	106.697700500488
0.858715909998864	31.8151512145996	103.012001037598	0.0205627996474504	106.997802734375
0.86121738422662	31.7966232299805	103.311996459961	0.020439799875021	107.397796630859
0.863361463416368	31.8533782958984	103.611999511719	0.0207122005522251	107.597702026367
0.865743844769895	31.8516006469727	103.912002563477	0.0204818993806839	107.89769744873
0.868185714352876	31.8727722167969	104.21199798584	0.0208874996751547	108.197700500488
0.870627642143518	31.9453639984131	104.512001037598	0.0207316000014544	108.497703552246
0.872890872415155	31.9424457550049	104.811996459961	0.0219481997191906	108.797698974609
0.875690137036145	31.9673862457275	105.111999511719	0.0215907990932465	109.097702026367
0.878489343449473	32.0859451293945	105.412002563477	0.0216995999217033	109.39769744873
0.88110996875912	32.1098823547363	105.71199798584	0.021764799952507	109.797698974609
0.883909175172448	32.0997161865234	106.012001037598	0.0216252002865076	109.998001098633
0.886232010088861	32.1714172363281	106.311996459961	0.0219867993146181	110.297698974609
0.888733426108956	32.2310829162598	106.611999511719	0.021849500015378	110.597801208496
0.891056202817708	32.1917915344238	106.912002563477	0.0218147002160549	110.89769744873
0.893676828127354	32.2960052490234	107.21199798584	0.0218529999256134	111.197700500488
0.895880453754216	32.2979774475098	107.512001037598	0.0221365001052618	111.497703552246
0.898322381544858	32.281795501709	107.811996459961	0.0231298003345728	111.89769744873
0.901062099728733	32.367603302002	108.111999511719	0.0230956003069878	112.097602844238
0.9034444228746	32.4202995300293	108.412002563477	0.0233622994273901	112.397598266602
0.905767199583352	32.3628540039063	108.71199798584	0.0232864990830421	112.697601318359
0.90868555707857	32.4650382995605	109.012001037598	0.0235575009137392	113.097602844238
0.910948787350208	32.5163879394531	109.311996459961	0.023301899433136	113.29759979248
0.913331168703735	32.4660110473633	109.611999511719	0.0232261996716261	113.597702026367
0.91595173580572	32.546443939209	109.912002563477	0.0234505999833345	113.897598266602
0.918453210033476	32.6015090942383	110.21199798584	0.0234191007912159	114.197601318359
0.920835533179343	32.5594863891602	110.512001037598	0.0234626997262239	114.497703552246
0.923396553844213	32.6334915161133	110.811996459961	0.0234983991831541	114.797500610352
0.926076667383313	32.7002487182617	111.111999511719	0.0234383996576071	115.097503662109
0.928518595173955	32.6615829467773	111.412002563477	0.0234977994114161	115.397598266602
0.930543581489474	32.6676445007324	111.71199798584	0.0234850998967886	115.697601318359
0.933700182940811	32.8106689453125	112.012001037598	0.0237738005816936	115.997596740723
0.936022959649563	32.7551956176758	112.311996459961	0.0236086007207632	116.29759979248
0.9382861899212	32.8009414672852	112.611999511719	0.023607799783349	116.597503662109
0.940966361667961	32.8836135864258	112.912002563477	0.0237932000309229	116.897499084473
0.943467777688056	32.8541374206543	113.21199798584	0.0237192008644342	117.19750213623
0.945671461522579	32.8693580627441	113.512001037598	0.0234820991754532	117.497497558594
0.948470726143569	32.9727783203125	113.811996459961	0.023845300078392	117.797500610352
0.950972200371325	32.9471015930176	114.111999511719	0.0238090995699167	118.097503662109
0.953414069954306	32.9419860839844	114.412002563477	0.0236626006662846	118.397499084473
0.955915544182062	33.0378189086914	114.71199798584	0.0239247009158134	118.69750213623
0.958595657721162	33.0498466491699	115.012001037598	0.0238857008516788	118.997497558594
0.960978039074689	33.0396766662598	115.311996459961	0.0231695994734764	119.297500610352
0.963241269346327	33.0974044799805	115.611999511719	0.0238837990909815	119.597503662109
0.966100080404431	33.1321067810059	115.912002563477	0.0237607005983591	119.897499084473
0.968661101069301	33.1243209838867	116.21199798584	0.0250029005110264	120.19750213623
0.971102970652282	33.193920135498	116.512001037598	0.0239010993391275	120.497497558594
0.973961781710386	33.234302520752	116.811996459961	0.0238684993237257	120.797500610352
0.976105919107795	33.1895179748535	117.111999511719	0.0244867000728846	121.19750213623
0.97860733512789	33.2919998168945	117.412002563477	0.0246603991836309	121.397399902344
0.981168355792761	33.3200073242188	117.71199798584	0.0246954001486301	121.69750213623
0.983669888228178	33.2899589538574	118.012001037598	0.0246158000081778	121.997398376465
0.985754420980811	33.3407554626465	118.311996459961	0.024847099557519	122.297401428223
0.988255837000906	33.3658828735352	118.611999511719	0.0248489007353783	122.597396850586
0.990876462310553	33.3352928161621	118.912002563477	0.0246562995016575	122.897399902344
0.993199180811644	33.3943748474121	119.21199798584	0.0246897991746664	123.197402954102
0.995700713247061	33.457878112793	119.512001037598	0.0248034000396729	123.497398376465
0.998678617179394	33.4505767822266	119.811996459961	0.024719899520278	123.797302246094
1.00106094032526	33.5211448669434	120.111999511719	0.0247400999069214	124.097396850586
1.0033241705969	33.5325775146484	120.412002563477	0.0248905997723341	124.397300720215
1.00612349342555	33.5160255432129	120.71199798584	0.0249802991747856	124.697402954102
1.00862490944564	33.6038780212402	121.012001037598	0.0262972004711628	124.997299194336
1.01088813971728	33.6169509887695	121.311996459961	0.0263515003025532	125.297302246094
1.01350876502693	33.5795745849609	121.611999511719	0.0264478996396065	125.598503112793
1.01601018104702	33.6481399536133	121.912002563477	0.0263998992741108	125.997299194336
1.01839250419289	33.6799430847168	122.21199798584	0.0263652000576258	126.197303771973
1.02077482733876	33.6452827453613	122.512001037598	0.0265475995838642	126.497299194336
1.02369324304163	33.7137794494629	122.811996459961	0.0266232993453741	126.897300720215
1.02601596154273	33.7424392700195	123.111999511719	0.0265526007860899	127.097297668457
1.02845788933337	33.6983642578125	123.412002563477	0.0280744004994631	127.397300720215
1.03107851464301	33.7395553588867	123.71199798584	0.0253408998250961	127.697303771973
1.03352044243366	33.7963485717773	124.012001037598	0.0281681995838881	127.997299194336
1.03584316093475	33.7219924926758	124.311996459961	0.0264561008661985	128.297302246094
1.0386424837634	33.7706260681152	124.611999511719	0.0265252999961376	128.597503662109
1.04108429513872	33.7961502075195	124.912002563477	0.0269146002829075	128.89729309082
1.0432880371809	33.6835060119629	125.21199798584	0.0265095997601748	129.197296142578
1.04561075568199	-6.12699222564697	125.512001037598	0.0266260001808405	129.497192382813
1.04572996497154	-7.53895425796509	125.518997192383	0.0266260001808405	129.497192382813